Workbook

Sheet ★Master Code List
D1: * Maximum Code Capacity 100ea
B2: Don't Delete | D2: ↓ Key in New Code/Project/Item Below | I2: Formula - Don’t delete
B3: No | D3: Code | E3: Project | F3: Item | I3: Code | J3: Project | K3: Item
A4: =IF(E4="Components","2nd","1st") -> 2nd | B4: 1 | D4: BEE22-CT009 | E4: Components | F4: BEV_E_TML_1 | I4: {=_xlfn.SORTBY(D4:F167,A4:A167,1,D4:D167,1)} -> PZ38-10B694-AD | J4: PHEV-E (V710) / (P703) | K4: Main Harness
A5: =IF(E5="Components","2nd","1st") -> 2nd | B5: 2 | D5: BEE22-CT010 | E5: Components | F5: BEV_E_TML_2 | I5: PZ38-10B694-BD | J5: BEV-E1(V710) | K5: Main Harness
A6: =IF(E6="Components","2nd","1st") -> 2nd | B6: 3 | D6: BEE22-CT011 | E6: Components | F6: BEV_E_TML_3 | I6: PZ38-14A033-AB | J6: PHEV-E (V710) / (P703) | K6: BUSBAR - Array to Array (short)
A7: =IF(E7="Components","2nd","1st") -> 1st | B7: 4 | D7: PZ38-10B694-AD | E7: PHEV-E (V710) / (P703) | F7: Main Harness | I7: PZ38-14A033-BB | J7: PHEV-E (V710) / (P703) | K7: BUSBAR - Array to Array (long)
A8: =IF(E8="Components","2nd","1st") -> 1st | B8: 5 | D8: PZ38-14A033-AB | E8: PHEV-E (V710) / (P703) | F8: BUSBAR - Array to Array (short) | I8: PZ38-14A033-CB | J8: PHEV-E (V710) / (P703) | K8: BUSBAR - Array 3 to 4
A9: =IF(E9="Components","2nd","1st") -> 1st | B9: 6 | D9: PZ38-14A033-BB | E9: PHEV-E (V710) / (P703) | F9: BUSBAR - Array to Array (long) | I9: PZ38-14A033-FE | J9: EV-V4 Test Parts | K9: BUSBAR - Array to Array (Straight)_Insert
A10: =IF(E10="Components","2nd","1st") -> 1st | B10: 7 | D10: PZ38-14A033-CB | E10: PHEV-E (V710) / (P703) | F10: BUSBAR - Array 3 to 4 | I10: PZ38-14A033-GD | J10: BEV-E (V710) | K10: BUSBAR - Array to Array (Angled)_Insert
A11: =IF(E11="Components","2nd","1st") -> 1st | B11: 8 | D11: PZ38-14A033-HF | E11: BEV-E (V710) | F11: BUSBAR - Array4 to Array 5_Insert | I11: PZ38-14A033-HF | J11: BEV-E (V710) | K11: BUSBAR - Array4 to Array 5_Insert
A12: =IF(E12="Components","2nd","1st") -> 1st | B12: 9 | D12: PZ38-14A033-LF | E12: BEV-E (V710) | F12: BUSBAR - Array 9 to Pos BEC_Insert | I12: PZ38-14A033-JD | J12: BEV-E1 | K12: BEV-E1 BUSBAR Array 8 to Array 9
A13: =IF(E13="Components","2nd","1st") -> 1st | B13: 10 | D13: PZ38-14A033-MC | E13: BEV-E (V710) | F13: BUSBAR - Pos BEC to DCFC_Protector | I13: PZ38-14A033-KD | J13: BEV-E (V710) | K13: BUSBAR - Array 1 to Neg BEC_Insert
A14: =IF(E14="Components","2nd","1st") -> 1st | B14: 11 | D14: PZ38-14B252-AB | E14: PHEV-E (V710) / (P703) | F14: Jumper | I14: PZ38-14A033-LF | J14: BEV-E (V710) | K14: BUSBAR - Array 9 to Pos BEC_Insert
A15: =IF(E15="Components","2nd","1st") -> 1st | B15: 12 | D15: PZ38-14B680-AD | E15: BEV-E (V710) | F15: PDU | I15: PZ38-14A033-MC | J15: BEV-E (V710) | K15: BUSBAR - Pos BEC to DCFC_Protector
A16: =IF(E16="Components","2nd","1st") -> 1st | B16: 13 | D16: S2X8-14A033-AC | E16: BEV-M | F16: BUS BAR ASY – POS BEC TO ARRAY 6 POS | I16: PZ38-14A033-NB | J16: BEV-E (V710) | K16: BUSBAR - Neg BEC to DCFC_Protector
... A51: =IF(E51="Components","2nd","1st") -> 1st | B51: 48 | D51: PZ38-10B694-BD | E51: BEV-E1(V710) | F51: Main Harness | I51: TZ38-14A033-DA04 | J51: EV-V4 | K51: BUSBAR
A52: =IF(E52="","3rd",IF(E52="Components","2nd","1st")) -> 1st | B52: 49 | D52: PZ38-14A033-GD | E52: BEV-E (V710) | F52: BUSBAR - Array to Array (Angled)_Insert | I52: TZ38-14A033-EA | J52: EV-V4 | K52: BUSBAR ASY
A53: =IF(E53="","3rd",IF(E53="Components","2nd","1st")) -> 1st | B53: 50 | D53: PZ38-14A033-KD | E53: BEV-E (V710) | F53: BUSBAR - Array 1 to Neg BEC_Insert | I53: TZ38-14A033-EA04 | J53: EV-V4 | K53: BUSBAR
A54: =IF(E54="","3rd",IF(E54="Components","2nd","1st")) -> 1st | B54: 51 | D54: PZ38-14A033-NB | E54: BEV-E (V710) | F54: BUSBAR - Neg BEC to DCFC_Protector | I54: TZ38-14A033-FA | J54: BEV-E (AWD/RWD, V710) | K54: BUS BAR ASY
A55: =IF(E55="","3rd",IF(E55="Components","2nd","1st")) -> 1st | B55: 52 | D55: PZ38-14A033-PC | E55: BEV-E (V710) | F55: BUSBAR - CIRCUIT BREAKER_A_Insert | I55: TZ38-14A033-GA | J55: EV-V4 | K55: BUSBAR ASY
A56: =IF(E56="","3rd",IF(E56="Components","2nd","1st")) -> 1st | B56: 53 | D56: PZ38-14A033-RC | E56: BEV-E (V710) | F56: BUSBAR - CIRCUIT BREAKER_B_Insert | I56: TZ38-14A033-GA04 | J56: EV-V4 | K56: BUSBAR
A57: =IF(E57="","3rd",IF(E57="Components","2nd","1st")) -> 1st | B57: 54 | D57: SZ38-10B694-AC | E57: BEV-E2 (V710) | F57: Main Harness | I57: TZ38-14A033-HB | J57: BEV-E (AWD/RWD, V710) | K57: MCA CONNECTOR CLIP
A58: =IF(E58="","3rd",IF(E58="Components","2nd","1st")) -> 1st | B58: 55 | D58: SZ38-14A033-AB | E58: BEV-E2 (V710) | F58: BUSBAR - Array 2 to Array3_Insert | I58: TZ38-14A033-JA | J58: BEV-E (AWD, V710) | K58: BUS BAR ASY
A59: =IF(E59="","3rd",IF(E59="Components","2nd","1st")) -> 1st | B59: 56 | D59: SZ38-14A033-BB | E59: BEV-E2 (V710) | F59: BUSBAR - Array 6 to Pos BEC_Insert | I59: TZ38-14A033-JB | J59: BEV-E (AWD/RWD, V710) | K59: MCA CONNECTOR CLIP
A60: =IF(E60="","3rd",IF(E60="Components","2nd","1st")) -> 1st | B60: 57 | D60: TZ38-10B694-AA | E60: BEV-E1 | F60: V710 AWD MAIN W/H ASSY | I60: TZ38-14A033-KA | J60: EV-V4 | K60: MCA CONNECTOR CLIP
A61: =IF(E61="","3rd",IF(E61="Components","2nd","1st")) -> 1st | B61: 58 | D61: TZ38-10B694-AD | E61: BEV-E (AWD, V710) | F61: Main Harness | I61: TZ38-14A033-LA | J61: EV-V4 | K61: MCA CONNECTOR CLIP
A62: =IF(E62="","3rd",IF(E62="Components","2nd","1st")) -> 1st | B62: 59 | D62: TZ38-10B694-DB | E62: BEV-E (RWD, V710) | F62: Main Harness | I62: TZ38-14A033-MA | J62: EV-V4 | K62: MCA CONNECTOR CLIP
A63: =IF(E63="","3rd",IF(E63="Components","2nd","1st")) -> 1st | B63: 60 | D63: TZ38-14A033-JA | E63: BEV-E (AWD, V710) | F63: BUS BAR ASY | I63: TZ38-14A033-NA | J63: BEV-E (AWD/RWD, V710) | K63: BUSBAR ASY
... A66: =IF(E66="","3rd",IF(E66="Components","2nd","1st")) -> 1st | B66: 63 | D66: TZ38-14A033-TA04 | E66: EV-V4 | F66: BUSBAR | I66: TZ38-14A033-SA | J66: BEV-E (AWD/RWD, V710) | K66: BUSBAR ASY
A67: 2nd | B67: 64 | D67: TUBE0000101 | E67: EV-V4 Test Parts | F67: DBJ033 | I67: TZ38-14A033-TA | J67: EV-V4 | K67: BUSBAR ASY
A68: 2nd | B68: 65 | D68: TUBE0000104 | E68: EV-V4 Test Parts | F68: CG13-38 (5M) | I68: TZ38-14A033-TA04 | J68: EV-V4 | K68: BUSBAR
A69: 2nd | B69: 66 | D69: UKLA0-05011 | E69: EV-V4 Test Parts | F69: CG19-38 (08) (7M) | I69: TZ38-14B680-AA | J69: EV-V4 | K69: PDU_CONN_ASSY
A70: =IF(E70="","3rd",IF(E70="Components","2nd","1st")) -> 2nd | B70: 67 | D70: BEE25-CT001 | E70: Components | F70: Terminal | I70: TZ38-14B680-BA | J70: BEV-E (AWD, V710) | K70: PDU
A71: =IF(E71="","3rd",IF(E71="Components","2nd","1st")) -> 2nd | B71: 68 | D71: BEE22-CP007 | E71: Components | F71: CHANNEL | I71: TZ38-14B680-BB | J71: BEV-E (AWD/RWD, V710) | K71: AWD/RWD PDU CONN ASSY
A72: =IF(E72="","3rd",IF(E72="Components","2nd","1st")) -> 2nd | B72: 69 | D72: BEE24-CP001 | E72: Components | F72: CHANNEL | I72: BEE22-CP007 | J72: Components | K72: CHANNEL
A73: =IF(E73="","3rd",IF(E73="Components","2nd","1st")) -> 2nd | B73: 70 | D73: BEE24-CP002 | E73: Components | F73: CHANNEL | I73: BEE22-CT009 | J73: Components | K73: BEV_E_TML_1
A74: =IF(E74="","3rd",IF(E74="Components","2nd","1st")) -> 2nd | B74: 71 | D74: BEE24-CP003 | E74: Components | F74: CHANNEL | I74: BEE22-CT010 | J74: Components | K74: BEV_E_TML_2
A75: =IF(E75="","3rd",IF(E75="Components","2nd","1st")) -> 1st | B75: 72 | D75: PZ38-14A033-JD | E75: BEV-E1 | F75: BEV-E1 BUSBAR Array 8 to Array 9 | I75: BEE22-CT011 | J75: Components | K75: BEV_E_TML_3
A76: =IF(E76="","3rd",IF(E76="Components","2nd","1st")) -> 1st | B76: 73 | D76: TZ38-14A033-AA04 | E76: EV-V4 | F76: BUSBAR | I76: BEE24-CP001 | J76: Components | K76: CHANNEL
...

Sheet 2026 List
F1: Management Master List | H1: 2026 MAF
A2: Catergory | B2: Code | C2: Project Code | D2: Project Name | E2: Item | F2: Project | G2: Item | H2: Project Name | I2: Item
A3: List of received items | B3: BEE22-CT009 | C3: V769 | D3: Yazaki (BEV-M) | E3: BEV_E_TML_1 | F3: Components | G3: BEV-E1/BEV_E_TML_1 | H3: Components (BEV-M) | I3: BEV_E_TML_1
A4: List of received items | B4: BEE22-CT010 | C4: V769 | D4: Yazaki (BEV-M) | E4: BEV_E_TML_2 | F4: Components | G4: BEV-E1/BEV_E_TML_2 | H4: Components (BEV-M) | I4: BEV_E_TML_2
A5: List of received items | B5: BEE22-CT011 | C5: V769 | D5: Yazaki (BEV-M) | E5: BEV_E_TML_3 | F5: Components | G5: BEV-E1/BEV_E_TML_3 | H5: Components (BEV-M) | I5: BEV_E_TML_3
A6: List of received items | B6: PZ38-10B694-AD | C6: V710 / P703 | D6: PHEV-E | E6: Main Harness | F6: FORD PHEV-E(V710) / (P703) | G6: Main Harness | H6: PHEV-E (V710) / (P703) | I6: Main Harness
A7: List of received items | B7: PZ38-14A033-AB | C7: V710 / P703 | D7: PHEV-E | E7: BUSBAR - Array to Array (short) | F7: FORD PHEV-E(V710) / (P703) | G7: BUSBAR - Array to Array (short) | H7: PHEV-E (V710) / (P703) | I7: BUSBAR - Array to Array (short)
A8: List of received items | B8: PZ38-14A033-BB | C8: V710 / P703 | D8: PHEV-E | E8: BUSBAR - Array to Array (long) | F8: FORD PHEV-E(V710) / (P703) | G8: BUSBAR - Array to Array (long) | H8: PHEV-E (V710) / (P703) | I8: BUSBAR - Array to Array (long)
A9: List of received items | B9: PZ38-14A033-CB | C9: V710 / P703 | D9: PHEV-E | E9: BUSBAR - Array 3 to 4 | F9: FORD PHEV-E(V710) / (P703) | G9: BUSBAR - Array 3 to 4 | H9: PHEV-E (V710) / (P703) | I9: BUSBAR - Array 3 to 4
A10: List of received items | B10: PZ38-14A033-HF | C10: V710 | D10: BEV | E10: BUSBAR - Array4 to Array 5_Insert | F10: BEV-E1(V710) | G10: BUSBAR - Array4 to Array 5_Insert | H10: BEV-E (V710) | I10: BUSBAR - Array4 to Array 5_Insert
A11: List of received items | B11: PZ38-14A033-LF | C11: V710 | D11: BEV | E11: BUSBAR - Array 9 to Pos BEC_Insert | F11: BEV-E1(V710) | G11: BUSBAR - Array 9 to Pos BEC_Insert | H11: BEV-E (V710) | I11: BUSBAR - Array 9 to Pos BEC_Insert
A12: List of received items | B12: PZ38-14A033-MC | C12: V710 | D12: BEV | E12: BUSBAR - Pos BEC to DCFC_Protector | F12: BEV-E1(V710) / E2(V710) | G12: BUSBAR - Pos BEC to DCFC_Protector | H12: BEV-E (V710) | I12: BUSBAR - Pos BEC to DCFC_Protector
A13: List of received items | B13: PZ38-14B252-AB | C13: V710 / P703 | D13: PHEV-E | E13: Jumper | F13: FORD PHEV-E(V710) / (P703) | G13: Jumper | H13: PHEV-E (V710) / (P703) | I13: Jumper
... A46: List of received items | B46: TZ38-14A033-SA | C46: V710 | D46: BEV AWD/RWD | E46: BUSBAR ASY | F46: V710 AWD | G46: BUS BAR ASY | H46: BEV-E (AWD/RWD, V710) | I46: BUSBAR ASY
A47: List of received items | B47: TZ38-14A033-TA | C47: V710 | D47: EV-V4 | E47: BUSBAR ASY | F47: #N/A | G47: #N/A | H47: EV-V4 | I47: BUSBAR ASY
A48: List of received items | B48: TZ38-14B680-AA | C48: V710 | D48: EV-V4 | E48: PDU_CONN_ASSY | F48: BEV-E1 | G48: PDU_CONN_ASSY | H48: EV-V4 | I48: PDU_CONN_ASSY
A49: List of received items | B49: TZ38-14B680-BB | C49: V710 | D49: BEV AWD/RWD | E49: AWD/RWD PDU CONN ASSY | F49: BEV-E1 | G49: V710 BEV-E1 AWD/RWD PDU CONN ASSY | H49: BEV-E (AWD/RWD, V710) | I49: AWD/RWD PDU CONN ASSY
A50: MAF Inventory | B50: PZ38-10B694-BD | E50: Main Harness | F50: BEV-E1(V710) | G50: Main Harness | H50: BEV-E1(V710) | I50: Main Harness
A51: MAF Inventory | B51: PZ38-14A033-GD | E51: BUSBAR - Array to Array (Angled)_Insert | F51: BEV-E1(V710) / E2(V710) | G51: BUSBAR - Array to Array (Angled)_Insert | H51: BEV-E (V710) | I51: BUSBAR - Array to Array (Angled)_Insert
A52: MAF Inventory | B52: PZ38-14A033-KD | E52: BUSBAR - Array 1 to Neg BEC_Insert | F52: BEV-E1(V710) / E2(V710) | G52: BUSBAR - Array 1 to Neg BEC_Insert | H52: BEV-E (V710) | I52: BUSBAR - Array 1 to Neg BEC_Insert
A53: MAF Inventory | B53: PZ38-14A033-NB | E53: BUSBAR - Neg BEC to DCFC_Protector | F53: BEV-E1(V710) | G53: BUSBAR - Neg BEC to DCFC_Protector | H53: BEV-E (V710) | I53: BUSBAR - Neg BEC to DCFC_Protector
A54: MAF Inventory | B54: PZ38-14A033-PC | E54: BUSBAR - CIRCUIT BREAKER_A_Insert | F54: BEV-E1(V710) / E2(V710) | G54: BUSBAR - CIRCUIT BREAKER_A_Insert | H54: BEV-E (V710) | I54: BUSBAR - CIRCUIT BREAKER_A_Insert
A55: MAF Inventory | B55: PZ38-14A033-RC | E55: BUSBAR - CIRCUIT BREAKER_B_Insert | F55: BEV-E1(V710) / E2(V710) | G55: BUSBAR - CIRCUIT BREAKER_B_Insert | H55: BEV-E (V710) | I55: BUSBAR - CIRCUIT BREAKER_B_Insert
A56: MAF Inventory | B56: SZ38-10B694-AC | E56: Main Harness | F56: BEV-E2(V710) | G56: Main Harness | H56: BEV-E2 (V710) | I56: Main Harness
A57: MAF Inventory | B57: SZ38-14A033-AB | E57: BUSBAR - Array 2 to Array3_Insert | F57: BEV-E2(V710) | G57: BUSBAR - Array 2 to Array3_Insert | H57: BEV-E2 (V710) | I57: BUSBAR - Array 2 to Array3_Insert
A58: MAF Inventory | B58: SZ38-14A033-BB | E58: BUSBAR - Array 6 to Pos BEC_Insert | F58: BEV-E2(V710) | G58: BUSBAR - Array 6 to Pos BEC_Insert | H58: BEV-E2 (V710) | I58: BUSBAR - Array 6 to Pos BEC_Insert
A59: MAF Inventory | B59: TZ38-10B694-AA | E59: V710 AWD MAIN W/H ASSY | F59: BEV-E1 | G59: V710 AWD MAIN W/H ASSY | H59: BEV-E1 | I59: V710 AWD MAIN W/H ASSY
A60: MAF Inventory | B60: TZ38-10B694-AD | E60: Main Harness | F60: V710 AWD | G60: Main Harness | H60: BEV-E (AWD, V710) | I60: Main Harness
A61: MAF Inventory | B61: TZ38-10B694-DB | E61: Main Harness | F61: V710 RWD | G61: Main Harness | H61: BEV-E (RWD, V710) | I61: Main Harness
... A64: MAF Inventory | B64: PZ38-14A033-FE | E64: BUSBAR - Array to Array (Straight)_Insert | F64: EV-V4 Test Parts | G64: BUSBAR - Array to Array (Straight)_Insert | H64: EV-V4 Test Parts | I64: BUSBAR - Array to Array (Straight)_Insert
A65: Inventory Report | B65: TUBE0000093 | F65: =_xlfn.XLOOKUP(B65,'★Master Code List'!$D:$D,'★Master Code List'!$E:$E,) -> #N/A | G65: =_xlfn.XLOOKUP(B65,'★Master Code List'!$D$4:$D$160,'★Master Code List'!$F$4:$F$160,) -> #N/A | H65: EV-V4 Test Parts | I65: CG01-38 (5M)
A66: Inventory Report | B66: TUBE0000101 | F66: =_xlfn.XLOOKUP(B66,'★Master Code List'!$D:$D,'★Master Code List'!$E:$E,) -> EV-V4 Test Parts | G66: =_xlfn.XLOOKUP(B66,'★Master Code List'!$D$4:$D$160,'★Master Code List'!$F$4:$F$160,) -> DBJ033 | H66: EV-V4 Test Parts | I66: DBJ033
A67: Inventory Report | B67: TUBE0000104 | F67: =_xlfn.XLOOKUP(B67,'★Master Code List'!$D:$D,'★Master Code List'!$E:$E,) -> EV-V4 Test Parts | G67: =_xlfn.XLOOKUP(B67,'★Master Code List'!$D$4:$D$160,'★Master Code List'!$F$4:$F$160,) -> CG13-38 (5M) | H67: EV-V4 Test Parts | I67: CG13-38 (5M)
A68: Inventory Report | B68: UKLA0-05011 | F68: =_xlfn.XLOOKUP(B68,'★Master Code List'!$D:$D,'★Master Code List'!$E:$E,) -> EV-V4 Test Parts | G68: =_xlfn.XLOOKUP(B68,'★Master Code List'!$D$4:$D$160,'★Master Code List'!$F$4:$F$160,) -> CG19-38 (08) (7M) | H68: EV-V4 Test Parts | I68: CG19-38 (08) (7M)
H74: `

Sheet 2026 Plan PL (New)
F1: 0.76682497 | G1: 0.76611273 | H1: 0.76564981 | I1: 0.76475524 | J1: 0.76203145 | K1: 0.76557737 | L1: 0.7644828 | M1: 0.76573661 | N1: 0.76567589 | O1: 0.83251355 | P1: 0.85948776 | Q1: 0.85913698
B2: Profit and Loss statement FY 2026 | Q2: (Affiliate Company: Kyungshin cable Türkiye)
B4: 구분 | D4: FY | E4: 12 | F4: 1 | G4: 2 | H4: 3 | I4: 4 | J4: 5 | K4: 6 | L4: 7 | M4: 8 | N4: 9 | O4: 10 | P4: 11 | Q4: 12
B5: Ⅰ. 매출액 | C5: Ⅰ. SALES | D5: 1.8562269e+09 | F5: 93531068 | G5: 1.1672241e+08 | H5: 1.6614614e+08 | I5: 1.385977e+08 | J5: 1.2682473e+08 | K5: 1.9324117e+08 | L5: 1.1829519e+08 | M5: 1.7613515e+08 | N5: 1.5905064e+08 | O5: 2.3366351e+08 | P5: 1.6558768e+08 | Q5: 1.6843153e+08
B6: 1.상품매출 | C6: 1. Merchandise | D6: 1.8546969e+09 | F6: 93531068 | G6: 1.1672241e+08 | H6: 1.6614614e+08 | I6: 1.385977e+08 | J6: 1.2682473e+08 | K6: 1.9324117e+08 | L6: 1.1829519e+08 | M6: 1.7613515e+08 | N6: 1.5905064e+08 | O6: 2.3366351e+08 | P6: 1.6558768e+08 | Q6: 1.6690153e+08
C7: FORD PHEV-E (V710) | D7: 3.0822942e+08 | F7: 21737517 | G7: 23596647 | H7: 28172967 | I7: 20593438 | J7: 17018188 | K7: 35466476 | L7: 19592368 | M7: 31891226 | N7: 31176176 | O7: 24254493 | P7: 26571255 | Q7: 28158666
C8: FORD PHEV-E (P703) | D8: 1.6412277e+08 | F8: 11440799 | G8: 10236504 | H8: 12645093 | I8: 12645093 | J8: 13849388 | K8: 18666566 | L8: 13247241 | M8: 13548314 | N8: 14105300 | O8: 14346159 | P8: 14632179 | Q8: 14760136
C9: BEV-E RWD | D9: 6.1849335e+08 | F9: 39254495 | G9: 40331839 | H9: 77686291 | I9: 65698392 | J9: 52476443 | K9: 83131775 | L9: 50556812 | M9: 79958508 | N9: 66619031 | O9: 62779769 | P9: 0 | Q9: 0
C10: BEV-E AWD | D10: 1.4457127e+08 | F10: 1339959 | G10: 11503033 | H10: 20202459 | I10: 16141352 | J10: 12121475 | K10: 20697213 | L10: 11379344 | M10: 19377868 | N10: 15790901 | O10: 16017664 | P10: 0 | Q10: 0
C11: FORD BEV-M | D11: 3.1895775e+08 | F11: 18887593 | G11: 28331389 | H11: 26423506 | I11: 22648720 | J11: 30198293 | K11: 33973080 | L11: 22648720 | M11: 30198293 | N11: 30198293 | O11: 20066661 | P11: 27884925 | Q11: 27498272
C12: EV-V4 | D12: 2.8052389e+08 | F12: 0 | G12: 1378803.9 | H12: 0 | I12: 0 | J12: 0 | K12: 0 | L12: 0 | M12: 0 | N12: 0 | O12: 93048362 | P12: 93048362 | Q12: 93048362
C13: Components | D13: 19798467 | F13: 870704.64 | G13: 1344193.2 | H13: 1015822.1 | I13: 870704.64 | J13: 1160939.5 | K13: 1306057 | L13: 870704.64 | M13: 1160939.5 | N13: 1160939.5 | O13: 3150399.2 | P13: 3450963.6 | Q13: 3436099.1
B15: 2. 기타 매출 | C15: 2. Other sales | D15: 1530000 | F15: 0 | G15: 0 | H15: 0 | I15: 0 | J15: 0 | K15: 0 | L15: 0 | M15: 0 | N15: 0 | O15: 0 | P15: 0 | Q15: 1530000
B16: └ scrap | C16: └ Scrap | D16: 0
B17: └ Test Parts | C17: └ Test Parts | D17: 0
B18: └ 기타 | C18: └ Other | D18: 1530000 | Q18: 1530000 | U18: 30000 | V18: BEV-H RESIDENCE Q.C Contract
B19: └ 기타(투자비) | C19: └ Investment | D19: 0
C20: *(Deductions)
C21: *(Returns)
B23: Ⅱ. 매출원가 | C23: Ⅱ. COST OF SALES | D23: 1.466262e+09 | F23: 71721958 | G23: 89422523 | H23: 1.2720976e+08 | I23: 1.0599332e+08 | J23: 96644431 | K23: 1.4794106e+08 | L23: 90434637 | M23: 1.3487313e+08 | N23: 1.2178124e+08 | O23: 1.9452804e+08 | P23: 1.4232059e+08 | Q23: 1.4339128e+08
C24: % | D24: =IFERROR(D23/D$5,) -> 0.78991526 | F24: =IFERROR(F23/F$5,) -> 0.76682497 | G24: =IFERROR(G23/G$5,) -> 0.76611273 | H24: =IFERROR(H23/H$5,) -> 0.76564981 | I24: =IFERROR(I23/I$5,) -> 0.76475524 | J24: =IFERROR(J23/J$5,) -> 0.76203145 | K24: =IFERROR(K23/K$5,) -> 0.76557737 | L24: =IFERROR(L23/L$5,) -> 0.7644828 | M24: =IFERROR(M23/M$5,) -> 0.76573661 | ... Q24: =IFERROR(Q23/Q$5,) -> 0.85133274
B25: 상품매출원가 | C25: Cost of merchandise sold | D25: 1.466262e+09 | F25: 71721958 | G25: 89422523 | H25: 1.2720976e+08 | I25: 1.0599332e+08 | J25: 96644431 | K25: 1.4794106e+08 | L25: 90434637 | M25: 1.3487313e+08 | N25: 1.2178124e+08 | O25: 1.9452804e+08 | P25: 1.4232059e+08 | Q25: 1.4339128e+08
C26: % | D26: =IFERROR(D25/D$6,) -> 0.79056689 | F26: =IFERROR(F25/F$6,) -> 0.76682497 | G26: =IFERROR(G25/G$6,) -> 0.76611273 | H26: =IFERROR(H25/H$6,) -> 0.76564981 | I26: =IFERROR(I25/I$6,) -> 0.76475524 | J26: =IFERROR(J25/J$6,) -> 0.76203145 | K26: =IFERROR(K25/K$6,) -> 0.76557737 | L26: =IFERROR(L25/L$6,) -> 0.7644828 | M26: =IFERROR(M25/M$6,) -> 0.76573661 | ... Q26: =IFERROR(Q25/Q$6,) -> 0.85913698
B27: 1.기초 상품재고 | C27: 1. Beginning Merchandise | D27: 0
B28: 2.당기 상품매입원가 | C28: 2. Cost of Merchandise | D28: 1.466262e+09 | F28: 71721958 | G28: 89422523 | H28: 1.2720976e+08 | I28: 1.0599332e+08 | J28: 96644431 | K28: 1.4794106e+08 | L28: 90434637 | M28: 1.3487313e+08 | N28: 1.2178124e+08 | O28: 1.9452804e+08 | P28: 1.4232059e+08 | Q28: 1.4339128e+08
B29: 3.타계정전입 (+) | C29: 3. Transferred from other accounts | D29: 0
B30: 4.타계정대체 (-) | C30: 4. Transferred to other accounts | D30: 0
B31: 5.기말 상품재고 | C31: 5. Ending Merchandise | D31: 0
B32: 기타매출원가 | C32: Cost of other sold | D32: 0 | F32: 0 | G32: 0 | H32: 0 | I32: 0 | J32: 0 | K32: 0 | L32: 0 | M32: 0 | N32: 0 | O32: 0 | P32: 0 | Q32: 0
B33: 원재료 매출원가 | C33: Raw material | D33: 0
B34: 반제품 매출원가 | C34: Halb | D34: 0
B35: 기타 | C35: Other | D35: 0
B36: 기타(투자비) | C36: Investment | D36: 0
B37: Ⅲ. 매출총이익 | C37: Ⅲ. GROSS PROFIT (or GROSS LOSS) | D37: 3.8996495e+08 | F37: 21809110 | G37: 27299886 | H37: 38936379 | I37: 32604383 | J37: 30180296 | K37: 45300103 | L37: 27860551 | M37: 41262017 | N37: 37269400 | O37: 39135470 | P37: 23267097 | Q37: 25040255
B38: (이익률) | C38: (Rate) | D38: 0.21008474 | F38: 0.23317503 | G38: 0.23388727 | H38: 0.23435019 | I38: 0.23524476 | J38: 0.23796855 | K38: 0.23442263 | L38: 0.2355172 | M38: 0.23426339 | N38: 0.23432411 | O38: 0.16748645 | P38: 0.14051224 | Q38: 0.14866726
B39: Ⅳ.판매관리비 | C39: SELLING AND MARKETING EXPENSES | D39: =SUM(D40:D46) -> 32457954 | E39: 0 | F39: =SUM(F40:F46) -> 1864869.9 | G39: =SUM(G40:G46) -> 2111319.2 | H39: =SUM(H40:H46) -> 2624130.2 | I39: =SUM(I40:I46) -> 2295347.5 | J39: =SUM(J40:J46) -> 4211534.9 | K39: =SUM(K40:K46) -> 2905578.6 | L39: =SUM(L40:L46) -> 2097975.2 | M39: =SUM(M40:M46) -> 2807689.8 | ... Q39: =SUM(Q40:Q46) -> 2745091.2
C40: Export Expenses | D40: =SUM(F40:Q40) -> 1628307.2 | F40: 95782.779 | G40: 95782.779 | H40: 95782.779 | I40: 95782.779 | J40: 95782.779 | K40: 95782.779 | L40: 95782.779 | M40: 191565.56 | N40: 191565.56 | O40: 191565.56 | P40: 191565.56 | Q40: 191565.56
C41: Import Expenses | D41: =SUM(F41:Q41) -> 334367.46 | F41: 20897.966 | G41: 20897.966 | H41: 20897.966 | I41: 20897.966 | J41: 20897.966 | K41: 20897.966 | L41: 20897.966 | M41: 20897.966 | N41: 41795.933 | O41: 41795.933 | P41: 41795.933 | Q41: 41795.933
C42: Domestic Transportation Expenses | D42: =SUM(F42:Q42) -> 6658033.8 | F42: 554836.15 | G42: 554836.15 | H42: 554836.15 | I42: 554836.15 | J42: 554836.15 | K42: 554836.15 | L42: 554836.15 | M42: 554836.15 | N42: 554836.15 | O42: 554836.15 | P42: 554836.15 | Q42: 554836.15
C43: Sample Expenses | D43: =SUM(F43:Q43) -> 496289.82 | F43: 41357.485 | G43: 41357.485 | H43: 41357.485 | I43: 41357.485 | J43: 41357.485 | K43: 41357.485 | L43: 41357.485 | M43: 41357.485 | N43: 41357.485 | O43: 41357.485 | P43: 41357.485 | Q43: 41357.485
...

Sheet ★PL(Report)
B3: Profit and Loss statement FY 2026 | N3: (Affiliate Company: Kyungshin cable Türkiye)
B4: MONTH | C4: 2 | N4: (UNIT:TRY)
B5: 구분 | C5: ITEM | D5: Accumulated Plan | E5: Accumulated Actual | F5: Actual /Plan | G5: Prior month Actual | H5: costs /sales | I5: Month plan | J5: costs /sales | K5: Month Actual | L5: costs /sales | M5: Current /Prior | N5: Actual /Plan
B6: Ⅰ. 매출액 | C6: Ⅰ. SALES | D6: =SUM(D7,D16) -> 2.1025348e+08 | E6: =+E7+E16 -> 1.3952397e+08 | F6: =+IFERROR(E6/D6,) -> 0.66359887 | G6: =SUM(G7,G16) -> 75810248 | H6: =+IFERROR(G6/$G$6,) -> 1 | I6: =SUM(I7,I16) -> 1.1672241e+08 | J6: =+IFERROR(I6/$I$6,) -> 1 | K6: =SUM(K7,K16) -> 63713722 | L6: =+IFERROR(K6/$K$6,) -> 1 | M6: =+IFERROR(K6/G6,) -> 0.8404368 | N6: =+IFERROR(K6/I6,) -> 0.54585681
B7: 1. 상품 매출 | C7: 1 Merchandise | D7: =SUM(D8:D15) -> 2.1025348e+08 | E7: =SUM(E8:E15) -> 1.3269795e+08 | F7: =+IFERROR(E7/D7,) -> 0.6311332 | G7: =SUM(G8:G15) -> 68982368 | H7: =+IFERROR(G7/$G$6,) -> 0.9099346 | I7: =SUM(I8:I15) -> 1.1672241e+08 | J7: =+IFERROR(I7/$I$6,) -> 1 | K7: =SUM(K8:K15) -> 63715583 | L7: =+IFERROR(K7/$K$6,) -> 1.0000292 | M7: =+IFERROR(K7/G7,) -> 0.92365028 | N7: =+IFERROR(K7/I7,) -> 0.54587275
C8: FORD PHEV-E (V710) | D8: =IF($C$4=0,0,SUM('2026 Plan PL (New)'!$F7:OFFSET('2026 Plan PL (New)'!$F7,0,$C$4-1))) -> 45334165 | E8: =IF($C$4=0,0,SUM(PL!$F7:OFFSET(PL!$F7,0,$C$4-1))) -> 45828053 | F8: =+IFERROR(E8/D8,) -> 1.0108944 | G8: =OFFSET(PL!F7,0,$C$4-2) -> 23920697 | H8: =+IFERROR(G8/$G$6,) -> 0.31553382 | I8: =OFFSET('2026 Plan PL (New)'!F7,0,$C$4-1) -> 23596647 | J8: =+IFERROR(I8/$I$6,) -> 0.20216038 | K8: =OFFSET(PL!F7,0,$C$4-1) -> 21907356 | L8: =+IFERROR(K8/$K$6,) -> 0.34384047 | M8: =+IFERROR(K8/G8,) -> 0.9158327 | N8: =+IFERROR(K8/I8,) -> 0.92840971
C9: FORD PHEV-E (P703) | D9: =IF($C$4=0,0,SUM('2026 Plan PL (New)'!$F8:OFFSET('2026 Plan PL (New)'!$F8,0,$C$4-1))) -> 21677303 | E9: =IF($C$4=0,0,SUM(PL!$F8:OFFSET(PL!$F8,0,$C$4-1))) -> 25162751 | F9: =+IFERROR(E9/D9,) -> 1.1607879 | G9: =OFFSET(PL!F8,0,$C$4-2) -> 12070960 | H9: =+IFERROR(G9/$G$6,) -> 0.15922597 | I9: =OFFSET('2026 Plan PL (New)'!F8,0,$C$4-1) -> 10236504 | J9: =+IFERROR(I9/$I$6,) -> 0.087699561 | K9: =OFFSET(PL!F8,0,$C$4-1) -> 13091791 | L9: =+IFERROR(K9/$K$6,) -> 0.20547835 | M9: =+IFERROR(K9/G9,) -> 1.0845691 | N9: =+IFERROR(K9/I9,) -> 1.2789318
C10: BEV-E RWD | D10: =IF($C$4=0,0,SUM('2026 Plan PL (New)'!$F9:OFFSET('2026 Plan PL (New)'!$F9,0,$C$4-1))) -> 79586334 | E10: =IF($C$4=0,0,SUM(PL!$F9:OFFSET(PL!$F9,0,$C$4-1))) -> 1747054.9 | F10: =+IFERROR(E10/D10,) -> 0.021951695 | G10: =OFFSET(PL!F9,0,$C$4-2) -> 371310.73 | H10: =+IFERROR(G10/$G$6,) -> 0.0048978963 | I10: =OFFSET('2026 Plan PL (New)'!F9,0,$C$4-1) -> 40331839 | J10: =+IFERROR(I10/$I$6,) -> 0.34553638 | K10: =OFFSET(PL!F9,0,$C$4-1) -> 1375744.2 | L10: =+IFERROR(K10/$K$6,) -> 0.021592588 | M10: =+IFERROR(K10/G10,) -> 3.7051021 | N10: =+IFERROR(K10/I10,) -> 0.034110624
C11: BEV-E AWD | D11: =IF($C$4=0,0,SUM('2026 Plan PL (New)'!$F10:OFFSET('2026 Plan PL (New)'!$F10,0,$C$4-1))) -> 12842992 | E11: =IF($C$4=0,0,SUM(PL!$F10:OFFSET(PL!$F10,0,$C$4-1))) -> 350302.84 | F11: =+IFERROR(E11/D11,) -> 0.027275798 | G11: =OFFSET(PL!F10,0,$C$4-2) -> 240833.21 | H11: =+IFERROR(G11/$G$6,) -> 0.0031767896 | I11: =OFFSET('2026 Plan PL (New)'!F10,0,$C$4-1) -> 11503033 | J11: =+IFERROR(I11/$I$6,) -> 0.098550335 | K11: =OFFSET(PL!F10,0,$C$4-1) -> 109469.63 | L11: =+IFERROR(K11/$K$6,) -> 0.0017181485 | M11: =+IFERROR(K11/G11,) -> 0.45454543 | N11: =+IFERROR(K11/I11,) -> 0.0095165891
C12: FORD BEV-M | D12: =IF($C$4=0,0,SUM('2026 Plan PL (New)'!$F11:OFFSET('2026 Plan PL (New)'!$F11,0,$C$4-1))) -> 47218982 | E12: =IF($C$4=0,0,SUM(PL!$F12:OFFSET(PL!$F12,0,$C$4-1))) -> 35440595 | F12: =+IFERROR(E12/D12,) -> 0.7505582 | G12: =OFFSET(PL!F12,0,$C$4-2) -> 15721984 | H12: =+IFERROR(G12/$G$6,) -> 0.20738599 | I12: =OFFSET('2026 Plan PL (New)'!F11,0,$C$4-1) -> 28331389 | J12: =+IFERROR(I12/$I$6,) -> 0.24272451 | K12: =OFFSET(PL!F12,0,$C$4-1) -> 19718611 | L12: =+IFERROR(K12/$K$6,) -> 0.30948766 | M12: =+IFERROR(K12/G12,) -> 1.2542063 | N12: =+IFERROR(K12/I12,) -> 0.69599873
C13: EV-V4 | D13: =IF($C$4=0,0,SUM('2026 Plan PL (New)'!$F12:OFFSET('2026 Plan PL (New)'!$F12,0,$C$4-1))) -> 1378803.9 | E13: =IF($C$4=0,0,SUM(PL!$F13:OFFSET(PL!$F13,0,$C$4-1))) -> 74025.583 | F13: =+IFERROR(E13/D13,) -> 0.053688262 | G13: =OFFSET(PL!F13,0,$C$4-2) -> 67848.567 | H13: =+IFERROR(G13/$G$6,) -> 0.00089497883 | I13: =OFFSET('2026 Plan PL (New)'!F12,0,$C$4-1) -> 1378803.9 | J13: =+IFERROR(I13/$I$6,) -> 0.011812675 | K13: =OFFSET(PL!F13,0,$C$4-1) -> 6177.0163 | L13: =+IFERROR(K13/$K$6,) -> 9.6949544e-05 | M13: =+IFERROR(K13/G13,) -> 0.091041221 | N13: =+IFERROR(K13/I13,) -> 0.0044799819
C14: Components | D14: =IF($C$4=0,0,SUM('2026 Plan PL (New)'!$F13:OFFSET('2026 Plan PL (New)'!$F13,0,$C$4-1))) -> 2214897.8 | E14: =IF($C$4=0,0,SUM(PL!$F14:OFFSET(PL!$F14,0,$C$4-1))) -> 1628059.3 | F14: =+IFERROR(E14/D14,) -> 0.73504941 | G14: =OFFSET(PL!F14,0,$C$4-2) -> 932361.78 | H14: =+IFERROR(G14/$G$6,) -> 0.012298625 | I14: =OFFSET('2026 Plan PL (New)'!F13,0,$C$4-1) -> 1344193.2 | J14: =+IFERROR(I14/$I$6,) -> 0.011516153 | K14: =OFFSET(PL!F14,0,$C$4-1) -> 695697.55 | L14: =+IFERROR(K14/$K$6,) -> 0.010919116 | M14: =+IFERROR(K14/G14,) -> 0.74616696 | N14: =+IFERROR(K14/I14,) -> 0.51755772
C15: BEV-E1 | D15: 0 | E15: =IF($C$4=0,0,SUM(PL!$F15:OFFSET(PL!$F15,0,$C$4-1))) -> 22467110 | G15: =OFFSET(PL!F15,0,$C$4-2) -> 15656373 | H15: =+IFERROR(G15/$G$6,) -> 0.20652054 | I15: =OFFSET('2026 Plan PL (New)'!F14,0,$C$4-1) -> 0 | J15: =+IFERROR(I15/$I$6,) -> 0 | K15: =OFFSET(PL!F15,0,$C$4-1) -> 6810736.6 | L15: =+IFERROR(K15/$K$6,) -> 0.10689591 | M15: =+IFERROR(K15/G15,) -> 0.43501369 | N15: =+IFERROR(K15/I15,) -> 0
B16: 2. 기타 매출 | C16: 2. Other sales | D16: =SUM(D17:D22) -> 0 | E16: =SUM(E17:E20) -> 6826019.2 | F16: =+IFERROR(E16/D16,) -> 0 | G16: =SUM(G17:G20) -> 6827880.1 | H16: =+IFERROR(G16/$G$6,) -> 0.090065397 | I16: =SUM(I17:I20) -> 0 | J16: =+IFERROR(I16/$I$6,) -> 0 | K16: =SUM(K17:K20) -> -1860.8359 | L16: =+IFERROR(K16/$K$6,) -> -2.9206203e-05 | M16: =+IFERROR(K16/G16,) -> -0.00027253494 | N16: =+IFERROR(K16/I16,) -> 0
B17: └ scrap | C17: └ Scrap | D17: =IF($C$4=0,0,SUM('2026 Plan PL (New)'!$F16:OFFSET('2026 Plan PL (New)'!$F16,0,$C$4-1))) -> 0 | E17: =IF($C$4=0,0,SUM(PL!$F18:OFFSET(PL!$F18,0,$C$4-1))) -> 0 | F17: =+IFERROR(E17/D17,) -> 0 | G17: =OFFSET(PL!F18,0,$C$4-2) -> 0 | H17: =+IFERROR(G17/$G$6,) -> 0 | I17: =OFFSET('2026 Plan PL (New)'!F16,0,$C$4-1) -> 0 | J17: =+IFERROR(I17/$I$6,) -> 0 | K17: =OFFSET(PL!F18,0,$C$4-1) -> 0 | L17: =+IFERROR(K17/$K$6,) -> 0 | M17: =+IFERROR(K17/G17,) -> 0 | N17: =+IFERROR(K17/I17,) -> 0
B18: └ Test Parts | C18: └ Test Parts | D18: =IF($C$4=0,0,SUM('2026 Plan PL (New)'!$F17:OFFSET('2026 Plan PL (New)'!$F17,0,$C$4-1))) -> 0 | E18: =IF($C$4=0,0,SUM(PL!$F19:OFFSET(PL!$F19,0,$C$4-1))) -> 0 | F18: =+IFERROR(E18/D18,) -> 0 | G18: =OFFSET(PL!F19,0,$C$4-2) -> 0 | H18: =+IFERROR(G18/$G$6,) -> 0 | I18: =OFFSET('2026 Plan PL (New)'!F17,0,$C$4-1) -> 0 | J18: =+IFERROR(I18/$I$6,) -> 0 | K18: =OFFSET(PL!F19,0,$C$4-1) -> 0 | L18: =+IFERROR(K18/$K$6,) -> 0 | M18: =+IFERROR(K18/G18,) -> 0 | N18: =+IFERROR(K18/I18,) -> 0
B19: └ 기타 | C19: └ Other | D19: =IF($C$4=0,0,SUM('2026 Plan PL (New)'!$F18:OFFSET('2026 Plan PL (New)'!$F18,0,$C$4-1))) -> 0 | E19: =IF($C$4=0,0,SUM(PL!$F20:OFFSET(PL!$F20,0,$C$4-1))) -> 6826019.2 | F19: =+IFERROR(E19/D19,) -> 0 | G19: =OFFSET(PL!F20,0,$C$4-2) -> 6827880.1 | H19: =+IFERROR(G19/$G$6,) -> 0.090065397 | I19: =OFFSET('2026 Plan PL (New)'!F18,0,$C$4-1) -> 0 | J19: =+IFERROR(I19/$I$6,) -> 0 | K19: =OFFSET(PL!F20,0,$C$4-1) -> -1860.8359 | L19: =+IFERROR(K19/$K$6,) -> -2.9206203e-05 | M19: =+IFERROR(K19/G19,) -> -0.00027253494 | N19: =+IFERROR(K19/I19,) -> 0
B20: └ 기타(투자비) | C20: └ Investment | D20: =IF($C$4=0,0,SUM('2026 Plan PL (New)'!$F19:OFFSET('2026 Plan PL (New)'!$F19,0,$C$4-1))) -> 0 | E20: =IF($C$4=0,0,SUM(PL!$F21:OFFSET(PL!$F21,0,$C$4-1))) -> 0 | F20: =+IFERROR(E20/D20,) -> 0 | G20: =OFFSET(PL!F21,0,$C$4-2) -> 0 | H20: =+IFERROR(G20/$G$6,) -> 0 | I20: =OFFSET('2026 Plan PL (New)'!F19,0,$C$4-1) -> 0 | J20: =+IFERROR(I20/$I$6,) -> 0 | K20: =OFFSET(PL!F21,0,$C$4-1) -> 0 | L20: =+IFERROR(K20/$K$6,) -> 0 | M20: =+IFERROR(K20/G20,) -> 0 | N20: =+IFERROR(K20/I20,) -> 0
C21: *(Deductions) | D21: =IF($C$4=0,0,SUM('2026 Plan PL (New)'!$F20:OFFSET('2026 Plan PL (New)'!$F20,0,$C$4-1))) -> 0 | E21: =IF($C$4=0,0,SUM(PL!$F22:OFFSET(PL!$F22,0,$C$4-1))) -> 0 | F21: =+IFERROR(E21/D21,) -> 0 | G21: =OFFSET(PL!F22,0,$C$4-2) -> 0 | H21: =+IFERROR(G21/$G$6,) -> 0 | I21: =OFFSET('2026 Plan PL (New)'!F20,0,$C$4-1) -> 0 | J21: =+IFERROR(I21/$I$6,) -> 0 | K21: =OFFSET(PL!F22,0,$C$4-1) -> 0 | L21: =+IFERROR(K21/$K$6,) -> 0 | M21: =+IFERROR(K21/G21,) -> 0 | N21: =+IFERROR(K21/I21,) -> 0
C22: *(Returns) | D22: =IF($C$4=0,0,SUM('2026 Plan PL (New)'!$F21:OFFSET('2026 Plan PL (New)'!$F21,0,$C$4-1))) -> 0 | E22: =IF($C$4=0,0,SUM(PL!$F23:OFFSET(PL!$F23,0,$C$4-1))) -> -2259709.7 | F22: =+IFERROR(E22/D22,) -> 0 | G22: =OFFSET(PL!F23,0,$C$4-2) -> -2257848.9 | H22: =+IFERROR(G22/$G$6,) -> -0.029782898 | I22: =OFFSET('2026 Plan PL (New)'!F21,0,$C$4-1) -> 0 | J22: =+IFERROR(I22/$I$6,) -> 0 | K22: =OFFSET(PL!F23,0,$C$4-1) -> -1860.8359 | L22: =+IFERROR(K22/$K$6,) -> -2.9206203e-05 | M22: =+IFERROR(K22/G22,) -> 0.00082416318 | N22: =+IFERROR(K22/I22,) -> 0
B24: Ⅱ. 매출원가 | C24: Ⅱ. COST OF SALES | D24: =+SUM(D26,D33) -> 1.6114448e+08 | E24: =+SUM(E26,E33) -> 1.7824785e+08 | F24: =+IFERROR(E24/D24,) -> 1.1061368 | G24: =+SUM(G26,G33) -> 72379542 | H24: =+IFERROR(G24/$G$6,) -> 0.95474615 | I24: =+SUM(I26,I33) -> 89422523 | J24: =+IFERROR(I24/$I$6,) -> 0.76611273 | K24: =+SUM(K26,K33) -> 1.0586831e+08 | L24: =+IFERROR(K24/$K$6,) -> 1.6616249 | M24: =+IFERROR(K24/G24,) -> 1.4626828 | N24: =+IFERROR(K24/I24,) -> 1.183911
B26: 상품매출원가 | C26: Cost of merchandise sold | D26: =D28+D29+D30-D31-D32 -> 1.6114448e+08 | E26: =E28+E29+E30-E31-E32 -> 1.7820411e+08 | F26: =+IFERROR(E26/D26,) -> 1.1058654 | G26: =G28+G29+G30-G31-G32 -> 72365419 | H26: =+IFERROR(G26/$G$6,) -> 0.95455985 | I26: =I28+I29+I30-I31-I32 -> 89422523 | J26: =+IFERROR(I26/$I$6,) -> 0.76611273 | K26: =K28+K29+K30-K31-K32 -> 1.0583869e+08 | L26: =+IFERROR(K26/$K$6,) -> 1.66116 | M26: =+IFERROR(K26/G26,) -> 1.4625589 | N26: =+IFERROR(K26/I26,) -> 1.1835797
B28: 1.기초 상품재고 | C28: 1. Beginning Merchandise | D28: =IF($C$4=0,0,SUM('2026 Plan PL (New)'!$F27:OFFSET('2026 Plan PL (New)'!$F27,0,$C$4-1))) -> 0 | E28: =IF($C$4=0,0,SUM(PL!$F29:OFFSET(PL!$F29,0,$C$4-1))) -> 33327888 | F28: =+IFERROR(E28/D28,) -> 0 | G28: =OFFSET(PL!F29,0,$C$4-2) -> 25971576 | H28: =+IFERROR(G28/$G$6,) -> 0.34258661 | I28: =OFFSET('2026 Plan PL (New)'!F27,0,$C$4-1) -> 0 | J28: =+IFERROR(I28/$I$6,) -> 0 | K28: =OFFSET(PL!F29,0,$C$4-1) -> 7356311.9 | L28: =+IFERROR(K28/$K$6,) -> 0.11545883 | M28: =+IFERROR(K28/G28,) -> 0.28324472 | N28: =+IFERROR(K28/I28,) -> 0
B29: 2.당기 상품매입원가 | C29: 2. Cost of Merchandise | D29: =IF($C$4=0,0,SUM('2026 Plan PL (New)'!$F28:OFFSET('2026 Plan PL (New)'!$F28,0,$C$4-1))) -> 1.6114448e+08 | E29: =IF($C$4=0,0,SUM(PL!$F30:OFFSET(PL!$F30,0,$C$4-1))) -> 1.6363327e+08 | F29: =+IFERROR(E29/D29,) -> 1.0154445 | G29: =OFFSET(PL!F30,0,$C$4-2) -> 53750154 | H29: =+IFERROR(G29/$G$6,) -> 0.70900909 | I29: =OFFSET('2026 Plan PL (New)'!F28,0,$C$4-1) -> 89422523 | J29: =+IFERROR(I29/$I$6,) -> 0.76611273 | K29: =OFFSET(PL!F30,0,$C$4-1) -> 1.0988312e+08 | L29: =+IFERROR(K29/$K$6,) -> 1.7246382 | M29: =+IFERROR(K29/G29,) -> 2.0443312 | N29: =+IFERROR(K29/I29,) -> 1.2288081
B30: 3.타계정전입 (+) | C30: 3. Transferred from other accounts | D30: =IF($C$4=0,0,SUM('2026 Plan PL (New)'!$F29:OFFSET('2026 Plan PL (New)'!$F29,0,$C$4-1))) -> 0 | E30: =IF($C$4=0,0,SUM(PL!$F31:OFFSET(PL!$F31,0,$C$4-1))) -> 0 | F30: =+IFERROR(E30/D30,) -> 0 | G30: =OFFSET(PL!F31,0,$C$4-2) -> 0 | H30: =+IFERROR(G30/$G$6,) -> 0 | I30: =OFFSET('2026 Plan PL (New)'!F29,0,$C$4-1) -> 0 | J30: =+IFERROR(I30/$I$6,) -> 0 | K30: =OFFSET(PL!F31,0,$C$4-1) -> 0 | L30: =+IFERROR(K30/$K$6,) -> 0 | M30: =+IFERROR(K30/G30,) -> 0 | N30: =+IFERROR(K30/I30,) -> 0
B31: 4.타계정대체 (-) | C31: 4. Transferred to other accounts | D31: =IF($C$4=0,0,SUM('2026 Plan PL (New)'!$F30:OFFSET('2026 Plan PL (New)'!$F30,0,$C$4-1))) -> 0 | E31: =IF($C$4=0,0,SUM(PL!$F32:OFFSET(PL!$F32,0,$C$4-1))) -> 0 | F31: =+IFERROR(E31/D31,) -> 0 | G31: =OFFSET(PL!F32,0,$C$4-2) -> 0 | H31: =+IFERROR(G31/$G$6,) -> 0 | I31: =OFFSET('2026 Plan PL (New)'!F30,0,$C$4-1) -> 0 | J31: =+IFERROR(I31/$I$6,) -> 0 | K31: =OFFSET(PL!F32,0,$C$4-1) -> 0 | L31: =+IFERROR(K31/$K$6,) -> 0 | M31: =+IFERROR(K31/G31,) -> 0 | N31: =+IFERROR(K31/I31,) -> 0
B32: 5.기말 상품재고 | C32: 5. Ending Merchandise | D32: =IF($C$4=0,0,SUM('2026 Plan PL (New)'!$F31:OFFSET('2026 Plan PL (New)'!$F31,0,$C$4-1))) -> 0 | E32: =IF($C$4=0,0,SUM(PL!$F33:OFFSET(PL!$F33,0,$C$4-1))) -> 18757054 | F32: =+IFERROR(E32/D32,) -> 0 | G32: =OFFSET(PL!F33,0,$C$4-2) -> 7356311.9 | H32: =+IFERROR(G32/$G$6,) -> 0.097035851 | I32: =OFFSET('2026 Plan PL (New)'!F31,0,$C$4-1) -> 0 | J32: =+IFERROR(I32/$I$6,) -> 0 | K32: =OFFSET(PL!F33,0,$C$4-1) -> 11400742 | L32: =+IFERROR(K32/$K$6,) -> 0.178937 | M32: =+IFERROR(K32/G32,) -> 1.5497905 | N32: =+IFERROR(K32/I32,) -> 0
B33: 기타매출원가 | C33: Cost of other sold | D33: =+D34+D35+D36 -> 0 | E33: =+E34+E35+E36 -> 43743.03 | F33: =+IFERROR(E33/D33,) -> 0 | G33: =+G34+G35+G36 -> 14123.12 | H33: =++IFERROR(G33/G16,) -> 0.0020684488 | I33: =+I34+I35+I36 -> 0 | J33: =++IFERROR(I33/I16,) -> 0 | K33: =+K34+K35+K36 -> 29619.91 | L33: =++IFERROR(K33/K16,) -> -15.917529 | M33: =+IFERROR(K33/G33,) -> 2.0972639 | N33: =+IFERROR(K33/I33,) -> 0
B34: 원재료 매출원가 | C34: Raw material | D34: =IF($C$4=0,0,SUM('2026 Plan PL (New)'!$F33:OFFSET('2026 Plan PL (New)'!$F33,0,$C$4-1))) -> 0 | E34: =IF($C$4=0,0,SUM(PL!$F35:OFFSET(PL!$F35,0,$C$4-1))) -> 0 | F34: =+IFERROR(E34/D34,) -> 0 | G34: =OFFSET(PL!F35,0,$C$4-2) -> 0 | H34: =+IFERROR(G34/$G$6,) -> 0 | I34: =OFFSET('2026 Plan PL (New)'!F33,0,$C$4-1) -> 0 | J34: =+IFERROR(I34/$I$6,) -> 0 | K34: =OFFSET(PL!F35,0,$C$4-1) -> 0 | L34: =+IFERROR(K34/$K$6,) -> 0 | M34: =+IFERROR(K34/G34,) -> 0 | N34: =+IFERROR(K34/I34,) -> 0
B35: 반제품 매출원가 | C35: Halb | D35: =IF($C$4=0,0,SUM('2026 Plan PL (New)'!$F34:OFFSET('2026 Plan PL (New)'!$F34,0,$C$4-1))) -> 0 | E35: =IF($C$4=0,0,SUM(PL!$F36:OFFSET(PL!$F36,0,$C$4-1))) -> 0 | F35: =+IFERROR(E35/D35,) -> 0 | G35: =OFFSET(PL!F36,0,$C$4-2) -> 0 | H35: =+IFERROR(G35/$G$6,) -> 0 | I35: =OFFSET('2026 Plan PL (New)'!F34,0,$C$4-1) -> 0 | J35: =+IFERROR(I35/$I$6,) -> 0 | K35: =OFFSET(PL!F36,0,$C$4-1) -> 0 | L35: =+IFERROR(K35/$K$6,) -> 0 | M35: =+IFERROR(K35/G35,) -> 0 | N35: =+IFERROR(K35/I35,) -> 0
B36: 기타 | C36: Other | D36: =IF($C$4=0,0,SUM('2026 Plan PL (New)'!$F35:OFFSET('2026 Plan PL (New)'!$F35,0,$C$4-1))) -> 0 | E36: =IF($C$4=0,0,SUM(PL!$F37:OFFSET(PL!$F37,0,$C$4-1))) -> 43743.03 | F36: =+IFERROR(E36/D36,) -> 0 | G36: =OFFSET(PL!F37,0,$C$4-2) -> 14123.12 | H36: =+IFERROR(G36/$G$6,) -> 0.00018629566 | I36: =OFFSET('2026 Plan PL (New)'!F35,0,$C$4-1) -> 0 | J36: =+IFERROR(I36/$I$6,) -> 0 | K36: =OFFSET(PL!F37,0,$C$4-1) -> 29619.91 | L36: =+IFERROR(K36/$K$6,) -> 0.00046489059 | M36: =+IFERROR(K36/G36,) -> 2.0972639 | N36: =+IFERROR(K36/I36,) -> 0
B37: 기타(투자비) | C37: Investment | D37: =IF($C$4=0,0,SUM('2026 Plan PL (New)'!$F36:OFFSET('2026 Plan PL (New)'!$F36,0,$C$4-1))) -> 0 | E37: =IF($C$4=0,0,SUM(PL!$F38:OFFSET(PL!$F38,0,$C$4-1))) -> 0 | F37: =+IFERROR(E37/D37,) -> 0 | G37: =OFFSET(PL!F38,0,$C$4-2) -> 0 | H37: =+IFERROR(G37/$G$6,) -> 0 | I37: =OFFSET('2026 Plan PL (New)'!F36,0,$C$4-1) -> 0 | J37: =+IFERROR(I37/$I$6,) -> 0 | K37: =OFFSET(PL!F38,0,$C$4-1) -> 0 | L37: =+IFERROR(K37/$K$6,) -> 0 | M37: =+IFERROR(K37/G37,) -> 0 | N37: =+IFERROR(K37/I37,) -> 0
B38: Ⅲ. 매출총이익 | C38: Ⅲ. GROSS PROFIT (or GROSS LOSS) | D38: =+D6-D24 -> 49108995 | E38: =+E6-E24 -> -38723879 | F38: =+IFERROR(E38/D38,) -> -0.78852925 | G38: =+G6-G24 -> 3430705.9 | H38: =+IFERROR(G38/$G$6,) -> 0.045253855 | I38: =+I6-I24 -> 27299886 | J38: =+IFERROR(I38/$I$6,) -> 0.23388727 | K38: =+K6-K24 -> -42154585 | L38: =+IFERROR(K38/$K$6,) -> -0.6616249 | M38: =+IFERROR(K38/G38,) -> -12.287438 | N38: =+IFERROR(K38/I38,) -> -1.5441305
B39: (이익률) | C39: (Rate) | D39: =IFERROR(D38/D6,) -> 0.23357043 | E39: =IFERROR(E38/E6,) -> -0.27754284 | G39: =IFERROR(G38/G6,) -> 0.045253855 | I39: =IFERROR(I38/I6,) -> 0.23388727 | K39: =IFERROR(K38/K6,) -> -0.6616249
B40: Ⅳ.판매관리비 | C40: SELLING AND MARKETING EXPENSES | D40: =SUM(D41:D47) -> 3976189.2 | E40: =SUM(E41:E47) -> 3732292.6 | F40: =+IFERROR(E40/D40,) -> 0.93866074 | G40: =SUM(G41:G47) -> 1545174.3 | H40: =+IFERROR(G40/$G$6,) -> 0.02038213 | I40: =SUM(I41:I47) -> 2111319.2 | K40: =SUM(K41:K47) -> 2187118.3 | L40: =+IFERROR(K40/$K$6,) -> 0.034327273 | M40: =+IFERROR(K40/G40,) -> 1.4154509
C41: Export Expenses | D41: =IF($C$4=0,0,SUM('2026 Plan PL (New)'!$F40:OFFSET('2026 Plan PL (New)'!$F40,0,$C$4-1))) -> 191565.56 | E41: =IF($C$4=0,0,SUM(PL!$F42:OFFSET(PL!$F42,0,$C$4-1))) -> 136263.82 | F41: =+IFERROR(E41/D41,) -> 0.71131691 | G41: =OFFSET(PL!F42,0,$C$4-2) -> 74012.66 | H41: =+IFERROR(G41/$G$6,) -> 0.00097628833 | I41: =OFFSET('2026 Plan PL (New)'!F40,0,$C$4-1) -> 95782.779 | J41: =+IFERROR(I41/$I$6,) -> 0.00082060317 | K41: =OFFSET(PL!F42,0,$C$4-1) -> 62251.16 | L41: =+IFERROR(K41/$K$6,) -> 0.00097704479 | M41: =+IFERROR(K41/G41,) -> 0.841088 | N41: =+IFERROR(K41/I41,) -> 0.64992017
C42: Import Expenses | D42: =IF($C$4=0,0,SUM('2026 Plan PL (New)'!$F41:OFFSET('2026 Plan PL (New)'!$F41,0,$C$4-1))) -> 41795.933 | E42: =IF($C$4=0,0,SUM(PL!$F43:OFFSET(PL!$F43,0,$C$4-1))) -> 0 | F42: =+IFERROR(E42/D42,) -> 0 | G42: =OFFSET(PL!F43,0,$C$4-2) -> 0 | H42: =+IFERROR(G42/$G$6,) -> 0 | I42: =OFFSET('2026 Plan PL (New)'!F41,0,$C$4-1) -> 20897.966 | J42: =+IFERROR(I42/$I$6,) -> 0.00017903988 | K42: =OFFSET(PL!F43,0,$C$4-1) -> 0 | L42: =+IFERROR(K42/$K$6,) -> 0 | M42: =+IFERROR(K42/G42,) -> 0 | N42: =+IFERROR(K42/I42,) -> 0
C43: Domestic Transportation Expenses | D43: =IF($C$4=0,0,SUM('2026 Plan PL (New)'!$F42:OFFSET('2026 Plan PL (New)'!$F42,0,$C$4-1))) -> 1109672.3 | E43: =IF($C$4=0,0,SUM(PL!$F44:OFFSET(PL!$F44,0,$C$4-1))) -> 2297201 | F43: =+IFERROR(E43/D43,) -> 2.0701616 | G43: =OFFSET(PL!F44,0,$C$4-2) -> 865151 | H43: =+IFERROR(G43/$G$6,) -> 0.011412059 | I43: =OFFSET('2026 Plan PL (New)'!F42,0,$C$4-1) -> 554836.15 | J43: =+IFERROR(I43/$I$6,) -> 0.0047534673 | K43: =OFFSET(PL!F44,0,$C$4-1) -> 1432050 | L43: =+IFERROR(K43/$K$6,) -> 0.02247632 | M43: =+IFERROR(K43/G43,) -> 1.6552602 | N43: =+IFERROR(K43/I43,) -> 2.5810323
C44: Sample Expenses | D44: =IF($C$4=0,0,SUM('2026 Plan PL (New)'!$F43:OFFSET('2026 Plan PL (New)'!$F43,0,$C$4-1))) -> 82714.97 | E44: =IF($C$4=0,0,SUM(PL!$F45:OFFSET(PL!$F45,0,$C$4-1))) -> 159863.27 | F44: =+IFERROR(E44/D44,) -> 1.9327006 | G44: =OFFSET(PL!F45,0,$C$4-2) -> 0 | H44: =+IFERROR(G44/$G$6,) -> 0 | I44: =OFFSET('2026 Plan PL (New)'!F43,0,$C$4-1) -> 41357.485 | J44: =+IFERROR(I44/$I$6,) -> 0.00035432344 | K44: =OFFSET(PL!F45,0,$C$4-1) -> 159863.27 | L44: =+IFERROR(K44/$K$6,) -> 0.002509087 | M44: =+IFERROR(K44/G44,) -> 0 | N44: =+IFERROR(K44/I44,) -> 3.8654011
C45: Rework & Sorting Expenses | D45: =IF($C$4=0,0,SUM('2026 Plan PL (New)'!$F44:OFFSET('2026 Plan PL (New)'!$F44,0,$C$4-1))) -> 2102534.8 | E45: =IF($C$4=0,0,SUM(PL!$F46:OFFSET(PL!$F46,0,$C$4-1))) -> 100468.19 | F45: =+IFERROR(E45/D45,) -> 0.047784318 | G45: =OFFSET(PL!F46,0,$C$4-2) -> 100468.19 | H45: =+IFERROR(G45/$G$6,) -> 0.0013252587 | I45: =OFFSET('2026 Plan PL (New)'!F44,0,$C$4-1) -> 1167224.1 | J45: =+IFERROR(I45/$I$6,) -> 0.01 | K45: =OFFSET(PL!F46,0,$C$4-1) -> 0 | L45: =+IFERROR(K45/$K$6,) -> 0 | M45: =+IFERROR(K45/G45,) -> 0 | N45: =+IFERROR(K45/I45,) -> 0
...

Sheet PL
F1: =+F27/F6 -> 1.0371105 | G1: =+G27/G6 -> 1.5927174 | H1: =+H27/H6 -> #DIV/0! | I1: =+I27/I6 -> #DIV/0! | J1: =+J27/J6 -> #DIV/0! | K1: =+K27/K6 -> #DIV/0! | L1: =+L27/L6 -> #DIV/0! | M1: =+M27/M6 -> #DIV/0! | ... Q1: =+Q27/Q6 -> #DIV/0!
B2: Profit and Loss statement FY 2026 | M2: (UNIT:TRY) | Q2: (Affiliate Company: Kyungshin cable Türkiye)
B3: MONTH | C3: 12 | F3: =IF(F4>$C$3,0,F4) -> 1 | G3: =IF(G4>$C$3,0,G4) -> 2 | H3: =IF(H4>$C$3,0,H4) -> 3 | I3: =IF(I4>$C$3,0,I4) -> 4 | J3: =IF(J4>$C$3,0,J4) -> 5 | K3: =IF(K4>$C$3,0,K4) -> 6 | L3: =IF(L4>$C$3,0,L4) -> 7 | M3: =IF(M4>$C$3,0,M4) -> 8 | ... Q3: =IF(Q4>$C$3,0,Q4) -> 12
B4: 구분 | D4: FY | E4: 12 | F4: 1 | G4: 2 | H4: =+G4+1 -> 3 | I4: =+H4+1 -> 4 | J4: =+I4+1 -> 5 | K4: =+J4+1 -> 6 | L4: =+K4+1 -> 7 | M4: =+L4+1 -> 8 | N4: =+M4+1 -> 9 | O4: =+N4+1 -> 10 | ... Q4: =+P4+1 -> 12
B5: Ⅰ. 매출액 | C5: Ⅰ. SALES | D5: =SUM(F5:Q5) -> 1.4305366e+08 | F5: =+F6+F17 -> 76603878 | G5: =+G6+G17 -> 66449780 | H5: =+H6+H17 -> 0 | I5: =+I6+I17 -> 0 | J5: =+J6+J17 -> 0 | K5: =+K6+K17 -> 0 | L5: =+L6+L17 -> 0 | M5: =+M6+M17 -> 0 | ... Q5: =+Q6+Q17 -> 0
B6: 1.상품매출 | C6: 1. Merchandise | D6: =SUM(F6:Q6) -> 1.3622764e+08 | F6: =SUM(F7:F15) -> 69775998 | G6: =SUM(G7:G15) -> 66451641 | H6: =SUM(H7:H15) -> 0 | I6: =SUM(I7:I15) -> 0 | J6: =SUM(J7:J15) -> 0 | K6: =SUM(K7:K15) -> 0 | L6: =SUM(L7:L15) -> 0 | M6: =SUM(M7:M15) -> 0 | ... Q6: =SUM(Q7:Q15) -> 0
C7: FORD PHEV-E (V710) | D7: =SUM(F7:Q7) -> 45828053 | F7: =SUMIFS('sales data'!$N:$N,'sales data'!$B:$B,F$3,'sales data'!$H:$H,$C7,'sales data'!$O:$O,"") -> 23920697 | G7: =SUMIFS('sales data'!$N:$N,'sales data'!$B:$B,G$3,'sales data'!$H:$H,$C7,'sales data'!$O:$O,"") -> 21907356 | H7: =SUMIFS('sales data'!$N:$N,'sales data'!$B:$B,H$3,'sales data'!$H:$H,$C7,'sales data'!$O:$O,"") -> 0 | I7: =SUMIFS('sales data'!$N:$N,'sales data'!$B:$B,I$3,'sales data'!$H:$H,$C7,'sales data'!$O:$O,"") -> 0 | J7: =SUMIFS('sales data'!$N:$N,'sales data'!$B:$B,J$3,'sales data'!$H:$H,$C7,'sales data'!$O:$O,"") -> 0 | K7: =SUMIFS('sales data'!$N:$N,'sales data'!$B:$B,K$3,'sales data'!$H:$H,$C7,'sales data'!$O:$O,"") -> 0 | L7: =SUMIFS('sales data'!$N:$N,'sales data'!$B:$B,L$3,'sales data'!$H:$H,$C7,'sales data'!$O:$O,"") -> 0 | M7: =SUMIFS('sales data'!$N:$N,'sales data'!$B:$B,M$3,'sales data'!$H:$H,$C7,'sales data'!$O:$O,"") -> 0 | ... Q7: =SUMIFS('sales data'!$N:$N,'sales data'!$B:$B,Q$3,'sales data'!$H:$H,$C7,'sales data'!$O:$O,"") -> 0
C8: FORD PHEV-E (P703) | D8: =SUM(F8:Q8) -> 25162751 | F8: =SUMIFS('sales data'!$N:$N,'sales data'!$B:$B,F$3,'sales data'!$H:$H,$C8,'sales data'!$O:$O,"") -> 12070960 | G8: =SUMIFS('sales data'!$N:$N,'sales data'!$B:$B,G$3,'sales data'!$H:$H,$C8,'sales data'!$O:$O,"") -> 13091791 | H8: =SUMIFS('sales data'!$N:$N,'sales data'!$B:$B,H$3,'sales data'!$H:$H,$C8,'sales data'!$O:$O,"") -> 0 | I8: =SUMIFS('sales data'!$N:$N,'sales data'!$B:$B,I$3,'sales data'!$H:$H,$C8,'sales data'!$O:$O,"") -> 0 | J8: =SUMIFS('sales data'!$N:$N,'sales data'!$B:$B,J$3,'sales data'!$H:$H,$C8,'sales data'!$O:$O,"") -> 0 | K8: =SUMIFS('sales data'!$N:$N,'sales data'!$B:$B,K$3,'sales data'!$H:$H,$C8,'sales data'!$O:$O,"") -> 0 | L8: =SUMIFS('sales data'!$N:$N,'sales data'!$B:$B,L$3,'sales data'!$H:$H,$C8,'sales data'!$O:$O,"") -> 0 | M8: =SUMIFS('sales data'!$N:$N,'sales data'!$B:$B,M$3,'sales data'!$H:$H,$C8,'sales data'!$O:$O,"") -> 0 | ... Q8: =SUMIFS('sales data'!$N:$N,'sales data'!$B:$B,Q$3,'sales data'!$H:$H,$C8,'sales data'!$O:$O,"") -> 0
C9: BEV-E RWD | D9: =SUM(F9:Q9) -> 1747054.9 | F9: =SUMIFS('sales data'!$N:$N,'sales data'!$B:$B,F$3,'sales data'!$H:$H,$C9,'sales data'!$O:$O,"") -> 371310.73 | G9: =SUMIFS('sales data'!$N:$N,'sales data'!$B:$B,G$3,'sales data'!$H:$H,$C9,'sales data'!$O:$O,"") -> 1375744.2 | H9: =SUMIFS('sales data'!$N:$N,'sales data'!$B:$B,H$3,'sales data'!$H:$H,$C9,'sales data'!$O:$O,"") -> 0 | I9: =SUMIFS('sales data'!$N:$N,'sales data'!$B:$B,I$3,'sales data'!$H:$H,$C9,'sales data'!$O:$O,"") -> 0 | J9: =SUMIFS('sales data'!$N:$N,'sales data'!$B:$B,J$3,'sales data'!$H:$H,$C9,'sales data'!$O:$O,"") -> 0 | K9: =SUMIFS('sales data'!$N:$N,'sales data'!$B:$B,K$3,'sales data'!$H:$H,$C9,'sales data'!$O:$O,"") -> 0 | L9: =SUMIFS('sales data'!$N:$N,'sales data'!$B:$B,L$3,'sales data'!$H:$H,$C9,'sales data'!$O:$O,"") -> 0 | M9: =SUMIFS('sales data'!$N:$N,'sales data'!$B:$B,M$3,'sales data'!$H:$H,$C9,'sales data'!$O:$O,"") -> 0 | ... Q9: =SUMIFS('sales data'!$N:$N,'sales data'!$B:$B,Q$3,'sales data'!$H:$H,$C9,'sales data'!$O:$O,"") -> 0
C10: BEV-E AWD | D10: =SUM(F10:Q10) -> 350302.84 | F10: =SUMIFS('sales data'!$N:$N,'sales data'!$B:$B,F$3,'sales data'!$H:$H,$C10,'sales data'!$O:$O,"") -> 240833.21 | G10: =SUMIFS('sales data'!$N:$N,'sales data'!$B:$B,G$3,'sales data'!$H:$H,$C10,'sales data'!$O:$O,"") -> 109469.63 | H10: =SUMIFS('sales data'!$N:$N,'sales data'!$B:$B,H$3,'sales data'!$H:$H,$C10,'sales data'!$O:$O,"") -> 0 | I10: =SUMIFS('sales data'!$N:$N,'sales data'!$B:$B,I$3,'sales data'!$H:$H,$C10,'sales data'!$O:$O,"") -> 0 | J10: =SUMIFS('sales data'!$N:$N,'sales data'!$B:$B,J$3,'sales data'!$H:$H,$C10,'sales data'!$O:$O,"") -> 0 | K10: =SUMIFS('sales data'!$N:$N,'sales data'!$B:$B,K$3,'sales data'!$H:$H,$C10,'sales data'!$O:$O,"") -> 0 | L10: =SUMIFS('sales data'!$N:$N,'sales data'!$B:$B,L$3,'sales data'!$H:$H,$C10,'sales data'!$O:$O,"") -> 0 | M10: =SUMIFS('sales data'!$N:$N,'sales data'!$B:$B,M$3,'sales data'!$H:$H,$C10,'sales data'!$O:$O,"") -> 0 | ... Q10: =SUMIFS('sales data'!$N:$N,'sales data'!$B:$B,Q$3,'sales data'!$H:$H,$C10,'sales data'!$O:$O,"") -> 0
C11: BEV (AWD/RWD) | D11: =SUM(F11:Q11) -> 3529688.1 | F11: =SUMIFS('sales data'!$N:$N,'sales data'!$B:$B,F$3,'sales data'!$H:$H,$C11,'sales data'!$O:$O,"") -> 793630.18 | G11: =SUMIFS('sales data'!$N:$N,'sales data'!$B:$B,G$3,'sales data'!$H:$H,$C11,'sales data'!$O:$O,"") -> 2736058 | H11: =SUMIFS('sales data'!$N:$N,'sales data'!$B:$B,H$3,'sales data'!$H:$H,$C11,'sales data'!$O:$O,"") -> 0 | I11: =SUMIFS('sales data'!$N:$N,'sales data'!$B:$B,I$3,'sales data'!$H:$H,$C11,'sales data'!$O:$O,"") -> 0 | J11: =SUMIFS('sales data'!$N:$N,'sales data'!$B:$B,J$3,'sales data'!$H:$H,$C11,'sales data'!$O:$O,"") -> 0 | K11: =SUMIFS('sales data'!$N:$N,'sales data'!$B:$B,K$3,'sales data'!$H:$H,$C11,'sales data'!$O:$O,"") -> 0 | L11: =SUMIFS('sales data'!$N:$N,'sales data'!$B:$B,L$3,'sales data'!$H:$H,$C11,'sales data'!$O:$O,"") -> 0 | M11: =SUMIFS('sales data'!$N:$N,'sales data'!$B:$B,M$3,'sales data'!$H:$H,$C11,'sales data'!$O:$O,"") -> 0 | ... Q11: =SUMIFS('sales data'!$N:$N,'sales data'!$B:$B,Q$3,'sales data'!$H:$H,$C11,'sales data'!$O:$O,"") -> 0
C12: FORD BEV-M | D12: =SUM(F12:Q12) -> 35440595 | F12: =SUMIFS('sales data'!$N:$N,'sales data'!$B:$B,F$3,'sales data'!$H:$H,$C12,'sales data'!$O:$O,"") -> 15721984 | G12: =SUMIFS('sales data'!$N:$N,'sales data'!$B:$B,G$3,'sales data'!$H:$H,$C12,'sales data'!$O:$O,"") -> 19718611 | H12: =SUMIFS('sales data'!$N:$N,'sales data'!$B:$B,H$3,'sales data'!$H:$H,$C12,'sales data'!$O:$O,"") -> 0 | I12: =SUMIFS('sales data'!$N:$N,'sales data'!$B:$B,I$3,'sales data'!$H:$H,$C12,'sales data'!$O:$O,"") -> 0 | J12: =SUMIFS('sales data'!$N:$N,'sales data'!$B:$B,J$3,'sales data'!$H:$H,$C12,'sales data'!$O:$O,"") -> 0 | K12: =SUMIFS('sales data'!$N:$N,'sales data'!$B:$B,K$3,'sales data'!$H:$H,$C12,'sales data'!$O:$O,"") -> 0 | L12: =SUMIFS('sales data'!$N:$N,'sales data'!$B:$B,L$3,'sales data'!$H:$H,$C12,'sales data'!$O:$O,"") -> 0 | M12: =SUMIFS('sales data'!$N:$N,'sales data'!$B:$B,M$3,'sales data'!$H:$H,$C12,'sales data'!$O:$O,"") -> 0 | ... Q12: =SUMIFS('sales data'!$N:$N,'sales data'!$B:$B,Q$3,'sales data'!$H:$H,$C12,'sales data'!$O:$O,"") -> 0
C13: EV-V4 | D13: =SUM(F13:Q13) -> 74025.583 | F13: =SUMIFS('sales data'!$N:$N,'sales data'!$B:$B,F$3,'sales data'!$H:$H,$C13,'sales data'!$O:$O,"") -> 67848.567 | G13: =SUMIFS('sales data'!$N:$N,'sales data'!$B:$B,G$3,'sales data'!$H:$H,$C13,'sales data'!$O:$O,"") -> 6177.0163 | H13: =SUMIFS('sales data'!$N:$N,'sales data'!$B:$B,H$3,'sales data'!$H:$H,$C13,'sales data'!$O:$O,"") -> 0 | I13: =SUMIFS('sales data'!$N:$N,'sales data'!$B:$B,I$3,'sales data'!$H:$H,$C13,'sales data'!$O:$O,"") -> 0 | J13: =SUMIFS('sales data'!$N:$N,'sales data'!$B:$B,J$3,'sales data'!$H:$H,$C13,'sales data'!$O:$O,"") -> 0 | K13: =SUMIFS('sales data'!$N:$N,'sales data'!$B:$B,K$3,'sales data'!$H:$H,$C13,'sales data'!$O:$O,"") -> 0 | L13: =SUMIFS('sales data'!$N:$N,'sales data'!$B:$B,L$3,'sales data'!$H:$H,$C13,'sales data'!$O:$O,"") -> 0 | M13: =SUMIFS('sales data'!$N:$N,'sales data'!$B:$B,M$3,'sales data'!$H:$H,$C13,'sales data'!$O:$O,"") -> 0 | ... Q13: =SUMIFS('sales data'!$N:$N,'sales data'!$B:$B,Q$3,'sales data'!$H:$H,$C13,'sales data'!$O:$O,"") -> 0
C14: Components | D14: =SUM(F14:Q14) -> 1628059.3 | F14: =SUMIFS('sales data'!$N:$N,'sales data'!$B:$B,F$3,'sales data'!$H:$H,$C14,'sales data'!$O:$O,"") -> 932361.78 | G14: =SUMIFS('sales data'!$N:$N,'sales data'!$B:$B,G$3,'sales data'!$H:$H,$C14,'sales data'!$O:$O,"") -> 695697.55 | H14: =SUMIFS('sales data'!$N:$N,'sales data'!$B:$B,H$3,'sales data'!$H:$H,$C14,'sales data'!$O:$O,"") -> 0 | I14: =SUMIFS('sales data'!$N:$N,'sales data'!$B:$B,I$3,'sales data'!$H:$H,$C14,'sales data'!$O:$O,"") -> 0 | J14: =SUMIFS('sales data'!$N:$N,'sales data'!$B:$B,J$3,'sales data'!$H:$H,$C14,'sales data'!$O:$O,"") -> 0 | K14: =SUMIFS('sales data'!$N:$N,'sales data'!$B:$B,K$3,'sales data'!$H:$H,$C14,'sales data'!$O:$O,"") -> 0 | L14: =SUMIFS('sales data'!$N:$N,'sales data'!$B:$B,L$3,'sales data'!$H:$H,$C14,'sales data'!$O:$O,"") -> 0 | M14: =SUMIFS('sales data'!$N:$N,'sales data'!$B:$B,M$3,'sales data'!$H:$H,$C14,'sales data'!$O:$O,"") -> 0 | ... Q14: =SUMIFS('sales data'!$N:$N,'sales data'!$B:$B,Q$3,'sales data'!$H:$H,$C14,'sales data'!$O:$O,"") -> 0
C15: BEV-E1 | D15: =SUM(F15:Q15) -> 22467110 | F15: =SUMIFS('sales data'!$N:$N,'sales data'!$B:$B,F$3,'sales data'!$H:$H,$C15,'sales data'!$O:$O,"") -> 15656373 | G15: =SUMIFS('sales data'!$N:$N,'sales data'!$B:$B,G$3,'sales data'!$H:$H,$C15,'sales data'!$O:$O,"") -> 6810736.6 | H15: =SUMIFS('sales data'!$N:$N,'sales data'!$B:$B,H$3,'sales data'!$H:$H,$C15,'sales data'!$O:$O,"") -> 0 | I15: =SUMIFS('sales data'!$N:$N,'sales data'!$B:$B,I$3,'sales data'!$H:$H,$C15,'sales data'!$O:$O,"") -> 0 | J15: =SUMIFS('sales data'!$N:$N,'sales data'!$B:$B,J$3,'sales data'!$H:$H,$C15,'sales data'!$O:$O,"") -> 0 | K15: =SUMIFS('sales data'!$N:$N,'sales data'!$B:$B,K$3,'sales data'!$H:$H,$C15,'sales data'!$O:$O,"") -> 0 | L15: =SUMIFS('sales data'!$N:$N,'sales data'!$B:$B,L$3,'sales data'!$H:$H,$C15,'sales data'!$O:$O,"") -> 0 | M15: =SUMIFS('sales data'!$N:$N,'sales data'!$B:$B,M$3,'sales data'!$H:$H,$C15,'sales data'!$O:$O,"") -> 0 | ... Q15: =SUMIFS('sales data'!$N:$N,'sales data'!$B:$B,Q$3,'sales data'!$H:$H,$C15,'sales data'!$O:$O,"") -> 0
C16: SALES CHECK | F16: =SUMIFS('sales data'!$N:$N,'sales data'!$B:$B,F3)-F5 -> 0 | G16: =SUMIFS('sales data'!$N:$N,'sales data'!$B:$B,G3)-G5 -> 0 | H16: =SUMIFS('sales data'!$N:$N,'sales data'!$B:$B,H3)=H5 -> TRUE | I16: =SUMIFS('sales data'!$N:$N,'sales data'!$B:$B,I3)=I5 -> TRUE | J16: =SUMIFS('sales data'!$N:$N,'sales data'!$B:$B,J3)=J5 -> TRUE | K16: =SUMIFS('sales data'!$N:$N,'sales data'!$B:$B,K3)=K5 -> TRUE | L16: =SUMIFS('sales data'!$N:$N,'sales data'!$B:$B,L3)=L5 -> TRUE | M16: =SUMIFS('sales data'!$N:$N,'sales data'!$B:$B,M3)=M5 -> TRUE | N16: =SUMIFS('sales data'!$N:$N,'sales data'!$B:$B,N3)=N5 -> TRUE | O16: =SUMIFS('sales data'!$N:$N,'sales data'!$B:$B,O3)=O5 -> TRUE | ... Q16: =SUMIFS('sales data'!$N:$N,'sales data'!$B:$B,Q3)=Q5 -> TRUE
B17: 2. 기타 매출 | C17: 2. Other sales | D17: =SUM(F17:Q17) -> 6826019.2 | F17: =SUM(F18:F21) -> 6827880.1 | G17: =SUM(G18:G21) -> -1860.8359 | H17: =SUM(H18:H21) -> 0 | I17: =SUM(I18:I21) -> 0 | J17: =SUM(J18:J21) -> 0 | K17: =SUM(K18:K21) -> 0 | L17: =SUM(L18:L21) -> 0 | M17: =SUM(M18:M21) -> 0 | ... Q17: =SUM(Q18:Q21) -> 0
B18: └ scrap | C18: └ Scrap | D18: =SUM(F18:Q18) -> 0 | F18: =SUMIFS('sales data'!$N:$N,'sales data'!$B:$B,F$3,'sales data'!$H:$H,$C18,'sales data'!$O:$O,"") -> 0 | G18: =SUMIFS('sales data'!$N:$N,'sales data'!$B:$B,G$3,'sales data'!$H:$H,$C18,'sales data'!$O:$O,"") -> 0 | H18: =SUMIFS('sales data'!$N:$N,'sales data'!$B:$B,H$3,'sales data'!$H:$H,$C18,'sales data'!$O:$O,"") -> 0 | I18: =SUMIFS('sales data'!$N:$N,'sales data'!$B:$B,I$3,'sales data'!$H:$H,$C18,'sales data'!$O:$O,"") -> 0 | J18: =SUMIFS('sales data'!$N:$N,'sales data'!$B:$B,J$3,'sales data'!$H:$H,$C18,'sales data'!$O:$O,"") -> 0 | K18: =SUMIFS('sales data'!$N:$N,'sales data'!$B:$B,K$3,'sales data'!$H:$H,$C18,'sales data'!$O:$O,"") -> 0 | L18: =SUMIFS('sales data'!$N:$N,'sales data'!$B:$B,L$3,'sales data'!$H:$H,$C18,'sales data'!$O:$O,"") -> 0 | M18: =SUMIFS('sales data'!$N:$N,'sales data'!$B:$B,M$3,'sales data'!$H:$H,$C18,'sales data'!$O:$O,"") -> 0 | ... Q18: =SUMIFS('sales data'!$N:$N,'sales data'!$B:$B,Q$3,'sales data'!$H:$H,$C18,'sales data'!$O:$O,"") -> 0
B19: └ Test Parts | C19: └ Test Parts | D19: =SUM(F19:Q19) -> 0 | F19: =SUMIFS('sales data'!$N:$N,'sales data'!$B:$B,F$3,'sales data'!$H:$H,$C19,'sales data'!$O:$O,"") -> 0 | G19: =SUMIFS('sales data'!$N:$N,'sales data'!$B:$B,G$3,'sales data'!$H:$H,$C19,'sales data'!$O:$O,"") -> 0 | H19: =SUMIFS('sales data'!$N:$N,'sales data'!$B:$B,H$3,'sales data'!$H:$H,$C19,'sales data'!$O:$O,"") -> 0 | I19: =SUMIFS('sales data'!$N:$N,'sales data'!$B:$B,I$3,'sales data'!$H:$H,$C19,'sales data'!$O:$O,"") -> 0 | J19: =SUMIFS('sales data'!$N:$N,'sales data'!$B:$B,J$3,'sales data'!$H:$H,$C19,'sales data'!$O:$O,"") -> 0 | K19: =SUMIFS('sales data'!$N:$N,'sales data'!$B:$B,K$3,'sales data'!$H:$H,$C19,'sales data'!$O:$O,"") -> 0 | L19: =SUMIFS('sales data'!$N:$N,'sales data'!$B:$B,L$3,'sales data'!$H:$H,$C19,'sales data'!$O:$O,"") -> 0 | M19: =SUMIFS('sales data'!$N:$N,'sales data'!$B:$B,M$3,'sales data'!$H:$H,$C19,'sales data'!$O:$O,"") -> 0 | ... Q19: =SUMIFS('sales data'!$N:$N,'sales data'!$B:$B,Q$3,'sales data'!$H:$H,$C19,'sales data'!$O:$O,"") -> 0
B20: └ 기타 | C20: └ Other | D20: =SUM(F20:Q20) -> 6826019.2 | F20: =SUMIFS('sales data'!$N:$N,'sales data'!$B:$B,F$3,'sales data'!$H:$H,$C20,'sales data'!$O:$O,"")+F$22+F$23 -> 6827880.1 | G20: =SUMIFS('sales data'!$N:$N,'sales data'!$B:$B,G$3,'sales data'!$H:$H,$C20,'sales data'!$O:$O,"")+G$22+G$23 -> -1860.8359 | H20: =SUMIFS('sales data'!$N:$N,'sales data'!$B:$B,H$3,'sales data'!$H:$H,$C20,'sales data'!$O:$O,"")+H$22+H$23 -> 0 | I20: =SUMIFS('sales data'!$N:$N,'sales data'!$B:$B,I$3,'sales data'!$H:$H,$C20,'sales data'!$O:$O,"")+I$22+I$23 -> 0 | J20: =SUMIFS('sales data'!$N:$N,'sales data'!$B:$B,J$3,'sales data'!$H:$H,$C20,'sales data'!$O:$O,"")+J$22+J$23 -> 0 | K20: =SUMIFS('sales data'!$N:$N,'sales data'!$B:$B,K$3,'sales data'!$H:$H,$C20,'sales data'!$O:$O,"")+K$22+K$23 -> 0 | L20: =SUMIFS('sales data'!$N:$N,'sales data'!$B:$B,L$3,'sales data'!$H:$H,$C20,'sales data'!$O:$O,"")+L$22+L$23 -> 0 | M20: =SUMIFS('sales data'!$N:$N,'sales data'!$B:$B,M$3,'sales data'!$H:$H,$C20,'sales data'!$O:$O,"")+M$22+M$23 -> 0 | ... Q20: =SUMIFS('sales data'!$N:$N,'sales data'!$B:$B,Q$3,'sales data'!$H:$H,$C20,'sales data'!$O:$O,"")+Q$22+Q$23 -> 0
B21: └ 기타(투자비) | C21: └ Investment | D21: =SUM(F21:Q21) -> 0 | F21: =+SUMIFS('sales(mold)'!$O:$O,'sales(mold)'!$B:$B,F$3,'sales(mold)'!$I:$I,$C$21) -> 0 | G21: =+SUMIFS('sales(mold)'!$O:$O,'sales(mold)'!$B:$B,G$3,'sales(mold)'!$I:$I,$C$21) -> 0 | H21: =+SUMIFS('sales(mold)'!$O:$O,'sales(mold)'!$B:$B,H$3,'sales(mold)'!$I:$I,$C$21) -> 0 | I21: =+SUMIFS('sales(mold)'!$O:$O,'sales(mold)'!$B:$B,I$3,'sales(mold)'!$I:$I,$C$21) -> 0 | J21: =+SUMIFS('sales(mold)'!$O:$O,'sales(mold)'!$B:$B,J$3,'sales(mold)'!$I:$I,$C$21) -> 0 | K21: =+SUMIFS('sales(mold)'!$O:$O,'sales(mold)'!$B:$B,K$3,'sales(mold)'!$I:$I,$C$21) -> 0 | L21: =+SUMIFS('sales(mold)'!$O:$O,'sales(mold)'!$B:$B,L$3,'sales(mold)'!$I:$I,$C$21) -> 0 | M21: =+SUMIFS('sales(mold)'!$O:$O,'sales(mold)'!$B:$B,M$3,'sales(mold)'!$I:$I,$C$21) -> 0 | ... Q21: =+SUMIFS('sales(mold)'!$O:$O,'sales(mold)'!$B:$B,Q$3,'sales(mold)'!$I:$I,$C$21) -> 0
C22: *(Deductions) | D22: =SUM(F22:Q22) -> 0 | F22: =SUMIFS('sales data'!$N:$N,'sales data'!$B:$B,F$3,'sales data'!$H:$H,$C22,'sales data'!$O:$O,"") -> 0 | G22: =SUMIFS('sales data'!$N:$N,'sales data'!$B:$B,G$3,'sales data'!$H:$H,$C22,'sales data'!$O:$O,"") -> 0 | H22: =SUMIFS('sales data'!$N:$N,'sales data'!$B:$B,H$3,'sales data'!$H:$H,$C22,'sales data'!$O:$O,"") -> 0 | I22: =SUMIFS('sales data'!$N:$N,'sales data'!$B:$B,I$3,'sales data'!$H:$H,$C22,'sales data'!$O:$O,"") -> 0 | J22: =SUMIFS('sales data'!$N:$N,'sales data'!$B:$B,J$3,'sales data'!$H:$H,$C22,'sales data'!$O:$O,"") -> 0 | K22: =SUMIFS('sales data'!$N:$N,'sales data'!$B:$B,K$3,'sales data'!$H:$H,$C22,'sales data'!$O:$O,"") -> 0 | L22: =SUMIFS('sales data'!$N:$N,'sales data'!$B:$B,L$3,'sales data'!$H:$H,$C22,'sales data'!$O:$O,"") -> 0 | M22: =SUMIFS('sales data'!$N:$N,'sales data'!$B:$B,M$3,'sales data'!$H:$H,$C22,'sales data'!$O:$O,"") -> 0 | ... Q22: =SUMIFS('sales data'!$N:$N,'sales data'!$B:$B,Q$3,'sales data'!$H:$H,$C22,'sales data'!$O:$O,"") -> 0
C23: *(Returns) | D23: =SUM(F23:Q23) -> -2259709.7 | F23: =SUMIFS('sales data'!$N:$N,'sales data'!$B:$B,F$3,'sales data'!$H:$H,$C23,'sales data'!$O:$O,"") -> -2257848.9 | G23: =SUMIFS('sales data'!$N:$N,'sales data'!$B:$B,G$3,'sales data'!$H:$H,$C23,'sales data'!$O:$O,"") -> -1860.8359 | H23: =SUMIFS('sales data'!$N:$N,'sales data'!$B:$B,H$3,'sales data'!$H:$H,$C23,'sales data'!$O:$O,"") -> 0 | I23: =SUMIFS('sales data'!$N:$N,'sales data'!$B:$B,I$3,'sales data'!$H:$H,$C23,'sales data'!$O:$O,"") -> 0 | J23: =SUMIFS('sales data'!$N:$N,'sales data'!$B:$B,J$3,'sales data'!$H:$H,$C23,'sales data'!$O:$O,"") -> 0 | K23: =SUMIFS('sales data'!$N:$N,'sales data'!$B:$B,K$3,'sales data'!$H:$H,$C23,'sales data'!$O:$O,"") -> 0 | L23: =SUMIFS('sales data'!$N:$N,'sales data'!$B:$B,L$3,'sales data'!$H:$H,$C23,'sales data'!$O:$O,"") -> 0 | M23: =SUMIFS('sales data'!$N:$N,'sales data'!$B:$B,M$3,'sales data'!$H:$H,$C23,'sales data'!$O:$O,"") -> 0 | ... Q23: =SUMIFS('sales data'!$N:$N,'sales data'!$B:$B,Q$3,'sales data'!$H:$H,$C23,'sales data'!$O:$O,"") -> 0
B25: Ⅱ. 매출원가 | C25: Ⅱ. COST OF SALES | D25: =SUM(F25:Q25) -> 2.8085453e+08 | F25: =+F27+F34 -> 72379542 | G25: =+G27+G34 -> 1.0586831e+08 | H25: =+H27+H34 -> 1.0260668e+08 | I25: =+I27+I34 -> 0 | J25: =+J27+J34 -> 0 | K25: =+K27+K34 -> 0 | L25: =+L27+L34 -> 0 | M25: =+M27+M34 -> 0 | ... Q25: =+Q27+Q34 -> 0
