Workbook

Sheet 1월종합
A3: CarName | B3: SubPno | C3: 합계 : P/Amount(Won) | D3: 합계 : M/Amount(Won)
A4: EV2020_87 | B4: MFR01053AD | C4: 6.2209534e+08 | D4: 5.2057894e+08
B5: MFR01055AC | C5: 8.489576e+08 | D5: 7.0998149e+08
A6: EV2020_87 요약 | C6: 1.4710529e+09 | D6: 1.2305604e+09
A7: Firewall support | B7: (비어 있음) | C7: 10897286 | D7: 0
A8: Firewall support 요약 | C8: 10897286 | D8: 0
A9: PSA_PHEV | B9: EBB00412AC | C9: 2279970 | D9: 2120580
B10: EBB00414AE | C10: 11176704 | D10: 10291050
B11: EBB00416AC | C11: 10866240 | D11: 6486480
B12: EBB00418AC | C12: 14514192 | D12: 11343024
B13: EBB00420AD | C13: 24934140 | D13: 19265400
B14: EBB00422AD | C14: 17172540 | D14: 13277880
B15: ECW01188AD | C15: 99961646 | D15: 98025682
B16: ECW01190AD | C16: 477571248 | D16: 5.4849675e+08
B17: EEA00306AD | C17: 1.4745488e+08 | D17: 1.1232588e+08
B18: EEA00308AF | C18: 851641560 | D18: 6.5979809e+08
A19: PSA_PHEV 요약 | C19: 1.6575731e+09 | D19: 1.4814308e+09
A20: (비어 있음) | B20: (비어 있음)
A21: (비어 있음) 요약
A22: BMW_12V | B22: ECW01550AF | C22: 13700610 | D22: 13118490
A23: BMW_12V 요약 | C23: 13700610 | D23: 13118490
A24: 총합계 | C24: 3.153224e+09 | D24: 2.7251097e+09
C26: 계획 | D26: 실적 | E26: 달성율 | F26: 비율
A27: 매출액 | C27: 2.6696758e+09 | D27: =GETPIVOTDATA("합계 : P/Amount(Won)",$A$3) -> 3.153224e+09 | E27: =D27/C27 -> 1.1811262 | F27: =D27/$D$27 -> 1
A28: 매출원가 | C28: 2.4536116e+09 | D28: =D31+D37+D40 -> 2.8226846e+09 | E28: =D28/C28 -> 1.1504203 | F28: =D28/$D$27 -> 0.89517417
A29: 매출총이익 | C29: 2.1606415e+08 | D29: =D27-D28 -> 3.3053932e+08 | E29: =D29/C29 -> 1.5298203 | F29: =D29/$D$27 -> 0.10482583
A30: 영업이익 | C30: 1.4072717e+08 | D30: =D29-D41 -> 2.5998499e+08 | E30: =D30/C30 -> 1.8474399 | F30: =D30/$D$27 -> 0.082450532
A31: 재료비(\) | C31: 2.4171336e+09 | D31: =SUM(D32:D36) -> 2.790412e+09 | E31: =D31/C31 -> 1.1544302 | F31: =D31/$D$27 -> 0.88493937
B32: 원재료 | C32: 2.3462186e+09 | D32: =GETPIVOTDATA("합계 : M/Amount(Won)",$A$3) -> 2.7251097e+09 | E32: =D32/C32 -> 1.1614901 | F32: =D32/$D$27 -> 0.86422968
B33: 관세 | C33: 60751007 | D33: =D50 -> 61451005 | E33: =D33/C33 -> 1.0115224 | F33: =D33/$D$27 -> 0.01948831
B34: 통관, 물류 | C34: 6930000 | D34: =D55 -> 1152046.1 | E34: =D34/C34 -> 0.16624042 | F34: =D34/$D$27 -> 0.00036535499
B35: 운반비(고객) | C35: 3234000 | D35: =D58 -> 2699235 | E35: =D35/C35 -> 0.83464286 | F35: =D35/$D$27 -> 0.00085602388
B36: 재고평가손실 | C36: 0 | D36: =IF(재고평가!H32>0,재고평가!H32,0) -> 0 | E36: =D36/C36 -> #DIV/0! | F36: =D36/$D$27 -> 0
A37: 노무비(\) | C37: 33398020 | D37: =SUM(D38:D39) -> 30584011 | E37: =D37/C37 -> 0.91574324 | F37: =D37/$D$27 -> 0.0096992829
B38: 직접 | C38: 20181700 | D38: =D54 -> 16442310 | E38: =D38/C38 -> 0.81471385 | F38: =D38/$D$27 -> 0.0052144442
B39: 간접 | C39: 13216320 | D39: =D53 -> 14141701 | E39: =D39/C39 -> 1.070018 | F39: =D39/$D$27 -> 0.0044848386
A40: 기계경비(\) | C40: 3080000 | D40: =D62 -> 1688602 | E40: =D40/C40 -> 0.5482474 | F40: =D40/$D$27 -> 0.00053551604
A41: 판관비(\) | C41: 75336976 | D41: =SUM(D42:D45) -> 70554328 | E41: =D41/C41 -> 0.9365166 | F41: =D41/$D$27 -> 0.022375299
B42: 급여 | C42: 9408858.3 | D42: =D52 -> 7728142.4 | E42: =D42/C42 -> 0.82136877 | F42: =D42/$D$27 -> 0.0024508701
B43: 임대,용역,리스 | C43: 43828617 | D43: =D60 -> 40557270 | E43: =D43/C43 -> 0.92536047 | F43: =D43/$D$27 -> 0.01286216
...

Sheet 1월매출
A1: Order Date | B1: CarName | C1: SubPno | D1: Car Maker Factory | E1: ItemName | F1: QtyOrder | G1: Price | H1: Material | I1: P/Amount | J1: M/Amount | K1: P/Amount(Won) | L1: M/Amount(Won) | M1: Remark
A2: 46027 | B2: PSA_PHEV | C2: EBB00412AC | D2: LG Energy Solution Wroclaw (C00001) | E2: BUSBAR_ASSY_#1_SDN | F2: 400 | G2: 2.35 | H2: 2.55 | I2: =F2*G2 -> 940 | J2: =F2*H2 -> 1020 | K2: =I2*4.2*385 -> 1519980 | L2: =J2*3.6*385 -> 1413720 | M2: 판가(2024.4Q),원가(2024.4Q)
A3: 46027 | B3: PSA_PHEV | C3: EBB00414AE | D3: LG Energy Solution Wroclaw (C00001) | E3: BUSBAR_ASSY_#4_SDN | F3: 600 | G3: 7.68 | H3: 8.25 | I3: =F3*G3 -> 4608 | J3: =F3*H3 -> 4950 | K3: =I3*4.2*385 -> 7451136 | L3: =J3*3.6*385 -> 6860700 | M3: 판가(2024.4Q),원가(2024.4Q)
A4: 46027 | B4: PSA_PHEV | C4: EBB00416AC | D4: LG Energy Solution Wroclaw (C00001) | E4: INTER_BUSBAR_ASSY | F4: 3000 | G4: 0.56 | H4: 0.39 | I4: =F4*G4 -> 1680 | J4: =F4*H4 -> 1170 | K4: =I4*4.2*385 -> 2716560 | L4: =J4*3.6*385 -> 1621620
A5: 46027 | B5: PSA_PHEV | C5: EBB00418AC | D5: LG Energy Solution Wroclaw (C00001) | E5: BUSBAR_ASSY_#1_SUV | F5: 600 | G5: 3.74 | H5: 3.41 | I5: =F5*G5 -> 2244 | J5: =F5*H5 -> 2046 | K5: =I5*4.2*385 -> 3628548 | L5: =J5*3.6*385 -> 2835756 | M5: A/S판가, 원가 적용
A6: 46027 | B6: PSA_PHEV | C6: EBB00420AD | D6: LG Energy Solution Wroclaw (C00001) | E6: BUSBAR_ASSY_#5_SUV | F6: 1000 | G6: 7.71 | H6: 6.95 | I6: =F6*G6 -> 7710 | J6: =F6*H6 -> 6950 | K6: =I6*4.2*385 -> 12467070 | L6: =J6*3.6*385 -> 9632700 | M6: A/S판가, 원가 적용
A7: 46027 | B7: PSA_PHEV | C7: EBB00422AD | D7: LG Energy Solution Wroclaw (C00001) | E7: BUSBAR_ASSY_#4_SUV | F7: 1000 | G7: 5.31 | H7: 4.79 | I7: =F7*G7 -> 5310 | J7: =F7*H7 -> 4790 | K7: =I7*4.2*385 -> 8586270 | L7: =J7*3.6*385 -> 6638940 | M7: A/S판가, 원가 적용
A8: 46027 | B8: PSA_PHEV | C8: ECW01188AD | D8: LG Energy Solution Wroclaw (C00001) | E8: WH_ASSY_SDN | F8: 360 | G8: 85.86 | H8: 98.23 | I8: =F8*G8 -> 30909.6 | J8: =F8*H8 -> 35362.8 | K8: =I8*4.2*385 -> 49980823 | L8: =J8*3.6*385 -> 49012841 | M8: 판가(2024.4Q),원가(2024.4Q)
A9: 46027 | B9: PSA_PHEV | C9: ECW01190AD | D9: LG Energy Solution Wroclaw (C00001) | E9: WH_ASSY_SUV | F9: 600 | G9: 117.2 | H9: 157.04 | I9: =F9*G9 -> 70320 | J9: =F9*H9 -> 94224 | K9: =I9*4.2*385 -> 113707440 | L9: =J9*3.6*385 -> 1.3059446e+08 | M9: A/S판가, 원가 적용
A10: 46027 | B10: PSA_PHEV | C10: EEA00306AD | D10: LG Energy Solution Wroclaw (C00001) | E10: FUSE_BOX_ASSY | F10: 960 | G10: 27.14 | H10: 24.12 | I10: =F10*G10 -> 26054.4 | J10: =F10*H10 -> 23155.2 | K10: =I10*4.2*385 -> 42129965 | L10: =J10*3.6*385 -> 32093107 | M10: A/S판가, 원가 적용
A11: 46027 | B11: PSA_PHEV | C11: EEA00308AF | D11: LG Energy Solution Wroclaw (C00001) | E11: BDU_ASSY | F11: 840 | G11: 156.75 | H11: 141.68 | I11: =F11*G11 -> 131670 | J11: =F11*H11 -> 119011.2 | K11: =I11*4.2*385 -> 212910390 | L11: =J11*3.6*385 -> 1.6494952e+08 | M11: A/S판가, 원가 적용
A12: 46035 | B12: PSA_PHEV | C12: EBB00414AE | D12: LG Energy Solution Wroclaw (C00001) | E12: BUSBAR_ASSY_#4_SDN | F12: 300 | G12: 7.68 | H12: 8.25 | I12: =F12*G12 -> 2304 | J12: =F12*H12 -> 2475 | K12: =I12*4.2*385 -> 3725568 | L12: =J12*3.6*385 -> 3430350 | M12: 판가(2024.4Q),원가(2024.4Q)
A13: 46035 | B13: PSA_PHEV | C13: EBB00416AC | D13: LG Energy Solution Wroclaw (C00001) | E13: INTER_BUSBAR_ASSY | F13: 3000 | G13: 0.56 | H13: 0.39 | I13: =F13*G13 -> 1680 | J13: =F13*H13 -> 1170 | K13: =I13*4.2*385 -> 2716560 | L13: =J13*3.6*385 -> 1621620
A14: 46035 | B14: PSA_PHEV | C14: EBB00418AC | D14: LG Energy Solution Wroclaw (C00001) | E14: BUSBAR_ASSY_#1_SUV | F14: 600 | G14: 3.74 | H14: 3.41 | I14: =F14*G14 -> 2244 | J14: =F14*H14 -> 2046 | K14: =I14*4.2*385 -> 3628548 | L14: =J14*3.6*385 -> 2835756 | M14: A/S판가, 원가 적용
A15: 46035 | B15: PSA_PHEV | C15: ECW01188AD | D15: LG Energy Solution Wroclaw (C00001) | E15: WH_ASSY_SDN | F15: 360 | G15: 85.86 | H15: 98.23 | I15: =F15*G15 -> 30909.6 | J15: =F15*H15 -> 35362.8 | K15: =I15*4.2*385 -> 49980823 | L15: =J15*3.6*385 -> 49012841 | M15: 판가(2024.4Q),원가(2024.4Q)
A16: 46035 | B16: PSA_PHEV | C16: ECW01190AD | D16: LG Energy Solution Wroclaw (C00001) | E16: WH_ASSY_SUV | F16: 360 | G16: 117.2 | H16: 157.04 | I16: =F16*G16 -> 42192 | J16: =F16*H16 -> 56534.4 | K16: =I16*4.2*385 -> 68224464 | L16: =J16*3.6*385 -> 78356678 | M16: A/S판가, 원가 적용
A17: 46035 | B17: PSA_PHEV | C17: EEA00306AD | D17: LG Energy Solution Wroclaw (C00001) | E17: FUSE_BOX_ASSY | F17: 480 | G17: 27.14 | H17: 24.12 | I17: =F17*G17 -> 13027.2 | J17: =F17*H17 -> 11577.6 | K17: =I17*4.2*385 -> 21064982 | L17: =J17*3.6*385 -> 16046554 | M17: A/S판가, 원가 적용
A18: 46035 | B18: PSA_PHEV | C18: EEA00308AF | D18: LG Energy Solution Wroclaw (C00001) | E18: BDU_ASSY | F18: 600 | G18: 156.75 | H18: 141.68 | I18: =F18*G18 -> 94050 | J18: =F18*H18 -> 85008 | K18: =I18*4.2*385 -> 152078850 | L18: =J18*3.6*385 -> 117821088 | M18: A/S판가, 원가 적용
A19: 46041 | B19: PSA_PHEV | C19: EBB00412AC | D19: LG Energy Solution Wroclaw (C00001) | E19: BUSBAR_ASSY_#1_SDN | F19: 200 | G19: 2.35 | H19: 2.55 | I19: =F19*G19 -> 470 | J19: =F19*H19 -> 510 | K19: =I19*4.2*385 -> 759990 | L19: =J19*3.6*385 -> 706860 | M19: 판가(2024.4Q),원가(2024.4Q)
A20: 46041 | B20: PSA_PHEV | C20: EBB00416AC | D20: LG Energy Solution Wroclaw (C00001) | E20: INTER_BUSBAR_ASSY | F20: 3000 | G20: 0.56 | H20: 0.39 | I20: =F20*G20 -> 1680 | J20: =F20*H20 -> 1170 | K20: =I20*4.2*385 -> 2716560 | L20: =J20*3.6*385 -> 1621620
A21: 46041 | B21: PSA_PHEV | C21: EBB00418AC | D21: LG Energy Solution Wroclaw (C00001) | E21: BUSBAR_ASSY_#1_SUV | F21: 600 | G21: 3.74 | H21: 3.41 | I21: =F21*G21 -> 2244 | J21: =F21*H21 -> 2046 | K21: =I21*4.2*385 -> 3628548 | L21: =J21*3.6*385 -> 2835756 | M21: A/S판가, 원가 적용
A22: 46041 | B22: PSA_PHEV | C22: EBB00420AD | D22: LG Energy Solution Wroclaw (C00001) | E22: BUSBAR_ASSY_#5_SUV | F22: 1000 | G22: 7.71 | H22: 6.95 | I22: =F22*G22 -> 7710 | J22: =F22*H22 -> 6950 | K22: =I22*4.2*385 -> 12467070 | L22: =J22*3.6*385 -> 9632700 | M22: A/S판가, 원가 적용
A23: 46041 | B23: PSA_PHEV | C23: EBB00422AD | D23: LG Energy Solution Wroclaw (C00001) | E23: BUSBAR_ASSY_#4_SUV | F23: 1000 | G23: 5.31 | H23: 4.79 | I23: =F23*G23 -> 5310 | J23: =F23*H23 -> 4790 | K23: =I23*4.2*385 -> 8586270 | L23: =J23*3.6*385 -> 6638940 | M23: A/S판가, 원가 적용
A24: 46041 | B24: PSA_PHEV | C24: ECW01190AD | D24: LG Energy Solution Wroclaw (C00001) | E24: WH_ASSY_SUV | F24: 720 | G24: 117.2 | H24: 157.04 | I24: =F24*G24 -> 84384 | J24: =F24*H24 -> 113068.8 | K24: =I24*4.2*385 -> 136448928 | L24: =J24*3.6*385 -> 1.5671336e+08 | M24: A/S판가, 원가 적용
A25: 46041 | B25: PSA_PHEV | C25: EEA00306AD | D25: LG Energy Solution Wroclaw (C00001) | E25: FUSE_BOX_ASSY | F25: 960 | G25: 27.14 | H25: 24.12 | I25: =F25*G25 -> 26054.4 | J25: =F25*H25 -> 23155.2 | K25: =I25*4.2*385 -> 42129965 | L25: =J25*3.6*385 -> 32093107 | M25: A/S판가, 원가 적용
A26: 46041 | B26: PSA_PHEV | C26: EEA00308AF | D26: LG Energy Solution Wroclaw (C00001) | E26: BDU_ASSY | F26: 960 | G26: 156.75 | H26: 141.68 | I26: =F26*G26 -> 150480 | J26: =F26*H26 -> 136012.8 | K26: =I26*4.2*385 -> 243326160 | L26: =J26*3.6*385 -> 1.8851374e+08 | M26: A/S판가, 원가 적용
A27: 46050 | B27: PSA_PHEV | C27: EBB00416AC | D27: LG Energy Solution Wroclaw (C00001) | E27: INTER_BUSBAR_ASSY | F27: 3000 | G27: 0.56 | H27: 0.39 | I27: =F27*G27 -> 1680 | J27: =F27*H27 -> 1170 | K27: =I27*4.2*385 -> 2716560 | L27: =J27*3.6*385 -> 1621620
A28: 46050 | B28: PSA_PHEV | C28: EBB00418AC | D28: LG Energy Solution Wroclaw (C00001) | E28: BUSBAR_ASSY_#1_SUV | F28: 600 | G28: 3.74 | H28: 3.41 | I28: =F28*G28 -> 2244 | J28: =F28*H28 -> 2046 | K28: =I28*4.2*385 -> 3628548 | L28: =J28*3.6*385 -> 2835756 | M28: A/S판가, 원가 적용
A29: 46050 | B29: PSA_PHEV | C29: ECW01190AD | D29: LG Energy Solution Wroclaw (C00001) | E29: WH_ASSY_SUV | F29: 840 | G29: 117.2 | H29: 157.04 | I29: =F29*G29 -> 98448 | J29: =F29*H29 -> 131913.6 | K29: =I29*4.2*385 -> 159190416 | L29: =J29*3.6*385 -> 1.8283225e+08 | M29: A/S판가, 원가 적용
A30: 46050 | B30: PSA_PHEV | C30: EEA00306AD | D30: LG Energy Solution Wroclaw (C00001) | E30: FUSE_BOX_ASSY | F30: 960 | G30: 27.14 | H30: 24.12 | I30: =F30*G30 -> 26054.4 | J30: =F30*H30 -> 23155.2 | K30: =I30*4.2*385 -> 42129965 | L30: =J30*3.6*385 -> 32093107 | M30: A/S판가, 원가 적용
A31: 46050 | B31: PSA_PHEV | C31: EEA00308AF | D31: LG Energy Solution Wroclaw (C00001) | E31: BDU_ASSY | F31: 960 | G31: 156.75 | H31: 141.68 | I31: =F31*G31 -> 150480 | J31: =F31*H31 -> 136012.8 | K31: =I31*4.2*385 -> 243326160 | L31: =J31*3.6*385 -> 1.8851374e+08 | M31: A/S판가, 원가 적용
A32: 46024 | B32: EV2020_87 | C32: MFR01053AD | D32: LG Energy Solution Wroclaw (C00001) | E32: REAR BUSBAR FRAME ASSY | F32: 2688 | G32: 7.59 | H32: 7.41 | I32: =F32*G32 -> 20401.92 | J32: =F32*H32 -> 19918.08 | K32: =I32*4.2*385 -> 32989905 | L32: =J32*3.6*385 -> 27606459 | M32: 신규 MDM단가
A33: 46024 | B33: EV2020_87 | C33: MFR01055AC | D33: LG Energy Solution Wroclaw (C00001) | E33: FRONT BUSBAR FRAME ASSY | F33: 2688 | G33: 10.28 | H33: 10.03 | I33: =F33*G33 -> 27632.64 | J33: =F33*H33 -> 26960.64 | K33: =I33*4.2*385 -> 44681979 | L33: =J33*3.6*385 -> 37367447 | M33: 신규 MDM단가
A34: 46025 | B34: EV2020_87 | C34: MFR01053AD | D34: LG Energy Solution Wroclaw (C00001) | E34: REAR BUSBAR FRAME ASSY | F34: 4224 | G34: 7.59 | H34: 7.41 | I34: =F34*G34 -> 32060.16 | J34: =F34*H34 -> 31299.84 | K34: =I34*4.2*385 -> 51841279 | L34: =J34*3.6*385 -> 43381578 | M34: 신규 MDM단가
A35: 46025 | B35: EV2020_87 | C35: MFR01055AC | D35: LG Energy Solution Wroclaw (C00001) | E35: FRONT BUSBAR FRAME ASSY | F35: 4480 | G35: 10.28 | H35: 10.03 | I35: =F35*G35 -> 46054.4 | J35: =F35*H35 -> 44934.4 | K35: =I35*4.2*385 -> 74469965 | L35: =J35*3.6*385 -> 62279078 | M35: 신규 MDM단가
A36: 46028 | B36: EV2020_87 | C36: MFR01053AD | D36: LG Energy Solution Wroclaw (C00001) | E36: REAR BUSBAR FRAME ASSY | F36: 2688 | G36: 7.59 | H36: 7.41 | I36: =F36*G36 -> 20401.92 | J36: =F36*H36 -> 19918.08 | K36: =I36*4.2*385 -> 32989905 | L36: =J36*3.6*385 -> 27606459 | M36: 신규 MDM단가
A37: 46028 | B37: EV2020_87 | C37: MFR01055AC | D37: LG Energy Solution Wroclaw (C00001) | E37: FRONT BUSBAR FRAME ASSY | F37: 2688 | G37: 10.28 | H37: 10.03 | I37: =F37*G37 -> 27632.64 | J37: =F37*H37 -> 26960.64 | K37: =I37*4.2*385 -> 44681979 | L37: =J37*3.6*385 -> 37367447 | M37: 신규 MDM단가
A38: 46029 | B38: EV2020_87 | C38: MFR01053AD | D38: LG Energy Solution Wroclaw (C00001) | E38: REAR BUSBAR FRAME ASSY | F38: 2688 | G38: 7.59 | H38: 7.41 | I38: =F38*G38 -> 20401.92 | J38: =F38*H38 -> 19918.08 | K38: =I38*4.2*385 -> 32989905 | L38: =J38*3.6*385 -> 27606459 | M38: 신규 MDM단가
A39: 46029 | B39: EV2020_87 | C39: MFR01055AC | D39: LG Energy Solution Wroclaw (C00001) | E39: FRONT BUSBAR FRAME ASSY | F39: 2688 | G39: 10.28 | H39: 10.03 | I39: =F39*G39 -> 27632.64 | J39: =F39*H39 -> 26960.64 | K39: =I39*4.2*385 -> 44681979 | L39: =J39*3.6*385 -> 37367447 | M39: 신규 MDM단가
... A66: 46053 | B66: EV2020_87 | C66: MFR01055AC | D66: LG Energy Solution Wroclaw (C00001) | E66: FRONT BUSBAR FRAME ASSY | F66: -4032 | G66: 10.28 | H66: 10.03 | I66: =F66*G66 -> -41448.96 | J66: =F66*H66 -> -40440.96 | K66: =I66*4.2*385 -> -67022968 | L66: =J66*3.6*385 -> -56051171 | M66: 신규 MDM단가
...

Sheet Sheet1
A3: 행 레이블 | B3: 합계 : 금액
A4: 관세 | B4: -61451005
A5: 교육비 | B5: -385000
A6: 급여 | B6: -7728142.4
A7: 노무비(간접) | B7: -14141701
A8: 노무비(직접) | B8: -16442311
A9: 물류비 | B9: -1152046.1
A10: 세금공과 | B10: -19891737
A11: 소모품비 | B11: -1803101.3
A12: 운반비 | B12: -2699235
A13: 이자비용 | B13: -49354227
A14: 임대,용역,리스 | B14: -40557270
A15: 후생비,접대비 | B15: -189077.35
... A17: 총합계 | B17: -2.1748345e+08

Sheet 1월지출
A1: 구분 | B1: 금액 | C1: 소구분
A2: 후생비,접대비 | B2: -29202.25
A3: 후생비,접대비 | B3: -102125.1
A4: 후생비,접대비 | B4: -57750
A5: 소모품비 | B5: -252175
A6: 소모품비 | B6: -41965
A7: 소모품비 | B7: -32447.8
A8: 이자비용 | B8: -25025
A9: 이자비용 | B9: -15085494
A10: 이자비용 | B10: -31636966
A11: 이자비용 | B11: -2201742
A12: 이자비용 | B12: -405000
A13: 기계경비 | B13: -1688602
... A17: 임대,용역,리스 | B17: -334919.2
A18: 임대,용역,리스 | B18: -8364217.4 | C18: 공장 관리비
A19: 임대,용역,리스 | B19: -23947808 | C19: 공장 임대료
A20: 급여 | B20: -1675080
A21: 급여 | B21: -3680973.4
A22: 급여 | B22: -2372089
A23: 노무비(간접) | B23: -2135937.6
A24: 노무비(간접) | B24: -3153827.6
A25: 노무비(간접) | B25: -2583858.2
A26: 노무비(간접) | B26: -3517637.2
A27: 노무비(간접) | B27: -2750440
A28: 노무비(직접) | B28: -16442311
A29: 임대,용역,리스 | B29: -1831560.5
A30: 소모품비 | B30: -151305
A31: 소모품비 | B31: -1325208.5
A32: 임대,용역,리스 | B32: -133595
A33: 물류비 | B33: -11342.1 | C33: DHL
A34: 임대,용역,리스 | B34: -49722.75
A35: 운반비 | B35: -2699235
A36: 세금공과 | B36: -12824319 | C36: ZUS
A37: 세금공과 | B37: -6009080 | C37: PIT4
A38: 세금공과 | B38: -1058338.1 | C38: PPK
A39: 관세 | B39: -13756050 | C39: KSCE2026-P001
A40: 관세 | B40: -8295210 | C40: KSCE2026-P003
A41: 교육비 | B41: -385000
A42: 관세 | B42: -6442590 | C42: KSCCP2025-R012
A43: 임대,용역,리스 | B43: -1918597.4
...

Sheet 2월종합
A3: CarName | B3: SubPno | C3: 합계 : P/Amount(Won) | D3: 합계 : M/Amount(Won)
A4: BMW_12V | B4: ECW01550AF | C4: 13264020 | D4: 12702690
A5: BMW_12V 요약 | C5: 13264020 | D5: 12702690
A6: EV2020_87 | B6: MFR01053AD | C6: 6.1140296e+08 | D6: 5.1160564e+08
B7: MFR01055AC | C7: 8.1989403e+08 | D7: 6.8549209e+08
A8: EV2020_87 요약 | C8: 1.431297e+09 | D8: 1.1970977e+09
A9: PSA_PHEV | B9: EBB00412AC | C9: 2279970 | D9: 2120580
B10: EBB00414AE | C10: 3725568 | D10: 3430350
B11: EBB00416AC | C11: 9055200 | D11: 5405400
B12: EBB00418AC | C12: 9676128 | D12: 7562016
B13: EBB00420AD | C13: 24934140 | D13: 19265400
B14: EBB00422AD | C14: 17172540 | D14: 13277880
B15: ECW01188AD | C15: 49980823 | D15: 49012841
B16: ECW01190AD | C16: 341122320 | D16: 3.9178339e+08
B17: EEA00306AD | C17: 85708147 | D17: 65289415
B18: EEA00308AF | C18: 2.3572222e+08 | D18: 1.8262269e+08
B19: EEA00308AG | C19: 243326160 | D19: 1.8851374e+08
A20: PSA_PHEV 요약 | C20: 1.0227032e+09 | D20: 9.282837e+08
A21: (비어 있음) | B21: (비어 있음)
A22: (비어 있음) 요약
A23: 총합계 | C23: 2.4672642e+09 | D23: 2.1380841e+09
C25: 계획 | D25: 실적 | E25: 달성율 | F25: 비율
A26: 매출액 | C26: 2.4316188e+09 | D26: =GETPIVOTDATA("합계 : P/Amount(Won)",$A$3) -> 2.4672642e+09 | E26: =D26/C26 -> 1.0146592 | F26: =D26/$D$26 -> 1
A27: 매출원가 | C27: 2.2460183e+09 | D27: =D30+D36+D39 -> 2.24068e+09 | E27: =D27/C27 -> 0.99762322 | F27: =D27/$D$26 -> 0.90816377
A28: 매출총이익 | C28: 1.8560049e+08 | D28: =D26-D27 -> 2.2658425e+08 | E28: =D28/C28 -> 1.2208171 | F28: =D28/$D$26 -> 0.091836233
A29: 영업이익 | C29: 1.1005764e+08 | D29: =D28-D40 -> 1.5204924e+08 | E29: =D29/C29 -> 1.3815419 | F29: =D29/$D$26 -> 0.061626655
A30: 재료비(\) | C30: 2.1739618e+09 | D30: =SUM(D31:D35) -> 2.212992e+09 | E30: =D30/C30 -> 1.0179535 | F30: =D30/$D$26 -> 0.89694162
B31: 원재료 | C31: 2.0891907e+09 | D31: =GETPIVOTDATA("합계 : M/Amount(Won)",$A$3) -> 2.1380841e+09 | E31: =D31/C31 -> 1.023403 | F31: =D31/$D$26 -> 0.86658093
B32: 관세 | C32: 74607094 | D32: =D49 -> 62521305 | E32: =D32/C32 -> 0.83800751 | F32: =D32/$D$26 -> 0.025340336
B33: 통관, 물류 | C33: 6930000 | D33: =D54 -> 8740214 | E33: =D33/C33 -> 1.2612141 | F33: =D33/$D$26 -> 0.0035424718
B34: 운반비(고객) | C34: 3234000 | D34: =D57 -> 3646335 | E34: =D34/C34 -> 1.1275 | F34: =D34/$D$26 -> 0.0014778859
B35: 재고평가손실 | C35: 33998800 | D35: =IF(재고평가!I31>0,재고평가!I31,0) -> 0.0588 | E35: =D35/C35 -> 1.7294728e-09 | F35: =D35/$D$26 -> 2.3832064e-11
A36: 노무비(\) | C36: 34977643 | D36: =SUM(D37:D38) -> 25384213 | E36: =D36/C36 -> 0.7257268 | F36: =D36/$D$26 -> 0.010288405
B37: 직접 | C37: 20181700 | D37: =D53 -> 13293419 | E37: =D37/C37 -> 0.65868676 | F37: =D37/$D$26 -> 0.0053879185
B38: 간접 | C38: 14795943 | D38: =D52 -> 12090794 | E38: =D38/C38 -> 0.81716958 | F38: =D38/$D$26 -> 0.0049004861
A39: 기계경비(\) | C39: 3080000 | D39: =D51 -> 2303782.2 | E39: =D39/C39 -> 0.74798125 | F39: =D39/$D$26 -> 0.00093373957
A40: 판관비(\) | C40: 75542842 | D40: =SUM(D41:D44) -> 74535009 | E40: =D40/C40 -> 0.98665879 | F40: =D40/$D$26 -> 0.030209577
B41: 급여 | C41: 9614724.3 | D41: =D50 -> 8745970.8 | E41: =D41/C41 -> 0.90964342 | F41: =D41/$D$26 -> 0.0035448051
B42: 임대,용역,리스 | C42: 43828617 | D42: =D59 -> 42167221 | E42: =D42/C42 -> 0.96209334 | F42: =D42/$D$26 -> 0.017090679
B43: 세금공과 | C43: 17325000 | D43: =D55 -> 17592467 | E43: =D43/C43 -> 1.0154382 | F43: =D43/$D$26 -> 0.0071303539
...

Sheet 2월매출
A1: Order Date | B1: CarName | C1: SubPno | D1: Car Maker Factory | E1: ItemName | F1: QtyOrder | G1: Price | H1: Material | I1: P/Amount | J1: M/Amount | K1: P/Amount(Won) | L1: M/Amount(Won) | M1: Remark
A2: 46054 | B2: PSA_PHEV | C2: EBB00412AC | D2: LG Energy Solution Wroclaw (C00001) | E2: BUSBAR_ASSY_#1_SDN | F2: 400 | G2: 2.35 | H2: 2.55 | I2: =F2*G2 -> 940 | J2: =F2*H2 -> 1020 | K2: =I2*4.2*385 -> 1519980 | L2: =J2*3.6*385 -> 1413720 | M2: 판가(2024.4Q),원가(2024.4Q)
A3: 46054 | B3: PSA_PHEV | C3: EBB00416AC | D3: LG Energy Solution Wroclaw (C00001) | E3: INTER_BUSBAR_ASSY | F3: 3000 | G3: 0.56 | H3: 0.39 | I3: =F3*G3 -> 1680 | J3: =F3*H3 -> 1170 | K3: =I3*4.2*385 -> 2716560 | L3: =J3*3.6*385 -> 1621620
A4: 46054 | B4: PSA_PHEV | C4: EBB00418AC | D4: LG Energy Solution Wroclaw (C00001) | E4: BUSBAR_ASSY_#1_SUV | F4: 600 | G4: 3.74 | H4: 3.41 | I4: =F4*G4 -> 2244 | J4: =F4*H4 -> 2046 | K4: =I4*4.2*385 -> 3628548 | L4: =J4*3.6*385 -> 2835756 | M4: A/S판가, 원가 적용
A5: 46054 | B5: PSA_PHEV | C5: EBB00420AD | D5: LG Energy Solution Wroclaw (C00001) | E5: BUSBAR_ASSY_#5_SUV | F5: 1000 | G5: 7.71 | H5: 6.95 | I5: =F5*G5 -> 7710 | J5: =F5*H5 -> 6950 | K5: =I5*4.2*385 -> 12467070 | L5: =J5*3.6*385 -> 9632700 | M5: A/S판가, 원가 적용
A6: 46054 | B6: PSA_PHEV | C6: EBB00422AD | D6: LG Energy Solution Wroclaw (C00001) | E6: BUSBAR_ASSY_#4_SUV | F6: 1000 | G6: 5.31 | H6: 4.79 | I6: =F6*G6 -> 5310 | J6: =F6*H6 -> 4790 | K6: =I6*4.2*385 -> 8586270 | L6: =J6*3.6*385 -> 6638940 | M6: A/S판가, 원가 적용
A7: 46054 | B7: PSA_PHEV | C7: ECW01188AD | D7: LG Energy Solution Wroclaw (C00001) | E7: WH_ASSY_SDN | F7: 360 | G7: 85.86 | H7: 98.23 | I7: =F7*G7 -> 30909.6 | J7: =F7*H7 -> 35362.8 | K7: =I7*4.2*385 -> 49980823 | L7: =J7*3.6*385 -> 49012841 | M7: 판가(2024.4Q),원가(2024.4Q)
A8: 46054 | B8: PSA_PHEV | C8: ECW01190AD | D8: LG Energy Solution Wroclaw (C00001) | E8: WH_ASSY_SUV | F8: 600 | G8: 117.2 | H8: 157.04 | I8: =F8*G8 -> 70320 | J8: =F8*H8 -> 94224 | K8: =I8*4.2*385 -> 113707440 | L8: =J8*3.6*385 -> 1.3059446e+08 | M8: A/S판가, 원가 적용
A9: 46054 | B9: PSA_PHEV | C9: EEA00306AD | D9: LG Energy Solution Wroclaw (C00001) | E9: FUSE_BOX_ASSY | F9: 480 | G9: 27.14 | H9: 24.12 | I9: =F9*G9 -> 13027.2 | J9: =F9*H9 -> 11577.6 | K9: =I9*4.2*385 -> 21064982 | L9: =J9*3.6*385 -> 16046554 | M9: A/S판가, 원가 적용
A10: 46054 | B10: PSA_PHEV | C10: EEA00308AF | D10: LG Energy Solution Wroclaw (C00001) | E10: BDU_ASSY | F10: 480 | G10: 156.75 | H10: 141.68 | I10: =F10*G10 -> 75240 | J10: =F10*H10 -> 68006.4 | K10: =I10*4.2*385 -> 121663080 | L10: =J10*3.6*385 -> 94256870 | M10: A/S판가, 원가 적용
A11: 46055 | B11: PSA_PHEV | C11: EEA00306AD | D11: LG Energy Solution Wroclaw (C00001) | E11: FUSE_BOX_ASSY | F11: 33 | G11: 27.14 | H11: 24.12 | I11: =F11*G11 -> 895.62 | J11: =F11*H11 -> 795.96 | K11: =I11*4.2*385 -> 1448217.5 | L11: =J11*3.6*385 -> 1103200.6 | M11: A/S판가, 원가 적용
A12: 46060 | B12: PSA_PHEV | C12: EBB00412AC | D12: LG Energy Solution Wroclaw (C00001) | E12: BUSBAR_ASSY_#1_SDN | F12: 200 | G12: 2.35 | H12: 2.55 | I12: =F12*G12 -> 470 | J12: =F12*H12 -> 510 | K12: =I12*4.2*385 -> 759990 | L12: =J12*3.6*385 -> 706860 | M12: 판가(2024.4Q),원가(2024.4Q)
A13: 46060 | B13: PSA_PHEV | C13: EBB00414AE | D13: LG Energy Solution Wroclaw (C00001) | E13: BUSBAR_ASSY_#4_SDN | F13: 300 | G13: 7.68 | H13: 8.25 | I13: =F13*G13 -> 2304 | J13: =F13*H13 -> 2475 | K13: =I13*4.2*385 -> 3725568 | L13: =J13*3.6*385 -> 3430350 | M13: 판가(2024.4Q),원가(2024.4Q)
A14: 46060 | B14: PSA_PHEV | C14: EBB00416AC | D14: LG Energy Solution Wroclaw (C00001) | E14: INTER_BUSBAR_ASSY | F14: 5000 | G14: 0.56 | H14: 0.39 | I14: =F14*G14 -> 2800 | J14: =F14*H14 -> 1950 | K14: =I14*4.2*385 -> 4527600 | L14: =J14*3.6*385 -> 2702700
A15: 46060 | B15: PSA_PHEV | C15: EBB00418AC | D15: LG Energy Solution Wroclaw (C00001) | E15: BUSBAR_ASSY_#1_SUV | F15: 600 | G15: 3.74 | H15: 3.41 | I15: =F15*G15 -> 2244 | J15: =F15*H15 -> 2046 | K15: =I15*4.2*385 -> 3628548 | L15: =J15*3.6*385 -> 2835756 | M15: A/S판가, 원가 적용
A16: 46060 | B16: PSA_PHEV | C16: EBB00420AD | D16: LG Energy Solution Wroclaw (C00001) | E16: BUSBAR_ASSY_#5_SUV | F16: 1000 | G16: 7.71 | H16: 6.95 | I16: =F16*G16 -> 7710 | J16: =F16*H16 -> 6950 | K16: =I16*4.2*385 -> 12467070 | L16: =J16*3.6*385 -> 9632700 | M16: A/S판가, 원가 적용
A17: 46060 | B17: PSA_PHEV | C17: EBB00422AD | D17: LG Energy Solution Wroclaw (C00001) | E17: BUSBAR_ASSY_#4_SUV | F17: 1000 | G17: 5.31 | H17: 4.79 | I17: =F17*G17 -> 5310 | J17: =F17*H17 -> 4790 | K17: =I17*4.2*385 -> 8586270 | L17: =J17*3.6*385 -> 6638940 | M17: A/S판가, 원가 적용
A18: 46060 | B18: PSA_PHEV | C18: ECW01190AD | D18: LG Energy Solution Wroclaw (C00001) | E18: WH_ASSY_SUV | F18: 600 | G18: 117.2 | H18: 157.04 | I18: =F18*G18 -> 70320 | J18: =F18*H18 -> 94224 | K18: =I18*4.2*385 -> 113707440 | L18: =J18*3.6*385 -> 1.3059446e+08 | M18: A/S판가, 원가 적용
A19: 46060 | B19: PSA_PHEV | C19: EEA00306AD | D19: LG Energy Solution Wroclaw (C00001) | E19: FUSE_BOX_ASSY | F19: 960 | G19: 27.14 | H19: 24.12 | I19: =F19*G19 -> 26054.4 | J19: =F19*H19 -> 23155.2 | K19: =I19*4.2*385 -> 42129965 | L19: =J19*3.6*385 -> 32093107 | M19: A/S판가, 원가 적용
A20: 46060 | B20: PSA_PHEV | C20: EEA00308AF | D20: LG Energy Solution Wroclaw (C00001) | E20: BDU_ASSY | F20: 450 | G20: 156.75 | H20: 141.68 | I20: =F20*G20 -> 70537.5 | J20: =F20*H20 -> 63756 | K20: =I20*4.2*385 -> 1.1405914e+08 | L20: =J20*3.6*385 -> 88365816 | M20: A/S판가, 원가 적용
A21: 46070 | B21: PSA_PHEV | C21: EBB00416AC | D21: LG Energy Solution Wroclaw (C00001) | E21: INTER_BUSBAR_ASSY | F21: 2000 | G21: 0.56 | H21: 0.39 | I21: =F21*G21 -> 1120 | J21: =F21*H21 -> 780 | K21: =I21*4.2*385 -> 1811040 | L21: =J21*3.6*385 -> 1081080
A22: 46070 | B22: PSA_PHEV | C22: EBB00418AC | D22: LG Energy Solution Wroclaw (C00001) | E22: BUSBAR_ASSY_#1_SUV | F22: 400 | G22: 3.74 | H22: 3.41 | I22: =F22*G22 -> 1496 | J22: =F22*H22 -> 1364 | K22: =I22*4.2*385 -> 2419032 | L22: =J22*3.6*385 -> 1890504 | M22: A/S판가, 원가 적용
A23: 46070 | B23: PSA_PHEV | C23: ECW01190AD | D23: LG Energy Solution Wroclaw (C00001) | E23: WH_ASSY_SUV | F23: 600 | G23: 117.2 | H23: 157.04 | I23: =F23*G23 -> 70320 | J23: =F23*H23 -> 94224 | K23: =I23*4.2*385 -> 113707440 | L23: =J23*3.6*385 -> 1.3059446e+08 | M23: A/S판가, 원가 적용
A24: 46070 | B24: PSA_PHEV | C24: EEA00306AD | D24: LG Energy Solution Wroclaw (C00001) | E24: FUSE_BOX_ASSY | F24: 480 | G24: 27.14 | H24: 24.12 | I24: =F24*G24 -> 13027.2 | J24: =F24*H24 -> 11577.6 | K24: =I24*4.2*385 -> 21064982 | L24: =J24*3.6*385 -> 16046554 | M24: A/S판가, 원가 적용
A25: 46070 | B25: PSA_PHEV | C25: EEA00308AG | D25: LG Energy Solution Wroclaw (C00001) | E25: BDU_ASSY | F25: 960 | G25: 156.75 | H25: 141.68 | I25: =F25*G25 -> 150480 | J25: =F25*H25 -> 136012.8 | K25: =I25*4.2*385 -> 243326160 | L25: =J25*3.6*385 -> 1.8851374e+08 | M25: A/S판가, 원가 적용
A26: 46054 | B26: EV2020_87 | C26: MFR01053AD | D26: LG Energy Solution Wroclaw (C00001) | E26: REAR BUSBAR FRAME ASSY | F26: 2304 | G26: 7.59 | H26: 7.41 | I26: =F26*G26 -> 17487.36 | J26: =F26*H26 -> 17072.64 | K26: =I26*4.2*385 -> 28277061 | L26: =J26*3.6*385 -> 23662679 | M26: 신규 MDM단가
A27: 46054 | B27: EV2020_87 | C27: MFR01055AC | D27: LG Energy Solution Wroclaw (C00001) | E27: FRONT BUSBAR FRAME ASSY | F27: 1792 | G27: 10.28 | H27: 10.03 | I27: =F27*G27 -> 18421.76 | J27: =F27*H27 -> 17973.76 | K27: =I27*4.2*385 -> 29787986 | L27: =J27*3.6*385 -> 24911631 | M27: 신규 MDM단가
A28: 46055 | B28: EV2020_87 | C28: MFR01053AD | D28: LG Energy Solution Wroclaw (C00001) | E28: REAR BUSBAR FRAME ASSY | F28: 2304 | G28: 7.59 | H28: 7.41 | I28: =F28*G28 -> 17487.36 | J28: =F28*H28 -> 17072.64 | K28: =I28*4.2*385 -> 28277061 | L28: =J28*3.6*385 -> 23662679 | M28: 신규 MDM단가
A29: 46055 | B29: EV2020_87 | C29: MFR01055AC | D29: LG Energy Solution Wroclaw (C00001) | E29: FRONT BUSBAR FRAME ASSY | F29: 2240 | G29: 10.28 | H29: 10.03 | I29: =F29*G29 -> 23027.2 | J29: =F29*H29 -> 22467.2 | K29: =I29*4.2*385 -> 37234982 | L29: =J29*3.6*385 -> 31139539 | M29: 신규 MDM단가
A30: 46056 | B30: EV2020_87 | C30: MFR01053AD | D30: LG Energy Solution Wroclaw (C00001) | E30: REAR BUSBAR FRAME ASSY | F30: 1536 | G30: 7.59 | H30: 7.41 | I30: =F30*G30 -> 11658.24 | J30: =F30*H30 -> 11381.76 | K30: =I30*4.2*385 -> 18851374 | L30: =J30*3.6*385 -> 15775119 | M30: 신규 MDM단가
A31: 46056 | B31: EV2020_87 | C31: MFR01055AC | D31: LG Energy Solution Wroclaw (C00001) | E31: FRONT BUSBAR FRAME ASSY | F31: 1344 | G31: 10.28 | H31: 10.03 | I31: =F31*G31 -> 13816.32 | J31: =F31*H31 -> 13480.32 | K31: =I31*4.2*385 -> 22340989 | L31: =J31*3.6*385 -> 18683724 | M31: 신규 MDM단가
A32: 46057 | B32: EV2020_87 | C32: MFR01053AD | D32: LG Energy Solution Wroclaw (C00001) | E32: REAR BUSBAR FRAME ASSY | F32: 2688 | G32: 7.59 | H32: 7.41 | I32: =F32*G32 -> 20401.92 | J32: =F32*H32 -> 19918.08 | K32: =I32*4.2*385 -> 32989905 | L32: =J32*3.6*385 -> 27606459 | M32: 신규 MDM단가
A33: 46057 | B33: EV2020_87 | C33: MFR01055AC | D33: LG Energy Solution Wroclaw (C00001) | E33: FRONT BUSBAR FRAME ASSY | F33: 3136 | G33: 10.28 | H33: 10.03 | I33: =F33*G33 -> 32238.08 | J33: =F33*H33 -> 31454.08 | K33: =I33*4.2*385 -> 52128975 | L33: =J33*3.6*385 -> 43595355 | M33: 신규 MDM단가
... A36: 46059 | B36: EV2020_87 | C36: MFR01053AD | D36: LG Energy Solution Wroclaw (C00001) | E36: REAR BUSBAR FRAME ASSY | F36: 1536 | G36: 7.59 | H36: 7.41 | I36: =F36*G36 -> 11658.24 | J36: =F36*H36 -> 11381.76 | K36: =I36*4.2*385 -> 18851374 | L36: =J36*3.6*385 -> 15775119 | M36: 신규 MDM단가
A37: 46059 | B37: EV2020_87 | C37: MFR01055AC | D37: LG Energy Solution Wroclaw (C00001) | E37: FRONT BUSBAR FRAME ASSY | F37: =1344+448 -> 1792 | G37: 10.28 | H37: 10.03 | I37: =F37*G37 -> 18421.76 | J37: =F37*H37 -> 17973.76 | K37: =I37*4.2*385 -> 29787986 | L37: =J37*3.6*385 -> 24911631 | M37: 신규 MDM단가
A38: 46062 | B38: EV2020_87 | C38: MFR01053AD | D38: LG Energy Solution Wroclaw (C00001) | E38: REAR BUSBAR FRAME ASSY | F38: 2688 | G38: 7.59 | H38: 7.41 | I38: =F38*G38 -> 20401.92 | J38: =F38*H38 -> 19918.08 | K38: =I38*4.2*385 -> 32989905 | L38: =J38*3.6*385 -> 27606459 | M38: 신규 MDM단가
A39: 46062 | B39: EV2020_87 | C39: MFR01055AC | D39: LG Energy Solution Wroclaw (C00001) | E39: FRONT BUSBAR FRAME ASSY | F39: =2688+448 -> 3136 | G39: 10.28 | H39: 10.03 | I39: =F39*G39 -> 32238.08 | J39: =F39*H39 -> 31454.08 | K39: =I39*4.2*385 -> 52128975 | L39: =J39*3.6*385 -> 43595355 | M39: 신규 MDM단가
A40: 46064 | B40: EV2020_87 | C40: MFR01053AD | D40: LG Energy Solution Wroclaw (C00001) | E40: REAR BUSBAR FRAME ASSY | F40: 4992 | G40: 7.59 | H40: 7.41 | I40: =F40*G40 -> 37889.28 | J40: =F40*H40 -> 36990.72 | K40: =I40*4.2*385 -> 61266966 | L40: =J40*3.6*385 -> 51269138 | M40: 신규 MDM단가
A41: 46064 | B41: EV2020_87 | C41: MFR01055AC | D41: LG Energy Solution Wroclaw (C00001) | E41: FRONT BUSBAR FRAME ASSY | F41: 5376 | G41: 10.28 | H41: 10.03 | I41: =F41*G41 -> 55265.28 | J41: =F41*H41 -> 53921.28 | K41: =I41*4.2*385 -> 89363958 | L41: =J41*3.6*385 -> 74734894 | M41: 신규 MDM단가
A42: 46065 | B42: EV2020_87 | C42: MFR01053AD | D42: LG Energy Solution Wroclaw (C00001) | E42: REAR BUSBAR FRAME ASSY | F42: 1920 | G42: 7.59 | H42: 7.41 | I42: =F42*G42 -> 14572.8 | J42: =F42*H42 -> 14227.2 | K42: =I42*4.2*385 -> 23564218 | L42: =J42*3.6*385 -> 19718899 | M42: 신규 MDM단가
...

Sheet Sheet3
A3: 행 레이블 | B3: 합계 : 금액
A4: 관세 | B4: -62521305
A5: 급여 | B5: -8745970.8
A6: 기계경비 | B6: -2303782.2
A7: 노무비(간접) | B7: -12090794
A8: 노무비(직접) | B8: -13293419
A9: 물류비 | B9: -8740214
A10: 세금공과 | B10: -17592467
A11: 소모품비 | B11: -1592660.3
A12: 운반비 | B12: -3646335
A13: 이자비용 | B13: -50356017
A14: 임대,용역,리스 | B14: -42167221
A15: 출장비 | B15: -4037949.3
A16: 후생비,접대비 | B16: -398740.65
A17: (비어 있음)
A18: 총합계 | B18: -2.2748687e+08

Sheet 2월지출
A1: 구분 | B1: 금액 | C1: 소구분
A2: 소모품비 | B2: -30515.1
A3: 후생비,접대비 | B3: -133960.75
A4: 후생비,접대비 | B4: -96149.9
A5: 소모품비 | B5: -21024.85
A6: 소모품비 | B6: -77000
A7: 출장비 | B7: -687071
A8: 소모품비 | B8: -346496.15
A9: 세금공과 | B9: -151805.5
A10: 세금공과 | B10: -179952.85
A11: 세금공과 | B11: -180141.5
A12: 세금공과 | B12: -277488.75
A13: 후생비,접대비 | B13: -168630
... A23: 이자비용 | B23: -405000
A24: 관세 | B24: -27335 | C24: KSCCP2025-S003 환율 변경 추가분
A25: 임대,용역,리스 | B25: -334919.2
A26: 세금공과 | B26: -170859.15
A27: 물류비 | B27: -13732.95
A28: 임대,용역,리스 | B28: -473550
A29: 임대,용역,리스 | B29: -2427890.9
A30: 운반비 | B30: -3646335
A31: 임대,용역,리스 | B31: -8364217.4 | C31: 공장 관리비
A32: 임대,용역,리스 | B32: -23947808 | C32: 공장 임대료
A33: 기계경비 | B33: -2303782.2
A34: 소모품비 | B34: -235827.9
A35: 관세 | B35: -11040260 | C35: KSCE2026-P013
A36: 임대,용역,리스 | B36: -519750
A37: 임대,용역,리스 | B37: -195907.25
A38: 관세 | B38: -6485325 | C38: KSCE2026-P015
A39: 급여 | B39: -1675080
A40: 급여 | B40: -4156413.8
A41: 급여 | B41: -2914476.9
A42: 노무비(간접) | B42: -717640
A43: 노무비(간접) | B43: -3945784.2
A44: 노무비(간접) | B44: -3278398.2
A45: 노무비(간접) | B45: -4148971.7
A46: 노무비(직접) | B46: -13293419
A47: 임대,용역,리스 | B47: -1923140.4
A48: 임대,용역,리스 | B48: -470708.7
A49: 이자비용 | B49: -462000
...

Sheet 재고평가
A1: Project | B1: MDM | C1: Price(USD) | D1: 46022 | E1: 46053 | F1: 46081 | G1: DEC | H1: JAN | I1: FEB
A2: LOCO | B2: MHU00264AE | C2: 10.02 | D2: 345 | E2: 345 | F2: 345 | G2: =C2*D2 -> 3456.9 | H2: =C2*E2 -> 3456.9 | I2: =C2*F2 -> 3456.9
A3: W1 SDN | B3: EBB00412AC | C3: 2.35 | D3: 5000 | E3: 4400 | F3: 3800 | G3: =C3*D3 -> 11750 | H3: =C3*E3 -> 10340 | I3: =C3*F3 -> 8930
A4: W1 SDN | B4: EBB00414AE | C4: 7.68 | D4: 4800 | E4: 3900 | F4: 3600 | G4: =C4*D4 -> 36864 | H4: =C4*E4 -> 29952 | I4: =C4*F4 -> 27648
A5: W1 SDN | B5: ECW01188AD | C5: 85.86 | D5: 1272 | E5: 552 | F5: 192 | G5: =C5*D5 -> 109213.92 | H5: =C5*E5 -> 47394.72 | I5: =C5*F5 -> 16485.12
A6: W1 SUV | B6: EBB00418AC | C6: 3.74 | D6: 8000 | E6: 7600 | F6: 7000 | G6: =C6*D6 -> 29920 | H6: =C6*E6 -> 28424 | I6: =C6*F6 -> 26180
A7: W1 SUV | B7: EBB00420AD | C7: 7.71 | D7: 7850 | E7: 7850 | F7: 7000 | G7: =C7*D7 -> 60523.5 | H7: =C7*E7 -> 60523.5 | I7: =C7*F7 -> 53970
A8: W1 SUV | B8: EBB00422AD | C8: 5.31 | D8: 7950 | E8: 8000 | F8: 7000 | G8: =C8*D8 -> 42214.5 | H8: =C8*E8 -> 42480 | I8: =C8*F8 -> 37170
A9: W1 SUV | B9: ECW01190AD | C9: 117.2 | D9: 1024 | E9: 772 | F9: 748 | G9: =C9*D9 -> 120012.8 | H9: =C9*E9 -> 90478.4 | I9: =C9*F9 -> 87665.6
A10: W1 Commen | B10: EBB00416AC | C10: 0.39 | D10: 133385 | E10: 121385 | F10: 111385 | G10: =C10*D10 -> 52020.15 | H10: =C10*E10 -> 47340.15 | I10: =C10*F10 -> 43440.15
A11: W1 Commen | B11: EEA00306AD | C11: 27.14 | D11: 11520 | E11: 9633 | F11: 10224 | G11: =C11*D11 -> 312652.8 | H11: =C11*E11 -> 261439.62 | I11: =C11*F11 -> 277479.36
A12: W1 Commen | B12: EEA00308AF | C12: 156.75 | D12: 4290 | E12: 930 | F12: 0 | G12: =C12*D12 -> 672457.5 | H12: =C12*E12 -> 145777.5 | I12: =C12*F12 -> 0
A13: W1 Commen | B13: EEA00308AG | C13: 156.75 | D13: 1758 | E13: 3558 | F13: 4134 | G13: =C13*D13 -> 275566.5 | H13: =C13*E13 -> 557716.5 | I13: =C13*F13 -> 648004.5
... A27: BMW 12V | B27: ECW01550AF | C27: 6.38 | D27: 1500 | E27: 1500 | F27: 1200 | G27: =C27*D27 -> 9570 | H27: =C27*E27 -> 9570 | I27: =C27*F27 -> 7656
G28: =SUM(G2:G27) -> 2626713.8 | H28: =SUM(H2:H27) -> 1925899.5 | I28: =SUM(I2:I27) -> 1641993.3
H29: =H28-G28 -> -700814.24 | I29: =I28-G28 -> -984720.5
H30: =H29*1350 -> -946099224 | I30: =I29*1350 -> -1329372675
H31: 0.0588 | I31: 0.0588
H32: =H30*H31 -> -55630634 | I32: =I30*I31 -> -78167113

Sheet 월종합
C1: 1월 | D1: 2월 | E1: 3월 | F1: 4월 | G1: 5월 | H1: 6월 | I1: 7월 | J1: 8월 | K1: 9월 | L1: 10월 | M1: 11월 | N1: 12월 | O1: 계획 Total | P1: 2월 누계계획 | S1: 1월 | T1: 2월 | U1: 3월 | V1: 4월 | W1: 5월 | X1: 6월 | Y1: 7월 | Z1: 8월 | AA1: 9월 | AB1: 10월 | AC1: 11월 | AD1: 12월 | AE1: 실적 Total
A2: 매출액 | C2: 2.6696758e+09 | D2: 2.4316188e+09 | E2: 2.044309e+09 | F2: 3.1098224e+09 | G2: 2.583104e+09 | H2: 1.8719342e+09 | I2: 1.583896e+09 | J2: 1.8023497e+09 | K2: 1.3293694e+09 | L2: 1.6913608e+09 | M2: 1.1832582e+09 | N2: 1.1832582e+09 | O2: =SUM(C2:N2) -> 2.3483956e+10 | P2: =SUM(C2:D2) -> 5.1012945e+09 | Q2: =O2/$O$2 -> 1 | R2: =P2/$O$2 -> 0.21722466 | S2: 3.153224e+09 | T2: 2.4672642e+09 | AE2: =SUM(S2:AD2) -> 5.6204882e+09 | AF2: =AE2/O2 -> 0.23933311
A3: 매출원가 | C3: 2.4536116e+09 | D3: 2.2460183e+09 | E3: 1.9382749e+09 | F3: 2.8392261e+09 | G3: 2.3397325e+09 | H3: 1.8005205e+09 | I3: 1.5214959e+09 | J3: 1.7598649e+09 | K3: 1.2927727e+09 | L3: 1.635274e+09 | M3: 1.1426967e+09 | N3: 1.1345222e+09 | O3: =SUM(C3:N3) -> 2.210401e+10 | P3: =SUM(C3:D3) -> 4.6996299e+09 | Q3: =O3/$O$2 -> 0.94123878 | R3: =P3/$O$2 -> 0.20012087 | S3: 2.8226846e+09 | T3: 2.24068e+09 | AE3: =SUM(S3:AD3) -> 5.0633646e+09 | AF3: =AE3/O3 -> 0.22906995
A4: 매출총이익 | C4: =C2-C3 -> 2.1606415e+08 | D4: =D2-D3 -> 1.8560049e+08 | E4: =E2-E3 -> 1.060341e+08 | F4: =F2-F3 -> 2.705963e+08 | G4: =G2-G3 -> 2.4337145e+08 | H4: =H2-H3 -> 71413685 | I4: =I2-I3 -> 62400041 | J4: =J2-J3 -> 42484859 | ... N4: =N2-N3 -> 48735952 | O4: =SUM(C4:N4) -> 1.3799459e+09 | P4: =SUM(C4:D4) -> 4.0166463e+08 | Q4: =O4/$O$2 -> 0.058761218 | R4: =P4/$O$2 -> 0.017103789 | S4: 3.3053932e+08 | T4: 2.2658425e+08 | AE4: =SUM(S4:AD4) -> 5.5712357e+08 | AF4: =AE4/AE2 -> 0.099123698
A5: 영업이익 | C5: =C4-C16 -> 1.4072717e+08 | D5: =D4-D16 -> 1.1005764e+08 | E5: =E4-E16 -> -214597.33 | F5: =F4-F16 -> 1.9575337e+08 | G5: =G4-G16 -> 1.6900004e+08 | H5: =H4-H16 -> -2910158.6 | I5: =I4-I16 -> -13124342 | J5: =J4-J16 -> -33039669 | ... N5: =N4-N16 -> -26174216 | O5: =SUM(C5:N5) -> 4.3315815e+08 | P5: =SUM(C5:D5) -> 2.5078481e+08 | Q5: =O5/$O$2 -> 0.018444854 | R5: =P5/$O$2 -> 0.010678985 | S5: 2.5998499e+08 | T5: 1.5204924e+08 | AE5: =SUM(S5:AD5) -> 4.1203424e+08 | AF5: =AE5/AE2 -> 0.073309332
A6: 재료비(\) | C6: =SUM(C7:C10) -> 2.4171336e+09 | D6: =SUM(D7:D10) -> 2.1739618e+09 | E6: =SUM(E7:E10) -> 1.8240296e+09 | F6: =SUM(F7:F10) -> 2.8010826e+09 | G6: =SUM(G7:G10) -> 2.2875636e+09 | H6: =SUM(H7:H10) -> 1.6901187e+09 | I6: =SUM(I7:I10) -> 1.432105e+09 | J6: =SUM(J7:J10) -> 1.6419955e+09 | ... N6: =SUM(N7:N10) -> 1.0725509e+09 | O6: =SUM(C6:N6) -> 2.1165327e+10 | P6: =SUM(C6:D6) -> 4.5910954e+09 | Q6: =O6/$O$2 -> 0.90126753 | R6: =P6/$O$2 -> 0.19549923 | S6: 2.790412e+09 | T6: 2.212992e+09 | AE6: =SUM(S6:AD6) -> 5.003404e+09 | AF6: =AE6/O6 -> 0.23639625
B7: 원재료 | C7: 2.3462186e+09 | D7: 2.0891907e+09 | E7: 1.7351459e+09 | F7: 2.712114e+09 | G7: 2.1961215e+09 | H7: 1.5960224e+09 | I7: 1.354825e+09 | J7: 1.5380463e+09 | K7: 1.1421888e+09 | L7: 1.4449085e+09 | M7: 1.0200016e+09 | N7: 1.0200016e+09 | O7: =SUM(C7:N7) -> 2.0194785e+10 | P7: =SUM(C7:D7) -> 4.4354093e+09 | Q7: =O7/$O$2 -> 0.85993964 | R7: =P7/$O$2 -> 0.18886977 | S7: 2.7251097e+09 | T7: 2.1380841e+09 | AE7: =SUM(S7:AD7) -> 4.8631939e+09 | AF7: =AE7/O7 -> 0.24081434
B8: 관세 | C8: 60751007 | D8: 74607094 | E8: 77626297 | F8: 78642832 | G8: 81601453 | H8: 83000657 | I8: 66630967 | J8: 93785135 | K8: 60137430 | L8: 78365229 | M8: 47437273 | N8: 42061896 | O8: =SUM(C8:N8) -> 8.4464727e+08 | P8: =SUM(C8:D8) -> 1.353581e+08 | Q8: =O8/$O$2 -> 0.035966992 | R8: =P8/$O$2 -> 0.0057638542 | S8: 61451005 | T8: 62521305 | AE8: =SUM(S8:AD8) -> 123972310 | AF8: =AE8/O8 -> 0.14677406
B9: 통관, 물류 | C9: 6930000 | D9: 6930000 | E9: 7700000 | F9: 6930000 | G9: 6930000 | H9: 7700000 | I9: 6930000 | J9: 6930000 | K9: 7700000 | L9: 6930000 | M9: 6930000 | N9: 6930000 | O9: =SUM(C9:N9) -> 85470000 | P9: =SUM(C9:D9) -> 13860000 | Q9: =O9/$O$2 -> 0.003639506 | R9: =P9/$O$2 -> 0.00059019016 | S9: 1152046.1 | T9: 8740214 | AE9: =SUM(S9:AD9) -> 9892260.1 | AF9: =AE9/O9 -> 0.11573956
B10: 운반비(고객) | C10: 3234000 | D10: 3234000 | E10: 3557400 | F10: 3395700 | G10: 2910600 | H10: 3395700 | I10: 3719100 | J10: 3234000 | K10: 3557400 | L10: 3557400 | M10: 3072300 | N10: 3557400 | O10: =SUM(C10:N10) -> 40425000 | P10: =SUM(C10:D10) -> 6468000 | Q10: =O10/$O$2 -> 0.001721388 | R10: =P10/$O$2 -> 0.00027542208 | S10: 2699235 | T10: 3646335 | AE10: =SUM(S10:AD10) -> 6345570 | AF10: =AE10/O10 -> 0.15697143
B11: 재고평가 손실 | C11: 0 | D11: 33998800 | E11: 74861680 | F11: 0 | G11: 17189229 | H11: 71446137 | I11: 55394685 | J11: 87077481 | K11: 46231828 | L11: 69368767 | M11: 35498750 | N11: 28749008 | O11: =SUM(C11:N11) -> 5.1981637e+08 | P11: =SUM(C11:D11) -> 33998800 | Q11: =O11/$O$2 -> 0.022134957 | R11: =P11/$O$2 -> 0.0014477458 | S11: 0 | T11: 0.0588 | AE11: =SUM(S11:AD11) -> 0.0588 | AF11: =AE11/O11 -> 1.1311687e-10
A12: 노무비(\) | C12: =SUM(C13:C14) -> 33398020 | D12: =SUM(D13:D14) -> 34977643 | E12: =SUM(E13:E14) -> 36611594 | F12: =SUM(F13:F14) -> 35371532 | G12: =SUM(G13:G14) -> 32207725 | H12: =SUM(H13:H14) -> 35875584 | I12: =SUM(I13:I14) -> 30916209 | J12: =SUM(J13:J14) -> 27711928 | ... N12: =SUM(N13:N14) -> 30142291 | O12: =SUM(C12:N12) -> 3.8375475e+08 | P12: =SUM(C12:D12) -> 68375663 | Q12: =O12/$O$2 -> 0.016341146 | R12: =P12/$O$2 -> 0.0029115904 | S12: 30584011 | T12: 25384213 | AE12: =SUM(S12:AD12) -> 55968224 | AF12: =AE12/O12 -> 0.14584373
B13: 직접 | C13: 20181700 | D13: 20181700 | E13: 22180620 | F13: 21181160 | G13: 18182780 | H13: 21181160 | I13: 23180080 | J13: 20181700 | K13: 22180620 | L13: 22180620 | M13: 19182240 | N13: 22180620 | O13: =SUM(C13:N13) -> 252175000 | P13: =SUM(C13:D13) -> 40363400 | Q13: =O13/$O$2 -> 0.010738182 | R13: =P13/$O$2 -> 0.0017187649 | S13: 16442310 | T13: 13293419 | AE13: =SUM(S13:AD13) -> 29735729 | AF13: =AE13/O13 -> 0.11791704
B14: 간접 | C14: 13216320 | D14: 14795943 | E14: 14430974 | F14: 14190372 | G14: 14024945 | H14: 14694424 | I14: 7736128.6 | J14: 7530228.3 | K14: 8004643.6 | L14: 7191559.4 | M14: 7802543.4 | N14: 7961670.6 | O14: =SUM(C14:N14) -> 1.3157975e+08 | P14: =SUM(C14:D14) -> 28012263 | Q14: =O14/$O$2 -> 0.0056029636 | R14: =P14/$O$2 -> 0.0011928255 | S14: 14141701 | T14: 12090794 | AE14: =SUM(S14:AD14) -> 26232495 | AF14: =AE14/O14 -> 0.19936574
A15: 기계경비(\) | C15: 3080000 | D15: 3080000 | E15: 2772000 | F15: 2772000 | G15: 2772000 | H15: 3080000 | I15: 3080000 | J15: 3080000 | K15: 2772000 | L15: 2772000 | M15: 2772000 | N15: 3080000 | O15: =SUM(C15:N15) -> 35112000 | P15: =SUM(C15:D15) -> 6160000 | Q15: =O15/$O$2 -> 0.0014951484 | R15: =P15/$O$2 -> 0.00026230674 | S15: 1688602 | T15: 2303782.2 | AE15: =SUM(S15:AD15) -> 3992384.2 | AF15: =AE15/O15 -> 0.11370427
A16: 판관비(\) | C16: =SUM(C17:C20) -> 75336976 | D16: =SUM(D17:D20) -> 75542842 | E16: =SUM(E17:E20) -> 1.062487e+08 | F16: =SUM(F17:F20) -> 74842932 | G16: =SUM(G17:G20) -> 74371411 | H16: =SUM(H17:H20) -> 74323844 | I16: =SUM(I17:I20) -> 75524382 | J16: =SUM(J17:J20) -> 75524529 | ... N16: =SUM(N17:N20) -> 74910167 | O16: =SUM(C16:N16) -> 9.4678773e+08 | P16: =SUM(C16:D16) -> 1.5087982e+08 | Q16: =O16/$O$2 -> 0.040316364 | R16: =P16/$O$2 -> 0.006424804 | S16: 70554328 | T16: 74535009 | AE16: =SUM(S16:AD16) -> 1.4508934e+08 | AF16: =AE16/O16 -> 0.15324379
B17: 급여 | C17: 9408858.3 | D17: 9614724.3 | E17: 9520581.6 | F17: 9838814.6 | G17: 9559793.9 | H17: 9512226.5 | I17: 9557764.9 | J17: 9557911.2 | K17: 10054712 | L17: 9428137.1 | M17: 9843244.2 | N17: 10329550 | O17: =SUM(C17:N17) -> 1.1622632e+08 | P17: =SUM(C17:D17) -> 19023583 | Q17: =O17/$O$2 -> 0.0049491797 | R17: =P17/$O$2 -> 0.0008100672 | S17: 7728142.4 | T17: 8745970.8 | AE17: =SUM(S17:AD17) -> 16474113 | AF17: =AE17/O17 -> 0.14174168
B18: 임대,용역,리스 | C18: 43828617 | D18: 43828617 | E18: 43828617 | F18: 43674617 | G18: 43482117 | H18: 43482117 | I18: 43867117 | J18: 43867117 | K18: 43867117 | L18: 43251117 | M18: 43251117 | N18: 43251117 | O18: =SUM(C18:N18) -> 5.2347941e+08 | P18: =SUM(C18:D18) -> 87657235 | Q18: =O18/$O$2 -> 0.022290938 | R18: =P18/$O$2 -> 0.0037326434 | S18: 40557270 | T18: 42167221 | AE18: =SUM(S18:AD18) -> 82724491 | AF18: =AE18/O18 -> 0.15802817
B19: 세금공과 | C19: 17325000 | D19: 17325000 | E19: 17325000 | F19: 17325000 | G19: 17325000 | H19: 17325000 | I19: 17325000 | J19: 17325000 | K19: 17325000 | L19: 17325000 | M19: 17325000 | N19: 17325000 | O19: =SUM(C19:N19) -> 207900000 | P19: =SUM(C19:D19) -> 34650000 | Q19: =O19/$O$2 -> 0.0088528525 | R19: =P19/$O$2 -> 0.0014754754 | S19: 19891737 | T19: 17592467 | AE19: =SUM(S19:AD19) -> 37484204 | AF19: =AE19/O19 -> 0.1802992
B20: 기타 | C20: 4774500 | D20: 4774500 | E20: 35574500 | F20: 4004500 | G20: 4004500 | H20: 4004500 | I20: 4774500 | J20: 4774500 | K20: 4774500 | L20: 8162500 | M20: 15554500 | N20: 4004500 | O20: =SUM(C20:N20) -> 99182000 | P20: =SUM(C20:D20) -> 9549000 | Q20: =O20/$O$2 -> 0.004223394 | R20: =P20/$O$2 -> 0.00040661803 | S20: 2377178.6 | T20: 6029350.2 | AE20: =SUM(S20:AD20) -> 8406528.9 | AF20: =AE20/O20 -> 0.084758614
A21: 당기순이익 | C21: =C5-C22 -> 79127170 | D21: =D5-D22 -> 48457643 | E21: =E5-E22 -> -61814597 | F21: =F5-F22 -> 1.3415337e+08 | G21: =G5-G22 -> 1.0740004e+08 | H21: =H5-H22 -> -64510159 | I21: =I5-I22 -> -74724342 | J21: =J5-J22 -> -94639669 | ... N21: =N5-N22 -> -87774216 | O21: =SUM(C21:N21) -> -3.0604185e+08 | P21: =SUM(C21:D21) -> 1.2758481e+08 | Q21: =O21/$O$2 -> -0.013031955 | R21: =P21/$O$2 -> 0.0054328501 | S21: 2.1063077e+08 | T21: 1.0169323e+08 | AE21: =SUM(S21:AD21) -> 3.1232399e+08 | AF21: =AE21/AE2 -> 0.055568837
B22: 이자비용 | C22: 61600000 | D22: 61600000 | E22: 61600000 | F22: 61600000 | G22: 61600000 | H22: 61600000 | I22: 61600000 | J22: 61600000 | K22: 61600000 | L22: 61600000 | M22: 61600000 | N22: 61600000 | O22: =SUM(C22:N22) -> 739200000 | P22: =SUM(C22:D22) -> 123200000 | Q22: =O22/$O$2 -> 0.031476809 | R22: =P22/$O$2 -> 0.0052461348 | S22: 49354227 | T22: 50356017 | AE22: =SUM(S22:AD22) -> 99710244 | AF22: =AE22/O22 -> 0.1348894

Sheet 보고용자료
B3: 구분 | C3: 2026년 계획 | D3: 당월누계 계획 | E3: 당월누계 실적 | F3: 년계획 진척율 | G3: 누계계획 진척율 | H3: 전월 실적 | I3: 매출 구성비 | J3: 2월 계획 | K3: 매출 구성비 | L3: 2월 실적 | M3: 매출 구성비 | N3: 전월 대비 | O3: 계획 대비 | P3: 비고
B4: 매출액 | C4: =월종합!O2 -> 2.3483956e+10 | D4: =월종합!P2 -> 5.1012945e+09 | E4: =월종합!AE2 -> 5.6204882e+09 | F4: =E4/C4 -> 0.23933311 | G4: =E4/D4 -> 1.1017768 | H4: 3.153224e+09 | I4: =H4/$H$4 -> 1 | J4: =월종합!D2 -> 2.4316188e+09 | K4: =J4/$J$4 -> 1 | L4: =월종합!T2 -> 2.4672642e+09 | M4: =L4/$L$4 -> 1 | N4: =L4/H4 -> 0.78245766 | O4: =L4/J4 -> 1.0146592
B5: 매출원가 | C5: =월종합!O3 -> 2.210401e+10 | D5: =월종합!P3 -> 4.6996299e+09 | E5: =월종합!AE3 -> 5.0633646e+09 | F5: =E5/C5 -> 0.22906995 | G5: =E5/D5 -> 1.0773965 | H5: 2.8226846e+09 | I5: =H5/$H$4 -> 0.89517417 | J5: =월종합!D3 -> 2.2460183e+09 | K5: =J5/$J$4 -> 0.92367205 | L5: =월종합!T3 -> 2.24068e+09 | M5: =L5/$L$4 -> 0.90816377 | N5: =L5/H5 -> 0.79381166 | O5: =L5/J5 -> 0.99762322
B6: 영업이익 | C6: =월종합!O5 -> 4.3315815e+08 | D6: =월종합!P5 -> 2.5078481e+08 | E6: =월종합!AE5 -> 4.1203424e+08 | F6: =C6/C4 -> 0.018444854 | G6: =E6/E4 -> 0.073309332 | H6: 2.5998499e+08 | I6: =H6/$H$4 -> 0.082450532 | J6: =월종합!D5 -> 1.1005764e+08 | K6: =J6/$J$4 -> 0.04526106 | L6: =월종합!T5 -> 1.5204924e+08 | M6: =L6/$L$4 -> 0.061626655 | N6: =L6/H6 -> 0.58483853 | O6: =L6/J6 -> 1.3815419
B7: 재료비 | C7: =월종합!O6 -> 2.1165327e+10 | D7: =월종합!P6 -> 4.5910954e+09 | E7: =월종합!AE6 -> 5.003404e+09 | F7: =E7/C7 -> 0.23639625 | G7: =E7/D7 -> 1.0898061 | H7: 2.790412e+09 | I7: =H7/$H$4 -> 0.88493937 | J7: =월종합!D6 -> 2.1739618e+09 | K7: =J7/$J$4 -> 0.89403893 | L7: =월종합!T6 -> 2.212992e+09 | M7: =L7/$L$4 -> 0.89694162 | N7: =L7/H7 -> 0.79306997 | O7: =L7/J7 -> 1.0179535
B8: 노무비 | C8: =월종합!O12 -> 3.8375475e+08 | D8: =월종합!P12 -> 68375663 | E8: =월종합!AE12 -> 55968224 | F8: =E8/C8 -> 0.14584373 | G8: =E8/D8 -> 0.81854013 | H8: 30584011 | I8: =H8/$H$4 -> 0.0096992829 | J8: =월종합!D12 -> 34977643 | K8: =J8/$J$4 -> 0.014384509 | L8: =월종합!T12 -> 25384213 | M8: =L8/$L$4 -> 0.010288405 | N8: =L8/H8 -> 0.82998311 | O8: =L8/J8 -> 0.7257268
B9: 기계경비 | C9: =월종합!O15 -> 35112000 | D9: =월종합!P15 -> 6160000 | E9: =월종합!AE15 -> 3992384.2 | F9: =E9/C9 -> 0.11370427 | G9: =E9/D9 -> 0.64811433 | H9: 1688602 | I9: =H9/$H$4 -> 0.00053551604 | J9: =월종합!D15 -> 3080000 | K9: =J9/$J$4 -> 0.0012666459 | L9: =월종합!T15 -> 2303782.2 | M9: =L9/$L$4 -> 0.00093373957 | N9: =L9/H9 -> 1.3643133 | O9: =L9/J9 -> 0.74798125
B10: 판관비 | C10: =월종합!O16 -> 9.4678773e+08 | D10: =월종합!P16 -> 1.5087982e+08 | E10: =월종합!AE16 -> 1.4508934e+08 | F10: =E10/C10 -> 0.15324379 | G10: =E10/D10 -> 0.9616219 | H10: 70554328 | I10: =H10/$H$4 -> 0.022375299 | J10: =월종합!D16 -> 75542842 | K10: =J10/$J$4 -> 0.031066894 | L10: =월종합!T16 -> 74535009 | M10: =L10/$L$4 -> 0.030209577 | N10: =L10/H10 -> 1.0564201 | O10: =L10/J10 -> 0.98665879
C22: =C11/1000000 -> 0

Sheet 재무VS관리
A1: ► 관리회계 결산기준(환율: 1,600원/EUR, 1,350원/USD, 385원/PLN)
A2: 구분 | D2: 1월 | E2: 2월 | F2: 3월 | G2: 4월 | H2: 5월 | I2: 6월 | J2: 7월 | K2: 8월 | L2: 9월 | M2: 10월 | N2: 11월 | O2: 12월 | P2: Total
A3: 매출 | D3: =월종합!S2 -> 3.153224e+09 | E3: =월종합!T2 -> 2.4672642e+09 | P3: =SUM(D3:O3) -> 5.6204882e+09
A4: 매출원가 | D4: =월종합!S3 -> 2.8226846e+09 | E4: =월종합!T3 -> 2.24068e+09 | P4: =SUM(D4:O4) -> 5.0633646e+09
A5: 매출총이익 | D5: =D3-D4 -> 3.3053932e+08 | E5: =E3-E4 -> 2.2658425e+08 | F5: =F3-F4 -> 0 | G5: =G3-G4 -> 0 | H5: =H3-H4 -> 0 | I5: =I3-I4 -> 0 | J5: =J3-J4 -> 0 | K5: =K3-K4 -> 0 | ... O5: =O3-O4 -> 0 | P5: =SUM(D5:O5) -> 5.5712357e+08
A6: 판관비 | D6: =월종합!S16 -> 70554328 | E6: =월종합!T16 -> 74535009 | P6: =SUM(D6:O6) -> 1.4508934e+08
A7: 영업이익 | D7: =D5-D6 -> 2.5998499e+08 | E7: =E5-E6 -> 1.5204924e+08 | F7: =F5-F6 -> 0 | G7: =G5-G6 -> 0 | H7: =H5-H6 -> 0 | I7: =I5-I6 -> 0 | J7: =J5-J6 -> 0 | K7: =K5-K6 -> 0 | ... O7: =O5-O6 -> 0 | P7: =SUM(D7:O7) -> 4.1203424e+08
A8: 영업이익율 | D8: =D7/D3 -> 0.082450532 | E8: =E7/E3 -> 0.061626655 | F8: =F7/F3 -> #DIV/0! | G8: =G7/G3 -> #DIV/0! | H8: =H7/H3 -> #DIV/0! | I8: =I7/I3 -> #DIV/0! | J8: =J7/J3 -> #DIV/0! | K8: =K7/K3 -> #DIV/0! | ... P8: =P7/P3 -> 0.073309332
A10: ► 재무회계 결산기준(환율: 각월 일별 고시 환율에 따름, 단 금액 산출시 385원/PLN적용)
A11: 구분 | D11: 1월 | E11: 2월 | F11: 3월 | G11: 4월 | H11: 5월 | I11: 6월 | J11: 7월 | K11: 8월 | L11: 9월 | M11: 10월 | N11: 11월 | O11: 12월 | P11: Total
A12: 매출 | D12: =D26 -> 3.1628918e+09 | E12: =E26-D26 -> -3.1628918e+09 | F12: =F26-E26 -> 0 | G12: =G26-F26 -> 0 | H12: =H26-G26 -> 0 | I12: =I26-H26 -> 0 | J12: =J26-I26 -> 0 | K12: =K26-J26 -> 0 | L12: =L26-K26 -> 0 | ... O12: =O26-N26 -> 0 | P12: =SUM(D12:D12) -> 3.1628918e+09
A13: 매출원가 | D13: =D27 -> 2.6960418e+09 | E13: =E27-D27 -> -2.6960418e+09 | F13: =F27-E27 -> 0 | G13: =G27-F27 -> 0 | H13: =H27-G27 -> 0 | I13: =I27-H27 -> 0 | J13: =J27-I27 -> 0 | K13: =K27-J27 -> 0 | L13: =L27-K27 -> 0 | ... O13: =O27-N27 -> 0 | P13: =SUM(D13:D13) -> 2.6960418e+09
A14: 매출총이익 | D14: =D12-D13 -> 4.6685e+08 | E14: =E12-E13 -> -4.6685e+08 | F14: =F12-F13 -> 0 | G14: =G12-G13 -> 0 | H14: =H12-H13 -> 0 | I14: =I12-I13 -> 0 | J14: =J12-J13 -> 0 | K14: =K12-K13 -> 0 | ... O14: =O12-O13 -> 0 | P14: =SUM(D14:D14) -> 4.6685e+08
A15: 판관비 | D15: =D28 -> 80568342 | E15: =E28-D28 -> -80568342 | F15: =F28-E28 -> 0 | G15: =G28-F28 -> 0 | H15: =H28-G28 -> 0 | I15: =I28-H28 -> 0 | J15: =J28-I28 -> 0 | K15: =K28-J28 -> 0 | L15: =L28-K28 -> 0 | ... O15: =O28-N28 -> 0 | P15: =SUM(D15:D15) -> 80568342
A16: 영업이익 | D16: =D14-D15 -> 3.8628166e+08 | E16: =E14-E15 -> -3.8628166e+08 | F16: =F14-F15 -> 0 | G16: =G14-G15 -> 0 | H16: =H14-H15 -> 0 | I16: =I14-I15 -> 0 | J16: =J14-J15 -> 0 | K16: =K14-K15 -> 0 | ... O16: =O14-O15 -> 0 | P16: =SUM(D16:D16) -> 3.8628166e+08
A17: 영업이익율 | D17: =D16/D12 -> 0.12212927 | E17: =E16/E12 -> 0.12212927 | F17: =F16/F12 -> #DIV/0! | G17: =G16/G12 -> #DIV/0! | H17: =H16/H12 -> #DIV/0! | I17: =I16/I12 -> #DIV/0! | J17: =J16/J12 -> #DIV/0! | K17: =K16/K12 -> #DIV/0! | ... P17: =P16/P12 -> 0.12212927
A19: ►관리-재무 차액
A20: 구분 | D20: 1월 | E20: 2월 | F20: 3월 | G20: 4월 | H20: 5월 | I20: 6월 | J20: 7월 | K20: 8월 | L20: 9월 | M20: 10월 | N20: 11월 | O20: 12월 | P20: Total
A21: 매출 | D21: =D3-D12 -> -9667832.8 | E21: =E3-E12 -> 5.630156e+09 | F21: =F3-F12 -> 0 | G21: =G3-G12 -> 0 | H21: =H3-H12 -> 0 | I21: =I3-I12 -> 0 | J21: =J3-J12 -> 0 | K21: =K3-K12 -> 0 | ... O21: =O3-O12 -> 0 | P21: =SUM(D21) -> -9667832.8
A22: 매출원가 | D22: =D4-D13 -> 1.2664284e+08 | E22: =E4-E13 -> 4.9367218e+09 | F22: =F4-F13 -> 0 | G22: =G4-G13 -> 0 | H22: =H4-H13 -> 0 | I22: =I4-I13 -> 0 | J22: =J4-J13 -> 0 | K22: =K4-K13 -> 0 | ... O22: =O4-O13 -> 0 | P22: =SUM(D22) -> 1.2664284e+08
A23: 판관비 | D23: =D6-D15 -> -10014013 | E23: =E6-E15 -> 1.5510335e+08 | F23: =F6-F15 -> 0 | G23: =G6-G15 -> 0 | H23: =H6-H15 -> 0 | I23: =I6-I15 -> 0 | J23: =J6-J15 -> 0 | K23: =K6-K15 -> 0 | ... O23: =O6-O15 -> 0 | P23: =SUM(D23) -> -10014013
A25: ►재무재표 결산기준 누적
A26: 매출 | D26: 3.1628918e+09
A27: 매출원가 | D27: 2.6960418e+09
A28: 판관비 | D28: 80568342
