Workbook

Sheet ★TOTAL
B2: 계획환율 | C2: 실적환율
B3: 195 | C3: 195
C5: 2026년 | D5: 당월 누계 | E5: 당월 누계 | F5: 년 계획비 | G5: 누계 계획비 | H5: 전월 | I5: 매출/생산 | J5: 당월 | K5: 매출/생산 | L5: 당월 | M5: 매출/생산
B6: (백만 원,ton) | C6: 계획 | D6: 계획 | E6: 실적 | F6: 진척률 | G6: 진척률 | H6: 실적 | I6: 구성비 | J6: 계획 | K6: 구성비 | L6: 실적 | M6: 구성비 | N6: 전월비 | O6: 계획비 | P6: 비고
B7: 매출액 | C7: 75538.697 | D7: 11062.467 | E7: 8702.6684 | F7: 0.11520808 | G7: 0.78668426 | H7: 4664.3588 | I7: 1 | J7: 4847.3134 | K7: 1 | L7: 4038.3096 | M7: 1 | N7: 0.86578022 | O7: 0.83310263
B8: 전선 | C8: 70374.311 | D8: 10130.356 | E8: 7828.2442 | F8: 0.11123724 | G8: 0.77275118 | H8: 4199.0068 | I8: 0.90023237 | J8: 4380.3348 | K8: 0.90366238 | L8: 3629.2374 | M8: 0.89870213 | N8: 0.86430855 | O8: 0.82852969
B9: 전장 | C9: 5164.386 | D9: 932.11097 | E9: 874.42417 | F9: 0.16931813 | G9: 0.93811166 | H9: 465.35203 | I9: 0.099767632 | J9: 466.97862 | K9: 0.096337617 | L9: 409.07214 | M9: 0.10129787 | N9: 0.87905954 | O9: 0.87599758
B10: * 매출동량 | C10: 5115.836 | D10: 732.6495 | E10: 467.83998 | F10: 0.09144937 | G10: 0.63855907 | H10: 249.86897 | J10: 316.8214 | L10: 217.97101 | N10: 0.87234125 | O10: 0.68799332
B11: 매출원가 | C11: 65633.005 | D11: 9608.8017 | E11: 7429.5251 | F11: 0.113198 | G11: 0.77319996 | H11: 3906.5206 | I11: 0.83752576 | J11: 4238.3198 | K11: 0.87436471 | L11: 3523.0044 | M11: 0.87239583 | N11: 0.90182666 | O11: 0.83122667
B12: 판매관리비 | C12: 5439.1898 | D12: 860.78846 | E12: 702.65876 | F12: 0.12918445 | G12: 0.81629668 | H12: 364.44748 | I12: 0.07813453 | J12: 433.23779 | K12: 0.089376888 | L12: 338.21128 | M12: 0.083750707 | N12: 0.92801102 | O12: 0.7806597
B13: 급여 | C13: 881.85064 | D13: 141.46127 | E13: 137.90227 | F13: 0.15637826 | G13: 0.9748412 | H13: 69.515911 | I13: 0.014903637 | J13: 70.087602 | K13: 0.014459061 | L13: 68.386362 | M13: 0.016934403 | N13: 0.98375121 | O13: 0.97572694
B14: 운반비 | C14: 1578.1842 | D14: 250.55345 | E14: 124.7493 | F14: 0.079046096 | G14: 0.49789496 | H14: 67.072184 | I14: 0.014379722 | J14: 116.02952 | K14: 0.023936873 | L14: 57.677116 | M14: 0.01428249 | N14: 0.85992601 | O14: 0.49708999
B15: 지급수수료 | C15: 365.15299 | D15: 60.858831 | E15: 56.409696 | F15: 0.15448236 | G15: 0.92689417 | H15: 7.1961318 | I15: 0.0015427912 | J15: 30.429416 | K15: 0.0062775837 | L15: 49.213564 | M15: 0.012186674 | N15: 6.8388914 | O15: 1.6173023
B16: 감가상각비 | C16: 218.4763 | D16: 36.412717 | E16: 36.170616 | F16: 0.16555854 | G16: 0.99335122 | H16: 18.085308 | I16: 0.0038773407 | J16: 18.206358 | K16: 0.0037559689 | L16: 18.085308 | M16: 0.0044784353 | N16: 1 | O16: 0.99335122
B17: 후생비 | C17: 377.9584 | D17: 89.436262 | E17: 60.462554 | F17: 0.15997145 | G17: 0.67604071 | H17: 39.843361 | I17: 0.0085420876 | J17: 70.8981 | K17: 0.014626267 | L17: 20.619193 | M17: 0.005105897 | N17: 0.51750636 | O17: 0.29082857
B18: 기타 | C18: 2017.5672 | D18: 282.06593 | E18: 286.96432 | F18: 0.14223284 | G18: 1.0173661 | H18: 162.73458 | I18: 0.034888951 | J18: 127.58679 | K18: 0.026321134 | L18: 124.22974 | M18: 0.030762807 | N18: 0.76338867 | O18: 0.97368811
B19: 영업이익 | C19: 4466.5016 | D19: 592.8764 | E19: 570.48451 | F19: 0.12772513 | G19: 0.96223177 | H19: 393.39067 | I19: 0.084339711 | J19: 175.75585 | K19: 0.036258405 | L19: 177.09384 | M19: 0.043853459 | N19: 0.45017296 | O19: 1.0076128
B21: 생산액 | C21: 65633.005 | D21: 9553.3734 | E21: 4082.3466 | F21: 0.062199599 | G21: 0.4273199 | H21: 4066.4536 | I21: 1 | J21: 4238.3198 | K21: 1 | L21: 3081.988 | M21: 1 | N21: 0.75790562 | O21: 0.72717213
B22: 재료비 | C22: 57561.416 | D22: 8305.0504 | E22: 3033.4561 | F22: 0.05269947 | G22: 0.36525439 | H22: 3443.2355 | I22: 0.84674163 | J22: 3635.0266 | K22: 0.85765747 | L22: 2537.7435 | M22: 0.8234112 | N22: 0.7370229 | O22: 0.69813614
B23: 노무비 | C23: 2192.994 | D23: 325.42269 | E23: 321.38714 | F23: 0.14655177 | G23: 0.98759906 | H23: 166.89904 | I23: 0.041042899 | J23: 156.22115 | K23: 0.036859218 | L23: 154.4881 | M23: 0.05012612 | N23: 0.92563802 | O23: 0.98890641
... B31: 기타 | C31: 1213.7315 | D31: 199.31118 | E31: 130.18512 | F31: 0.10726024 | G31: 0.65317522 | H31: 74.83592 | I31: 0.01840324 | J31: 106.02738 | K31: 0.025016372 | L31: 55.349202 | M31: 0.017958928 | N31: 0.73960742 | O31: 0.52202742
C35: 4466.5016 | D35: 592.8764 | E35: 570.48451 | H35: 393.39067 | J35: 175.75585 | L35: 177.09384
C36: =+C35-C19 -> 0 | D36: =+D35-D19 -> 0 | E36: =+E35-E19 -> 0 | H36: =+H35-H19 -> -5.6843419e-13 | J36: =+J35-J19 -> 0 | L36: =+L35-L19 -> -7.3896445e-13

Sheet ★WIRE SBU
B2: 계획환율 | C2: 실적환율
B3: 195 | C3: 195
C5: 2026년 | D5: 당월 누계 | E5: 당월 누계 | F5: 년 계획비 | G5: 누계 계획비 | H5: 전월 | I5: 매출/생산 | J5: 당월 | K5: 매출/생산 | L5: 당월 | M5: 매출/생산
B6: (백만 원,ton) | C6: 계획 | D6: 계획 | E6: 실적 | F6: 진척률 | G6: 진척률 | H6: 실적 | I6: 구성비 | J6: 계획 | K6: 구성비 | L6: 실적 | M6: 구성비 | N6: 전월비 | O6: 계획비 | P6: 비고
B7: 매출액 | C7: 70374.311 | D7: 10130.356 | E7: 7828.2442 | F7: 0.11123724 | G7: 0.77275118 | H7: 4199.0068 | I7: 1 | J7: 4380.3348 | K7: 1 | L7: 3629.2374 | M7: 1 | N7: 0.86430855 | O7: 0.82852969
B8: └ 江苏京信 | C8: 38240.128 | D8: 5775.0398 | E8: 5016.5944 | F8: 0.13118665 | G8: 0.86866837 | H8: 2706.9135 | I8: 0.64465567 | J8: 2497.3145 | K8: 0.57011955 | L8: 2309.6809 | M8: 0.63640941 | N8: 0.85325255 | O8: 0.92486584
B9: └ KSCI | C9: 17060.875 | D9: 2576.5403 | E9: 1355.8214 | F9: 0.079469632 | G9: 0.52621784 | H9: 758.01558 | I9: 0.18052259 | J9: 1114.1796 | K9: 0.25435946 | L9: 597.80586 | M9: 0.16471941 | N9: 0.78864588 | O9: 0.53654355
B10: └ B/B | C10: 6993.8315 | D10: 176.23703 | E10: 344.88109 | F10: 0.049312182 | G10: 1.9569161 | H10: 109.09542 | I10: 0.025981244 | J10: 76.210607 | K10: 0.017398352 | L10: 235.78567 | M10: 0.064968378 | N10: 2.1612793 | O10: 3.0938694
B11: └ 기타 | C11: 8079.4765 | D11: 1602.5385 | E11: 1110.9473 | F11: 0.13750238 | G11: 0.69324218 | H11: 624.98224 | I11: 0.14884049 | J11: 692.63012 | K11: 0.15812264 | L11: 485.96504 | M11: 0.1339028 | N11: 0.77756615 | O11: 0.70162273
B12: * 매출동량 | C12: 5115.836 | D12: 732.6495 | E12: 467.83998 | F12: 0.09144937 | G12: 0.63855907 | H12: 249.86897 | J12: 316.8214 | L12: 217.97101 | N12: 0.87234125 | O12: 0.68799332
B13: 매출원가 | C13: 60397.168 | D13: 8671.2902 | E13: 6594.0801 | F13: 0.10917863 | G13: 0.76044971 | H13: 3472.5341 | I13: 0.82698941 | J13: 3759.0697 | K13: 0.85816949 | L13: 3121.546 | M13: 0.86011072 | N13: 0.8989245 | O13: 0.83040387
B14: 판매관리비 | C14: 5014.8539 | D14: 788.69616 | E14: 639.2477 | F14: 0.12747085 | G14: 0.81051199 | H14: 332.3115 | I14: 0.079140502 | J14: 394.57432 | K14: 0.090078577 | L14: 306.9362 | M14: 0.084573192 | N14: 0.92364 | O14: 0.77789196
B15: 급여 | C15: 820.1211 | D15: 131.55898 | E15: 128.73491 | F15: 0.15697061 | G15: 0.97853381 | H15: 64.914472 | I15: 0.015459483 | J15: 65.18147 | K15: 0.014880477 | L15: 63.820437 | M15: 0.017585082 | N15: 0.9831465 | O15: 0.97911932
B16: 운반비 | C16: 1437.7842 | D16: 226.25345 | E16: 103.09078 | F16: 0.07170115 | G16: 0.45564291 | H16: 56.190186 | I16: 0.01338178 | J16: 103.87952 | K16: 0.023714974 | L16: 46.900595 | M16: 0.012922989 | N16: 0.83467591 | O16: 0.45149027
B17: 지급수수료 | C17: 339.59228 | D17: 56.598713 | E17: 53.026555 | F17: 0.15614771 | G17: 0.93688623 | H17: 6.5329368 | I17: 0.0015558291 | J17: 28.299356 | K17: 0.0064605465 | L17: 46.493618 | M17: 0.01281085 | N17: 7.116802 | O17: 1.6429214
B18: 감가상각비 | C18: 203.18296 | D18: 33.863826 | E18: 33.95042 | F18: 0.16709285 | G18: 1.0025571 | H18: 16.97521 | I18: 0.0040426728 | J18: 16.931913 | K18: 0.0038654382 | L18: 16.97521 | M18: 0.004677349 | N18: 1 | O18: 1.0025571
B19: 후생비 | C19: 337.99817 | D19: 81.525439 | E19: 51.451719 | F19: 0.15222485 | G19: 0.63111244 | H19: 33.797197 | I19: 0.0080488552 | J19: 64.284948 | K19: 0.014675807 | L19: 17.654522 | M19: 0.0048645266 | N19: 0.52236645 | O19: 0.27462917
B20: 기타 | C20: 1876.1752 | D20: 258.89576 | E20: 268.99331 | F20: 0.14337324 | G20: 1.0390024 | H20: 153.9015 | I20: 0.036651882 | J20: 115.99711 | K20: 0.026481335 | L20: 115.09181 | M20: 0.031712396 | N20: 0.74782776 | O20: 0.99219552
B21: 영업이익 | C21: 4962.2885 | D21: 670.3692 | E21: 594.91633 | F21: 0.11988749 | G21: 0.8874458 | H21: 394.16111 | I21: 0.093870083 | J21: 226.69079 | K21: 0.051751932 | L21: 200.75522 | M21: 0.055316089 | N21: 0.50932275 | O21: 0.88559055
B23: 생산액 | C23: 60397.168 | D23: 8615.862 | E23: 3268.0008 | F23: 0.05410851 | G23: 0.3793005 | H23: 3495.5716 | I23: 1 | J23: 3759.0697 | K23: 1 | L23: 2967.484 | M23: 1 | N23: 0.84892668 | O23: 0.78941979
B24: 재료비 | C24: 53694.89 | D24: 7596.3035 | E24: 2584.3628 | F24: 0.048130516 | G24: 0.34021321 | H24: 3020.8376 | I24: 0.86418989 | J24: 3272.9258 | K24: 0.87067442 | L24: 2511.048 | M24: 0.84618756 | N24: 0.83124231 | O24: 0.76721813
B25: 노무비 | C25: 1617.483 | D25: 234.25473 | E25: 98.443117 | F25: 0.06086192 | G25: 0.42023961 | H25: 110.49561 | I25: 0.031610169 | J25: 110.63717 | K25: 0.029432062 | L25: 98.443117 | M25: 0.033173934 | N25: 0.89092336 | O25: 0.88978337
... B33: 기타 | C33: 980.63952 | D33: 157.87946 | E33: 125.25211 | F33: 0.12772492 | G33: 0.79334009 | H33: 72.267482 | I33: 0.02067401 | J33: 83.10475 | K33: 0.022107797 | L33: 52.984624 | M33: 0.017855066 | N33: 0.7331738 | O33: 0.63756432

Sheet ★COM" SBU
B2: 계획환율 | C2: 실적환율
B3: 195 | C3: 195
C5: 2026년 | D5: 누계 | E5: 누계 | F5: 계 획 | G5: 계 획 | H5: 전월 | I5: 매출/생산 | J5: 당월 | K5: 매출/생산 | L5: 당월 | M5: 매출/생산
B6: (백만 원,ton) | C6: 계획 | D6: 계획 | E6: 실적 | F6: 진척율 | G6: 달성율 | H6: 실적 | I6: 구성비 | J6: 계획 | K6: 구성비 | L6: 실적 | M6: 구성비 | N6: 전월비 | O6: 계획비 | P6: 비고
B7: 매출액 | C7: 5164.386 | D7: 932.11097 | E7: 874.42417 | F7: 0.16931813 | G7: 0.93811166 | H7: 465.35203 | I7: 1 | J7: 466.97862 | K7: 1 | L7: 409.07214 | M7: 1 | N7: 0.87905954 | O7: 0.87599758
B8: └KSCP | C8: 5164.386 | D8: 932.11097 | E8: 841.15365 | F8: 0.16287583 | G8: 0.90241793 | H8: 440.09419 | I8: 0.94572315 | J8: 466.97862 | K8: 1 | L8: 401.05947 | M8: 0.98041256 | N8: 0.91130371 | O8: 0.85883903
B9: └KSCE | C9: 0 | D9: 0 | E9: 0 | F9: 0 | G9: 0 | H9: 0 | I9: 0 | J9: 0 | K9: 0 | L9: 0 | M9: 0 | N9: 0 | O9: 0
B10: └강소 경신 | C10: 0 | D10: 0 | E10: 0 | F10: 0 | G10: 0 | H10: 0 | I10: 0 | J10: 0 | K10: 0 | L10: 0 | M10: 0 | N10: 0 | O10: 0
B11: 기타 | C11: 0 | D11: 0 | E11: 33.27052 | F11: 0 | G11: 0 | H11: 25.257843 | I11: 0.054276851 | J11: 0 | K11: 0 | L11: 8.0126768 | M11: 0.019587442 | N11: 0.3172352 | O11: 0
B12: 매출원가 | C12: 5235.8369 | D12: 937.51148 | E12: 835.44493 | F12: 0.15956282 | G12: 0.89113035 | H12: 433.9865 | I12: 0.93259826 | J12: 479.25009 | K12: 1.0262784 | L12: 401.45844 | M12: 0.98138786 | N12: 0.92504822 | O12: 0.83768045
B13: 판매관리비 | C13: 424.33588 | D13: 72.092296 | E13: 63.411063 | F13: 0.14943601 | G13: 0.87958169 | H13: 32.135979 | I13: 0.069057351 | J13: 38.663464 | K13: 0.082794933 | L13: 31.275085 | M13: 0.076453714 | N13: 0.9732109 | O13: 0.8089054
B14: 급여 | C14: 61.729545 | D14: 9.9022888 | E14: 9.1673634 | F14: 0.14850852 | G14: 0.92578227 | H14: 4.6014384 | I14: 0.0098880806 | J14: 4.9061321 | K14: 0.010506117 | L14: 4.565925 | M14: 0.011161662 | N14: 0.99228211 | O14: 0.93065675
B15: 운반비 | C15: 140.4 | D15: 24.3 | E15: 21.658519 | F15: 0.15426296 | G15: 0.89129709 | H15: 10.881998 | I15: 0.023384444 | J15: 12.15 | K15: 0.026018322 | L15: 10.776521 | M15: 0.026343815 | N15: 0.99030716 | O15: 0.88695646
B16: 지급수수료 | C16: 25.560709 | D16: 4.2601182 | E16: 3.3831408 | F16: 0.13235708 | G16: 0.79414248 | H16: 0.663195 | I16: 0.0014251469 | J16: 2.1300591 | K16: 0.0045613632 | L16: 2.7199458 | M16: 0.0066490614 | N16: 4.1012761 | O16: 1.2769344
B17: 감가상각비 | C17: 15.293341 | D17: 2.5488902 | E17: 2.2201959 | F17: 0.14517403 | G17: 0.87104416 | H17: 1.110098 | I17: 0.0023855015 | J17: 1.2744451 | K17: 0.0027291294 | L17: 1.110098 | M17: 0.0027136973 | N17: 1 | O17: 0.87104416
B18: 후생비 | C18: 39.960236 | D18: 7.9108234 | E18: 9.010835 | F18: 0.22549504 | G18: 1.1390515 | H18: 6.0461642 | I18: 0.012992667 | J18: 6.613152 | K18: 0.014161573 | L18: 2.9646708 | M18: 0.0072473055 | N18: 0.49033912 | O18: 0.44829921
B19: 기타 | C19: 141.39205 | D19: 23.170175 | E19: 17.971009 | F19: 0.12710056 | G19: 0.77560954 | H19: 8.8330846 | I19: 0.018981511 | J19: 11.589675 | K19: 0.024818428 | L19: 9.1379243 | M19: 0.022338173 | N19: 1.0345111 | O19: 0.78845385
B20: 영업이익 | C20: -495.78687 | D20: -77.492799 | E20: -24.431821 | F20: (-) | G20: (-) | H20: -0.77044305 | I20: -0.0016556134 | J20: -50.934936 | K20: -0.10907338 | L20: -23.661378 | M20: -0.057841577 | N20: (-) | O20: (-)
B21: 0
B22: 생산액 | C22: 5235.8369 | D22: 937.51148 | E22: 703.85023 | H22: 570.88202 | J22: 479.25009 | L22: 114.50404
B23: 재료비 | C23: 3866.5261 | D23: 708.74686 | E23: 449.09335 | F23: 0.11614906 | G23: 0.63364422 | H23: 422.39793 | I23: 0.73990406 | J23: 362.10077 | K23: 0.75555702 | L23: 26.695424 | M23: 0.23313958 | N23: 0.063199704 | O23: 0.073723742
B24: 노무비 | C24: 575.51103 | D24: 91.16796 | E24: 112.44842 | F24: 0.19538882 | G24: 1.2334204 | H24: 56.403436 | I24: 0.098800512 | J24: 45.58398 | K24: 0.095115224 | L24: 56.044983 | M24: 0.48945856 | N24: 0.99364484 | O24: 1.2294886
B25: 제조경비 | C25: 793.79987 | D25: 137.59666 | E25: 142.30846 | F25: 0.17927499 | G25: 1.0342436 | H25: 86.390647 | I25: 0.15132837 | J25: 71.56534 | K25: 0.14932775 | L25: 55.917812 | M25: 0.48834794 | N25: 0.64726696 | O25: 0.78135327
B26: 감가상각비 | C26: 268.68479 | D26: 44.780798 | E26: 52.268658 | F26: 0.19453523 | G26: 1.1672114 | H26: 26.134329 | I26: 0.045778861 | J26: 22.390399 | K26: 0.046719655 | L26: 26.134329 | M26: 0.22823936 | N26: 1 | O26: 1.1672114
B27: 동력비 | C27: 150.79452 | D27: 27.641127 | E27: 21.295628 | F27: 0.14122283 | G27: 0.77043269 | H27: 10.516104 | I27: 0.018420801 | J27: 14.12193 | K27: 0.029466724 | L27: 10.779524 | M27: 0.094140992 | N27: 1.0250492 | O27: 0.76331803
B28: 소모품비 | C28: 61.864417 | D28: 11.33995 | E28: 44.642655 | F28: 0.72162087 | G28: 3.9367595 | H28: 41.077766 | I28: 0.071954912 | J28: 5.7936124 | K28: 0.012088912 | L28: 3.5648886 | M28: 0.031133299 | N28: 0.086783897 | O28: 0.61531362
B29: 수선비 | C29: 9.6663151 | D29: 1.7718671 | E29: 0 | F29: 0 | G29: 0 | H29: 0 | I29: 0 | J29: 0.90525194 | K29: 0.0018888926 | L29: 0 | M29: 0 | N29: 0 | O29: 0
B30: 지급수수료 | C30: 11.7 | D30: 0 | E30: 5.9017706 | F30: 0.50442483 | G30: 0 | H30: 0 | I30: 0 | J30: 0 | K30: 0 | L30: 5.9017706 | M30: 0.051542029 | N30: 0 | O30: 0
B31: 소모공구 | C31: 57.997891 | D31: 10.631203 | E31: 13.266731 | F31: 0.22874507 | G31: 1.247905 | H31: 6.0940094 | I31: 0.010674726 | J31: 5.4315116 | K31: 0.011333355 | L31: 7.1727221 | M31: 0.06264165 | N31: 1.177012 | O31: 1.3205757
B32: 기타 | C32: 233.09194 | D32: 41.431715 | E32: 4.9330164 | F32: 0.021163394 | G32: 0.11906378 | H32: 2.5684386 | I32: 0.0044990707 | J32: 22.922634 | K32: 0.047830214 | L32: 2.3645778 | M32: 0.020650606 | N32: 0.92062851 | O32: 0.10315471

Sheet Sheet2
B7: 전기일 | C7: 거래 번호 | D7: 출처 | E7: 원천 번호 | F7: 상계 계정 | G7: 세부사항 | H7: 대변/차변(현지 통화)
D8: OB
B9: 2022.03.31 | C9: 776956 | D9: JE | E9: 776956 | F9: S00186 | G9: 计提3月服务费 | H9: 100000 | I9: 전선 상해
B10: 2022.03.31 | C10: 776956 | D10: JE | E10: 776956 | F10: S00186 | G10: 计提3月服务费 | H10: 100000 | I10: 전장 상해
B11: 2022.03.31 | C11: 776956 | D11: JE | E11: 776956 | F11: S00001 | G11: 计提3月服务费 | H11: 825266 | I11: 전선 로열티
B12: 2022.03.31 | C12: 776956 | D12: JE | E12: 776956 | F12: S00001 | G12: 计提3月服务费 | H12: 444374 | I12: 전장 로열티
L13: 553432 | M13: =+L13*0.05 -> 27671.6 | N13: =+M13*175/1000 -> 4842.53
H14: 81017.628 | L14: 323218 | M14: =+L14*0.05 -> 16160.9 | N14: =+M14*175/1000 -> 2828.1575
M15: =+H21 -> 211365.64 | N15: =+M15*175/1000 -> 36988.988
H16: =+H12-H14 -> 363356.37
H20: =11650417.76*0.02 -> 233008.36
H21: 211365.64

Sheet Sheet1
A1: 업체명 | B1: 판매가에 적용하는 동가 (RMB/kg)세금 미포함 | N1: 적용동가 기준 표기 ( 월,분기 등등)
B2: 1월 | C2: 2월 | D2: 3월 | E2: 4월 | F2: 5월 | G2: 6월 | H2: 7월 | I2: 8월 | J2: 9월 | K2: 10월 | L2: 11월 | M2: 12월
A3: 江苏京信电子有限公司 | B3: 64.554 | C3: 64.554 | D3: 64.554 | E3: 65.270703 | F3: 69556.18 | G3: =+D3-E3 -> -0.71670269 | H3: =+G3*F3*188.8 -> -9411888 | N3: 전분기
A4: 上海李尔 | B4: 62.88 | C4: 62.88 | D4: 62.88 | E4: 65.270703 | F4: 108.08 | G4: =+D4-E4 -> -2.3907027 | H4: =+G4*F4*188.8 -> -48783.493 | N4: 3개월 평균
A5: 安波福连接器系统（中国）有限公司 | B5: 62.96208 | C5: 62.96208 | D5: 62.96208 | E5: 65.270703 | N5: 3개월 평균
A6: 江苏新进 | B6: 61.649 | C6: 62.398 | D6: 63.096 | E6: 65.270703 | F6: 788.28 | G6: =+D6-E6 -> -2.1747027 | H6: =+G6*F6*188.8 -> -323655.05 | N6: 전월
A7: 北京新进 | B7: 61.649 | C7: 63.398 | D7: 63.096 | E7: 65.270703 | F7: 763.38 | G7: =+D7-E7 -> -2.1747027 | H7: =+G7*F7*188.8 -> -313431.51 | N7: 전월
A8: 常州庆福 | B8: 61.649 | C8: 62.398 | D8: 63.096 | E8: 65.270703 | F8: 2836.39 | G8: =+D8-E8 -> -2.1747027 | H8: =+G8*F8*188.8 -> -1164576 | N8: 전월
A9: 盐城市晟广达汽车零部件有限公司 | B9: 61.649 | C9: 62.398 | D9: 63.096 | E9: 65.270703 | F9: 1251.8 | G9: =+D9-E9 -> -2.1747027 | H9: =+G9*F9*188.8 -> -513968.89 | N9: 전월
A10: 경신전선 본사 | B10: 12017 | C10: 11772 | D10: 12165 | E10: =+E9*188.8 -> 12323.109 | F10: 218211.84 | G10: =+D10-E10 -> -158.10867 | H10: =+G10*F10 -> -34501183 | N10: 2개월전월평균 원/KG
A11: KSCI | B11: 9550.31 | C11: 9775.93 | D11: =9941.35/1000 -> 9.94135 | E11: =+E10/1198 -> 10.286401 | F11: 39502.35 | G11: =+D11-E11 -> -0.34505123 | H11: =+G11*F11*1198 -> -16329140 | N11: 전월동가 평균 USD/TON
H12: =SUM(H3:H11) -> -62606627
H13: =+H12/175 -> -357752.15

Sheet ★손익요약
C3: ◇ 2월 손익 요약 | K3: (단위:RMB,톤,KM) | M3: ◇ 한화 환산 매출액 | O3: 195 | R3: (환율:195원, 단위: 백만원)
D4: 2026년 계획 | E4: 누계 실적 | F4: 진척율 | G4: 전 월 실 적 | H4: 계 획 | I4: 당 월 실 적 | J4: 계획비 | K4: 전월비 | N4: 전월 실 적 | O4: 계 획 | P4: 당 월 실 적 | Q4: 계획비 | R4: 전월비
C5: 매 출 액 | D5: =SUM(D6,D13) -> 3.8737793e+08 | E5: =E6+E13 -> 44629068 | F5: =+E5/D5 -> 0.11520808 | G5: 23919789 | H5: =E114 -> 24858017 | I5: =E63 -> 20709280 | J5: =+I5/H5 -> 0.83310263 | K5: =+I5/G5 -> 0.86578022 | M5: 매 출 액 | N5: =+G5*$O$3/1000000 -> 4664.3588 | O5: =+H5*$O$3/1000000 -> 4847.3134 | P5: =+I5*$O$3/1000000 -> 4038.3096 | Q5: =+P5/O5 -> 0.83310263 | R5: =+P5/N5 -> 0.86578022
C6: 일반시판 | D6: =SUM(D7:D11) -> 41433213 | E6: =SUM(E7:E11) -> 4054553.1 | F6: =+E6/D6 -> 0.09785756 | G6: 1933779.7 | H6: =E115 -> 1798464.8 | I6: =E64 -> 2120773.5 | J6: =+I6/H6 -> 1.1792132 | K6: =+I6/G6 -> 1.0966986 | M6: 일반시판 | N6: =+G6*$O$3/1000000 -> 377.08704 | O6: =+H6*$O$3/1000000 -> 350.70064 | P6: =+I6*$O$3/1000000 -> 413.55082 | Q6: =+P6/O6 -> 1.1792132 | R6: =+P6/N6 -> 1.0966986
C7: - 우즈코제 | D7: =P116 -> 13599029 | E7: =SUM(D65:O65) -> 152505.5 | F7: =+E7/D7 -> 0.011214441 | G7: 152505.5 | H7: =E116 -> 0 | I7: =E65 -> 0 | J7: =+I7/H7 -> #DIV/0! | K7: =+I7/G7 -> 0 | M7: - 우즈코제 | N7: =+G7*$O$3/1000000 -> 29.738573 | O7: =+H7*$O$3/1000000 -> 0 | P7: =+I7*$O$3/1000000 -> 0
C8: - 아센텍 | D8: =P117 -> 5984486.8 | E8: =SUM(D66:O66) -> 1768621 | F8: =+E8/D8 -> 0.29553427 | G8: 559463.68 | H8: =E117 -> 390823.63 | I8: =E66 -> 1209157.3 | J8: =+I8/H8 -> 3.0938694 | K8: =+I8/G8 -> 2.1612793 | M8: - 아센텍 | N8: =+G8*$O$3/1000000 -> 109.09542 | O8: =+H8*$O$3/1000000 -> 76.210607 | P8: =+I8*$O$3/1000000 -> 235.78567 | Q8: =+P8/O8 -> 3.0938694 | R8: =+P8/N8 -> 2.1612793
C9: - 성광다 | D9: =P118 -> 4269027.5 | E9: =SUM(D67:O67) -> 339848.03 | F9: =+E9/D9 -> 0.079607834 | G9: 120957.15 | H9: =E118 -> 278793.63 | I9: =E67 -> 218890.88 | J9: =+I9/H9 -> 0.78513587 | K9: =+I9/G9 -> 1.8096564 | M9: - 성광다 | N9: =+G9*$O$3/1000000 -> 23.586644 | O9: =+H9*$O$3/1000000 -> 54.364758 | P9: =+I9*$O$3/1000000 -> 42.683722 | Q9: =+P9/O9 -> 0.78513587 | R9: =+P9/N9 -> 1.8096564
C10: - 신진 | D10: =P119 -> 3120971.1 | E10: =SUM(D68:O68) -> 431601.6 | G10: 324228.2 | H10: =E119 -> 203818.52 | I10: =E68 -> 107373.4 | M10: - 신진 | N10: =+G10*$O$3/1000000 -> 63.224499 | O10: =+H10*$O$3/1000000 -> 39.744612 | P10: =+I10*$O$3/1000000 -> 20.937813 | Q10: =+P10/O10 -> 0.52680884 | R10: =+P10/N10 -> 0.33116614
C11: - 기타 | D11: =P120 -> 14459699 | E11: =SUM(D69:O69) -> 1361977.1 | F11: =+E11/D11 -> 0.094191245 | G11: 776625.16 | H11: =E120 -> 925029.06 | I11: =E69 -> 585351.89 | J11: =+I11/H11 -> 0.63279297 | K11: =+I11/G11 -> 0.75371224 | M11: - 기타 | N11: =+G11*$O$3/1000000 -> 151.44191 | O11: =+H11*$O$3/1000000 -> 180.38067 | P11: =+I11*$O$3/1000000 -> 114.14362 | Q11: =+P11/O11 -> 0.63279297 | R11: =+P11/N11 -> 0.75371224
C13: 경신계열 | D13: =SUM(D14:D18) -> 3.4594472e+08 | E13: =SUM(E14:E18) -> 40574515 | F13: =+E13/D13 -> 0.11728612 | G13: 21986009 | H13: =E122 -> 23059553 | I13: =E71 -> 18588506 | J13: =+I13/H13 -> 0.80610872 | K13: =+I13/G13 -> 0.84546979 | M13: 경신계열 | N13: =+G13*$O$3/1000000 -> 4287.2717 | O13: =+H13*$O$3/1000000 -> 4496.6128 | P13: =+I13*$O$3/1000000 -> 3624.7587 | Q13: =+P13/O13 -> 0.80610872 | R13: =+P13/N13 -> 0.84546979
C14: - 강소경신 | D14: =P123 -> 1.9610322e+08 | E14: =SUM(D72:O72) -> 25726125 | F14: =+E14/D14 -> 0.13118665 | G14: 13881608 | H14: =E123 -> 12806741 | I14: =E72 -> 11844517 | J14: =+I14/H14 -> 0.92486584 | K14: =+I14/G14 -> 0.85325255 | M14: - 강소경신 | N14: =+G14*$O$3/1000000 -> 2706.9135 | O14: =+H14*$O$3/1000000 -> 2497.3145 | P14: =+I14*$O$3/1000000 -> 2309.6809 | Q14: =+P14/O14 -> 0.92486584 | R14: =+P14/N14 -> 0.85325255
C15: - KSCI | D15: =P124 -> 87491665 | E15: =SUM(D73:O73) -> 6952930.4 | F15: =+E15/D15 -> 0.079469632 | G15: 3887259.4 | H15: =E124 -> 5713741.4 | I15: =E73 -> 3065671.1 | J15: =+I15/H15 -> 0.53654355 | K15: =+I15/G15 -> 0.78864588 | M15: - KSCI | N15: =+G15*$O$3/1000000 -> 758.01558 | O15: =+H15*$O$3/1000000 -> 1114.1796 | P15: =+I15*$O$3/1000000 -> 597.80586 | Q15: =+P15/O15 -> 0.53654355 | R15: =+P15/N15 -> 0.78864588
C16: - 경신 보림 B/B | D16: =P125 -> 35865802 | E16: =SUM(D74:O74) -> 3411233.3 | F16: =+E16/D16 -> 0.095111028 | G16: 1830721.1 | H16: =E125 -> 2144308.1 | I16: =E74 -> 1580512.2 | K16: =+I16/G16 -> 0.86332769 | M16: - 경신 보림 B/B | N16: =+G16*$O$3/1000000 -> 356.99062 | O16: =+H16*$O$3/1000000 -> 418.14008 | P16: =+I16*$O$3/1000000 -> 308.19988 | Q16: =+P16/O16 -> 0.73707329 | R16: =+P16/N16 -> 0.86332769
C17: - 전장사업부(상주) | E17: =SUM(D75:O75) -> 0 | G17: 0 | H17: 0 | I17: =E75 -> 0 | M17: - 전장사업부(상주) | N17: =+G17*$O$3/1000000 -> 0 | O17: =+H17*$O$3/1000000 -> 0 | P17: =+I17*$O$3/1000000 -> 0
C18: - KSCP (EV) | D18: =P126 -> 26484031 | E18: =SUM(D76:O76) -> 4484226.5 | F18: =+E18/D18 -> 0.16931813 | G18: 2386420.7 | H18: =E126 -> 2394762.2 | I18: =E76 -> 2097805.9 | J18: =+I18/H18 -> 0.87599758 | K18: =+I18/G18 -> 0.87905954 | M18: - KSCP (EV) | N18: =+G18*$O$3/1000000 -> 465.35203 | O18: =+H18*$O$3/1000000 -> 466.97862 | P18: =+I18*$O$3/1000000 -> 409.07214 | Q18: =+P18/O18 -> 0.87599758 | R18: =+P18/N18 -> 0.87905954
M19: 영업이익 | N19: =G47*195/1000000 -> 393.39067 | O19: =H47*195/1000000 -> 175.75585 | P19: =I47*195/1000000 -> 177.09384 | Q19: =+P19/O19 -> 1.0076128 | R19: =+P19/N19 -> 0.45017296
C20: 동 량(톤) | D20: =SUM(D21,D28) -> 4718118.1 | E20: =E21+E28 -> 467839.98 | F20: =+E20/D20 -> 0.099158175 | G20: 249868.97 | H20: =E128 -> 293011.4 | I20: =E79 -> 217971.01 | J20: =+I20/H20 -> 0.74389942 | K20: =+I20/G20 -> 0.87234125 | M20: 26년 매출계획 | N20: 누계실적 | O20: 영업이익계획 | P20: 누계실적
C21: 일반시판 | D21: =SUM(D22:D26) -> 390058.96 | E21: =SUM(E22:E27) -> 32653.07 | F21: =+E21/D21 -> 0.083713165 | G21: 16713.13 | H21: =E129 -> 15275.178 | I21: =E80 -> 15939.94 | J21: =+I21/H21 -> 1.0435191 | K21: =+I21/G21 -> 0.95373757 | M21: =D5*195 -> 7.5538697e+10 | N21: =E5*195 -> 8.7026684e+09 | O21: =D47*195 -> 4.4665016e+09 | P21: =E47*195 -> 5.7048451e+08
C22: - 우즈코제 | D22: =P130 -> 156157.8 | E22: =P81 -> 1909.42 | F22: =+E22/D22 -> 0.012227504 | G22: 1909.42 | H22: =E130 -> 0 | I22: =E81 -> 0 | J22: =+I22/H22 -> #DIV/0! | K22: =+I22/G22 -> 0 | N22: =N21/M21 -> 0.11520808 | O22: =O21/M21 -> 0.059128656 | P22: =P21/N21 -> 0.065552827 | Q22: =P21/O21 -> 0.12772513
C23: - 아센텍 | D23: =P131 -> 61412.939 | E23: =P82 -> 15347.17 | F23: =+E23/D23 -> 0.24990124 | G23: 4991.95 | H23: =E131 -> 4010.6409 | I23: =E82 -> 10355.22 | J23: =+I23/H23 -> 2.5819364 | K23: =+I23/G23 -> 2.0743838
C24: - 성광다 | D24: =P132 -> 43116.805 | E24: =P83 -> 3102.75 | F24: =+E24/D24 -> 0.071961501 | G24: 1144.84 | H24: =E132 -> 2815.7913 | I24: =E83 -> 1957.91 | J24: =+I24/H24 -> 0.69533206 | K24: =+I24/G24 -> 1.710204
C25: - 신진 | D25: =P133 -> 35545.713 | E25: =P84 -> 4211.31 | G25: 3223.91 | H25: =E133 -> 2321.3527 | I25: =E84 -> 987.4
C26: - 기타 | D26: =P134 -> 93825.706 | E26: =P85 -> 8082.42 | F26: =+E26/D26 -> 0.086142917 | G26: 5443.01 | H26: =E134 -> 6127.3931 | I26: =E85 -> 2639.41 | J26: =+I26/H26 -> 0.43075578 | K26: =+I26/G26 -> 0.48491735
G27: 0 | H27: =D135 -> 0 | I27: =E86 -> 0
C28: 경신계열 | D28: =SUM(D29:D32) -> 4328059.1 | E28: =SUM(E29:E32) -> 435186.91 | F28: =+E28/D28 -> 0.10055013 | G28: 233155.84 | H28: =E136 -> 277736.22 | I28: =E87 -> 202031.07 | J28: =+I28/H28 -> 0.72742068 | K28: =+I28/G28 -> 0.86650658
C29: - 강소경신 | D29: =P137 -> 2131647.1 | E29: =P88 -> 245269.41 | F29: =+E29/D29 -> 0.11506098 | G29: 132642.88 | H29: =E137 -> 139209.61 | I29: =E88 -> 112626.53 | J29: =+I29/H29 -> 0.80904281 | K29: =+I29/G29 -> 0.84909593
C30: - KSCI | D30: =P138 -> 902011.32 | E30: =P89 -> 50193.18 | F30: =+E30/D30 -> 0.055645843 | G30: 28411.88 | H30: =E138 -> 58906.862 | I30: =E89 -> 21781.3 | J30: =+I30/H30 -> 0.36975828 | K30: =+I30/G30 -> 0.7666265
C31: - 경신 보림 B/B | D31: =P139 -> 1294400.7 | E31: =P90 -> 139724.32 | F31: =+E31/D31 -> 0.10794518 | G31: 72101.08 | H31: =E139 -> 79619.752 | I31: =E90 -> 67623.24 | J31: =+I31/H31 -> 0.84932743 | K31: =+I31/G31 -> 0.93789497
C32: - 전장사업부(상주) | D32: =P140 -> 0 | E32: =P91 -> 0 | F32: =+E32/D32 -> #DIV/0! | G32: 0 | H32: =E140 -> 0 | I32: =E91 -> 0 | L32: =G32*1000 -> 0
C34: 수 량(KM) | D34: =SUM(D35,D42) -> 7.1763814e+08 | E34: =E35+E42 -> 78550847 | F34: =+E34/D34 -> 0.10945746 | G34: 41525388 | H34: =E141 -> 44207568 | I34: =E93 -> 37025459 | J34: =+I34/H34 -> 0.83753666 | K34: =+I34/G34 -> 0.89163427
C35: 일반시판 | D35: =SUM(D36:D40) -> 62107898 | E35: =SUM(E36:E41) -> 5363710 | F35: =+E35/D35 -> 0.086361159 | G35: 2881250 | H35: =E142 -> 2766620.6 | I35: =E94 -> 2482460 | J35: =+I35/H35 -> 0.89728964 | K35: =+I35/G35 -> 0.86159132
C36: - 우즈코제 | D36: =P143 -> 19744020 | E36: =P95 -> 117900 | F36: =+E36/D36 -> 0.0059714283 | G36: 117900 | H36: =E143 -> 0 | I36: =E95 -> 0 | J36: =+I36/H36 -> #DIV/0! | K36: =+I36/G36 -> 0
C37: - 아센텍 | D37: =P144 -> 8471367.7 | E37: =P96 -> 2093450 | F37: =+E37/D37 -> 0.24712066 | G37: 830500 | H37: =E144 -> 553232.18 | I37: =E96 -> 1262950 | J37: =+I37/H37 -> 2.2828571 | K37: =+I37/G37 -> 1.5207104
C38: - 성광다 | D38: =P145 -> 10329250 | E38: =P97 -> 893800 | F38: =+E38/D38 -> 0.086530968 | G38: 340500 | H38: =E145 -> 674563.27 | I38: =E97 -> 553300 | J38: =+I38/H38 -> 0.82023441 | K38: =+I38/G38 -> 1.6249633
C39: - 신진 | D39: =P146 -> 8602350 | E39: =P98 -> 1078400 | G39: 798550 | H39: =E146 -> 561786.12 | I39: =E98 -> 279850
C40: - 기타 | D40: =P147 -> 14960910 | E40: =P99 -> 1180160 | F40: =+E40/D40 -> 0.078882902 | G40: 793800 | H40: =E147 -> 977039.02 | I40: =E99 -> 386360 | J40: =+I40/H40 -> 0.39543968 | K40: =+I40/G40 -> 0.4867221
C42: 경신계열 | D42: =SUM(D43:D45) -> 6.5553024e+08 | E42: =SUM(E43:E45) -> 73187137 | F42: =+E42/D42 -> 0.11164571 | G42: 38644138 | H42: =E149 -> 41440948 | I42: =E101 -> 34542999 | J42: =+I42/H42 -> 0.83354752 | K42: =+I42/G42 -> 0.89387423
C43: - 강소경신 | D43: =P150 -> 3.142928e+08 | E43: =P102 -> 37783157 | F43: =+E43/D43 -> 0.12021643 | G43: 20194058 | H43: =E150 -> 20525244 | I43: =E102 -> 17589099 | J43: =+I43/H43 -> 0.85694958 | K43: =+I43/G43 -> 0.87100369
C44: - KSCI | D44: =P151 -> 31700085 | E44: =P103 -> 2252880 | F44: =+E44/D44 -> 0.071068579 | G44: 1319230 | H44: =E151 -> 2070209.6 | I44: =E103 -> 933650 | J44: =+I44/H44 -> 0.45099297 | K44: =+I44/G44 -> 0.70772344
C45: - 경신 보림 B/B | D45: =P152 -> 3.0953736e+08 | E45: =P104 -> 33151100 | F45: =+E45/D45 -> 0.10709886 | G45: 17130850 | H45: =E152 -> 18845494 | I45: =E104 -> 16020250 | K45: =+I45/G45 -> 0.93516959
...

Sheet ★전선업체별매출현황
A1: ▣ 고객별 매출현황
A3: 고객사 | B3: 매출 | C3: 영업이익 | D3: 영업이익률 | E3: 동가차이 | F3: 원인 | G3: 동가기준
A4: Kyungshin Cable international corporation | B4: 3098002.3 | C4: 492647.94 | D4: =C4/B4 -> 0.15902117 | E4: 50732.69 | G4: 전월 LME
A5: 江苏京信电子有限公司 | B5: 11969432 | C5: 214078.67 | D5: =C5/B5 -> 0.01788545 | E5: -992172.86 | G5: 전분기 상해동가
A6: 江苏新进汽车配件有限公司 | B6: 108505.78 | C6: 16066.076 | D6: =C6/B6 -> 0.14806655 | E6: 1474.61 | G6: 전월평균 상해동가
A7: 江苏阿现特传感器有限公司 | B7: 1221909.3 | C7: -57025.978 | D7: =C7/B7 -> -0.046669568 | E7: 15465.41 | F7: T4컴파운드 수입단가 인상 현지화 컴파운드 적용 예정 | G7: 전월평균 상해동가
A8: 晟广达电子（江苏）有限公司（盐城晟广达） | B8: 221199.35 | C8: 35869.323 | D8: =C8/B8 -> 0.16215836 | E8: 2924.08 | G8: 전월평균 상해동가
A9: 기타 | B9: 395244.85 | C9: 8283.1829 | D9: =C9/B9 -> 0.020957093 | E9: -5236.76 | G9: 전월평균 상해동가, 전분기 상해동가
A10: 安徽京信电子Kyungshin(안휘경신BB) | B10: 626186.5 | C10: -52687.467 | D10: =C10/B10 -> -0.084140215
A11: 青岛京信电子한국경신(QD청도경신BB) | B11: 202876.18 | C11: 75453.69 | D11: =C11/B11 -> 0.3719199
A12: 青岛即墨한국경신(GM즉묵경신BB) | B12: 58321.723 | C12: 23928.811 | D12: =C12/B12 -> 0.41028984
A13: 韩国甫林Bolim Co.,Ltd.(BB） | B13: 709796.21 | C13: 272899.7 | D13: =C13/B13 -> 0.38447613
A14: 합계 | B14: =SUM(B4:B13) -> 18611474 | C14: =SUM(C4:C13) -> 1029514 | D14: =C14/B14 -> 0.055316089

Sheet ★손익계산서
B1: 2 | J1: (단위: RMB)
B2: 구 분 | C2: [ 전 월 ] | D2: 매출구성비 | E2: [ 계 획 ] | F2: 매출구성비 | G2: [ 실 적 ] | H2: 매출구성비 | I2: [ 전월비 ] | J2: [ 계획비 ] | K2: [ 계획비 ]
B3: I. 총 매출액 | C3: 23919789 | D3: =C3/$C$3 -> 1 | E3: =E79+E155 -> 24858017 | F3: =+E3/$E$3 -> 1 | G3: =G79+G155 -> 20709280 | H3: =+G3/G3 -> 1 | I3: =+IF(AND(G3>0,C3>0),G3/C3,"") -> 0.86578022 | K3: =+IF(AND(I3>0,E3>0),G3/E3,"") -> 0.83310263
B4: 제품매출 | C4: 23271091 | D4: =C4/$C$3 -> 0.97288028 | E4: =E80+E156 -> 23682224 | F4: =+E4/$E$3 -> 0.95269964 | G4: =G80+G156 -> 20077030 | H4: =+G4/$G$3 -> 0.96947021 | I4: =+IF(AND(G4>0,C4>0),G4/C4,"") -> 0.86274554 | K4: =+IF(AND(I4>0,E4>0),G4/E4,"") -> 0.84776791
B5: 상품매출 | C5: 389149.87 | D5: =C5/$C$3 -> 0.016268951 | E5: =E81+E157 -> 914402.51 | F5: =+E5/$E$3 -> 0.036785013 | G5: =G81+G157 -> 426644.34 | H5: =+G5/$G$3 -> 0.020601602 | I5: =+IF(AND(G5>0,C5>0),G5/C5,"") -> 1.0963497 | K5: =+IF(AND(I5>0,E5>0),G5/E5,"") -> 0.46658265
B6: 기타매출 | C6: 259547.99 | D6: =C6/$C$3 -> 0.010850764 | E6: =E82+E158 -> 261390.66 | F6: =+E6/$E$3 -> 0.010515346 | G6: =G82+G158 -> 205605.65 | H6: =+G6/$G$3 -> 0.0099281893 | I6: =+IF(AND(G6>0,C6>0),G6/C6,"") -> 0.79216815 | K6: =+IF(AND(I6>0,E6>0),G6/E6,"") -> 0.78658375
B7: 매출수량(M) | I7: =+IF(AND(G7>0,C7>0),G7/C7,"") | K7: =+IF(AND(I7>0,E7>0),G7/E7,"")
B8: 내수 동중량(KG) | C8: 177767.89 | E8: =E83 -> 213392.61 | G8: =G83 -> 150347.77 | I8: =+IF(AND(G8>0,C8>0),G8/C8,"") -> 0.84575325 | K8: =+IF(AND(I8>0,E8>0),G8/E8,"") -> 0.70455939
B9: B/B 동중량(KG) | C9: 72101.08 | E9: =E84 -> 79619.752 | G9: =G84 -> 67623.24 | I9: =+IF(AND(G9>0,C9>0),G9/C9,"") -> 0.93789497 | K9: =+IF(AND(I9>0,E9>0),G9/E9,"") -> 0.84932743
B10: II.총 매출원가 | C10: 20033439 | D10: =C10/$C$3 -> 0.83752576 | E10: =E85+E159 -> 21734973 | F10: =+E10/$E$3 -> 0.87436471 | G10: =G85+G159 -> 18066689 | H10: =+G10/G3 -> 0.87239583 | I10: =+IF(AND(G10>0,C10>0),G10/C10,"") -> 0.90182666 | K10: =+IF(AND(I10>0,E10>0),G10/E10,"") -> 0.83122667
B11: 제품매출원가 | C11: 19807173 | D11: =C11/$C$3 -> 0.82806638 | E11: =E86+E160 -> 20844010 | F11: =+E11/$E$3 -> 0.83852261 | G11: =G86+G160 -> 17570900 | H11: =+G11/$G$3 -> 0.84845538 | I11: =+IF(AND(G11>0,C11>0),G11/C11,"") -> 0.88709782 | K11: =+IF(AND(I11>0,E11>0),G11/E11,"") -> 0.84297119
B12: 상품매출원가 | C12: 375973.11 | D12: =C12/$C$3 -> 0.015718078 | E12: =E87+E161 -> 755314.88 | F12: =+E12/$E$3 -> 0.030385162 | G12: =G87+G161 -> 454276.3 | H12: =+G12/$G$3 -> 0.021935881 | I12: =+IF(AND(G12>0,C12>0),G12/C12,"") -> 1.2082681 | K12: =+IF(AND(I12>0,E12>0),G12/E12,"") -> 0.60143962
B13: 반제품매출원가 | C13: 0 | E13: =E88+E162 -> 0 | G13: =G88+G162 -> 0
B14: 기타매출원가 | C14: -159006.69 | E14: =E89+E163 -> 0 | G14: =G89+G163 -> 10700.47
B15: 영업부가세 | C15: 9300 | D15: =C15/$C$3 -> 0.00038879942 | E15: =E90+E164 -> 135648.48 | F15: =+E15/$E$3 -> 0.0054569307 | G15: =G90+G164 -> 30812.89 | H15: =+G15/$G$3 -> 0.0014878784 | I15: =+IF(AND(G15>0,C15>0),G15/C15,"") -> 3.313214 | K15: =+IF(AND(I15>0,E15>0),G15/E15,"") -> 0.22715249
B16: III.매출 총이익 | C16: 3886349.5 | E16: =E91+E165 -> 3123044.3 | F16: =+E16/$E$3 -> 0.12563529 | G16: =G91+G165 -> 2642590.4 | I16: =+IF(AND(G16>0,C16>0),G16/C16,"") -> 0.67996725 | K16: =+IF(AND(I16>0,E16>0),G16/E16,"") -> 0.84615846
B17: 매출총이익율(%) | C17: 0.16247424 | E17: =E16/E3 -> 0.12563529 | G17: =G16/G3 -> 0.12760417 | I17: =+IF(AND(G17>0,C17>0),G17/C17,"") -> 0.7853809 | K17: =+IF(AND(I17>0,E17>0),G17/E17,"") -> 1.0156713
B18: IV.판매관리비 | C18: 1868961.4 | D18: =C18/$C$3 -> 0.07813453 | E18: =E93+E167 -> 2221732.2 | F18: =+E18/$E$3 -> 0.089376888 | G18: =G93+G167 -> 1734416.8 | H18: =+G18/G3 -> 0.083750707 | I18: =+IF(AND(G18>0,C18>0),G18/C18,"") -> 0.92801102 | K18: =+IF(AND(I18>0,E18>0),G18/E18,"") -> 0.7806597
B19: 급여 (52101000 - 工资板块) | C19: 356491.85 | D19: =C19/$C$3 -> 0.014903637 | E19: =E94+E168 -> 359423.6 | F19: =+E19/$E$3 -> 0.014459061 | G19: =G94+G168 -> 350699.29 | H19: =+G19/G3 -> 0.016934403 | I19: =+IF(AND(G19>0,C19>0),G19/C19,"") -> 0.98375121 | K19: =+IF(AND(I19>0,E19>0),G19/E19,"") -> 0.97572694
B20: 복리후생비 (52105000 - 福利费) | C20: 204324.93 | D20: =C20/$C$3 -> 0.0085420876 | E20: =E95+E169 -> 363580 | F20: =+E20/$E$3 -> 0.014626267 | G20: =G95+G169 -> 105739.45 | H20: =+G20/G3 -> 0.005105897 | I20: =+IF(AND(G20>0,C20>0),G20/C20,"") -> 0.51750636 | K20: =+IF(AND(I20>0,E20>0),G20/E20,"") -> 0.29082857
B21: 여비교통비 (52106000 - 差旅交通费) | C21: 18184.77 | D21: =C21/$C$3 -> 0.00076023958 | E21: =E96+E170 -> 11828.41 | F21: =+E21/$E$3 -> 0.00047583882 | G21: =G96+G170 -> 26166.35 | H21: =+G21/G3 -> 0.0012635084 | I21: =+IF(AND(G21>0,C21>0),G21/C21,"") -> 1.4389156 | K21: =+IF(AND(I21>0,E21>0),G21/E21,"") -> 2.2121613
B22: 접대비 (52107000 - 招待费) | C22: 366.15 | D22: =C22/$C$3 -> 1.530741e-05 | E22: =E97+E171 -> 5776.522 | F22: =+E22/$E$3 -> 0.00023238064 | G22: =G97+G171 -> 1235 | H22: =+G22/G3 -> 5.9635101e-05 | I22: =+IF(AND(G22>0,C22>0),G22/C22,"") -> 3.3729346 | K22: =+IF(AND(I22>0,E22>0),G22/E22,"") -> 0.21379647
B23: 통신비 (52108000 - 通信费) | C23: 8914.1 | D23: =C23/$C$3 -> 0.00037266634 | E23: =E98+E172 -> 7301.315 | F23: =+E23/$E$3 -> 0.00029372073 | G23: =G98+G172 -> 6382.59 | H23: =+G23/G3 -> 0.00030819951 | I23: =+IF(AND(G23>0,C23>0),G23/C23,"") -> 0.71601059 | K23: =+IF(AND(I23>0,E23>0),G23/E23,"") -> 0.87416992
B24: 수도광열비 (52109000 - 水电气费) | C24: 1868.59 | D24: 0 | E24: =E99+E173 -> 1645.0169 | F24: =+E24/$E$3 -> 6.6176512e-05 | G24: =G99+G173 -> 2265.97 | H24: =+G24/G3 -> 0.0001094181 | I24: =+IF(AND(G24>0,C24>0),G24/C24,"") -> 1.212663 | K24: =+IF(AND(I24>0,E24>0),G24/E24,"") -> 1.3774752
B25: 세금과공과 (52110000 - 税与费) | C25: 700 | D25: =C25/$C$3 -> 2.9264473e-05 | E25: =E100+E174 -> 0 | F25: =+E25/$E$3 -> 0 | G25: =G100+G174 -> 700 | H25: =+G25/G3 -> 3.3801272e-05 | I25: =+IF(AND(G25>0,C25>0),G25/C25,"") -> 1 | K25: =+IF(AND(I25>0,E25>0),G25/E25,"")
B26: 감가상각비 (52111000 - 折旧费) | C26: 92745.17 | D26: =C26/$C$3 -> 0.0038773407 | E26: =E101+E175 -> 93365.94 | F26: =+E26/$E$3 -> 0.0037559689 | G26: =G101+G175 -> 92745.17 | H26: =+G26/G3 -> 0.0044784353 | I26: =+IF(AND(G26>0,C26>0),G26/C26,"") -> 1 | K26: =+IF(AND(I26>0,E26>0),G26/E26,"") -> 0.99335122
B27: 지급임차료 (52112000 - 支付租金) | C27: 0 | D27: 0 | E27: =E102+E176 -> 0 | F27: =+E27/$E$3 -> 0 | G27: =G102+G176 -> 0 | H27: =+G27/G3 -> 0 | I27: =+IF(AND(G27>0,C27>0),G27/C27,"") | K27: =+IF(AND(I27>0,E27>0),G27/E27,"")
B28: 수선비 (52113000 - 维修费) | C28: 45699.75 | D28: 0 | E28: =E103+E177 -> 20000 | F28: =+E28/$E$3 -> 0.00080456939 | G28: =G103+G177 -> 93577.1 | H28: =+G28/G3 -> 0.0045186072 | I28: =+IF(AND(G28>0,C28>0),G28/C28,"") -> 2.0476502 | K28: =+IF(AND(I28>0,E28>0),G28/E28,"") -> 4.678855 | L28: 소방유지비 42,453
B29: 보험료 (52114000 - 保险费) | C29: 27342.49 | D29: =C29/$C$3 -> 0.0011430908 | E29: =E104+E178 -> 53267.14 | F29: =+E29/$E$3 -> 0.0021428555 | G29: =G104+G178 -> 25825.84 | H29: =+G29/G3 -> 0.0012470661 | I29: =+IF(AND(G29>0,C29>0),G29/C29,"") -> 0.94453139 | K29: =+IF(AND(I29>0,E29>0),G29/E29,"") -> 0.48483624
B30: 차량유지비 (52115000 - 车辆费) | C30: 31447.37 | D30: =C30/$C$3 -> 0.001314701 | E30: =E105+E179 -> 34734 | F30: =+E30/$E$3 -> 0.0013972957 | G30: =G105+G179 -> 31925.21 | H30: =+G30/G3 -> 0.0015415896 | I30: =+IF(AND(G30>0,C30>0),G30/C30,"") -> 1.0151949 | K30: =+IF(AND(I30>0,E30>0),G30/E30,"") -> 0.91913428
B31: 경상연구개발비 (52116000 - 经常研究开发费用) | C31: 186214 | D31: 0 | E31: =E106+E180 -> 21094.31 | F31: =+E31/$E$3 -> 0.00084859181 | G31: =G106+G180 -> 0 | H31: =+G31/G3 -> 0 | I31: =+IF(AND(G31>0,C31>0),G31/C31,"") | K31: =+IF(AND(I31>0,E31>0),G31/E31,"") -> 0
B32: 운반비 (52117000 - 运费(판)_운반비) | C32: 343959.92 | D32: =C32/$C$3 -> 0.014379722 | E32: =E107+E181 -> 595023.2 | F32: =+E32/$E$3 -> 0.023936873 | G32: =G107+G181 -> 295780.08 | H32: =+G32/G3 -> 0.01428249 | I32: =+IF(AND(G32>0,C32>0),G32/C32,"") -> 0.85992601 | K32: =+IF(AND(I32>0,E32>0),G32/E32,"") -> 0.49708999
B33: 교육훈련비 (52118000 - 教育训练费) | C33: 6944.85 | D33: =C33/$C$3 -> 0.0002903391 | E33: =E108+E182 -> 2450.0152 | F33: =+E33/$E$3 -> 9.8560361e-05 | G33: =G108+G182 -> 2456.31 | H33: =+G33/G3 -> 0.00011860915 | I33: =+IF(AND(G33>0,C33>0),G33/C33,"") -> 0.35368798 | K33: =+IF(AND(I33>0,E33>0),G33/E33,"") -> 1.0025693
B34: 도서인쇄비 (52119000 - 图书印刷费) | C34: 0 | D34: 0 | E34: =E109+E183 -> 0 | F34: =+E34/$E$3 -> 0 | G34: =G109+G183 -> 0 | H34: =+G34/G3 -> 0 | I34: =+IF(AND(G34>0,C34>0),G34/C34,"") | K34: =+IF(AND(I34>0,E34>0),G34/E34,"")
B35: 회의비 (52120000 - 会议费) | C35: 0 | D35: 0 | E35: =E110+E184 -> 0 | F35: =+E35/$E$3 -> 0 | G35: =G110+G184 -> 0 | H35: =+G35/G3 -> 0 | I35: =+IF(AND(G35>0,C35>0),G35/C35,"") | K35: =+IF(AND(I35>0,E35>0),G35/E35,"")
B36: 포장비 (52121000 - 包装费) | C36: 0 | D36: 0 | E36: =E111+E185 -> 0 | F36: =+E36/$E$3 -> 0 | G36: =G111+G185 -> 0 | H36: =+G36/G3 -> 0 | I36: =+IF(AND(G36>0,C36>0),G36/C36,"") | K36: =+IF(AND(I36>0,E36>0),G36/E36,"")
B37: 사무용품비 (52122000 - 办公用品费) | C37: 35614.8 | D37: =C37/$C$3 -> 0.0014889262 | E37: =E112+E186 -> 22550 | F37: =+E37/$E$3 -> 0.00090715199 | G37: =G112+G186 -> 18968.81 | H37: =+G37/G3 -> 0.00091595701 | I37: =+IF(AND(G37>0,C37>0),G37/C37,"") -> 0.53261032 | K37: =+IF(AND(I37>0,E37>0),G37/E37,"") -> 0.84118891
B38: 소모품비 (52123000 - 消耗品费) | C38: 1000.62 | D38: 0 | E38: =E113+E187 -> 0 | F38: =+E38/$E$3 -> 0 | G38: =G113+G187 -> 977.09 | H38: =+G38/G3 -> 4.7181264e-05 | I38: =+IF(AND(G38>0,C38>0),G38/C38,"") -> 0.97648458 | K38: =+IF(AND(I38>0,E38>0),G38/E38,"")
B39: 지급수수료 (52124000 - 手续费) | C39: 36903.24 | D39: =C39/$C$3 -> 0.0015427912 | E39: =E114+E188 -> 156048.28 | F39: =+E39/$E$3 -> 0.0062775837 | G39: =G114+G188 -> 252377.25 | H39: =+G39/G3 -> 0.012186674 | I39: =+IF(AND(G39>0,C39>0),G39/C39,"") -> 6.8388914 | K39: =+IF(AND(I39>0,E39>0),G39/E39,"") -> 1.6173023 | L39: 세무사 연비용, IT 1~2월비용
B40: 보관료 (52125000 - 保管费) | C40: 0 | D40: 0 | E40: =E115+E189 -> 0 | F40: =+E40/$E$3 -> 0 | G40: =G115+G189 -> 0 | H40: =+G40/G3 -> 0 | I40: =+IF(AND(G40>0,C40>0),G40/C40,"") | K40: =+IF(AND(I40>0,E40>0),G40/E40,"")
...

Sheet ★손익계산서 (월별)
B1: 2026년 월별 손익계산서 | D1: (단위: RMB) | P1: (단위: RMB)
B2: 구 분 | C2: 2026년 누계 | D2: 2025.12 | E2: 2026.01 | F2: 2026.02 | G2: 2026.03 | H2: 2026.04 | I2: 2026.05 | J2: 2026.06 | K2: 2026.07 | L2: 2026.08 | M2: 2026.09 | N2: 2026.10 | O2: 2026.11 | P2: 2026.12
B3: I. 총 매출액 | C3: =SUM(E3:P3) -> 44629068 | D3: =D4+D8+D12 -> 25693686 | E3: =E4+E8+E12 -> 23919789 | F3: =F4+F8+F12 -> 20709280 | G3: =G4+G8+G12 -> 0 | H3: =H4+H8+H12 -> 0 | I3: =I4+I8+I12 -> 0 | J3: =J4+J8+J12 -> 0 | K3: =K4+K8+K12 -> 0 | ... P3: =P4+P8+P12 -> 0
B4: 제품매출 | C4: =SUM(E4:P4) -> 43348121 | D4: =D81+D164 -> 25042763 | E4: =E81+E164 -> 23271091 | F4: =F81+F164 -> 20077030 | G4: =G81+G164 -> 0 | H4: =H81+H164 -> 0 | I4: =I81+I164 -> 0 | J4: =J81+J164 -> 0 | K4: =K81+K164 -> 0 | ... P4: =P81+P164 -> 0
B5: (사업부별) | C5: =SUM(E5:P5) -> 0
B6: 전선 | C6: =SUM(E6:P6) -> 38863894 | D6: =D81 -> 22841240 | E6: =E81 -> 20884670 | F6: =F81 -> 17979224 | G6: =G81 -> 0 | H6: =H81 -> 0 | I6: =I81 -> 0 | J6: =J81 -> 0 | K6: =K81 -> 0 | ... P6: =P81 -> 0
B7: 전장 | C7: =SUM(E7:P7) -> 4484226.5 | D7: =D164 -> 2201522.9 | E7: =E164 -> 2386420.7 | F7: =F164 -> 2097805.9 | G7: =G164 -> 0 | H7: =H164 -> 0 | I7: =I164 -> 0 | J7: =J164 -> 0 | K7: =K164 -> 0 | ... P7: =P164 -> 0
B8: 상품매출 | C8: =SUM(E8:P8) -> 815794.21 | D8: =SUM(D10:D11) -> 239827.8 | E8: =SUM(E10:E11) -> 389149.87 | F8: =SUM(F10:F11) -> 426644.34 | G8: =SUM(G10:G11) -> 0 | H8: =SUM(H10:H11) -> 0 | I8: =SUM(I10:I11) -> 0 | J8: =SUM(J10:J11) -> 0 | K8: =SUM(K10:K11) -> 0 | ... P8: =SUM(P10:P11) -> 0
B9: (사업부별) | C9: =SUM(E9:P9) -> 0
B10: 전선 | C10: =SUM(E10:P10) -> 815794.21 | D10: =D94 -> 239827.8 | E10: =E94 -> 389149.87 | F10: =F94 -> 426644.34 | G10: =G94 -> 0 | H10: =H94 -> 0 | I10: =I94 -> 0 | J10: =J94 -> 0 | K10: =K94 -> 0 | ... P10: =P94 -> 0
B11: 전장 | C11: =SUM(E11:P11) -> 0 | E11: 0
B12: 기타매출 | C12: =SUM(E12:P12) -> 465153.64 | D12: =D95+D170 -> 411095.75 | E12: =E95+E170 -> 259547.99 | F12: =F95+F170 -> 205605.65 | G12: =G95+G170 -> 0 | H12: =H95+H170 -> 0 | I12: =I95+I170 -> 0 | J12: =J95+J170 -> 0 | K12: =K95+K170 -> 0 | ... P12: =P95+P170 -> 0
B13: II.총 매출원가 | C13: =SUM(E13:P13) -> 38100129 | D13: =SUM(D14:D17) -> 22700123 | E13: =SUM(E14:E17) -> 20033439 | F13: =SUM(F14:F17) -> 18066689 | G13: =SUM(G14:G17) -> 0 | H13: =SUM(H14:H17) -> 0 | I13: =SUM(I14:I17) -> 0 | J13: =SUM(J14:J17) -> 0 | K13: =SUM(K14:K17) -> 0 | ... P13: =SUM(P14:P17) -> 0
B14: 제품매출원가 | C14: =SUM(E14:P14) -> 37378073 | D14: =D97+D172 -> 21988989 | E14: =E97+E172 -> 19807173 | F14: =F97+F172 -> 17570900 | G14: =G97+G172 -> 0 | H14: =H97+H172 -> 0 | I14: =I97+I172 -> 0 | J14: =J97+J172 -> 0 | K14: =K97+K172 -> 0 | ... P14: =P97+P172 -> 0
B15: 상품매출원가 | C15: =SUM(E15:P15) -> 830249.41 | D15: =D98+D173 -> 288860.99 | E15: =E98+E173 -> 375973.11 | F15: =F98+F173 -> 454276.3 | G15: =G98+G173 -> 0 | H15: =H98+H173 -> 0 | I15: =I98+I173 -> 0 | J15: =J98+J173 -> 0 | K15: =K98+K173 -> 0 | ... P15: =P98+P173 -> 0
B16: 기타매출원가 | C16: =SUM(E16:P16) -> -148306.22 | D16: =D99+D174 -> 2513.91 | E16: =E99+E174 -> -159006.69 | F16: =F99+F174 -> 10700.47 | G16: =G99+G174 -> 0 | H16: =H99+H174 -> 0 | I16: =I99+I174 -> 0 | J16: =J99+J174 -> 0 | K16: =K99+K174 -> 0 | ... P16: =P99+P174 -> 0
B17: 영업부가세 | C17: =SUM(E17:P17) -> 40112.89 | D17: =D100+D175 -> 419759.64 | E17: =E100+E175 -> 9300 | F17: =F100+F175 -> 30812.89 | G17: =G100+G175 -> 0 | H17: =H100+H175 -> 0 | I17: =I100+I175 -> 0 | J17: =J100+J175 -> 0 | K17: =K100+K175 -> 0 | ... P17: =P100+P175 -> 0
B18: III.매출 총이익 | C18: =+C3-C13 -> 6528939.9 | D18: =D3-D13 -> 2993562.7 | E18: =E3-E13 -> 3886349.5 | F18: =F3-F13 -> 2642590.4 | G18: =G3-G13 -> 0 | H18: =H3-H13 -> 0 | I18: =I3-I13 -> 0 | J18: =J3-J13 -> 0 | K18: =K3-K13 -> 0 | ... P18: =P3-P13 -> 0
B19: 매출총이익율(%) | C19: =+C18/C3 -> 0.14629344 | D19: =+D18/D3 -> 0.11650966 | E19: =+E18/E3 -> 0.16247424 | F19: =+F18/F3 -> 0.12760417 | G19: =+G18/G3 -> #DIV/0! | H19: =+H18/H3 -> #DIV/0! | I19: =+I18/I3 -> #DIV/0! | J19: =+J18/J3 -> #DIV/0! | ... P19: =+P18/P3 -> #DIV/0!
B20: IV.판매관리비 | C20: =SUM(E20:P20) -> 3603378.3 | D20: =SUM(D21:D47) -> 3005587 | E20: =SUM(E21:E47) -> 1868961.4 | F20: =SUM(F21:F47) -> 1734416.8 | G20: =SUM(G21:G47) -> 0 | H20: =SUM(H21:H47) -> 0 | I20: =SUM(I21:I47) -> 0 | J20: =SUM(J21:J47) -> 0 | K20: =SUM(K21:K47) -> 0 | ... P20: =SUM(P21:P47) -> 0
B21: 급여 | C21: =SUM(E21:P21) -> 707191.14 | D21: =D104+D179 -> 455188.93 | E21: =E104+E179 -> 356491.85 | F21: =F104+F179 -> 350699.29 | G21: =G104+G179 -> 0 | H21: =H104+H179 -> 0 | I21: =I104+I179 -> 0 | J21: =J104+J179 -> 0 | K21: =K104+K179 -> 0 | ... P21: =P104+P179 -> 0
B22: 복리후생비 | C22: =SUM(E22:P22) -> 310064.38 | D22: =D105+D180 -> 177065.75 | E22: =E105+E180 -> 204324.93 | F22: =F105+F180 -> 105739.45 | G22: =G105+G180 -> 0 | H22: =H105+H180 -> 0 | I22: =I105+I180 -> 0 | J22: =J105+J180 -> 0 | K22: =K105+K180 -> 0 | ... P22: =P105+P180 -> 0
B23: 여비교통비 | C23: =SUM(E23:P23) -> 44351.12 | D23: =D106+D181 -> 11187.54 | E23: =E106+E181 -> 18184.77 | F23: =F106+F181 -> 26166.35 | G23: =G106+G181 -> 0 | H23: =H106+H181 -> 0 | I23: =I106+I181 -> 0 | J23: =J106+J181 -> 0 | K23: =K106+K181 -> 0 | ... P23: =P106+P181 -> 0
B24: 접대비 | C24: =SUM(E24:P24) -> 1601.15 | D24: =D107+D182 -> 770 | E24: =E107+E182 -> 366.15 | F24: =F107+F182 -> 1235 | G24: =G107+G182 -> 0 | H24: =H107+H182 -> 0 | I24: =I107+I182 -> 0 | J24: =J107+J182 -> 0 | K24: =K107+K182 -> 0 | ... P24: =P107+P182 -> 0
B25: 통신비 | C25: =SUM(E25:P25) -> 15296.69 | D25: =D108+D183 -> 8847.53 | E25: =E108+E183 -> 8914.1 | F25: =F108+F183 -> 6382.59 | G25: =G108+G183 -> 0 | H25: =H108+H183 -> 0 | I25: =I108+I183 -> 0 | J25: =J108+J183 -> 0 | K25: =K108+K183 -> 0 | ... P25: =P108+P183 -> 0
B26: 수도광열비 | C26: =SUM(E26:P26) -> 4134.56 | D26: =D109+D184 -> 2115.84 | E26: =E109+E184 -> 1868.59 | F26: =F109+F184 -> 2265.97 | G26: =G109+G184 -> 0 | H26: =H109+H184 -> 0 | I26: =I109+I184 -> 0 | J26: =J109+J184 -> 0 | K26: =K109+K184 -> 0 | ... P26: =P109+P184 -> 0
B27: 세금과공과 | C27: =SUM(E27:P27) -> 1400 | D27: =D110+D185 -> 0 | E27: =E110+E185 -> 700 | F27: =F110+F185 -> 700 | G27: =G110+G185 -> 0 | H27: =H110+H185 -> 0 | I27: =I110+I185 -> 0 | J27: =J110+J185 -> 0 | K27: =K110+K185 -> 0 | ... P27: =P110+P185 -> 0
B28: 감가상각비 | C28: =SUM(E28:P28) -> 185490.34 | D28: =D111+D186 -> 93365.94 | E28: =E111+E186 -> 92745.17 | F28: =F111+F186 -> 92745.17 | G28: =G111+G186 -> 0 | H28: =H111+H186 -> 0 | I28: =I111+I186 -> 0 | J28: =J111+J186 -> 0 | K28: =K111+K186 -> 0 | ... P28: =P111+P186 -> 0
B29: 지급임차료 | C29: =SUM(E29:P29) -> 0 | D29: =D112+D187 -> 0 | E29: =E112+E187 -> 0 | F29: =F112+F187 -> 0 | G29: =G112+G187 -> 0 | H29: =H112+H187 -> 0 | I29: =I112+I187 -> 0 | J29: =J112+J187 -> 0 | K29: =K112+K187 -> 0 | ... P29: =P112+P187 -> 0
B30: 수선비 | C30: =SUM(E30:P30) -> 139276.85 | D30: =D113+D188 -> 57783.33 | E30: =E113+E188 -> 45699.75 | F30: =F113+F188 -> 93577.1 | G30: =G113+G188 -> 0 | H30: =H113+H188 -> 0 | I30: =I113+I188 -> 0 | J30: =J113+J188 -> 0 | K30: =K113+K188 -> 0 | ... P30: =P113+P188 -> 0
B31: 보험료 | C31: =SUM(E31:P31) -> 53168.33 | D31: =D114+D189 -> 26138.91 | E31: =E114+E189 -> 27342.49 | F31: =F114+F189 -> 25825.84 | G31: =G114+G189 -> 0 | H31: =H114+H189 -> 0 | I31: =I114+I189 -> 0 | J31: =J114+J189 -> 0 | K31: =K114+K189 -> 0 | ... P31: =P114+P189 -> 0
B32: 차량유지비 | C32: =SUM(E32:P32) -> 63372.58 | D32: =D115+D190 -> 36611.24 | E32: =E115+E190 -> 31447.37 | F32: =F115+F190 -> 31925.21 | G32: =G115+G190 -> 0 | H32: =H115+H190 -> 0 | I32: =I115+I190 -> 0 | J32: =J115+J190 -> 0 | K32: =K115+K190 -> 0 | ... P32: =P115+P190 -> 0
... B47: 잡비 | C47: =SUM(E47:P47) -> 5000 | D47: =D130+D205 -> 0 | E47: =E130+E205 -> 5000 | F47: =F130+F205 -> 0 | G47: =G130+G205 -> 0 | H47: =H130+H205 -> 0 | I47: =I130+I205 -> 0 | J47: =J130+J205 -> 0 | K47: =K130+K205 -> 0 | ... P47: =P130+P205 -> 0
B48: V.영업 이익 | C48: =SUM(E48:P48) -> 2925561.6 | D48: =D3-D13-D20 -> -12024.33 | E48: =E3-E13-E20 -> 2017388.1 | F48: =F3-F13-F20 -> 908173.55 | G48: =G3-G13-G20 -> 0 | H48: =H3-H13-H20 -> 0 | I48: =I3-I13-I20 -> 0 | J48: =J3-J13-J20 -> 0 | K48: =K3-K13-K20 -> 0 | ... P48: =P3-P13-P20 -> 0
B49: 영업이익율(%) | C49: =+C48/C3 -> 0.065552827 | D49: =+D48/D3 -> -0.00046798774 | E49: =+E48/E3 -> 0.084339711 | F49: =+F48/F3 -> 0.043853459 | G49: =+G48/G3 -> #DIV/0! | H49: =+H48/H3 -> #DIV/0! | I49: =+I48/I3 -> #DIV/0! | J49: =+J48/J3 -> #DIV/0! | ... P49: =+P48/P3 -> #DIV/0!
B50: - 영업외 수익 | C50: =SUM(E50:P50) -> 759159.79 | D50: =SUM(D51:D57) -> 2489457.8 | E50: =SUM(E51:E57) -> 364965.92 | F50: =SUM(F51:F57) -> 394193.87 | G50: =SUM(G51:G57) -> 0 | H50: =SUM(H51:H57) -> 0 | I50: =SUM(I51:I57) -> 0 | J50: =SUM(J51:J57) -> 0 | K50: =SUM(K51:K57) -> 0 | ... P50: =SUM(P51:P57) -> 0
B51: 단기투자자산익 | C51: =SUM(E51:P51) -> 0 | D51: =D134+D210 -> 0 | E51: =E134+E210 -> 0 | F51: =F134+F210 -> 0 | G51: =G134+G210 -> 0 | H51: =H134+H210 -> 0 | I51: =I134+I210 -> 0 | J51: =J134+J210 -> 0 | K51: =K134+K210 -> 0 | ... P51: =P134+P210 -> 0
B52: 외환차익 | C52: =SUM(E52:P52) -> 674695.99 | D52: =D135+D211 -> 1839249.6 | E52: =E135+E211 -> 327515.19 | F52: =F135+F211 -> 347180.8 | G52: =G135+G211 -> 0 | H52: =H135+H211 -> 0 | I52: =I135+I211 -> 0 | J52: =J135+J211 -> 0 | K52: =K135+K211 -> 0 | ... P52: =P135+P211 -> 0
B53: 외화환산이익 | C53: =SUM(E53:P53) -> 0 | D53: =D136+D212 -> 0 | E53: =E136+E212 -> 0 | F53: =F136+F212 -> 0 | G53: =G136+G212 -> 0 | H53: =H136+H212 -> 0 | I53: =I136+I212 -> 0 | J53: =J136+J212 -> 0 | K53: =K136+K212 -> 0 | ... P53: =P136+P212 -> 0
B54: 전기오류수정이익 | C54: =SUM(E54:P54) -> 0 | D54: =D137+D213 -> 0 | E54: =E137+E213 -> 0 | F54: =F137+F213 -> 0 | G54: =G137+G213 -> 0 | H54: =H137+H213 -> 0 | I54: =I137+I213 -> 0 | J54: =J137+J213 -> 0 | K54: =K137+K213 -> 0 | ... P54: =P137+P213 -> 0
...

Sheet ★제조원가명세서
B1: ■ 2월 제조원가 명세서 | K1: (단위: RMB)
C2: [ 전 월 ] | D2: 구성비 | E2: [ 계 획 ] | F2: 구성비 | G2: [ 실 적 ] | H2: 구성비 | I2: [ 전월비 ] | J2: [ 계획비 ] | K2: 비 고
B3: 1.재료비 | C3: 17281645 | D3: =+C3/$C$38 -> 0.85917743 | E3: =E46+E89 -> 17750199 | F3: =+E3/$E$38 -> 0.85157313 | G3: =G4+G5+G6-G7 -> 12559793 | H3: =+G3/$G$38 -> 0.8314336 | I3: =+IF(AND(C3>0,G3>0),G3/C3,) -> 0.72677067 | J3: =+IF(AND(E3>0,G3>0),G3/E3,) -> 0.70758603
B4: (1) 기초 재고 | C4: 12762105 | D4: =+C4/$C$38 -> 0.63448313 | E4: =E47+E90 -> 1856927 | F4: =+E4/$E$38 -> 0.089086844 | G4: =G47+G90 -> 11024319 | H4: =+G4/$G$38 -> 0.72978824 | I4: =+IF(AND(C4>0,G4>0),G4/C4,) -> 0.86383233 | J4: =+IF(AND(E4>0,G4>0),G4/E4,) -> 5.9368615
B5: (2) 당기 매입액 | C5: 15543749 | D5: =+C5/$C$38 -> 0.77277586 | E5: =E48+E91 -> 0 | F5: =+E5/$E$38 -> 0 | G5: =G48+G91 -> 16059743 | H5: =+G5/$G$38 -> 1.0631235 | I5: =+IF(AND(C5>0,G5>0),G5/C5,) -> 1.0331963 | J5: =+IF(AND(E5>0,G5>0),G5/E5,) -> 0
B6: (3) 타계정대체 원재료 | C6: 110.3 | D6: =+C6/$E$38 -> 5.2916882e-06 | E6: =E49+E92 -> 0 | F6: =+E6/$E$38 -> 0 | G6: =G49+G92 -> 73.82 | H6: =+G6/$G$38 -> 4.886739e-06 | I6: =+IF(AND(C6>0,G6>0),G6/C6,) -> 0.66926564 | J6: =+IF(AND(E6>0,G6>0),G6/E6,) -> 0
B7: (4) 기말 재고액 | C7: 11024319 | D7: =+C7/$C$38 -> 0.54808704 | E7: =E50+E93 -> 0 | F7: =+E7/$E$38 -> 0 | G7: =G50+G93 -> 14524343 | H7: =+G7/$G$38 -> 0.96148298 | I7: =+IF(AND(C7>0,G7>0),G7/C7,) -> 1.3174822 | J7: =+IF(AND(E7>0,G7>0),G7/E7,) -> 0
B8: 2. 노무비 | C8: 855892.53 | D8: =+C8/$C$38 -> 0.04255171 | E8: =E9 -> 801134.12 | F8: =+E8/$E$38 -> 0.038434741 | G8: =+G9 -> 792246.67 | H8: =+G8/$G$38 -> 0.052445173 | I8: =+IF(AND(C8>0,G8>0),G8/C8,) -> 0.92563802 | J8: =+IF(AND(E8>0,G8>0),G8/E8,) -> 0.98890641
B9: 1) 급여 | C9: 855892.53 | D9: =+C9/$C$38 -> 0.04255171 | E9: =E52+E95 -> 801134.12 | F9: =+E9/$E$38 -> 0.038434741 | G9: =G52+G95 -> 792246.67 | H9: =+G9/$G$38 -> 0.052445173 | I9: =+IF(AND(C9>0,G9>0),G9/C9,) -> 0.92563802 | J9: =+IF(AND(E9>0,G9>0),G9/E9,) -> 0.98890641
B10: 3. 제조경비 | C10: 1976637.2 | D10: =+C10/$C$38 -> 0.098270858 | E10: =SUM(E11:E37) -> 2292677 | F10: =+E10/$E$38 -> 0.10999213 | G10: =+SUM(G11:G37) -> 1754149.1 | H10: =+G10/$G$38 -> 0.11612122 | I10: =+IF(AND(C10>0,G10>0),G10/C10,) -> 0.88744109 | J10: =+IF(AND(E10>0,G10>0),G10/E10,) -> 0.76510955
B11: 1) 복리후생비 (61301000 - 福利费) | C11: 96008.11 | D11: =+C11/$C$38 -> 0.0047731568 | E11: =E54+E97 -> 159588 | F11: =+E11/$E$38 -> 0.0076563004 | G11: =G54+G97 -> 94406.66 | H11: =+G11/$G$38 -> 0.0062495354 | I11: =+IF(AND(C11>0,G11>0),G11/C11,) -> 0.98331964 | J11: =+IF(AND(E11>0,G11>0),G11/E11,) -> 0.5915649
B12: 2) 여비교통비 (61302000 - 差旅交通费) | C12: 0 | D12: =+C12/$E$38 -> 0 | E12: =E55+E98 -> 0 | F12: =+E12/$E$38 -> 0 | G12: =G55+G98 -> 0 | H12: =+G12/$G$38 -> 0 | I12: =+IF(AND(C12>0,G12>0),G12/C12,) -> 0 | J12: =+IF(AND(E12>0,G12>0),G12/E12,) -> 0
B13: 3) 접대비 (61303000 - 招待费) | C13: 0 | D13: =+C13/$E$38 -> 0 | E13: =E56+E99 -> 0 | F13: =+E13/$E$38 -> 0 | G13: =G56+G99 -> 0 | H13: =+G13/$G$38 -> 0 | I13: =+IF(AND(C13>0,G13>0),G13/C13,) -> 0 | J13: =+IF(AND(E13>0,G13>0),G13/E13,) -> 0
B14: 4) 통신비 (61304000 - 通信费) | C14: 0 | D14: =+C14/$E$38 -> 0 | E14: =E57+E100 -> 0 | F14: =+E14/$E$38 -> 0 | G14: =G57+G100 -> 0 | H14: =+G14/$G$38 -> 0 | I14: =+IF(AND(C14>0,G14>0),G14/C14,) -> 0 | J14: =+IF(AND(E14>0,G14>0),G14/E14,) -> 0
B15: 5) 수도광열비 (61305000 - 水电气费) | C15: 323033.87 | D15: =+C15/$C$38 -> 0.016060011 | E15: =E58+E101 -> 339876.21 | F15: =+E15/$E$38 -> 0.016305702 | G15: =G58+G101 -> 328478.14 | H15: =+G15/$G$38 -> 0.021744608 | I15: =+IF(AND(C15>0,G15>0),G15/C15,) -> 1.0168536 | J15: =+IF(AND(E15>0,G15>0),G15/E15,) -> 0.96646406
B16: 6) 세금과공과 (61306000 - 税金以及附加) | C16: 0 | D16: =+C16/$C$38 -> 0 | E16: =E59+E102 -> 0 | F16: =+E16/$E$38 -> 0 | G16: =G59+G102 -> 0 | H16: =+G16/$G$38 -> 0 | I16: =+IF(AND(C16>0,G16>0),G16/C16,) -> 0 | J16: =+IF(AND(E16>0,G16>0),G16/E16,) -> 0
B17: 7) 감가상각비 (61307000 - 折旧费) | C17: 923164.16 | D17: =+C17/$C$38 -> 0.045896199 | E17: =E60+E103 -> 931228.21 | F17: =+E17/$E$38 -> 0.044676059 | G17: =G60+G103 -> 931848.98 | H17: =+G17/$G$38 -> 0.061686572 | I17: =+IF(AND(C17>0,G17>0),G17/C17,) -> 1.0094077 | J17: =+IF(AND(E17>0,G17>0),G17/E17,) -> 1.0006666
B18: 8) 지급임차료 (61308000 - 支付租金) | C18: 0 | D18: =+C18/$C$38 -> 0 | E18: =E61+E104 -> 0 | F18: =+E18/$E$38 -> 0 | G18: =G61+G104 -> 13805.31 | H18: =+G18/$G$38 -> 0.0009138844 | I18: =+IF(AND(C18>0,G18>0),G18/C18,) -> 0 | J18: =+IF(AND(E18>0,G18>0),G18/E18,) -> 0
B19: 9) 수선비 (维修费) | C19: 4481.31 | D19: =+C19/$C$38 -> 0.00022279363 | E19: =E62+E105 -> 56803.002 | F19: =+E19/$E$38 -> 0.0027251476 | G19: =G62+G105 -> 9666.09 | H19: =+G19/$G$38 -> 0.00063987617 | I19: =+IF(AND(C19>0,G19>0),G19/C19,) -> 2.1569787 | J19: =+IF(AND(E19>0,G19>0),G19/E19,) -> 0.17016865
B20: 10) 보험료 (61310000 - 保险费) | C20: 138836.4 | D20: =+C20/$C$38 -> 0.0069024159 | E20: =E63+E106 -> 241582.61 | F20: =+E20/$E$38 -> 0.011590026 | G20: =G63+G106 -> 136750.9 | H20: =+G20/$G$38 -> 0.0090526409 | I20: =+IF(AND(C20>0,G20>0),G20/C20,) -> 0.98497872 | J20: =+IF(AND(E20>0,G20>0),G20/E20,) -> 0.56606268
B21: 11) 차량유지비 (61311000 - 车辆维修费) | C21: 0 | D21: =+C21/$E$38 -> 0 | E21: =E64+E107 -> 0 | F21: =+E21/$E$38 -> 0 | G21: =G64+G107 -> 0 | H21: =+G21/$G$38 -> 0 | I21: =+IF(AND(C21>0,G21>0),G21/C21,) -> 0 | J21: =+IF(AND(E21>0,G21>0),G21/E21,) -> 0
B22: 12) 경상연구개발비 (61312000 - 经常研究开发费用) | C22: 0 | D22: =+C22/$E$38 -> 0 | E22: =E65+E108 -> 0 | F22: =+E22/$E$38 -> 0 | G22: =G65+G108 -> 0 | H22: =+G22/$G$38 -> 0 | I22: =+IF(AND(C22>0,G22>0),G22/C22,) -> 0 | J22: =+IF(AND(E22>0,G22>0),G22/E22,) -> 0
B23: 13) 운반비 (61313000 - 运费) | C23: 0 | D23: =+C23/$E$38 -> 0 | E23: =E66+E109 -> 0 | F23: =+E23/$E$38 -> 0 | G23: =G66+G109 -> 0 | H23: =+G23/$G$38 -> 0 | I23: =+IF(AND(C23>0,G23>0),G23/C23,) -> 0 | J23: =+IF(AND(E23>0,G23>0),G23/E23,) -> 0
B24: 14) 교육훈련비 (61314000 - 教育培训费) | C24: 0 | D24: =+C24/$E$38 -> 0 | E24: =E67+E110 -> 0 | F24: =+E24/$E$38 -> 0 | G24: =G67+G110 -> 0 | H24: =+G24/$G$38 -> 0 | I24: =+IF(AND(C24>0,G24>0),G24/C24,) -> 0 | J24: =+IF(AND(E24>0,G24>0),G24/E24,) -> 0
B25: 15) 도서인쇄비 (61315000 - 图书印刷费) | C25: 0 | D25: =+C25/$E$38 -> 0 | E25: =E68+E111 -> 0 | F25: =+E25/$E$38 -> 0 | G25: =G68+G111 -> 0 | H25: =+G25/$G$38 -> 0 | I25: =+IF(AND(C25>0,G25>0),G25/C25,) -> 0 | J25: =+IF(AND(E25>0,G25>0),G25/E25,) -> 0
B26: 16) 회의비 (61316000 - 会议费) | C26: 0 | D26: =+C26/$E$38 -> 0 | E26: =E69+E112 -> 0 | F26: =+E26/$E$38 -> 0 | G26: =G69+G112 -> 0 | H26: =+G26/$G$38 -> 0 | I26: =+IF(AND(C26>0,G26>0),G26/C26,) -> 0 | J26: =+IF(AND(E26>0,G26>0),G26/E26,) -> 0
B27: 17) 포장비 (61317000 - 包装费) | C27: 50982.75 | D27: =+C27/$C$38 -> 0.0025346677 | E27: =E70+E113 -> 122691.07 | F27: =+E27/$E$38 -> 0.0058861547 | G27: =G70+G113 -> 35575.23 | H27: =+G27/$G$38 -> 0.0023550103 | I27: =+IF(AND(C27>0,G27>0),G27/C27,) -> 0.69778955 | J27: =+IF(AND(E27>0,G27>0),G27/E27,) -> 0.28995779
B28: 18) 사무용품비 (61318000 - 办公用品) | C28: 92140.7 | D28: =+C28/$E$38 -> 0.0044204882 | E28: =E71+E114 -> 16410.221 | F28: =+E28/$E$38 -> 0.00078728714 | G28: =G71+G114 -> 0 | H28: =+G28/$G$38 -> 0 | I28: =+IF(AND(C28>0,G28>0),G28/C28,) -> 0 | J28: =+IF(AND(E28>0,G28>0),G28/E28,) -> 0
B29: 19) 소모품비 (61319000 - 消耗品费) | C29: 316738.59 | D29: =+C29/$C$38 -> 0.015747034 | E29: =E72+E115 -> 146173.69 | F29: =+E29/$E$38 -> 0.0070127433 | G29: =G72+G115 -> 18281.48 | H29: =+G29/$G$38 -> 0.0012101981 | I29: =+IF(AND(C29>0,G29>0),G29/C29,) -> 0.05771788 | J29: =+IF(AND(E29>0,G29>0),G29/E29,) -> 0.12506683
B30: 20) 소모공구 (61320000 - 消耗工具) | C30: 31251.33 | D30: =+C30/$E$38 -> 0.0014992955 | E30: =E73+E116 -> 278324.01 | F30: =+E30/$E$38 -> 0.01335271 | G30: =G73+G116 -> 155070.8 | H30: =+G30/$G$38 -> 0.010265382 | I30: =+IF(AND(C30>0,G30>0),G30/C30,) -> 4.9620544 | J30: =+IF(AND(E30>0,G30>0),G30/E30,) -> 0.55715926
B31: 21) 지급수수료 (61321000 - 支付手续费) | C31: 0 | D31: =+C31/$C$38 -> 0 | E31: =E74+E117 -> 0 | F31: =+E31/$E$38 -> 0 | G31: =G74+G117 -> 30265.49 | H31: =+G31/$G$38 -> 0.002003516 | I31: =+IF(AND(C31>0,G31>0),G31/C31,) -> 0 | J31: =+IF(AND(E31>0,G31>0),G31/E31,) -> 0
B32: 22) 보관료 (61322000 - 保管费) | C32: 0 | D32: =+C32/$E$38 -> 0 | E32: =E75+E118 -> 0 | F32: =+E32/$E$38 -> 0 | G32: =G75+G118 -> 0 | H32: =+G32/$G$38 -> 0 | I32: =+IF(AND(C32>0,G32>0),G32/C32,) -> 0 | J32: =+IF(AND(E32>0,G32>0),G32/E32,) -> 0
B33: 23) 광고선전비 (61323000 - 广告宣传费) | C33: 0 | D33: =+C33/$E$38 -> 0 | E33: =E76+E119 -> 0 | F33: =+E33/$E$38 -> 0 | G33: =G76+G119 -> 0 | H33: =+G33/$G$38 -> 0 | I33: =+IF(AND(C33>0,G33>0),G33/C33,) -> 0 | J33: =+IF(AND(E33>0,G33>0),G33/E33,) -> 0
B34: 24) 수출제비용 (61324000 - 出口收费) | C34: 0 | D34: =+C34/$E$38 -> 0 | E34: =E77+E120 -> 0 | F34: =+E34/$E$38 -> 0 | G34: =G77+G120 -> 0 | H34: =+G34/$G$38 -> 0 | I34: =+IF(AND(C34>0,G34>0),G34/C34,) -> 0 | J34: =+IF(AND(E34>0,G34>0),G34/E34,) -> 0
B35: 25) B/B PVC로스 관세 (61325000 - 下脚料补税) | C35: 0 | D35: =+C35/$C$38 -> 0 | E35: =E78+E121 -> 0 | F35: =+E35/$E$38 -> 0 | G35: =G78+G121 -> 0 | H35: =+G35/$G$38 -> 0 | I35: =+IF(AND(C35>0,G35>0),G35/C35,) -> 0 | J35: =+IF(AND(E35>0,G35>0),G35/E35,) -> 0
B36: 26) 외주가공비 (61326000 - 委托加工费) | C36: 0 | D36: =+C36/$E$38 -> 0 | E36: =E79+E122 -> 0 | F36: =+E36/$E$38 -> 0 | G36: =G79+G122 -> 0 | H36: =+G36/$G$38 -> 0 | I36: =+IF(AND(C36>0,G36>0),G36/C36,) -> 0 | J36: =+IF(AND(E36>0,G36>0),G36/E36,) -> 0
B37: 27) 잡비 (61390000 - 杂费) | C37: 0 | D37: =+C37/$C$38 -> 0 | E37: =E80+E123 -> 0 | F37: =+E37/$E$38 -> 0 | G37: =G80+G123 -> 0 | H37: =+G37/$G$38 -> 0 | I37: =+IF(AND(C37>0,G37>0),G37/C37,) -> 0 | J37: =+IF(AND(E37>0,G37>0),G37/E37,) -> 0
B38: 4. 당기총제조비용 | C38: 20114175 | D38: =+C38/$C$38 -> 1 | E38: =+E3+E8+E10 -> 20844010 | F38: =+E38/$E$38 -> 1 | G38: =+G3+G8+G10 -> 15106188 | H38: =+G38/$G$38 -> 1 | I38: =+IF(AND(C38>0,G38>0),G38/C38,) -> 0.75102203 | J38: =+IF(AND(E38>0,G38>0),G38/E38,) -> 0.72472564
B39: (1) 기초재공품 | C39: 15279246 | G39: =G82+G125 -> 15452656 | I39: =+IF(AND(C39>0,G39>0),G39/C39,) -> 1.0113493 | J39: =+IF(AND(E39>0,G39>0),G39/E39,) -> 0
B40: (2) 기말재공품 | C40: 14820140 | G40: =G83+G126 -> 16439431 | I40: =+IF(AND(C40>0,G40>0),G40/C40,) -> 1.1092628 | J40: =+IF(AND(E40>0,G40>0),G40/E40,) -> 0
...

Sheet ★제조원가명세서 (월별)
B1: ■ 2026년 월별 제조원가 명세서 业绩 _ 制造费用明细书 _全体 | P1: (단위: RMB)
C2: 2026년 누계 | D2: 2025.12 | E2: 2026.01 | F2: 2026.02 | G2: 2026.03 | H2: 2026.04 | I2: 2026.05 | J2: 2026.06 | K2: 2026.07 | L2: 2026.08 | M2: 2026.09 | N2: 2026.10 | O2: 2026.11 | P2: 2026.12
B3: 1.재료비 | C3: =+C4+C5+C6-C7 -> 29841438 | D3: =D4+D5+D6-D7 -> 15473570 | E3: =E4+E5+E6-E7 -> 17281645 | F3: =F4+F5+F6-F7 -> 12559793 | G3: =G4+G5+G6-G7 -> 0 | H3: =H4+H5+H6-H7 -> 0 | I3: =I4+I5+I6-I7 -> 0 | J3: =J4+J5+J6-J7 -> 0 | K3: =K4+K5+K6-K7 -> 0 | L3: =L4+L5-L7+L6 -> 0 | M3: =M4+M5+M6-M7 -> 0 | N3: =N4+N5+N6-N7 -> 0 | O3: =O4+O5+O6-O7 -> 0 | P3: =P4+P5+P6-P7 -> 0
B4: (1) 기초 재고 | C4: =+E4 -> 12762105 | D4: =D48+D92 -> 8225102.1 | E4: =E48+E92 -> 12762105 | F4: =F48+F92 -> 11024319 | G4: =G48+G92 -> 0 | H4: =H48+H92 -> 0 | I4: =I48+I92 -> 0 | J4: =J48+J92 -> 0 | K4: =K48+K92 -> 0 | ... P4: =P48+P92 -> 0
B5: (2) 당기 매입액 | C5: =+SUM(E5:P5) -> 31603492 | D5: =D49+D93 -> 20010481 | E5: =E49+E93 -> 15543749 | F5: =F49+F93 -> 16059743 | G5: =G49+G93 -> 0 | H5: =H49+H93 -> 0 | I5: =I49+I93 -> 0 | J5: =J49+J93 -> 0 | K5: =K49+K93 -> 0 | ... P5: =P49+P93 -> 0
