Workbook

Sheet 1. 경신전선 요약_PPT
C4: =CONCATENATE("■ ",'2. 손익계산서'!$C$4,"월 KSCI 손익/원가 요약") -> ■ 2월 KSCI 손익/원가 요약 | K4: ( 1,350 KRW/USD )
D5: 단위 | E5: 연 계획 | F5: 누적 계획 | G5: 누적 실적 | H5: 누적 달성률 | I5: 연 계획 진행률
I6: KSCI | J6: KSCM-DG | K6: KSCM-GP
C7: 매출액 | D7: 백만원 | E7: ='1. 경신전선 요약'!D6 -> 234337.43 | F7: ='1. 경신전선 요약'!F6 -> 39126.549 | G7: ='1. 경신전선 요약'!G6 -> 37335.612 | H7: =G7/F7 -> 0.95422707 | I7: ='1. 경신전선 요약'!E6 -> 0.15932415 | J7: ='1. 경신전선 요약'!E7 -> 0.1558842 | K7: ='1. 경신전선 요약'!E8 -> 0.17890508
C8: 매출동량 | D8: 톤 | E8: ='1. 경신전선 요약'!D9 -> 0 | F8: ='1. 경신전선 요약'!F9 -> 0 | G8: ='1. 경신전선 요약'!G9 -> 1346.4872 | H8: =G8/F8 -> #DIV/0! | I8: ='1. 경신전선 요약'!E9 -> 0 | J8: =I8 -> 0
C9: 영업이익 | D9: 백만원 | E9: ='1. 경신전선 요약'!D22 -> 2134.2692 | F9: ='1. 경신전선 요약'!F22 -> 1279.7307 | G9: ='1. 경신전선 요약'!G22 -> 939.36468 | H9: =IF(AND(F9>0,G9>0),G9/F9,"(-)") -> 0.73403309 | I9: ='1. 경신전선 요약'!E22 -> 0.44013411 | J9: ='1. 경신전선 요약'!E24 -> 0.24100628 | K9: ='1. 경신전선 요약'!E25 -> (-)
C10: 영업이익률 | D10: % | E10: =E9/E7 -> 0.0091076752 | F10: =F9/F7 -> 0.032707478 | G10: =G9/G7 -> 0.025160018
K11: (단위:백만원)
C12: 구 분 | D12: 전 월 실 적 | E12: 구성비 | F12: 당 월 계 획 | G12: 구성비 | H12: 당 월 실 적 | I12: 구성비 | J12: 전 월 대 비 | K12: 계 획 대 비
C13: Ⅰ. 매출액 | D13: ='1. 경신전선 요약'!I6 -> 16877.673 | E13: ='1. 경신전선 요약'!J6 -> 1 | F13: ='1. 경신전선 요약'!K6 -> 19937.239 | G13: ='1. 경신전선 요약'!L6 -> 1 | H13: ='1. 경신전선 요약'!M6 -> 20457.939 | I13: ='1. 경신전선 요약'!N6 -> 1 | J13: ='1. 경신전선 요약'!O6 -> 1.2121303 | K13: ='1. 경신전선 요약'!P6 -> 1.026117
C14: 전선 | D14: ='1. 경신전선 요약'!I7 -> 13944.597 | E14: ='1. 경신전선 요약'!J7 -> 0.82621564 | F14: ='1. 경신전선 요약'!K7 -> 16067.61 | G14: ='1. 경신전선 요약'!L7 -> 0.80590952 | H14: ='1. 경신전선 요약'!M7 -> 17126.399 | I14: ='1. 경신전선 요약'!N7 -> 0.83715173 | J14: ='1. 경신전선 요약'!O7 -> 1.2281745 | K14: ='1. 경신전선 요약'!P7 -> 1.0658958
C15: 전장 | D15: ='1. 경신전선 요약'!I8 -> 2933.0755 | E15: ='1. 경신전선 요약'!J8 -> 0.17378436 | F15: ='1. 경신전선 요약'!K8 -> 3869.6282 | G15: ='1. 경신전선 요약'!L8 -> 0.19409048 | H15: ='1. 경신전선 요약'!M8 -> 3331.54 | I15: ='1. 경신전선 요약'!N8 -> 0.16284827 | J15: ='1. 경신전선 요약'!O8 -> 1.1358521 | K15: ='1. 경신전선 요약'!P8 -> 0.86094576
C16: *매출동량(ton) | D16: ='1. 경신전선 요약'!I9 -> 631.81666 | E16: ='1. 경신전선 요약'!J9 -> 0.037435058 | F16: ='1. 경신전선 요약'!K9 -> 0 | G16: ='1. 경신전선 요약'!L9 -> 0 | H16: ='1. 경신전선 요약'!M9 -> 714.67057 | I16: ='1. 경신전선 요약'!N9 -> 0.034933654 | J16: ='1. 경신전선 요약'!O9 -> 1.131136 | K16: ='1. 경신전선 요약'!P9 -> 0
D17: ='1. 경신전선 요약'!I10 -> 0 | E17: ='1. 경신전선 요약'!J10 -> 0 | F17: ='1. 경신전선 요약'!K10 -> 0 | G17: ='1. 경신전선 요약'!L10 -> 0 | H17: ='1. 경신전선 요약'!M10 -> 0 | I17: ='1. 경신전선 요약'!N10 -> 0 | J17: ='1. 경신전선 요약'!O10 -> 0 | K17: ='1. 경신전선 요약'!P10 -> 0
C18: Ⅱ. 매출원가 | D18: ='1. 경신전선 요약'!I11 -> 15846.995 | E18: ='1. 경신전선 요약'!J11 -> 0.93893244 | F18: ='1. 경신전선 요약'!K11 -> 17905.725 | G18: ='1. 경신전선 요약'!L11 -> 0.89810458 | H18: ='1. 경신전선 요약'!M11 -> 18657.391 | I18: ='1. 경신전선 요약'!N11 -> 0.9119878 | J18: ='1. 경신전선 요약'!O11 -> 1.1773457 | K18: ='1. 경신전선 요약'!P11 -> 1.0419791
C19: 전선 | D19: ='1. 경신전선 요약'!I12 -> 12587.262 | E19: ='1. 경신전선 요약'!J12 -> 0.90266231 | F19: ='1. 경신전선 요약'!K12 -> 14311.216 | G19: ='1. 경신전선 요약'!L12 -> 0.89068723 | H19: ='1. 경신전선 요약'!M12 -> 14848.113 | I19: ='1. 경신전선 요약'!N12 -> 0.86697224 | J19: ='1. 경신전선 요약'!O12 -> 1.1796141 | K19: ='1. 경신전선 요약'!P12 -> 1.0375158
C20: 전장 | D20: ='1. 경신전선 요약'!I13 -> 3259.7321 | E20: ='1. 경신전선 요약'!J13 -> 1.11137 | F20: ='1. 경신전선 요약'!K13 -> 3594.5099 | G20: ='1. 경신전선 요약'!L13 -> 0.92890317 | H20: ='1. 경신전선 요약'!M13 -> 3809.2783 | I20: ='1. 경신전선 요약'!N13 -> 1.1433986 | J20: ='1. 경신전선 요약'!O13 -> 1.1685863 | K20: ='1. 경신전선 요약'!P13 -> 1.059749
C21: └ 기타(GP2) | D21: ='1. 경신전선 요약'!I14 -> -397.8315 | E21: ='1. 경신전선 요약'!J14 -> -0.1356363 | F21: ='1. 경신전선 요약'!K14 -> 98.292417 | G21: ='1. 경신전선 요약'!L14 -> 0.025400998 | H21: ='1. 경신전선 요약'!M14 -> 0 | I21: ='1. 경신전선 요약'!N14 -> 0 | J21: ='1. 경신전선 요약'!O14 -> 0 | K21: ='1. 경신전선 요약'!P14 -> 0
D22: ='1. 경신전선 요약'!I15 -> 0 | E22: ='1. 경신전선 요약'!J15 -> 0 | F22: ='1. 경신전선 요약'!K15 -> 0 | G22: ='1. 경신전선 요약'!L15 -> 0 | H22: ='1. 경신전선 요약'!M15 -> 0 | I22: ='1. 경신전선 요약'!N15 -> 0 | J22: ='1. 경신전선 요약'!O15 -> 0 | K22: ='1. 경신전선 요약'!P15 -> 0
C23: Ⅲ. 매출총이익 | D23: ='1. 경신전선 요약'!I16 -> 1030.6783 | E23: ='1. 경신전선 요약'!J16 -> 0.06106756 | F23: ='1. 경신전선 요약'!K16 -> 2031.5132 | G23: ='1. 경신전선 요약'!L16 -> 0.10189542 | H23: ='1. 경신전선 요약'!M16 -> 1800.5482 | I23: ='1. 경신전선 요약'!N16 -> 0.088012198 | J23: ='1. 경신전선 요약'!O16 -> 1.7469546 | K23: ='1. 경신전선 요약'!P16 -> 0.88630886
C25: Ⅳ.판매관리비 | D25: ='1. 경신전선 요약'!I18 -> 938.54183 | E25: ='1. 경신전선 요약'!J18 -> 0.055608486 | F25: ='1. 경신전선 요약'!K18 -> 1026.875 | G25: ='1. 경신전선 요약'!L18 -> 0.051505376 | H25: ='1. 경신전선 요약'!M18 -> 953.31997 | I25: ='1. 경신전선 요약'!N18 -> 0.046599023 | J25: ='1. 경신전선 요약'!O18 -> 1.0157459 | K25: ='1. 경신전선 요약'!P18 -> 0.92837004
C26: [판매비] | D26: ='1. 경신전선 요약'!I19 -> 0 | E26: ='1. 경신전선 요약'!J19 -> 0 | F26: ='1. 경신전선 요약'!K19 -> 0 | G26: ='1. 경신전선 요약'!L19 -> 0 | H26: ='1. 경신전선 요약'!M19 -> 0 | I26: ='1. 경신전선 요약'!N19 -> 0 | J26: ='1. 경신전선 요약'!O19 -> 0 | K26: ='1. 경신전선 요약'!P19 -> 0
C28: [연구개발비] | D28: ='1. 경신전선 요약'!I21 -> 0 | E28: ='1. 경신전선 요약'!J21 -> 0 | F28: ='1. 경신전선 요약'!K21 -> 0 | G28: ='1. 경신전선 요약'!L21 -> 0 | H28: ='1. 경신전선 요약'!M21 -> 0 | I28: ='1. 경신전선 요약'!N21 -> 0 | J28: ='1. 경신전선 요약'!O21 -> 0 | K28: ='1. 경신전선 요약'!P21 -> 0
C29: Ⅴ.영업이익 | D29: ='1. 경신전선 요약'!I22 -> 92.136474 | E29: ='1. 경신전선 요약'!J22 -> 0.0054590745 | F29: ='1. 경신전선 요약'!K22 -> 1004.6382 | G29: ='1. 경신전선 요약'!L22 -> 0.05039004 | H29: ='1. 경신전선 요약'!M22 -> 847.22821 | I29: ='1. 경신전선 요약'!N22 -> 0.041413175 | J29: ='1. 경신전선 요약'!O22 -> 9.1953617 | K29: ='1. 경신전선 요약'!P22 -> 0.84331669
C30: (영업이익률) | D30: ='1. 경신전선 요약'!I23 -> 0.0054590745 | F30: ='1. 경신전선 요약'!K23 -> 0.05039004 | H30: ='1. 경신전선 요약'!M23 -> 0.041413175
C31: 전선 | D31: ='1. 경신전선 요약'!I24 -> 894.79166 | E31: ='1. 경신전선 요약'!J24 -> 0.064167623 | F31: ='1. 경신전선 요약'!K24 -> 964.3922 | G31: ='1. 경신전선 요약'!L24 -> 0.060020885 | H31: ='1. 경신전선 요약'!M24 -> 1769.0229 | I31: ='1. 경신전선 요약'!N24 -> 0.10329217 | J31: ='1. 경신전선 요약'!O24 -> 1.9770222 | K31: ='1. 경신전선 요약'!P24 -> 1.8343397
C32: 전장 | D32: ='1. 경신전선 요약'!I25 -> -802.65519 | E32: ='1. 경신전선 요약'!J25 -> -0.2736565 | F32: ='1. 경신전선 요약'!K25 -> 40.246044 | G32: ='1. 경신전선 요약'!L25 -> 0.010400494 | H32: ='1. 경신전선 요약'!M25 -> -921.79474 | I32: ='1. 경신전선 요약'!N25 -> -0.27668728 | J32: ='1. 경신전선 요약'!O25 -> (-) | K32: ='1. 경신전선 요약'!P25 -> (-)
C34: 구 분 | D34: 2025년 계 획 | E34: 년계획 진척률 | F34: 누 계 계 획 | G34: 누계 실적 | H34: 달성률 | I34: 전 월 실 적 | J34: 원 가 구성비 | K34: 당 월 계 획 | L34: 당 월 실 적 | M34: 원 가 구성비 | N34: 전 월 대 비 | O34: 계 획 대 비
C35: Ⅰ. 재료비
C36: Ⅱ. 노무비
C37: Ⅲ. 경비
C38: Ⅳ. 당기총제조비용
C39: Ⅴ. 당기제품제조원가
C42: =CONCATENATE("□ ",'2. 손익계산서'!$C$4,"월 KSCM-DG 손익/원가 요약") -> □ 2월 KSCM-DG 손익/원가 요약 | K42: =+K4 -> ( 1,350 KRW/USD )
D43: 단위 | E43: 연 계획 | F43: 누적 계획 | G43: 누적 실적 | H43: 누적 달성률 | I43: 연 계획 진행률
I44: KSCI | J44: KSCM-DG | K44: KSCM-GP
C45: 매출액 | D45: 백만원 | E45: ='1. 경신전선 요약'!D38 -> 199321.01 | F45: ='1. 경신전선 요약'!F38 -> 32075.728 | G45: ='1. 경신전선 요약'!G38 -> 31070.996 | H45: =G45/F45 -> 0.96867627 | I45: =I7 -> 0.15932415 | J45: =J7 -> 0.1558842 | K45: =K7 -> 0.17890508
C46: 매출동량 | D46: 톤 | E46: ='1. 경신전선 요약'!D48 -> 0 | F46: ='1. 경신전선 요약'!F48 -> 0 | G46: ='1. 경신전선 요약'!G48 -> 1346.4872 | H46: =G46/F46 -> #DIV/0! | I46: =I8 -> 0 | J46: =J8 -> 0
C47: 영업이익 | D47: 백만원 | E47: ='1. 경신전선 요약'!D58 -> 11052.884 | F47: ='1. 경신전선 요약'!F58 -> 1726.3818 | G47: ='1. 경신전선 요약'!G58 -> 2663.8146 | H47: =IF(AND(F47>0,G47>0),G47/F47,"(-)") -> 1.5430043 | I47: =I9 -> 0.44013411 | J47: =J9 -> 0.24100628 | K47: =K9 -> (-)
C48: 영업이익률 | D48: % | E48: =E47/E45 -> 0.055452681 | F48: =F47/F45 -> 0.053822062 | G48: =G47/G45 -> 0.085733157
...

Sheet 1. 경신전선 요약_PPT_1월임시
C4: =CONCATENATE("■ ",'2. 손익계산서'!$C$4,"월 KSCI 손익/원가 요약") -> ■ 2월 KSCI 손익/원가 요약 | K4: ( 1,350 KRW/USD )
D5: 단위 | E5: 연 계획 | F5: 누적 계획 | G5: 누적 실적 | H5: 누적 달성률 | I5: 연 계획 진행률
I6: KSCI | J6: KSCM-DG | K6: KSCM-GP
C7: 매출액 | D7: 백만원 | E7: ='1. 경신전선 요약'!D6 -> 234337.43 | F7: ='1. 경신전선 요약'!F6 -> 39126.549 | G7: ='1. 경신전선 요약'!G6 -> 37335.612 | H7: =G7/F7 -> 0.95422707 | I7: ='1. 경신전선 요약'!E6 -> 0.15932415 | J7: ='1. 경신전선 요약'!E7 -> 0.1558842 | K7: ='1. 경신전선 요약'!E8 -> 0.17890508
C8: 매출동량 | D8: 톤 | E8: ='1. 경신전선 요약'!D9 -> 0 | F8: ='1. 경신전선 요약'!F9 -> 0 | G8: ='1. 경신전선 요약'!G9 -> 1346.4872 | H8: =G8/F8 -> #DIV/0! | I8: ='1. 경신전선 요약'!E9 -> 0 | J8: =I8 -> 0
C9: 영업이익 | D9: 백만원 | E9: ='1. 경신전선 요약'!D22 -> 2134.2692 | F9: ='1. 경신전선 요약'!F22 -> 1279.7307 | G9: ='1. 경신전선 요약'!G22 -> 939.36468 | H9: =IF(AND(F9>0,G9>0),G9/F9,"(-)") -> 0.73403309 | I9: ='1. 경신전선 요약'!E22 -> 0.44013411 | J9: ='1. 경신전선 요약'!E24 -> 0.24100628 | K9: ='1. 경신전선 요약'!E25 -> (-)
C10: 영업이익률 | D10: % | E10: =E9/E7 -> 0.0091076752 | F10: =F9/F7 -> 0.032707478 | G10: =G9/G7 -> 0.025160018
K11: (단위:백만원)
C12: 구 분 | D12: 전 월 실 적 | E12: 구성비 | F12: 당 월 계 획 | G12: 구성비 | H12: 당 월 실 적 | I12: 구성비 | J12: 전 월 대 비 | K12: 계 획 대 비
C13: Ⅰ. 매출액 | D13: 13091.9 | E13: 1 | F13: ='1. 경신전선 요약'!K6 -> 19937.239 | G13: ='1. 경신전선 요약'!L6 -> 1 | H13: ='1. 경신전선 요약'!M6 -> 20457.939 | I13: ='1. 경신전선 요약'!N6 -> 1 | J13: =IF(D13>0,H13/D13,"(-)") -> 1.562641 | K13: ='1. 경신전선 요약'!P6 -> 1.026117
C14: 전선 | D14: 9928.7936 | E14: 0.75839214 | F14: ='1. 경신전선 요약'!K7 -> 16067.61 | G14: ='1. 경신전선 요약'!L7 -> 0.80590952 | H14: ='1. 경신전선 요약'!M7 -> 17126.399 | I14: ='1. 경신전선 요약'!N7 -> 0.83715173 | J14: =IF(D14>0,H14/D14,"(-)") -> 1.7249225 | K14: ='1. 경신전선 요약'!P7 -> 1.0658958
C15: 전장 | D15: 3163.1059 | E15: 0.24160786 | F15: ='1. 경신전선 요약'!K8 -> 3869.6282 | G15: ='1. 경신전선 요약'!L8 -> 0.19409048 | H15: ='1. 경신전선 요약'!M8 -> 3331.54 | I15: ='1. 경신전선 요약'!N8 -> 0.16284827 | J15: =IF(D15>0,H15/D15,"(-)") -> 1.0532496 | K15: ='1. 경신전선 요약'!P8 -> 0.86094576
C16: *매출동량(ton) | D16: 476.23611 | E16: 0.036376395 | F16: ='1. 경신전선 요약'!K9 -> 0 | G16: ='1. 경신전선 요약'!L9 -> 0 | H16: ='1. 경신전선 요약'!M9 -> 714.67057 | I16: ='1. 경신전선 요약'!N9 -> 0.034933654 | J16: =+H16/D16 -> 1.5006644 | K16: ='1. 경신전선 요약'!P9 -> 0
D17: 0 | E17: 0 | F17: ='1. 경신전선 요약'!K10 -> 0 | G17: ='1. 경신전선 요약'!L10 -> 0 | H17: ='1. 경신전선 요약'!M10 -> 0 | I17: ='1. 경신전선 요약'!N10 -> 0 | J17: =+H17/D17 -> #DIV/0! | K17: ='1. 경신전선 요약'!P10 -> 0
C18: Ⅱ. 매출원가 | D18: 12827.821 | E18: 0.97982887 | F18: ='1. 경신전선 요약'!K11 -> 17905.725 | G18: ='1. 경신전선 요약'!L11 -> 0.89810458 | H18: ='1. 경신전선 요약'!M11 -> 18657.391 | I18: ='1. 경신전선 요약'!N11 -> 0.9119878 | J18: =IF(D18>0,H18/D18,"(-)") -> 1.4544474 | K18: ='1. 경신전선 요약'!P11 -> 1.0419791
C19: 전선 | D19: 9050.1099 | E19: 0.91150146 | F19: ='1. 경신전선 요약'!K12 -> 14311.216 | G19: ='1. 경신전선 요약'!L12 -> 0.89068723 | H19: ='1. 경신전선 요약'!M12 -> 14848.113 | I19: ='1. 경신전선 요약'!N12 -> 0.86697224 | J19: =IF(D19>0,H19/D19,"(-)") -> 1.6406555 | K19: ='1. 경신전선 요약'!P12 -> 1.0375158
C20: 전장 | D20: 3777.7112 | E20: 1.1943044 | F20: ='1. 경신전선 요약'!K13 -> 3594.5099 | G20: ='1. 경신전선 요약'!L13 -> 0.92890317 | H20: ='1. 경신전선 요약'!M13 -> 3809.2783 | I20: ='1. 경신전선 요약'!N13 -> 1.1433986 | J20: =IF(D20>0,H20/D20,"(-)") -> 1.0083561 | K20: ='1. 경신전선 요약'!P13 -> 1.059749
C21: └ 기타(GP2) | D21: -216.33365 | E21: -0.068392793 | F21: ='1. 경신전선 요약'!K14 -> 98.292417 | G21: ='1. 경신전선 요약'!L14 -> 0.025400998 | H21: ='1. 경신전선 요약'!M14 -> 0 | I21: ='1. 경신전선 요약'!N14 -> 0 | J21: =IF(D21>0,H21/D21,"(-)") -> (-) | K21: ='1. 경신전선 요약'!P14 -> 0
D22: 0 | E22: 0 | F22: ='1. 경신전선 요약'!K15 -> 0 | G22: ='1. 경신전선 요약'!L15 -> 0 | H22: ='1. 경신전선 요약'!M15 -> 0 | I22: ='1. 경신전선 요약'!N15 -> 0 | J22: ='1. 경신전선 요약'!O15 -> 0 | K22: ='1. 경신전선 요약'!P15 -> 0
C23: Ⅲ. 매출총이익 | D23: 264.07841 | E23: 0.02017113 | F23: ='1. 경신전선 요약'!K16 -> 2031.5132 | G23: ='1. 경신전선 요약'!L16 -> 0.10189542 | H23: ='1. 경신전선 요약'!M16 -> 1800.5482 | I23: ='1. 경신전선 요약'!N16 -> 0.088012198 | J23: =IF(D23>0,H23/D23,"(-)") -> 6.8182331 | K23: ='1. 경신전선 요약'!P16 -> 0.88630886
C25: Ⅳ.판매관리비 | D25: 1070.2549 | E25: 0.081749399 | F25: ='1. 경신전선 요약'!K18 -> 1026.875 | G25: ='1. 경신전선 요약'!L18 -> 0.051505376 | H25: ='1. 경신전선 요약'!M18 -> 953.31997 | I25: ='1. 경신전선 요약'!N18 -> 0.046599023 | J25: =IF(D25>0,H25/D25,"(-)") -> 0.89074103 | K25: ='1. 경신전선 요약'!P18 -> 0.92837004
C26: [판매비] | D26: 0 | E26: 0 | F26: ='1. 경신전선 요약'!K19 -> 0 | G26: ='1. 경신전선 요약'!L19 -> 0 | H26: ='1. 경신전선 요약'!M19 -> 0 | I26: ='1. 경신전선 요약'!N19 -> 0 | J26: ='1. 경신전선 요약'!O19 -> 0 | K26: ='1. 경신전선 요약'!P19 -> 0
C28: [연구개발비] | D28: 0 | E28: 0 | F28: ='1. 경신전선 요약'!K21 -> 0 | G28: ='1. 경신전선 요약'!L21 -> 0 | H28: ='1. 경신전선 요약'!M21 -> 0 | I28: ='1. 경신전선 요약'!N21 -> 0 | J28: ='1. 경신전선 요약'!O21 -> 0 | K28: ='1. 경신전선 요약'!P21 -> 0
C29: Ⅴ.영업이익 | D29: -806.17651 | E29: -0.061578269 | F29: ='1. 경신전선 요약'!K22 -> 1004.6382 | G29: ='1. 경신전선 요약'!L22 -> 0.05039004 | H29: ='1. 경신전선 요약'!M22 -> 847.22821 | I29: ='1. 경신전선 요약'!N22 -> 0.041413175 | J29: =IF(D29>0,H29/D29,"(-)") -> (-) | K29: ='1. 경신전선 요약'!P22 -> 0.84331669
C30: (영업이익률) | D30: -0.061578269 | F30: ='1. 경신전선 요약'!K23 -> 0.05039004 | H30: ='1. 경신전선 요약'!M23 -> 0.041413175
C31: 전선 | D31: 237.39407 | E31: 0.023909659 | F31: ='1. 경신전선 요약'!K24 -> 964.3922 | G31: ='1. 경신전선 요약'!L24 -> 0.060020885 | H31: ='1. 경신전선 요약'!M24 -> 1769.0229 | I31: ='1. 경신전선 요약'!N24 -> 0.10329217 | J31: =IF(D31>0,H31/D31,"(-)") -> 7.4518414 | K31: ='1. 경신전선 요약'!P24 -> 1.8343397
C32: 전장 | D32: -1043.5706 | E32: -0.32991959 | F32: ='1. 경신전선 요약'!K25 -> 40.246044 | G32: ='1. 경신전선 요약'!L25 -> 0.010400494 | H32: ='1. 경신전선 요약'!M25 -> -921.79474 | I32: ='1. 경신전선 요약'!N25 -> -0.27668728 | J32: =IF(D32>0,H32/D32,"(-)") -> (-) | K32: ='1. 경신전선 요약'!P25 -> (-)
C34: 구 분 | D34: 2025년 계 획 | E34: 년계획 진척률 | F34: 누 계 계 획 | G34: 누계 실적 | H34: 달성률 | I34: 전 월 실 적 | J34: 원 가 구성비 | K34: 당 월 계 획 | L34: 당 월 실 적 | M34: 원 가 구성비 | N34: 전 월 대 비 | O34: 계 획 대 비
C35: Ⅰ. 재료비
C36: Ⅱ. 노무비
C37: Ⅲ. 경비
C38: Ⅳ. 당기총제조비용
C39: Ⅴ. 당기제품제조원가
C42: =CONCATENATE("□ ",'2. 손익계산서'!$C$4,"월 KSCM-DG 손익/원가 요약") -> □ 2월 KSCM-DG 손익/원가 요약 | K42: =+K4 -> ( 1,350 KRW/USD )
D43: 단위 | E43: 연 계획 | F43: 누적 계획 | G43: 누적 실적 | H43: 누적 달성률 | I43: 연 계획 진행률
I44: KSCI | J44: KSCM-DG | K44: KSCM-GP
C45: 매출액 | D45: 백만원 | E45: ='1. 경신전선 요약'!D38 -> 199321.01 | F45: ='1. 경신전선 요약'!F38 -> 32075.728 | G45: ='1. 경신전선 요약'!G38 -> 31070.996 | H45: =G45/F45 -> 0.96867627 | I45: =I7 -> 0.15932415 | J45: =J7 -> 0.1558842 | K45: =K7 -> 0.17890508
C46: 매출동량 | D46: 톤 | E46: ='1. 경신전선 요약'!D48 -> 0 | F46: ='1. 경신전선 요약'!F48 -> 0 | G46: ='1. 경신전선 요약'!G48 -> 1346.4872 | H46: =G46/F46 -> #DIV/0! | I46: =I8 -> 0 | J46: =J8 -> 0
C47: 영업이익 | D47: 백만원 | E47: ='1. 경신전선 요약'!D58 -> 11052.884 | F47: ='1. 경신전선 요약'!F58 -> 1726.3818 | G47: ='1. 경신전선 요약'!G58 -> 2663.8146 | H47: =IF(AND(F47>0,G47>0),G47/F47,"(-)") -> 1.5430043 | I47: =I9 -> 0.44013411 | J47: =J9 -> 0.24100628 | K47: =K9 -> (-)
C48: 영업이익률 | D48: % | E48: =E47/E45 -> 0.055452681 | F48: =F47/F45 -> 0.053822062 | G48: =G47/G45 -> 0.085733157
...

Sheet 1. 경신전선 요약
C4: =CONCATENATE("■ ",'2. 손익계산서'!$C$4,"월 KSCI 손익/원가 요약") -> ■ 2월 KSCI 손익/원가 요약 | N4: 1350 | O4: KRW/USD | P4: (단위:백만원)
C5: 구 분 | D5: 2026년 계 획 | E5: 년계획 진척률 | F5: 누 계 계 획 | G5: 누 계 실 적 | H5: 달성률 | I5: 전 월 실 적 | J5: 구성비 | K5: 당 월 계 획 | L5: 구성비 | M5: 당 월 실 적 | N5: 구성비 | O5: 전 월 대 비 | P5: 계 획 대 비 | R5: 계획대비 | S5: 전월대비
C6: Ⅰ. 매출액 | D6: =SUM(D7:D8) -> 234337.43 | E6: =IFERROR(G6/D6,) -> 0.15932415 | F6: =SUM(F7:F8) -> 39126.549 | G6: =SUM(G7:G8) -> 37335.612 | H6: =IFERROR(G6/F6,) -> 0.95422707 | I6: =SUM(I7:I8) -> 16877.673 | J6: =IFERROR(I6/$I$6,) -> 1 | K6: =SUM(K7:K8) -> 19937.239 | L6: =IFERROR(K6/$K$6,) -> 1 | M6: =SUM(M7:M8) -> 20457.939 | N6: =IFERROR(M6/$M$6,) -> 1 | O6: =IFERROR(M6/I6,) -> 1.2121303 | P6: =IFERROR(M6/K6,) -> 1.026117 | Q6: =P6-1 -> 0.026116976 | R6: =+M6-K6 -> 520.70039 | S6: =+M6-I6 -> 3580.2663 | T6: =O6-1 -> 0.21213033 | U6: ▲▼
C7: 전선 | D7: ='2. 손익계산서'!C7*$N$4/1000000 -> 199321.01 | E7: =IFERROR(G7/D7,) -> 0.1558842 | F7: ='2. 손익계산서'!E7*$N$4/1000000 -> 32075.728 | G7: ='2. 손익계산서'!F7*$N$4/1000000 -> 31070.996 | H7: =IFERROR(G7/F7,) -> 0.96867627 | I7: ='2. 손익계산서'!H7*$N$4/1000000 -> 13944.597 | J7: =IFERROR(I7/$I$6,) -> 0.82621564 | K7: ='2. 손익계산서'!J7*$N$4/1000000 -> 16067.61 | L7: =IFERROR(K7/$K$6,) -> 0.80590952 | M7: ='2. 손익계산서'!L7*$N$4/1000000 -> 17126.399 | N7: =IFERROR(M7/$M$6,) -> 0.83715173 | O7: =IFERROR(M7/I7,) -> 1.2281745 | P7: =IFERROR(M7/K7,) -> 1.0658958
C8: 전장 | D8: ='2. 손익계산서'!C9*$N$4/1000000 -> 35016.42 | E8: =IFERROR(G8/D8,) -> 0.17890508 | F8: ='2. 손익계산서'!E9*$N$4/1000000 -> 7050.8207 | G8: ='2. 손익계산서'!F9*$N$4/1000000 -> 6264.6155 | H8: =IFERROR(G8/F8,) -> 0.88849452 | I8: ='2. 손익계산서'!H9*$N$4/1000000 -> 2933.0755 | J8: =IFERROR(I8/$I$6,) -> 0.17378436 | K8: ='2. 손익계산서'!J9*$N$4/1000000 -> 3869.6282 | L8: =IFERROR(K8/$K$6,) -> 0.19409048 | M8: ='2. 손익계산서'!L9*$N$4/1000000 -> 3331.54 | N8: =IFERROR(M8/$M$6,) -> 0.16284827 | O8: =IFERROR(M8/I8,) -> 1.1358521 | P8: =IFERROR(M8/K8,) -> 0.86094576
C9: *매출동량(ton) | D9: ='2. 손익계산서'!C8 -> 0 | E9: =IFERROR(G9/D9,) -> 0 | F9: ='2. 손익계산서'!E8 -> 0 | G9: ='2. 손익계산서'!F8 -> 1346.4872 | H9: =IFERROR(G9/F9,) -> 0 | I9: ='2. 손익계산서'!H8 -> 631.81666 | J9: =IFERROR(I9/$I$6,) -> 0.037435058 | K9: ='2. 손익계산서'!J8 -> 0 | L9: =IFERROR(K9/$K$6,) -> 0 | M9: ='2. 손익계산서'!L8 -> 714.67057 | N9: =IFERROR(M9/$M$6,) -> 0.034933654 | O9: =IFERROR(M9/I9,) -> 1.131136 | P9: =IFERROR(M9/K9,) -> 0
C11: Ⅱ. 매출원가 | D11: =SUM(D12:D13) -> 219695.57 | E11: =IFERROR(G11/D11,) -> 0.15705544 | F11: =SUM(F12:F13) -> 35735.271 | G11: =SUM(G12:G13) -> 34504.385 | H11: =IFERROR(G11/F11,) -> 0.96555544 | I11: =SUM(I12:I13) -> 15846.995 | J11: =IFERROR(I11/$I$6,) -> 0.93893244 | K11: =SUM(K12:K13) -> 17905.725 | L11: =IFERROR(K11/K6,) -> 0.89810458 | M11: =SUM(M12:M13) -> 18657.391 | N11: =IFERROR(M11/M6,) -> 0.9119878 | O11: =IFERROR(M11/I11,) -> 1.1773457 | P11: =IFERROR(M11/K11,) -> 1.0419791 | R11: =+M11-K11 -> 751.66544 | S11: =+M11-I11 -> 2810.3964
C12: 전선 | D12: ='2. 손익계산서'!C91*$N$4/1000000 -> 178792.54 | E12: =IFERROR(G12/D12,) -> 0.1534481 | F12: ='2. 손익계산서'!E91*$N$4/1000000 -> 28716.486 | G12: ='2. 손익계산서'!F91*$N$4/1000000 -> 27435.375 | H12: =IFERROR(G12/F12,) -> 0.95538762 | I12: ='2. 손익계산서'!H91*$N$4/1000000 -> 12587.262 | J12: =IFERROR(I12/I7,) -> 0.90266231 | K12: ='2. 손익계산서'!J91*$N$4/1000000 -> 14311.216 | L12: =IFERROR(K12/K7,) -> 0.89068723 | M12: ='2. 손익계산서'!L91*$N$4/1000000 -> 14848.113 | N12: =IFERROR(M12/M7,) -> 0.86697224 | O12: =IFERROR(M12/I12,) -> 1.1796141 | P12: =IFERROR(M12/K12,) -> 1.0375158
C13: 전장 | D13: ='2. 손익계산서'!C160*$N$4/1000000 -> 40903.034 | E13: =IFERROR(G13/D13,) -> 0.17282362 | F13: ='2. 손익계산서'!E160*$N$4/1000000 -> 7018.7855 | G13: ='2. 손익계산서'!F160*$N$4/1000000 -> 7069.0104 | H13: =IFERROR(G13/F13,) -> 1.0071558 | I13: ='2. 손익계산서'!H160*$N$4/1000000 -> 3259.7321 | J13: =IFERROR(I13/I8,) -> 1.11137 | K13: ='2. 손익계산서'!J160*$N$4/1000000 -> 3594.5099 | L13: =IFERROR(K13/K8,) -> 0.92890317 | M13: ='2. 손익계산서'!L160*$N$4/1000000 -> 3809.2783 | N13: =IFERROR(M13/M8,) -> 1.1433986 | O13: =IFERROR(M13/I13,) -> 1.1685863 | P13: =IFERROR(M13/K13,) -> 1.059749
C14: └ 기타(GP2) | D14: ='2. 손익계산서'!C163*$N$4/1000000 -> 2403.7903 | E14: =IFERROR(G14/D14,) -> -0.16550175 | F14: ='2. 손익계산서'!E163*$N$4/1000000 -> 477.65483 | G14: ='2. 손익계산서'!F163*$N$4/1000000 -> -397.8315 | H14: =IFERROR(G14/F14,) -> -0.8328849 | I14: ='2. 손익계산서'!H163*$N$4/1000000 -> -397.8315 | J14: =IFERROR(I14/I8,) -> -0.1356363 | K14: ='2. 손익계산서'!J163*$N$4/1000000 -> 98.292417 | L14: =IFERROR(K14/K8,) -> 0.025400998 | M14: ='2. 손익계산서'!L163*$N$4/1000000 -> 0 | N14: =IFERROR(M14/M8,) -> 0 | O14: =IFERROR(M14/I14,) -> 0 | P14: =IFERROR(M14/K14,) -> 0
C16: Ⅲ. 매출총이익 | D16: =D6-D11 -> 14641.859 | E16: =IF(AND(D16>0,G16>0),G16/D16,"(-)") -> 0.19336524 | F16: =F6-F11 -> 3391.2774 | G16: =G6-G11 -> 2831.2265 | H16: =IF(AND(F16>0,G16>0),G16/F16,"(-)") -> 0.83485547 | I16: =I6-I11 -> 1030.6783 | J16: =IFERROR(I16/$I$6,) -> 0.06106756 | K16: =K6-K11 -> 2031.5132 | L16: =IFERROR(K16/$K$6,) -> 0.10189542 | M16: =M6-M11 -> 1800.5482 | N16: =IFERROR(M16/$M$6,) -> 0.088012198 | O16: =IF(AND(I16>0,M16>0),M16/I16,"(-)") -> 1.7469546 | P16: =IF(AND(K16>0,M16>0),M16/K16,"(-)") -> 0.88630886 | R16: =+M16-K16 -> -230.96505 | S16: =+M16-I16 -> 769.86987
C17: (이익률) | D17: =IFERROR(D16/D$6,) -> 0.062481946 | F17: =IFERROR(F16/F$6,) -> 0.086674585 | G17: =IFERROR(G16/G$6,) -> 0.075831795 | I17: =IFERROR(I16/I$6,) -> 0.06106756 | K17: =IFERROR(K16/K$6,) -> 0.10189542 | M17: =IFERROR(M16/M$6,) -> 0.088012198
C18: Ⅳ.판매관리비 | D18: =SUM(D19:D21) -> 12507.59 | E18: =IFERROR(G18/D18,) -> 0.15125711 | F18: =SUM(F19:F21) -> 2111.5467 | G18: =SUM(G19:G21) -> 1891.8618 | H18: =IFERROR(G18/F18,) -> 0.89596021 | I18: =SUM(I19:I21) -> 938.54183 | J18: =IFERROR(I18/$I$6,) -> 0.055608486 | K18: =SUM(K19:K21) -> 1026.875 | L18: =IFERROR(K18/$K$6,) -> 0.051505376 | M18: =SUM(M19:M21) -> 953.31997 | N18: =IFERROR(M18/$M$6,) -> 0.046599023 | O18: =IFERROR(M18/I18,) -> 1.0157459 | P18: =IFERROR(M18/K18,) -> 0.92837004 | R18: =+M18-K18 -> -73.555011 | S18: =+M18-I18 -> 14.77814
C19: [판매비] | D19: ='2. 손익계산서'!C19*$N$4/1000000 -> 0 | E19: =IFERROR(G19/D19,) -> 0 | F19: ='2. 손익계산서'!E19*$N$4/1000000 -> 0 | G19: ='2. 손익계산서'!F19*$N$4/1000000 -> 0 | H19: =IFERROR(G19/F19,) -> 0 | I19: ='2. 손익계산서'!H19*$N$4/1000000 -> 0 | J19: =IFERROR(I19/$I$6,) -> 0 | K19: ='2. 손익계산서'!J19*$N$4/1000000 -> 0 | L19: =IFERROR(K19/$K$6,) -> 0 | M19: ='2. 손익계산서'!L19*$N$4/1000000 -> 0 | N19: =IFERROR(M19/$M$6,) -> 0 | O19: =IFERROR(M19/I19,) -> 0 | P19: =IFERROR(M19/K19,) -> 0
C20: [관리비] | D20: ='2. 손익계산서'!C35*$N$4/1000000 -> 12507.59 | E20: =IFERROR(G20/D20,) -> 0.15125711 | F20: ='2. 손익계산서'!E35*$N$4/1000000 -> 2111.5467 | G20: ='2. 손익계산서'!F35*$N$4/1000000 -> 1891.8618 | H20: =IFERROR(G20/F20,) -> 0.89596021 | I20: ='2. 손익계산서'!H35*$N$4/1000000 -> 938.54183 | J20: =IFERROR(I20/$I$6,) -> 0.055608486 | K20: ='2. 손익계산서'!J35*$N$4/1000000 -> 1026.875 | L20: =IFERROR(K20/$K$6,) -> 0.051505376 | M20: ='2. 손익계산서'!L35*$N$4/1000000 -> 953.31997 | N20: =IFERROR(M20/$M$6,) -> 0.046599023 | O20: =IFERROR(M20/I20,) -> 1.0157459 | P20: =IFERROR(M20/K20,) -> 0.92837004
C21: [연구개발비] | D21: ='2. 손익계산서'!C53*$N$4/1000000 -> 0 | E21: =IFERROR(G21/D21,) -> 0 | F21: ='2. 손익계산서'!E53*$N$4/1000000 -> 0 | G21: ='2. 손익계산서'!F53*$N$4/1000000 -> 0 | H21: =IFERROR(G21/F21,) -> 0 | I21: ='2. 손익계산서'!H53*$N$4/1000000 -> 0 | J21: =IFERROR(I21/$I$6,) -> 0 | K21: ='2. 손익계산서'!J53*$N$4/1000000 -> 0 | L21: =IFERROR(K21/$K$6,) -> 0 | M21: ='2. 손익계산서'!L53*$N$4/1000000 -> 0 | N21: =IFERROR(M21/$M$6,) -> 0 | O21: =IFERROR(M21/I21,) -> 0 | P21: =IFERROR(M21/K21,) -> 0
C22: Ⅴ.영업이익 | D22: =D16-D18 -> 2134.2692 | E22: =IF(AND(D22>0,G22>0),G22/D22,"(-)") -> 0.44013411 | F22: =F16-F18 -> 1279.7307 | G22: =G16-G18 -> 939.36468 | H22: =IF(AND(F22>0,G22>0),G22/F22,"(-)") -> 0.73403309 | I22: =I16-I18 -> 92.136474 | J22: =IFERROR(I22/$I$6,) -> 0.0054590745 | K22: =K16-K18 -> 1004.6382 | L22: =IFERROR(K22/$K$6,) -> 0.05039004 | M22: =M16-M18 -> 847.22821 | N22: =IFERROR(M22/$M$6,) -> 0.041413175 | O22: =IF(AND(I22>0,M22>0),M22/I22,"(-)") -> 9.1953617 | P22: =IF(AND(K22>0,M22>0),M22/K22,"(-)") -> 0.84331669 | Q22: =P22-1 -> -0.15668331 | R22: =+M22-K22 -> -157.41004 | S22: =+M22-I22 -> 755.09173 | T22: =O22-1 -> 8.1953617
C23: (영업이익률) | D23: =D22/D6 -> 0.0091076752 | F23: =F22/F6 -> 0.032707478 | G23: =G22/G6 -> 0.025160018 | I23: =I22/I6 -> 0.0054590745 | K23: =K22/K6 -> 0.05039004 | M23: =IFERROR(M22/M6,) -> 0.041413175
C24: 전선 | D24: =D58 -> 11052.884 | E24: =IF(AND(D24>0,G24>0),G24/D24,"(-)") -> 0.24100628 | F24: =F58 -> 1726.3818 | G24: =G58 -> 2663.8146 | H24: =IF(AND(F24>0,G24>0),G24/F24,"(-)") -> 1.5430043 | I24: =I58 -> 894.79166 | J24: =IFERROR(I24/I7,) -> 0.064167623 | K24: =K58 -> 964.3922 | L24: =L58 -> 0.060020885 | M24: =M58 -> 1769.0229 | N24: =N58 -> 0.10329217 | O24: =IF(AND(I24>0,M24>0),M24/I24,"(-)") -> 1.9770222 | P24: =IF(AND(K24>0,M24>0),M24/K24,"(-)") -> 1.8343397
C25: 전장 | D25: =D78 -> -8918.6153 | E25: =IF(AND(D25>0,G25>0),G25/D25,"(-)") -> (-) | F25: =F78 -> -446.65111 | G25: =G78 -> -1724.4499 | H25: =IF(AND(F25>0,G25>0),G25/F25,"(-)") -> (-) | I25: =I78 -> -802.65519 | J25: =IFERROR(I25/I8,) -> -0.2736565 | K25: =K78 -> 40.246044 | L25: =L78 -> 0.010400494 | M25: =M78 -> -921.79474 | N25: =N78 -> -0.27668728 | O25: =IF(AND(I25>0,M25>0),M25/I25,"(-)") -> (-) | P25: =IF(AND(K25>0,M25>0),M25/K25,"(-)") -> (-)
C27: 구 분 | D27: 2026년 계 획 | E27: 년계획 진척률 | F27: 누 계 계 획 | G27: 누계 실적 | H27: 달성률 | I27: 전 월 실 적 | J27: 원 가 구성비 | K27: 당 월 계 획 | L27: 원 가 구성비 | M27: 당 월 실 적 | N27: 원 가 구성비 | O27: 전 월 대 비 | P27: 계 획 대 비
C28: Ⅰ. 재료비
C29: Ⅱ. 노무비
C30: Ⅲ. 경비
C31: Ⅳ. 당기총제조비용
C32: Ⅴ. 당기제품제조원가
Q35: =4352-3447 -> 905
C36: =CONCATENATE("□ ",'2. 손익계산서'!$C$4,"월 KSCM-DG 손익/원가 요약") -> □ 2월 KSCM-DG 손익/원가 요약 | N36: =$N$4 -> 1350 | O36: KRW/USD | P36: (단위:백만원)
C37: 구 분 | D37: 2026년 계 획 | E37: 년계획 진척률 | F37: 누 계 계 획 | G37: 누 계 실 적 | H37: 달성률 | I37: 전 월 실 적 | J37: 매출 구성비 | K37: 당 월 계 획 | L37: 매출 구성비 | M37: 당 월 실 적 | N37: 매출 구성비 | O37: 전 월 대 비 | P37: 계 획 대 비
C38: Ⅰ. 매출액 | D38: =SUM(D39:D40) -> 199321.01 | E38: =IFERROR(G38/D38,) -> 0.1558842 | F38: =SUM(F39:F40) -> 32075.728 | G38: =SUM(G39:G40) -> 31070.996 | H38: =IFERROR(G38/F38,) -> 0.96867627 | I38: =SUM(I39:I40) -> 13944.597 | J38: =IFERROR(I38/$I$38,) -> 1 | K38: =SUM(K39:K40) -> 16067.61 | L38: =IFERROR(K38/$K$38,) -> 1 | M38: =SUM(M39:M40) -> 17126.399 | N38: =IFERROR(M38/$M$38,) -> 1 | O38: =IFERROR(M38/I38,) -> 1.2281745 | P38: =IFERROR(M38/K38,) -> 1.0658958
C39: - 제품 | D39: ='2. 손익계산서'!C80*$N$4/1000000 -> 162935.8 | E39: =IFERROR(G39/D39,) -> 0.15420477 | F39: ='2. 손익계산서'!E80*$N$4/1000000 -> 25961.981 | G39: ='2. 손익계산서'!F80*$N$4/1000000 -> 25125.478 | H39: =IFERROR(G39/F39,) -> 0.96777968 | I39: ='2. 손익계산서'!H80*$N$4/1000000 -> 11979.263 | J39: =IFERROR(I39/$I$38,) -> 0.85906126 | K39: ='2. 손익계산서'!J80*$N$4/1000000 -> 13002.955 | L39: =IFERROR(K39/$K$38,) -> 0.80926501 | M39: ='2. 손익계산서'!L80*$N$4/1000000 -> 13146.214 | N39: =IFERROR(M39/$M$38,) -> 0.76759944 | O39: =IFERROR(M39/I39,) -> 1.0974143 | P39: =IFERROR(M39/K39,) -> 1.0110174
C40: - 상품 | D40: ='2. 손익계산서'!C81*$N$4/1000000 -> 36385.213 | E40: =IFERROR(G40/D40,) -> 0.16340481 | F40: ='2. 손익계산서'!E81*$N$4/1000000 -> 6113.7467 | G40: ='2. 손익계산서'!F81*$N$4/1000000 -> 5945.5186 | H40: =IFERROR(G40/F40,) -> 0.97248363 | I40: ='2. 손익계산서'!H81*$N$4/1000000 -> 1965.3339 | J40: =IFERROR(I40/$I$38,) -> 0.14093874 | K40: ='2. 손익계산서'!J81*$N$4/1000000 -> 3064.6555 | L40: =IFERROR(K40/$K$38,) -> 0.19073499 | M40: ='2. 손익계산서'!L81*$N$4/1000000 -> 3980.1847 | N40: =IFERROR(M40/$M$38,) -> 0.23240056 | O40: =IFERROR(M40/I40,) -> 2.0251951 | P40: =IFERROR(M40/K40,) -> 1.2987381
C41: DAWS | D41: ='2. 손익계산서'!C82*$N$4/1000000 -> 88697.11 | E41: =IFERROR(G41/D41,) -> 0.18492081 | F41: ='2. 손익계산서'!E82*$N$4/1000000 -> 14361.642 | G41: ='2. 손익계산서'!F82*$N$4/1000000 -> 16401.941 | H41: =IFERROR(G41/F41,) -> 1.1420659 | I41: ='2. 손익계산서'!H82*$N$4/1000000 -> 6653.3661 | J41: =IFERROR(I41/$I$38,) -> 0.47712859 | K41: ='2. 손익계산서'!J82*$N$4/1000000 -> 7192.9711 | L41: =IFERROR(K41/$K$38,) -> 0.447669 | M41: ='2. 손익계산서'!L82*$N$4/1000000 -> 9748.5749 | N41: =IFERROR(M41/$M$38,) -> 0.56921334 | O41: =IFERROR(M41/I41,) -> 1.4652094 | P41: =IFERROR(M41/K41,) -> 1.3552918
C42: HEDS | D42: ='2. 손익계산서'!C83*$N$4/1000000 -> 18279.223 | E42: =IFERROR(G42/D42,) -> 0.17279054 | F42: ='2. 손익계산서'!E83*$N$4/1000000 -> 4050.1658 | G42: ='2. 손익계산서'!F83*$N$4/1000000 -> 3158.4768 | H42: =IFERROR(G42/F42,) -> 0.77983888 | I42: ='2. 손익계산서'!H83*$N$4/1000000 -> 1399.9958 | J42: =IFERROR(I42/$I$38,) -> 0.10039701 | K42: ='2. 손익계산서'!J83*$N$4/1000000 -> 2028.5095 | L42: =IFERROR(K42/$K$38,) -> 0.12624836 | M42: ='2. 손익계산서'!L83*$N$4/1000000 -> 1758.481 | N42: =IFERROR(M42/$M$38,) -> 0.10267663 | O42: =IFERROR(M42/I42,) -> 1.2560616 | P42: =IFERROR(M42/K42,) -> 0.86688331
C43: CEWS | D43: ='2. 손익계산서'!C84*$N$4/1000000 -> 26755.106 | E43: =IFERROR(G43/D43,) -> 0.14145682 | F43: ='2. 손익계산서'!E84*$N$4/1000000 -> 4332.1282 | G43: ='2. 손익계산서'!F84*$N$4/1000000 -> 3784.6924 | H43: =IFERROR(G43/F43,) -> 0.87363352 | I43: ='2. 손익계산서'!H84*$N$4/1000000 -> 1518.0116 | J43: =IFERROR(I43/$I$38,) -> 0.10886019 | K43: ='2. 손익계산서'!J84*$N$4/1000000 -> 2169.7292 | L43: =IFERROR(K43/$K$38,) -> 0.13503745 | M43: ='2. 손익계산서'!L84*$N$4/1000000 -> 2266.6808 | N43: =IFERROR(M43/$M$38,) -> 0.13235011 | O43: =IFERROR(M43/I43,) -> 1.4931907 | P43: =IFERROR(M43/K43,) -> 1.0446837
C44: LEAR | D44: ='2. 손익계산서'!C85*$N$4/1000000 -> 22999.075 | E44: =IFERROR(G44/D44,) -> 0.19199841 | F44: ='2. 손익계산서'!E85*$N$4/1000000 -> 3723.9598 | G44: ='2. 손익계산서'!F85*$N$4/1000000 -> 4415.7858 | H44: =IFERROR(G44/F44,) -> 1.185777 | I44: ='2. 손익계산서'!H85*$N$4/1000000 -> 2584.558 | J44: =IFERROR(I44/$I$38,) -> 0.18534476 | K44: ='2. 손익계산서'!J85*$N$4/1000000 -> 1865.1305 | L44: =IFERROR(K44/$K$38,) -> 0.11608014 | M44: ='2. 손익계산서'!L85*$N$4/1000000 -> 1831.2278 | N44: =IFERROR(M44/$M$38,) -> 0.10692427 | O44: =IFERROR(M44/I44,) -> 0.70852646 | P44: =IFERROR(M44/K44,) -> 0.98182287
C45: KAC-OB | D45: ='2. 손익계산서'!C86*$N$4/1000000 -> 15452.857 | E45: =IFERROR(G45/D45,) -> 0.11894493 | F45: ='2. 손익계산서'!E86*$N$4/1000000 -> 2502.0927 | G45: ='2. 손익계산서'!F86*$N$4/1000000 -> 1838.0389 | H45: =IFERROR(G45/F45,) -> 0.73460064 | I45: ='2. 손익계산서'!H86*$N$4/1000000 -> 1128.1815 | J45: =IFERROR(I45/$I$38,) -> 0.08090456 | K45: ='2. 손익계산서'!J86*$N$4/1000000 -> 1253.1632 | L45: =IFERROR(K45/$K$38,) -> 0.077993127 | M45: ='2. 손익계산서'!L86*$N$4/1000000 -> 709.85741 | N45: =IFERROR(M45/$M$38,) -> 0.041448141 | O45: =IFERROR(M45/I45,) -> 0.62920496 | P45: =IFERROR(M45/K45,) -> 0.56645249
C46: SUMITOMO | D46: ='2. 손익계산서'!C87*$N$4/1000000 -> 19535.26 | E46: =IFERROR(G46/D46,) -> 0.010006482 | F46: ='2. 손익계산서'!E87*$N$4/1000000 -> 1874.7791 | G46: ='2. 손익계산서'!F87*$N$4/1000000 -> 195.47922 | H46: =IFERROR(G46/F46,) -> 0.10426787 | I46: ='2. 손익계산서'!H87*$N$4/1000000 -> 163.25667 | J46: =IFERROR(I46/$I$38,) -> 0.011707522 | K46: ='2. 손익계산서'!J87*$N$4/1000000 -> 941.58537 | L46: =IFERROR(K46/$K$38,) -> 0.058601456 | M46: ='2. 손익계산서'!L87*$N$4/1000000 -> 32.222543 | N46: =IFERROR(M46/$M$38,) -> 0.0018814546 | O46: =IFERROR(M46/I46,) -> 0.19737351 | P46: =IFERROR(M46/K46,) -> 0.034221584
C47: 기타 | D47: ='2. 손익계산서'!C88*$N$4/1000000 -> 7602.3794 | E47: =IFERROR(G47/D47,) -> 0.16791878 | F47: ='2. 손익계산서'!E88*$N$4/1000000 -> 1230.9606 | G47: ='2. 손익계산서'!F88*$N$4/1000000 -> 1276.5823 | H47: =IFERROR(G47/F47,) -> 1.0370619 | I47: ='2. 손익계산서'!H88*$N$4/1000000 -> 497.22756 | J47: =IFERROR(I47/$I$38,) -> 0.035657362 | K47: ='2. 손익계산서'!J88*$N$4/1000000 -> 616.52173 | L47: =IFERROR(K47/$K$38,) -> 0.038370467 | M47: ='2. 손익계산서'!L88*$N$4/1000000 -> 779.35474 | N47: =IFERROR(M47/$M$38,) -> 0.045506048 | O47: =IFERROR(M47/I47,) -> 1.5674005 | P47: =IFERROR(M47/K47,) -> 1.2641156
C48: (매출동량) | D48: ='2. 손익계산서'!C89 -> 0 | E48: =IFERROR(G48/D48,) -> 0 | F48: ='2. 손익계산서'!E89 -> 0 | G48: ='2. 손익계산서'!F89 -> 1346.4872 | H48: =IFERROR(G48/F48,) -> 0 | I48: ='2. 손익계산서'!H89 -> 631.81666 | J48: =IFERROR(I48/$I$38,) -> 0.045309065 | K48: ='2. 손익계산서'!J89 -> 0 | L48: =IFERROR(K48/$K$38,) -> 0 | M48: ='2. 손익계산서'!L89 -> 714.67057 | N48: =IFERROR(M48/$M$38,) -> 0.041729179 | O48: =IFERROR(M48/I48,) -> 1.131136 | P48: =IFERROR(M48/K48,) -> 0
...

Sheet 2. 손익계산서
B3: Plofit and Loss statement FY 2026
B4: MONTH | C4: 2 | O4: (단위:$)
B5: 구 분 | C5: 2026년 계 획 | D5: 년계획 진척률 | E5: 누 계 계 획 | F5: 누 계 실 적 | G5: 달성률 | H5: 전 월 실 적 | I5: 매 출 구성비 | J5: 당 월 계 획 | K5: 매 출 구성비 | L5: 당 월 실 적 | M5: 매 출 구성비 | N5: 전 월 대 비 | O5: 계 획 대 비 | Y5: 연계획 | Z5: 누계 계획 | AA5: 누계 실적 | AB5: 전월 실적 | AC5: 당월 계획 | AD5: 당월 실적
B6: Ⅰ. 매출액 | C6: =C7+C9 -> 1.7358328e+08 | D6: =+IFERROR(F6/C6,) -> 0.15932415 | E6: =E7+E9 -> 28982629 | F6: =F7+F9 -> 27656009 | G6: =+IFERROR(F6/E6,) -> 0.95422707 | H6: =H7+H9 -> 12501980 | I6: =+IFERROR(H6/$H$6,) -> 1 | J6: =J7+J9 -> 14768325 | K6: =+IFERROR(J6/$J$6,) -> 1 | L6: =L7+L9 -> 15154029 | M6: =+IFERROR(L6/$L$6,) -> 1 | N6: =+IFERROR(L6/H6,) -> 1.2121303 | O6: =+IFERROR(L6/J6,) -> 1.026117 | Q6: 당월실적 | S6: 당월계획 | U6: 전월실적 | Y6: =+C6*1330/1000000 -> 230865.76 | Z6: =+E6*1330/1000000 -> 38546.896 | AA6: =+F6*1330/1000000 -> 36782.492 | AB6: =+H6*1330/1000000 -> 16627.633 | AC6: =+J6*1330/1000000 -> 19641.872 | AD6: =+L6*1330/1000000 -> 20154.859
B7: - 전선 | C7: ='(계획)손익계산서 월별계획'!C7 -> 1.4764519e+08 | D7: =+IFERROR(F7/C7,) -> 0.1558842 | E7: =SUM('(계획)손익계산서 월별계획'!E7:(OFFSET('(계획)손익계산서 월별계획'!E7,0,$C$4-1))) -> 23759798 | F7: =SUM('3. 손익계산서 월별실적'!E7:(OFFSET('3. 손익계산서 월별실적'!E7,0,$C$4-1))) -> 23015553 | G7: =+IFERROR(F7/E7,) -> 0.96867627 | H7: =OFFSET('3. 손익계산서 월별실적'!E7,0,$C$4-2) -> 10329331 | I7: =+IFERROR(H7/$H$6,) -> 0.82621564 | J7: =OFFSET('(계획)손익계산서 월별계획'!E7,0,$C$4-1) -> 11901934 | K7: =+IFERROR(J7/$J$6,) -> 0.80590952 | L7: =OFFSET('3. 손익계산서 월별실적'!E7,0,$C$4-1) -> 12686222 | M7: =+IFERROR(L7/$L$6,) -> 0.83715173 | N7: =+IFERROR(L7/H7,) -> 1.2281745 | O7: =+IFERROR(L7/J7,) -> 1.0658958 | S7: =+Q8-S8 -> -182563.12 | U7: =+Q8-U8 -> -1164932.3
B8: └ 매출동량 | C8: ='(계획)손익계산서 월별계획'!C8 -> 0 | D8: =+IFERROR(F8/C8,) -> 0 | E8: =SUM('(계획)손익계산서 월별계획'!E8:(OFFSET('(계획)손익계산서 월별계획'!E8,0,$C$4-1))) -> 0 | F8: =SUM('3. 손익계산서 월별실적'!E8:(OFFSET('3. 손익계산서 월별실적'!E8,0,$C$4-1))) -> 1346.4872 | G8: =+IFERROR(F8/E8,) -> 0 | H8: =OFFSET('3. 손익계산서 월별실적'!E8,0,$C$4-2) -> 631.81666 | I8: =+IFERROR(H8/$H$6,) -> 5.0537328e-05 | J8: =OFFSET('(계획)손익계산서 월별계획'!E8,0,$C$4-1) -> 0 | K8: =+IFERROR(J8/$J$6,) -> 0 | L8: =OFFSET('3. 손익계산서 월별실적'!E8,0,$C$4-1) -> 714.67057 | M8: =+IFERROR(L8/$L$6,) -> 4.7160433e-05 | N8: =+IFERROR(L8/H8,) -> 1.131136 | O8: =+IFERROR(L8/J8,) -> 0 | Q8: =+L8-L13 -> -2362937.6 | R8: =+Q8/L8 -> -3306.3312 | S8: =+J8-J13 -> -2180374.5 | T8: =+S8/J8 -> #DIV/0! | U8: =+H8-H13 -> -1198005.3 | V8: =+U8/H8 -> -1896.1281
B9: - 전장 | C9: ='(계획)손익계산서 월별계획'!C9 -> 25938089 | D9: =+IFERROR(F9/C9,) -> 0.17890508 | E9: =SUM('(계획)손익계산서 월별계획'!E9:(OFFSET('(계획)손익계산서 월별계획'!E9,0,$C$4-1))) -> 5222830.1 | F9: =SUM('3. 손익계산서 월별실적'!E9:(OFFSET('3. 손익계산서 월별실적'!E9,0,$C$4-1))) -> 4640455.9 | G9: =+IFERROR(F9/E9,) -> 0.88849452 | H9: =OFFSET('3. 손익계산서 월별실적'!E9,0,$C$4-2) -> 2172648.5 | I9: =+IFERROR(H9/$H$6,) -> 0.17378436 | J9: =OFFSET('(계획)손익계산서 월별계획'!E9,0,$C$4-1) -> 2866391.3 | K9: =+IFERROR(J9/$J$6,) -> 0.19409048 | L9: =OFFSET('3. 손익계산서 월별실적'!E9,0,$C$4-1) -> 2467807.4 | M9: =+IFERROR(L9/$L$6,) -> 0.16284827 | N9: =+IFERROR(L9/H9,) -> 1.1358521 | O9: =+IFERROR(L9/J9,) -> 0.86094576 | Q9: =+L9-L14 -> 2467807.4 | R9: =+Q9/L9 -> 1 | S9: =+J9-J14 -> 2793582.1 | T9: =+S9/J9 -> 0.974599 | U9: =+H9-H14 -> 2467338.5 | V9: =+U9/H9 -> 1.1356363
B11: Ⅱ. 매출원가 | C11: =SUM(C12:C14) -> 1.6273746e+08 | D11: =+IFERROR(F11/C11,) -> 0.15705544 | E11: =SUM(E12:E15) -> 26470571 | F11: =SUM(F12:F15) -> 25558804 | G11: =+IFERROR(F11/E11,) -> 0.96555544 | H11: =SUM(H12:H15) -> 11738514 | I11: =+IFERROR(H11/$H$6,) -> 0.93893244 | J11: =SUM(J12:J15) -> 13263500 | K11: =+IFERROR(J11/$J$6,) -> 0.89810458 | L11: =SUM(L12:L15) -> 13820290 | M11: =+IFERROR(L11/$L$6,) -> 0.9119878 | N11: =+IFERROR(L11/H11,) -> 1.1773457 | O11: =+IFERROR(L11/J11,) -> 1.0419791 | S11: =+Q10-S10 -> 0 | U11: =+Q10-U10 -> 0 | Y11: =+C11*1330/1000000 -> 216440.82 | Z11: =+E11*1330/1000000 -> 35205.86 | AA11: =+F11*1330/1000000 -> 33993.209 | AB11: =+H11*1330/1000000 -> 15612.224 | AC11: =+J11*1330/1000000 -> 17640.455 | AD11: =+L11*1330/1000000 -> 18380.985
B12: - 제품 | C12: ='(계획)손익계산서 월별계획'!C12 -> 1.3515827e+08 | D12: =+IFERROR(F12/C12,) -> 0.16492668 | E12: =SUM('(계획)손익계산서 월별계획'!E12:(OFFSET('(계획)손익계산서 월별계획'!E12,0,$C$4-1))) -> 21765122 | F12: =SUM('3. 손익계산서 월별실적'!E12:(OFFSET('3. 손익계산서 월별실적'!E12,0,$C$4-1))) -> 22291205 | G12: =+IFERROR(F12/E12,) -> 1.0241709 | H12: =OFFSET('3. 손익계산서 월별실적'!E12,0,$C$4-2) -> 10834567 | I12: =+IFERROR(H12/$H$6,) -> 0.86662812 | J12: =OFFSET('(계획)손익계산서 월별계획'!E12,0,$C$4-1) -> 11010317 | K12: =+IFERROR(J12/$J$6,) -> 0.74553591 | L12: =OFFSET('3. 손익계산서 월별실적'!E12,0,$C$4-1) -> 11456637 | M12: =+IFERROR(L12/$L$6,) -> 0.75601263 | N12: =+IFERROR(L12/H12,) -> 1.0574153 | O12: =+IFERROR(L12/J12,) -> 1.0405366
B13: - 상품 | C13: ='(계획)손익계산서 월별계획'!C13 -> 25798607 | D13: =+IFERROR(F13/C13,) -> 0.13808069 | E13: =SUM('(계획)손익계산서 월별계획'!E13:(OFFSET('(계획)손익계산서 월별계획'!E13,0,$C$4-1))) -> 4351631.1 | F13: =SUM('3. 손익계산서 월별실적'!E13:(OFFSET('3. 손익계산서 월별실적'!E13,0,$C$4-1))) -> 3562289.4 | G13: =+IFERROR(F13/E13,) -> 0.81861016 | H13: =OFFSET('3. 손익계산서 월별실적'!E13,0,$C$4-2) -> 1198637.1 | I13: =+IFERROR(H13/$H$6,) -> 0.095875785 | J13: =OFFSET('(계획)손익계산서 월별계획'!E13,0,$C$4-1) -> 2180374.5 | K13: =+IFERROR(J13/$J$6,) -> 0.14763858 | L13: =OFFSET('3. 손익계산서 월별실적'!E13,0,$C$4-1) -> 2363652.3 | M13: =+IFERROR(L13/$L$6,) -> 0.15597517 | N13: =+IFERROR(L13/H13,) -> 1.9719498 | O13: =+IFERROR(L13/J13,) -> 1.0840579
B14: - 기타 | C14: ='(계획)손익계산서 월별계획'!C14 -> 1780585.4 | D14: =+IFERROR(F14/C14,) -> -0.16550175 | E14: =SUM('(계획)손익계산서 월별계획'!E14:(OFFSET('(계획)손익계산서 월별계획'!E14,0,$C$4-1))) -> 353818.4 | F14: =SUM('3. 손익계산서 월별실적'!E14:(OFFSET('3. 손익계산서 월별실적'!E14,0,$C$4-1))) -> -294690 | G14: =+IFERROR(F14/E14,) -> -0.8328849 | H14: =OFFSET('3. 손익계산서 월별실적'!E14,0,$C$4-2) -> -294690 | I14: =+IFERROR(H14/$H$6,) -> -0.023571467 | J14: =OFFSET('(계획)손익계산서 월별계획'!E14,0,$C$4-1) -> 72809.198 | K14: =+IFERROR(J14/$J$6,) -> 0.0049300918 | L14: =OFFSET('3. 손익계산서 월별실적'!E14,0,$C$4-1) -> 0 | M14: =+IFERROR(L14/$L$6,) -> 0 | N14: =+IFERROR(L14/H14,) -> 0 | O14: =+IFERROR(L14/J14,) -> 0
B16: Ⅲ. 매출총이익 | C16: =C6-C11 -> 10845821 | D16: =IF(AND(C16>0,F16>0),F16/C16,"(-)") -> 0.19336524 | E16: =+E6-E11 -> 2512057.3 | F16: =+F6-F11 -> 2097204.8 | G16: =IF(AND(E16>0,F16>0),F16/E16,"(-)") -> 0.83485547 | H16: =+H6-H11 -> 763465.41 | I16: =+IFERROR(H16/$H$6,) -> 0.06106756 | J16: =+J6-J11 -> 1504824.6 | K16: =+IFERROR(J16/$J$6,) -> 0.10189542 | L16: =+L6-L11 -> 1333739.4 | M16: =+IFERROR(L16/$L$6,) -> 0.088012198 | N16: =+IF(AND(H16>0,L16>0),L16/H16,"(-)") -> 1.7469546 | O16: =+IF(AND(J16>0,N16>0),L16/J16,"(-)") -> 0.88630886 | Y16: =+C16*1330/1000000 -> 14424.942 | Z16: =+E16*1330/1000000 -> 3341.0362 | AA16: =+F16*1330/1000000 -> 2789.2824 | AB16: =+H16*1330/1000000 -> 1015.409 | AC16: =+J16*1330/1000000 -> 2001.4167 | AD16: =+L16*1330/1000000 -> 1773.8734
B17: (이익률) | C17: =+IFERROR(C16/C6,) -> 0.062481946 | E17: =+IFERROR(E16/E6,) -> 0.086674585 | F17: =+IFERROR(F16/F6,) -> 0.075831795 | G17: =+IFERROR(F17/E17,) -> 0.87490231 | H17: =+IFERROR(H16/H6,) -> 0.06106756 | J17: =+IFERROR(J16/J6,) -> 0.10189542 | L17: =+IFERROR(L16/L6,) -> 0.088012198 | Y17: =+Y6-Y11 -> 14424.942 | Z17: =+Z6-Z11 -> 3341.0362 | AA17: =+AA6-AA11 -> 2789.2824 | AB17: =+AB6-AB11 -> 1015.409 | AC17: =+AC6-AC11 -> 2001.4167 | AD17: =+AD6-AD11 -> 1773.8734
B18: Ⅳ.판매관리비 | C18: =SUM(C19,C35,C53) -> 9264881.1 | D18: =+IFERROR(F18/C18,) -> 0.15125711 | E18: =+E19+E35+E53 -> 1564108.6 | F18: =+F19+F35+F53 -> 1401379.1 | G18: =+IFERROR(F18/E18,) -> 0.89596021 | H18: =+H19+H35+H53 -> 695216.17 | I18: =+IFERROR(H18/$H$6,) -> 0.055608486 | J18: =+J19+J35+J53 -> 760648.13 | K18: =+IFERROR(J18/$J$6,) -> 0.051505376 | L18: =+L19+L35+L53 -> 706162.94 | M18: =+IFERROR(L18/$L$6,) -> 0.046599023 | N18: =+IFERROR(L18/H18,) -> 1.0157459 | O18: =+IFERROR(L18/J18,) -> 0.92837004 | Q18: =+L18-J18 -> -54485.193 | R18: =+L18-H18 -> 10946.77 | Y18: =+C18*1330/1000000 -> 12322.292 | Z18: =+E18*1330/1000000 -> 2080.2645 | AA18: =+F18*1330/1000000 -> 1863.8342 | AB18: =+H18*1330/1000000 -> 924.63751 | AC18: =+J18*1330/1000000 -> 1011.662 | AD18: =+L18*1330/1000000 -> 939.19671
B19: [판매비] | C19: =SUM(C20:C33) -> 0 | D19: =+IFERROR(F19/C19,) -> 0 | E19: =SUM(E20:E34) -> 0 | F19: =SUM(F20:F34) -> 0 | G19: =+IFERROR(F19/E19,) -> 0 | H19: =SUM(H20:H34) -> 0 | I19: =+IFERROR(H19/$H$6,) -> 0 | J19: =SUM(J20:J34) -> 0 | K19: =+IFERROR(J19/$J$6,) -> 0 | L19: =SUM(L20:L34) -> 0 | M19: =+IFERROR(L19/$L$6,) -> 0 | N19: =+IFERROR(L19/H19,) -> 0 | O19: =+IFERROR(L19/J19,) -> 0 | R19: 누계 계획 | S19: 누계 실적
B20: 인건비 | C20: ='(계획)손익계산서 월별계획'!C20 -> 0 | D20: =+IFERROR(F20/C20,) -> 0 | E20: =SUM('(계획)손익계산서 월별계획'!E20:(OFFSET('(계획)손익계산서 월별계획'!E20,0,$C$4-1))) -> 0 | F20: =SUM('3. 손익계산서 월별실적'!E20:(OFFSET('3. 손익계산서 월별실적'!E20,0,$C$4-1))) -> 0 | G20: =+IFERROR(F20/E20,) -> 0 | H20: =OFFSET('3. 손익계산서 월별실적'!E20,0,$C$4-2) -> 0 | I20: =+IFERROR(H20/$H$6,) -> 0 | J20: =OFFSET('(계획)손익계산서 월별계획'!E20,0,$C$4-1) -> 0 | K20: =+IFERROR(J20/$J$6,) -> 0 | L20: =OFFSET('3. 손익계산서 월별실적'!E20,0,$C$4-1) -> 0 | M20: =+IFERROR(L20/$L$6,) -> 0 | N20: =+IFERROR(L20/H20,) -> 0 | O20: =+IFERROR(L20/J20,) -> 0 | Q20: 인건비 | R20: =+E20+E36+E54 -> 694634.81 | S20: =+F20+F36+F54 -> 646352.28 | T20: =+S20/R20 -> 0.93049221
B21: 유지비용 | C21: ='(계획)손익계산서 월별계획'!C21 -> 0 | D21: =+IFERROR(F21/C21,) -> 0 | E21: =SUM('(계획)손익계산서 월별계획'!E21:(OFFSET('(계획)손익계산서 월별계획'!E21,0,$C$4-1))) -> 0 | F21: =SUM('3. 손익계산서 월별실적'!E21:(OFFSET('3. 손익계산서 월별실적'!E21,0,$C$4-1))) -> 0 | G21: =+IFERROR(F21/E21,) -> 0 | H21: =OFFSET('3. 손익계산서 월별실적'!E21,0,$C$4-2) -> 0 | I21: =+IFERROR(H21/$H$6,) -> 0 | J21: =OFFSET('(계획)손익계산서 월별계획'!E21,0,$C$4-1) -> 0 | K21: =+IFERROR(J21/$J$6,) -> 0 | L21: =OFFSET('3. 손익계산서 월별실적'!E21,0,$C$4-1) -> 0 | M21: =+IFERROR(L21/$L$6,) -> 0 | N21: =+IFERROR(L21/H21,) -> 0 | O21: =+IFERROR(L21/J21,) -> 0 | Q21: 지급수수료비 | R21: =SUM(E27,E43,E61) -> 573325.33 | S21: =SUM(F27,F43,F61) -> 478068.05 | T21: =+S21/R21 -> 0.83385126
B22: 세금,보험 | C22: ='(계획)손익계산서 월별계획'!C22 -> 0 | D22: =+IFERROR(F22/C22,) -> 0 | E22: =SUM('(계획)손익계산서 월별계획'!E22:(OFFSET('(계획)손익계산서 월별계획'!E22,0,$C$4-1))) -> 0 | F22: =SUM('3. 손익계산서 월별실적'!E22:(OFFSET('3. 손익계산서 월별실적'!E22,0,$C$4-1))) -> 0 | G22: =+IFERROR(F22/E22,) -> 0 | H22: =OFFSET('3. 손익계산서 월별실적'!E22,0,$C$4-2) -> 0 | I22: =+IFERROR(H22/$H$6,) -> 0 | J22: =OFFSET('(계획)손익계산서 월별계획'!E22,0,$C$4-1) -> 0 | K22: =+IFERROR(J22/$J$6,) -> 0 | L22: =OFFSET('3. 손익계산서 월별실적'!E22,0,$C$4-1) -> 0 | M22: =+IFERROR(L22/$L$6,) -> 0 | N22: =+IFERROR(L22/H22,) -> 0 | O22: =+IFERROR(L22/J22,) -> 0 | Q22: 개발비 | R22: =SUM(E30,E46,E64) -> 0 | S22: =SUM(F30,F46,F64) -> 0 | T22: =+S22/R22 -> #DIV/0!
B23: 복리후생비 | C23: ='(계획)손익계산서 월별계획'!C23 -> 0 | D23: =+IFERROR(F23/C23,) -> 0 | E23: =SUM('(계획)손익계산서 월별계획'!E23:(OFFSET('(계획)손익계산서 월별계획'!E23,0,$C$4-1))) -> 0 | F23: =SUM('3. 손익계산서 월별실적'!E23:(OFFSET('3. 손익계산서 월별실적'!E23,0,$C$4-1))) -> 0 | G23: =+IFERROR(F23/E23,) -> 0 | H23: =OFFSET('3. 손익계산서 월별실적'!E23,0,$C$4-2) -> 0 | I23: =+IFERROR(H23/$H$6,) -> 0 | J23: =OFFSET('(계획)손익계산서 월별계획'!E23,0,$C$4-1) -> 0 | K23: =+IFERROR(J23/$J$6,) -> 0 | L23: =OFFSET('3. 손익계산서 월별실적'!E23,0,$C$4-1) -> 0 | M23: =+IFERROR(L23/$L$6,) -> 0 | N23: =+IFERROR(L23/H23,) -> 0 | O23: =+IFERROR(L23/J23,) -> 0
B24: 운반비 | C24: ='(계획)손익계산서 월별계획'!C24 -> 0 | D24: =+IFERROR(F24/C24,) -> 0 | E24: =SUM('(계획)손익계산서 월별계획'!E24:(OFFSET('(계획)손익계산서 월별계획'!E24,0,$C$4-1))) -> 0 | F24: =SUM('3. 손익계산서 월별실적'!E24:(OFFSET('3. 손익계산서 월별실적'!E24,0,$C$4-1))) -> 0 | G24: =+IFERROR(F24/E24,) -> 0 | H24: =OFFSET('3. 손익계산서 월별실적'!E24,0,$C$4-2) -> 0 | I24: =+IFERROR(H24/$H$6,) -> 0 | J24: =OFFSET('(계획)손익계산서 월별계획'!E24,0,$C$4-1) -> 0 | K24: =+IFERROR(J24/$J$6,) -> 0 | L24: =OFFSET('3. 손익계산서 월별실적'!E24,0,$C$4-1) -> 0 | M24: =+IFERROR(L24/$L$6,) -> 0 | N24: =+IFERROR(L24/H24,) -> 0 | O24: =+IFERROR(L24/J24,) -> 0
B25: 포장비 | C25: ='(계획)손익계산서 월별계획'!C25 -> 0 | D25: =+IFERROR(F25/C25,) -> 0 | E25: =SUM('(계획)손익계산서 월별계획'!E25:(OFFSET('(계획)손익계산서 월별계획'!E25,0,$C$4-1))) -> 0 | F25: =SUM('3. 손익계산서 월별실적'!E25:(OFFSET('3. 손익계산서 월별실적'!E25,0,$C$4-1))) -> 0 | G25: =+IFERROR(F25/E25,) -> 0 | H25: =OFFSET('3. 손익계산서 월별실적'!E25,0,$C$4-2) -> 0 | I25: =+IFERROR(H25/$H$6,) -> 0 | J25: =OFFSET('(계획)손익계산서 월별계획'!E25,0,$C$4-1) -> 0 | K25: =+IFERROR(J25/$J$6,) -> 0 | L25: =OFFSET('3. 손익계산서 월별실적'!E25,0,$C$4-1) -> 0 | M25: =+IFERROR(L25/$L$6,) -> 0 | N25: =+IFERROR(L25/H25,) -> 0 | O25: =+IFERROR(L25/J25,) -> 0
B26: 광고선전비 | C26: ='(계획)손익계산서 월별계획'!C26 -> 0 | D26: =+IFERROR(F26/C26,) -> 0 | E26: =SUM('(계획)손익계산서 월별계획'!E26:(OFFSET('(계획)손익계산서 월별계획'!E26,0,$C$4-1))) -> 0 | F26: =SUM('3. 손익계산서 월별실적'!E26:(OFFSET('3. 손익계산서 월별실적'!E26,0,$C$4-1))) -> 0 | G26: =+IFERROR(F26/E26,) -> 0 | H26: =OFFSET('3. 손익계산서 월별실적'!E26,0,$C$4-2) -> 0 | I26: =+IFERROR(H26/$H$6,) -> 0 | J26: =OFFSET('(계획)손익계산서 월별계획'!E26,0,$C$4-1) -> 0 | K26: =+IFERROR(J26/$J$6,) -> 0 | L26: =OFFSET('3. 손익계산서 월별실적'!E26,0,$C$4-1) -> 0 | M26: =+IFERROR(L26/$L$6,) -> 0 | N26: =+IFERROR(L26/H26,) -> 0 | O26: =+IFERROR(L26/J26,) -> 0
B27: 지급수수료 | C27: ='(계획)손익계산서 월별계획'!C27 -> 0 | D27: =+IFERROR(F27/C27,) -> 0 | E27: =SUM('(계획)손익계산서 월별계획'!E27:(OFFSET('(계획)손익계산서 월별계획'!E27,0,$C$4-1))) -> 0 | F27: =SUM('3. 손익계산서 월별실적'!E27:(OFFSET('3. 손익계산서 월별실적'!E27,0,$C$4-1))) -> 0 | G27: =+IFERROR(F27/E27,) -> 0 | H27: =OFFSET('3. 손익계산서 월별실적'!E27,0,$C$4-2) -> 0 | I27: =+IFERROR(H27/$H$6,) -> 0 | J27: =OFFSET('(계획)손익계산서 월별계획'!E27,0,$C$4-1) -> 0 | K27: =+IFERROR(J27/$J$6,) -> 0 | L27: =OFFSET('3. 손익계산서 월별실적'!E27,0,$C$4-1) -> 0 | M27: =+IFERROR(L27/$L$6,) -> 0 | N27: =+IFERROR(L27/H27,) -> 0 | O27: =+IFERROR(L27/J27,) -> 0
B28: 여비교통비 | C28: ='(계획)손익계산서 월별계획'!C28 -> 0 | D28: =+IFERROR(F28/C28,) -> 0 | E28: =SUM('(계획)손익계산서 월별계획'!E28:(OFFSET('(계획)손익계산서 월별계획'!E28,0,$C$4-1))) -> 0 | F28: =SUM('3. 손익계산서 월별실적'!E28:(OFFSET('3. 손익계산서 월별실적'!E28,0,$C$4-1))) -> 0 | G28: =+IFERROR(F28/E28,) -> 0 | H28: =OFFSET('3. 손익계산서 월별실적'!E28,0,$C$4-2) -> 0 | I28: =+IFERROR(H28/$H$6,) -> 0 | J28: =OFFSET('(계획)손익계산서 월별계획'!E28,0,$C$4-1) -> 0 | K28: =+IFERROR(J28/$J$6,) -> 0 | L28: =OFFSET('3. 손익계산서 월별실적'!E28,0,$C$4-1) -> 0 | M28: =+IFERROR(L28/$L$6,) -> 0 | N28: =+IFERROR(L28/H28,) -> 0 | O28: =+IFERROR(L28/J28,) -> 0
B29: 감가상각비 | C29: ='(계획)손익계산서 월별계획'!C29 -> 0 | D29: =+IFERROR(F29/C29,) -> 0 | E29: =SUM('(계획)손익계산서 월별계획'!E29:(OFFSET('(계획)손익계산서 월별계획'!E29,0,$C$4-1))) -> 0 | F29: =SUM('3. 손익계산서 월별실적'!E29:(OFFSET('3. 손익계산서 월별실적'!E29,0,$C$4-1))) -> 0 | G29: =+IFERROR(F29/E29,) -> 0 | H29: =OFFSET('3. 손익계산서 월별실적'!E29,0,$C$4-2) -> 0 | I29: =+IFERROR(H29/$H$6,) -> 0 | J29: =OFFSET('(계획)손익계산서 월별계획'!E29,0,$C$4-1) -> 0 | K29: =+IFERROR(J29/$J$6,) -> 0 | L29: =OFFSET('3. 손익계산서 월별실적'!E29,0,$C$4-1) -> 0 | M29: =+IFERROR(L29/$L$6,) -> 0 | N29: =+IFERROR(L29/H29,) -> 0 | O29: =+IFERROR(L29/J29,) -> 0
B30: 개발비 | C30: ='(계획)손익계산서 월별계획'!C30 -> 0 | D30: =+IFERROR(F30/C30,) -> 0 | E30: =SUM('(계획)손익계산서 월별계획'!E30:(OFFSET('(계획)손익계산서 월별계획'!E30,0,$C$4-1))) -> 0 | F30: =SUM('3. 손익계산서 월별실적'!E30:(OFFSET('3. 손익계산서 월별실적'!E30,0,$C$4-1))) -> 0 | G30: =+IFERROR(F30/E30,) -> 0 | H30: =OFFSET('3. 손익계산서 월별실적'!E30,0,$C$4-2) -> 0 | I30: =+IFERROR(H30/$H$6,) -> 0 | J30: =OFFSET('(계획)손익계산서 월별계획'!E30,0,$C$4-1) -> 0 | K30: =+IFERROR(J30/$J$6,) -> 0 | L30: =OFFSET('3. 손익계산서 월별실적'!E30,0,$C$4-1) -> 0 | M30: =+IFERROR(L30/$L$6,) -> 0 | N30: =+IFERROR(L30/H30,) -> 0 | O30: =+IFERROR(L30/J30,) -> 0
B31: 충당비용 | C31: ='(계획)손익계산서 월별계획'!C31 -> 0 | D31: =+IFERROR(F31/C31,) -> 0 | E31: =SUM('(계획)손익계산서 월별계획'!E31:(OFFSET('(계획)손익계산서 월별계획'!E31,0,$C$4-1))) -> 0 | F31: =SUM('3. 손익계산서 월별실적'!E31:(OFFSET('3. 손익계산서 월별실적'!E31,0,$C$4-1))) -> 0 | G31: =+IFERROR(F31/E31,) -> 0 | H31: =OFFSET('3. 손익계산서 월별실적'!E31,0,$C$4-2) -> 0 | I31: =+IFERROR(H31/$H$6,) -> 0 | J31: =OFFSET('(계획)손익계산서 월별계획'!E31,0,$C$4-1) -> 0 | K31: =+IFERROR(J31/$J$6,) -> 0 | L31: =OFFSET('3. 손익계산서 월별실적'!E31,0,$C$4-1) -> 0 | M31: =+IFERROR(L31/$L$6,) -> 0 | N31: =+IFERROR(L31/H31,) -> 0 | O31: =+IFERROR(L31/J31,) -> 0
B32: 외주비 | C32: ='(계획)손익계산서 월별계획'!C32 -> 0 | D32: =+IFERROR(F32/C32,) -> 0 | E32: =SUM('(계획)손익계산서 월별계획'!E32:(OFFSET('(계획)손익계산서 월별계획'!E32,0,$C$4-1))) -> 0 | F32: =SUM('3. 손익계산서 월별실적'!E32:(OFFSET('3. 손익계산서 월별실적'!E32,0,$C$4-1))) -> 0 | G32: =+IFERROR(F32/E32,) -> 0 | H32: =OFFSET('3. 손익계산서 월별실적'!E32,0,$C$4-2) -> 0 | I32: =+IFERROR(H32/$H$6,) -> 0 | J32: =OFFSET('(계획)손익계산서 월별계획'!E32,0,$C$4-1) -> 0 | K32: =+IFERROR(J32/$J$6,) -> 0 | L32: =OFFSET('3. 손익계산서 월별실적'!E32,0,$C$4-1) -> 0 | M32: =+IFERROR(L32/$L$6,) -> 0 | N32: =+IFERROR(L32/H32,) -> 0 | O32: =+IFERROR(L32/J32,) -> 0
B33: 기타비용 | C33: ='(계획)손익계산서 월별계획'!C33 -> 0 | D33: =+IFERROR(F33/C33,) -> 0 | E33: =SUM('(계획)손익계산서 월별계획'!E33:(OFFSET('(계획)손익계산서 월별계획'!E33,0,$C$4-1))) -> 0 | F33: =SUM('3. 손익계산서 월별실적'!E33:(OFFSET('3. 손익계산서 월별실적'!E33,0,$C$4-1))) -> 0 | G33: =+IFERROR(F33/E33,) -> 0 | H33: =OFFSET('3. 손익계산서 월별실적'!E33,0,$C$4-2) -> 0 | I33: =+IFERROR(H33/$H$6,) -> 0 | J33: =OFFSET('(계획)손익계산서 월별계획'!E33,0,$C$4-1) -> 0 | K33: =+IFERROR(J33/$J$6,) -> 0 | L33: =OFFSET('3. 손익계산서 월별실적'!E33,0,$C$4-1) -> 0 | M33: =+IFERROR(L33/$L$6,) -> 0 | N33: =+IFERROR(L33/H33,) -> 0 | O33: =+IFERROR(L33/J33,) -> 0
B35: [관리비] | C35: =SUM(C36:C51) -> 9264881.1 | D35: =+IFERROR(F35/C35,) -> 0.15125711 | E35: =SUM(E36:E51) -> 1564108.6 | F35: =SUM(F36:F51) -> 1401379.1 | G35: =+IFERROR(F35/E35,) -> 0.89596021 | H35: =SUM(H36:H51) -> 695216.17 | I35: =+IFERROR(H35/$H$6,) -> 0.055608486 | J35: =SUM(J36:J51) -> 760648.13 | K35: =+IFERROR(J35/$J$6,) -> 0.051505376 | L35: =SUM(L36:L51) -> 706162.94 | M35: =+IFERROR(L35/$L$6,) -> 0.046599023 | N35: =+IFERROR(L35/H35,) -> 1.0157459 | O35: =+IFERROR(L35/J35,) -> 0.92837004
B36: 인건비 | C36: ='(계획)손익계산서 월별계획'!C36 -> 4201174.1 | D36: =+IFERROR(F36/C36,) -> 0.15385039 | E36: =SUM('(계획)손익계산서 월별계획'!E36:(OFFSET('(계획)손익계산서 월별계획'!E36,0,$C$4-1))) -> 694634.81 | F36: =SUM('3. 손익계산서 월별실적'!E36:(OFFSET('3. 손익계산서 월별실적'!E36,0,$C$4-1))) -> 646352.28 | G36: =+IFERROR(F36/E36,) -> 0.93049221 | H36: =OFFSET('3. 손익계산서 월별실적'!E36,0,$C$4-2) -> 325645.54 | I36: =+IFERROR(H36/$H$6,) -> 0.026047518 | J36: =OFFSET('(계획)손익계산서 월별계획'!E36,0,$C$4-1) -> 347317.4 | K36: =+IFERROR(J36/$J$6,) -> 0.023517725 | L36: =OFFSET('3. 손익계산서 월별실적'!E36,0,$C$4-1) -> 320706.74 | M36: =+IFERROR(L36/$L$6,) -> 0.021163134 | N36: =+IFERROR(L36/H36,) -> 0.98483382 | O36: =+IFERROR(L36/J36,) -> 0.92338229
B37: 유지비용 | C37: ='(계획)손익계산서 월별계획'!C37 -> 132669.7 | D37: =+IFERROR(F37/C37,) -> 0.1950468 | E37: =SUM('(계획)손익계산서 월별계획'!E37:(OFFSET('(계획)손익계산서 월별계획'!E37,0,$C$4-1))) -> 22111.616 | F37: =SUM('3. 손익계산서 월별실적'!E37:(OFFSET('3. 손익계산서 월별실적'!E37,0,$C$4-1))) -> 25876.8 | G37: =+IFERROR(F37/E37,) -> 1.1702808 | H37: =OFFSET('3. 손익계산서 월별실적'!E37,0,$C$4-2) -> 12954.35 | I37: =+IFERROR(H37/$H$6,) -> 0.0010361839 | J37: =OFFSET('(계획)손익계산서 월별계획'!E37,0,$C$4-1) -> 11055.808 | K37: =+IFERROR(J37/$J$6,) -> 0.00074861625 | L37: =OFFSET('3. 손익계산서 월별실적'!E37,0,$C$4-1) -> 12922.45 | M37: =+IFERROR(L37/$L$6,) -> 0.00085274022 | N37: =+IFERROR(L37/H37,) -> 0.99753751 | O37: =+IFERROR(L37/J37,) -> 1.1688381
B38: 세금,보험 | C38: ='(계획)손익계산서 월별계획'!C38 -> 976247.63 | D38: =+IFERROR(F38/C38,) -> 0.063038832 | E38: =SUM('(계획)손익계산서 월별계획'!E38:(OFFSET('(계획)손익계산서 월별계획'!E38,0,$C$4-1))) -> 157341.97 | F38: =SUM('3. 손익계산서 월별실적'!E38:(OFFSET('3. 손익계산서 월별실적'!E38,0,$C$4-1))) -> 61541.51 | G38: =+IFERROR(F38/E38,) -> 0.3911322 | H38: =OFFSET('3. 손익계산서 월별실적'!E38,0,$C$4-2) -> 28636.21 | I38: =+IFERROR(H38/$H$6,) -> 0.002290534 | J38: =OFFSET('(계획)손익계산서 월별계획'!E38,0,$C$4-1) -> 79287.119 | K38: =+IFERROR(J38/$J$6,) -> 0.005368728 | L38: =OFFSET('3. 손익계산서 월별실적'!E38,0,$C$4-1) -> 32905.3 | M38: =+IFERROR(L38/$L$6,) -> 0.0021713895 | N38: =+IFERROR(L38/H38,) -> 1.1490801 | O38: =+IFERROR(L38/J38,) -> 0.41501445
B39: 복리후생비 | C39: ='(계획)손익계산서 월별계획'!C39 -> 262838.83 | D39: =+IFERROR(F39/C39,) -> 0.024967886 | E39: =SUM('(계획)손익계산서 월별계획'!E39:(OFFSET('(계획)손익계산서 월별계획'!E39,0,$C$4-1))) -> 41707.292 | F39: =SUM('3. 손익계산서 월별실적'!E39:(OFFSET('3. 손익계산서 월별실적'!E39,0,$C$4-1))) -> 6562.53 | G39: =+IFERROR(F39/E39,) -> 0.15734731 | H39: =OFFSET('3. 손익계산서 월별실적'!E39,0,$C$4-2) -> 2374.41 | I39: =+IFERROR(H39/$H$6,) -> 0.00018992272 | J39: =OFFSET('(계획)손익계산서 월별계획'!E39,0,$C$4-1) -> 20279.416 | K39: =+IFERROR(J39/$J$6,) -> 0.0013731697 | L39: =OFFSET('3. 손익계산서 월별실적'!E39,0,$C$4-1) -> 4188.12 | M39: =+IFERROR(L39/$L$6,) -> 0.00027637007 | N39: =+IFERROR(L39/H39,) -> 1.7638571 | O39: =+IFERROR(L39/J39,) -> 0.20652074
B40: 운반비 | C40: ='(계획)손익계산서 월별계획'!C40 -> 0 | D40: =+IFERROR(F40/C40,) -> 0 | E40: =SUM('(계획)손익계산서 월별계획'!E40:(OFFSET('(계획)손익계산서 월별계획'!E40,0,$C$4-1))) -> 0 | F40: =SUM('3. 손익계산서 월별실적'!E40:(OFFSET('3. 손익계산서 월별실적'!E40,0,$C$4-1))) -> 91123.68 | G40: =+IFERROR(F40/E40,) -> 0 | H40: =OFFSET('3. 손익계산서 월별실적'!E40,0,$C$4-2) -> 58276.9 | I40: =+IFERROR(H40/$H$6,) -> 0.0046614137 | J40: =OFFSET('(계획)손익계산서 월별계획'!E40,0,$C$4-1) -> 0 | K40: =+IFERROR(J40/$J$6,) -> 0 | L40: =OFFSET('3. 손익계산서 월별실적'!E40,0,$C$4-1) -> 32846.78 | M40: =+IFERROR(L40/$L$6,) -> 0.0021675279 | N40: =+IFERROR(L40/H40,) -> 0.56363293 | O40: =+IFERROR(L40/J40,) -> 0
B41: 포장비 | C41: ='(계획)손익계산서 월별계획'!C41 -> 0 | D41: =+IFERROR(F41/C41,) -> 0 | E41: =SUM('(계획)손익계산서 월별계획'!E41:(OFFSET('(계획)손익계산서 월별계획'!E41,0,$C$4-1))) -> 0 | F41: =SUM('3. 손익계산서 월별실적'!E41:(OFFSET('3. 손익계산서 월별실적'!E41,0,$C$4-1))) -> 0 | G41: =+IFERROR(F41/E41,) -> 0 | H41: =OFFSET('3. 손익계산서 월별실적'!E41,0,$C$4-2) -> 0 | I41: =+IFERROR(H41/$H$6,) -> 0 | J41: =OFFSET('(계획)손익계산서 월별계획'!E41,0,$C$4-1) -> 0 | K41: =+IFERROR(J41/$J$6,) -> 0 | L41: =OFFSET('3. 손익계산서 월별실적'!E41,0,$C$4-1) -> 0 | M41: =+IFERROR(L41/$L$6,) -> 0 | N41: =+IFERROR(L41/H41,) -> 0 | O41: =+IFERROR(L41/J41,) -> 0
B42: 광고선전비 | C42: ='(계획)손익계산서 월별계획'!C42 -> 0 | D42: =+IFERROR(F42/C42,) -> 0 | E42: =SUM('(계획)손익계산서 월별계획'!E42:(OFFSET('(계획)손익계산서 월별계획'!E42,0,$C$4-1))) -> 0 | F42: =SUM('3. 손익계산서 월별실적'!E42:(OFFSET('3. 손익계산서 월별실적'!E42,0,$C$4-1))) -> 18646.72 | G42: =+IFERROR(F42/E42,) -> 0 | H42: =OFFSET('3. 손익계산서 월별실적'!E42,0,$C$4-2) -> 4997.23 | I42: =+IFERROR(H42/$H$6,) -> 0.00039971509 | J42: =OFFSET('(계획)손익계산서 월별계획'!E42,0,$C$4-1) -> 0 | K42: =+IFERROR(J42/$J$6,) -> 0 | L42: =OFFSET('3. 손익계산서 월별실적'!E42,0,$C$4-1) -> 13649.49 | M42: =+IFERROR(L42/$L$6,) -> 0.0009007169 | N42: =+IFERROR(L42/H42,) -> 2.7314112 | O42: =+IFERROR(L42/J42,) -> 0
B43: 지급수수료 | C43: ='(계획)손익계산서 월별계획'!C43 -> 3243763.7 | D43: =+IFERROR(F43/C43,) -> 0.14738066 | E43: =SUM('(계획)손익계산서 월별계획'!E43:(OFFSET('(계획)손익계산서 월별계획'!E43,0,$C$4-1))) -> 573325.33 | F43: =SUM('3. 손익계산서 월별실적'!E43:(OFFSET('3. 손익계산서 월별실적'!E43,0,$C$4-1))) -> 478068.05 | G43: =+IFERROR(F43/E43,) -> 0.83385126 | H43: =OFFSET('3. 손익계산서 월별실적'!E43,0,$C$4-2) -> 225126.16 | I43: =+IFERROR(H43/$H$6,) -> 0.018007241 | J43: =OFFSET('(계획)손익계산서 월별계획'!E43,0,$C$4-1) -> 265214.57 | K43: =+IFERROR(J43/$J$6,) -> 0.017958338 | L43: =OFFSET('3. 손익계산서 월별실적'!E43,0,$C$4-1) -> 252941.89 | M43: =+IFERROR(L43/$L$6,) -> 0.016691395 | N43: =+IFERROR(L43/H43,) -> 1.1235562 | O43: =+IFERROR(L43/J43,) -> 0.95372546
B44: 여비교통비 | C44: ='(계획)손익계산서 월별계획'!C44 -> 191128.13 | D44: =+IFERROR(F44/C44,) -> 0.21273985 | E44: =SUM('(계획)손익계산서 월별계획'!E44:(OFFSET('(계획)손익계산서 월별계획'!E44,0,$C$4-1))) -> 31854.688 | F44: =SUM('3. 손익계산서 월별실적'!E44:(OFFSET('3. 손익계산서 월별실적'!E44,0,$C$4-1))) -> 40660.57 | G44: =+IFERROR(F44/E44,) -> 1.2764391 | H44: =OFFSET('3. 손익계산서 월별실적'!E44,0,$C$4-2) -> 18498.97 | I44: =+IFERROR(H44/$H$6,) -> 0.0014796832 | J44: =OFFSET('(계획)손익계산서 월별계획'!E44,0,$C$4-1) -> 15927.344 | K44: =+IFERROR(J44/$J$6,) -> 0.0010784801 | L44: =OFFSET('3. 손익계산서 월별실적'!E44,0,$C$4-1) -> 22161.6 | M44: =+IFERROR(L44/$L$6,) -> 0.001462423 | N44: =+IFERROR(L44/H44,) -> 1.197991 | O44: =+IFERROR(L44/J44,) -> 1.3914184
B45: 감가상각비 | C45: ='(계획)손익계산서 월별계획'!C45 -> 0 | D45: =+IFERROR(F45/C45,) -> 0 | E45: =SUM('(계획)손익계산서 월별계획'!E45:(OFFSET('(계획)손익계산서 월별계획'!E45,0,$C$4-1))) -> 0 | F45: =SUM('3. 손익계산서 월별실적'!E45:(OFFSET('3. 손익계산서 월별실적'!E45,0,$C$4-1))) -> 10328.31 | G45: =+IFERROR(F45/E45,) -> 0 | H45: =OFFSET('3. 손익계산서 월별실적'!E45,0,$C$4-2) -> 5419.12 | I45: =+IFERROR(H45/$H$6,) -> 0.00043346094 | J45: =OFFSET('(계획)손익계산서 월별계획'!E45,0,$C$4-1) -> 0 | K45: =+IFERROR(J45/$J$6,) -> 0 | L45: =OFFSET('3. 손익계산서 월별실적'!E45,0,$C$4-1) -> 4909.19 | M45: =+IFERROR(L45/$L$6,) -> 0.00032395279 | N45: =+IFERROR(L45/H45,) -> 0.9059017 | O45: =+IFERROR(L45/J45,) -> 0
...

Sheet 2. 손익계산서 (2)
B3: Plofit and Loss statement FY 2026
B4: MONTH | C4: 1 | O4: (단위:$)
B5: 구 분 | C5: 2026년 계 획 | D5: 년계획 진척률 | E5: 누 계 계 획 | F5: 누 계 실 적 | G5: 달성률 | H5: 전 월 실 적 | I5: 매 출 구성비 | J5: 당 월 계 획 | K5: 매 출 구성비 | L5: 당 월 실 적 | M5: 매 출 구성비 | N5: 전 월 대 비 | O5: 계 획 대 비 | Y5: 연계획 | Z5: 누계 계획 | AA5: 누계 실적 | AB5: 전월 실적 | AC5: 당월 계획 | AD5: 당월 실적
B6: Ⅰ. 매출액 | C6: =C7+C9 -> 1.7358328e+08 | D6: =+IFERROR(F6/C6,) -> 0.072022949 | E6: =E7+E9 -> 14214304 | F6: =F7+F9 -> 12501980 | G6: =+IFERROR(F6/E6,) -> 0.87953516 | H6: =H7+H9 -> 9843533.5 | I6: =+IFERROR(H6/$H$6,) -> 1 | J6: =J7+J9 -> 14214304 | K6: =+IFERROR(J6/$J$6,) -> 1 | L6: =L7+L9 -> 12501980 | M6: =+IFERROR(L6/$L$6,) -> 1 | N6: =+IFERROR(L6/H6,) -> 1.2700703 | O6: =+IFERROR(L6/J6,) -> 0.87953516 | Q6: 당월실적 | S6: 당월계획 | U6: 전월실적 | Y6: =+C6*1330/1000000 -> 230865.76 | Z6: =+E6*1330/1000000 -> 18905.024 | AA6: =+F6*1330/1000000 -> 16627.633 | AB6: =+H6*1330/1000000 -> 13091.9 | AC6: =+J6*1330/1000000 -> 18905.024 | AD6: =+L6*1330/1000000 -> 16627.633
B7: - 전선 | C7: ='(계획)손익계산서 월별계획'!C7 -> 1.4764519e+08 | D7: =+IFERROR(F7/C7,) -> 0.069960499 | E7: =SUM('(계획)손익계산서 월별계획'!E7:(OFFSET('(계획)손익계산서 월별계획'!E7,0,$C$4-1))) -> 11857865 | F7: =SUM('3. 손익계산서 월별실적'!E7:(OFFSET('3. 손익계산서 월별실적'!E7,0,$C$4-1))) -> 10329331 | G7: =+IFERROR(F7/E7,) -> 0.87109539 | H7: =OFFSET('3. 손익계산서 월별실적'!E7,0,$C$4-2) -> 7465258.4 | I7: =+IFERROR(H7/$H$6,) -> 0.75839214 | J7: =OFFSET('(계획)손익계산서 월별계획'!E7,0,$C$4-1) -> 11857865 | K7: =+IFERROR(J7/$J$6,) -> 0.83422059 | L7: =OFFSET('3. 손익계산서 월별실적'!E7,0,$C$4-1) -> 10329331 | M7: =+IFERROR(L7/$L$6,) -> 0.82621564 | N7: =+IFERROR(L7/H7,) -> 1.3836536 | O7: =+IFERROR(L7/J7,) -> 0.87109539 | S7: =+Q8-S8 -> 973251.25 | U7: =+Q8-U8 -> 305313.91
B8: └ 매출동량 | C8: ='(계획)손익계산서 월별계획'!C8 -> 0 | D8: =+IFERROR(F8/C8,) -> 0 | E8: =SUM('(계획)손익계산서 월별계획'!E8:(OFFSET('(계획)손익계산서 월별계획'!E8,0,$C$4-1))) -> 0 | F8: =SUM('3. 손익계산서 월별실적'!E8:(OFFSET('3. 손익계산서 월별실적'!E8,0,$C$4-1))) -> 631.81666 | G8: =+IFERROR(F8/E8,) -> 0 | H8: =OFFSET('3. 손익계산서 월별실적'!E8,0,$C$4-2) -> 476.23611 | I8: =+IFERROR(H8/$H$6,) -> 4.8380606e-05 | J8: =OFFSET('(계획)손익계산서 월별계획'!E8,0,$C$4-1) -> 0 | K8: =+IFERROR(J8/$J$6,) -> 0 | L8: =OFFSET('3. 손익계산서 월별실적'!E8,0,$C$4-1) -> 631.81666 | M8: =+IFERROR(L8/$L$6,) -> 5.0537328e-05 | N8: =+IFERROR(L8/H8,) -> 1.3266878 | O8: =+IFERROR(L8/J8,) -> 0 | Q8: =+L8-L13 -> -1198005.3 | R8: =+Q8/L8 -> -1896.1281 | S8: =+J8-J13 -> -2171256.6 | T8: =+S8/J8 -> #DIV/0! | U8: =+H8-H13 -> -1503319.2 | V8: =+U8/H8 -> -3156.6678
B9: - 전장 | C9: ='(계획)손익계산서 월별계획'!C9 -> 25938089 | D9: =+IFERROR(F9/C9,) -> 0.083762862 | E9: =SUM('(계획)손익계산서 월별계획'!E9:(OFFSET('(계획)손익계산서 월별계획'!E9,0,$C$4-1))) -> 2356438.9 | F9: =SUM('3. 손익계산서 월별실적'!E9:(OFFSET('3. 손익계산서 월별실적'!E9,0,$C$4-1))) -> 2172648.5 | G9: =+IFERROR(F9/E9,) -> 0.92200505 | H9: =OFFSET('3. 손익계산서 월별실적'!E9,0,$C$4-2) -> 2378275.1 | I9: =+IFERROR(H9/$H$6,) -> 0.24160786 | J9: =OFFSET('(계획)손익계산서 월별계획'!E9,0,$C$4-1) -> 2356438.9 | K9: =+IFERROR(J9/$J$6,) -> 0.16577941 | L9: =OFFSET('3. 손익계산서 월별실적'!E9,0,$C$4-1) -> 2172648.5 | M9: =+IFERROR(L9/$L$6,) -> 0.17378436 | N9: =+IFERROR(L9/H9,) -> 0.91353963 | O9: =+IFERROR(L9/J9,) -> 0.92200505 | Q9: =+L9-L14 -> 2467338.5 | R9: =+Q9/L9 -> 1.1356363 | S9: =+J9-J14 -> 2075429.7 | T9: =+S9/J9 -> 0.88074836 | U9: =+H9-H14 -> 2540932 | V9: =+U9/H9 -> 1.0683928
B11: Ⅱ. 매출원가 | C11: =SUM(C12:C14) -> 1.6273746e+08 | D11: =+IFERROR(F11/C11,) -> 0.072131606 | E11: =SUM(E12:E15) -> 13207071 | F11: =SUM(F12:F15) -> 11738514 | G11: =+IFERROR(F11/E11,) -> 0.88880529 | H11: =SUM(H12:H15) -> 9644978.3 | I11: =+IFERROR(H11/$H$6,) -> 0.97982887 | J11: =SUM(J12:J15) -> 13207071 | K11: =+IFERROR(J11/$J$6,) -> 0.9291395 | L11: =SUM(L12:L15) -> 11738514 | M11: =+IFERROR(L11/$L$6,) -> 0.93893244 | N11: =+IFERROR(L11/H11,) -> 1.2170597 | O11: =+IFERROR(L11/J11,) -> 0.88880529 | S11: =+Q10-S10 -> 0 | U11: =+Q10-U10 -> 0 | Y11: =+C11*1330/1000000 -> 216440.82 | Z11: =+E11*1330/1000000 -> 17565.404 | AA11: =+F11*1330/1000000 -> 15612.224 | AB11: =+H11*1330/1000000 -> 12827.821 | AC11: =+J11*1330/1000000 -> 17565.404 | AD11: =+L11*1330/1000000 -> 15612.224
B12: - 제품 | C12: ='(계획)손익계산서 월별계획'!C12 -> 1.3515827e+08 | D12: =+IFERROR(F12/C12,) -> 0.080162076 | E12: =SUM('(계획)손익계산서 월별계획'!E12:(OFFSET('(계획)손익계산서 월별계획'!E12,0,$C$4-1))) -> 10754805 | F12: =SUM('3. 손익계산서 월별실적'!E12:(OFFSET('3. 손익계산서 월별실적'!E12,0,$C$4-1))) -> 10834567 | G12: =+IFERROR(F12/E12,) -> 1.0074164 | H12: =OFFSET('3. 손익계산서 월별실적'!E12,0,$C$4-2) -> 8303839.7 | I12: =+IFERROR(H12/$H$6,) -> 0.84358322 | J12: =OFFSET('(계획)손익계산서 월별계획'!E12,0,$C$4-1) -> 10754805 | K12: =+IFERROR(J12/$J$6,) -> 0.75661851 | L12: =OFFSET('3. 손익계산서 월별실적'!E12,0,$C$4-1) -> 10834567 | M12: =+IFERROR(L12/$L$6,) -> 0.86662812 | N12: =+IFERROR(L12/H12,) -> 1.304766 | O12: =+IFERROR(L12/J12,) -> 1.0074164
