Workbook

Sheet Exchange Rate
B2: '2026년 사업계획 기준 환율
B3: 구 분 | D3: '26 사업계획 | E3: 비 고 | G3: 확정 | H3: 26.09.15
B4: 주요 통화 | C4: KRW/USD | D4: 1350 | E4: 홀딩스 배포 | G4: 1350 | H4: 1381.14 | I4: =G4/H4 -> 0.97745341
C5: KRW/CNY | D5: 195 | G5: 195 | H5: 194.798 | I5: =G5/H5 -> 1.001037
C6: KRW/EUR | D6: 1600 | G6: 1600 | H6: 1627.1 | I6: =G6/H6 -> 0.9833446
C7: MXN/USD | D7: 19 | G7: 19 | H7: 18.4248 | I7: =G7/H7 -> 1.0312188
C8: CNY/USD | D8: 6.9 | G8: 6.9 | H8: 7.12 | I8: =G8/H8 -> 0.96910112
B9: 세르비아 | C9: KRW/RSD | D9: 14 | E9: KSC 배포 | G9: 14 | H9: 13.9 | I9: =G9/H9 -> 1.0071942
C10: RSD/EUR | D10: 117 | G10: 117 | H10: 116.81 | I10: =G10/H10 -> 1.0016266
C11: RSD/USD | D11: 100 | G11: 100 | H11: 99.55 | I11: =G11/H11 -> 1.0045203
B12: 터키 | C12: KRW/TRY | D12: 32 | G12: 32 | H12: 33.55 | I12: =G12/H12 -> 0.9538003
C13: TRY/USD | D13: 43 | G13: 43 | H13: 41.37 | I13: =G13/H13 -> 1.0394005
C14: TRY/EUR | D14: 51 | G14: 51 | H14: 48.58 | I14: =G14/H14 -> 1.0498147
B15: 폴란드 | C15: KRW/PLN | D15: 385 | G15: 385 | H15: 383.45 | I15: =G15/H15 -> 1.0040422
C16: PLN/EUR | D16: 4.2 | G16: 4.2 | H16: 4.24 | I16: =G16/H16 -> 0.99056604
C17: PLN/USD | D17: 3.6 | G17: 3.6 | H17: 3.62 | I17: =G17/H17 -> 0.99447514
B18: ※ 동가 : 13,826[원/kg] / 9,900[$/Ton] - 6/1부 현대차 인정 동가 기준

Sheet Summary
F1: =+F21/F6 -> 0.76682497 | G1: =+G21/G6 -> 0.76611273 | H1: =+H21/H6 -> 0.76564981 | I1: =+I21/I6 -> 0.76475524 | J1: =+J21/J6 -> 0.76203145 | K1: =+K21/K6 -> 0.76557737 | L1: =+L21/L6 -> 0.7644828 | M1: =+M21/M6 -> 0.76573661 | ... Q1: =+Q21/Q6 -> 0.85913698
B2: Profit and Loss statement FY 2026 | Q2: (Affiliate Company: Kyungshin cable Türkiye)
B4: 구분 | D4: FY | E4: 12 | F4: 1 | G4: 2 | H4: =+G4+1 -> 3 | I4: =+H4+1 -> 4 | J4: =+I4+1 -> 5 | K4: =+J4+1 -> 6 | L4: =+K4+1 -> 7 | M4: =+L4+1 -> 8 | N4: =+M4+1 -> 9 | O4: =+N4+1 -> 10 | ... Q4: =+P4+1 -> 12
B5: Ⅰ. 매출액 | C5: Ⅰ. SALES | D5: =SUM(F5:Q5) -> 1.8562269e+09 | F5: =+F6+F14 -> 93531068 | G5: =+G6+G14 -> 1.1672241e+08 | H5: =+H6+H14 -> 1.6614614e+08 | I5: =+I6+I14 -> 1.385977e+08 | J5: =+J6+J14 -> 1.2682473e+08 | K5: =+K6+K14 -> 1.9324117e+08 | L5: =+L6+L14 -> 1.1829519e+08 | M5: =+M6+M14 -> 1.7613515e+08 | ... Q5: =+Q6+Q14 -> 1.6843153e+08
B6: 1.상품매출 | C6: 1. Merchandise | D6: =SUM(F6:Q6) -> 1.8546969e+09 | F6: =SUM(F7:F13) -> 93531068 | G6: =SUM(G7:G13) -> 1.1672241e+08 | H6: =SUM(H7:H13) -> 1.6614614e+08 | I6: =SUM(I7:I13) -> 1.385977e+08 | J6: =SUM(J7:J13) -> 1.2682473e+08 | K6: =SUM(K7:K13) -> 1.9324117e+08 | L6: =SUM(L7:L13) -> 1.1829519e+08 | M6: =SUM(M7:M13) -> 1.7613515e+08 | ... Q6: =SUM(Q7:Q13) -> 1.6690153e+08
C7: FORD PHEV-E (V710) | D7: =SUM(F7:Q7) -> 3.0822942e+08 | F7: ='1. Sales'!J242 -> 21737517 | G7: ='1. Sales'!K242 -> 23596647 | H7: ='1. Sales'!L242 -> 28172967 | I7: ='1. Sales'!M242 -> 20593438 | J7: ='1. Sales'!N242 -> 17018188 | K7: ='1. Sales'!O242 -> 35466476 | L7: ='1. Sales'!P242 -> 19592368 | M7: ='1. Sales'!Q242 -> 31891226 | ... Q7: ='1. Sales'!U242 -> 28158666
C8: FORD PHEV-E (P703) | D8: =SUM(F8:Q8) -> 1.6412277e+08 | F8: ='1. Sales'!J248 -> 11440799 | G8: ='1. Sales'!K248 -> 10236504 | H8: ='1. Sales'!L248 -> 12645093 | I8: ='1. Sales'!M248 -> 12645093 | J8: ='1. Sales'!N248 -> 13849388 | K8: ='1. Sales'!O248 -> 18666566 | L8: ='1. Sales'!P248 -> 13247241 | M8: ='1. Sales'!Q248 -> 13548314 | ... Q8: ='1. Sales'!U248 -> 14760136
C9: BEV-E RWD | D9: =SUM(F9:Q9) -> 6.1849335e+08 | F9: ='1. Sales'!J262 -> 39254495 | G9: ='1. Sales'!K262 -> 40331839 | H9: ='1. Sales'!L262 -> 77686291 | I9: ='1. Sales'!M262 -> 65698392 | J9: ='1. Sales'!N262 -> 52476443 | K9: ='1. Sales'!O262 -> 83131775 | L9: ='1. Sales'!P262 -> 50556812 | M9: ='1. Sales'!Q262 -> 79958508 | ... Q9: ='1. Sales'!U262 -> 0
C10: BEV-E AWD | D10: =SUM(F10:Q10) -> 1.4457127e+08 | F10: ='1. Sales'!J276 -> 1339959 | G10: ='1. Sales'!K276 -> 11503033 | H10: ='1. Sales'!L276 -> 20202459 | I10: ='1. Sales'!M276 -> 16141352 | J10: ='1. Sales'!N276 -> 12121475 | K10: ='1. Sales'!O276 -> 20697213 | L10: ='1. Sales'!P276 -> 11379344 | M10: ='1. Sales'!Q276 -> 19377868 | ... Q10: ='1. Sales'!U276 -> 0
C11: FORD BEV-M | D11: =SUM(F11:Q11) -> 3.1895775e+08 | F11: ='1. Sales'!J290 -> 18887593 | G11: ='1. Sales'!K290 -> 28331389 | H11: ='1. Sales'!L290 -> 26423506 | I11: ='1. Sales'!M290 -> 22648720 | J11: ='1. Sales'!N290 -> 30198293 | K11: ='1. Sales'!O290 -> 33973080 | L11: ='1. Sales'!P290 -> 22648720 | M11: ='1. Sales'!Q290 -> 30198293 | ... Q11: ='1. Sales'!U290 -> 27498272
C12: EV-V4 | D12: =SUM(F12:Q12) -> 2.8052389e+08 | F12: ='1. Sales'!J308 -> 0 | G12: ='1. Sales'!K308 -> 1378803.9 | H12: ='1. Sales'!L308 -> 0 | I12: ='1. Sales'!M308 -> 0 | J12: ='1. Sales'!N308 -> 0 | K12: ='1. Sales'!O308 -> 0 | L12: ='1. Sales'!P308 -> 0 | M12: ='1. Sales'!Q308 -> 0 | ... Q12: ='1. Sales'!U308 -> 93048362
C13: Components | D13: =SUM(F13:Q13) -> 19798467 | F13: ='1. Sales'!J294+'1. Sales'!J317 -> 870704.64 | G13: ='1. Sales'!K294+'1. Sales'!K317 -> 1344193.2 | H13: ='1. Sales'!L294+'1. Sales'!L317 -> 1015822.1 | I13: ='1. Sales'!M294+'1. Sales'!M317 -> 870704.64 | J13: ='1. Sales'!N294+'1. Sales'!N317 -> 1160939.5 | K13: ='1. Sales'!O294+'1. Sales'!O317 -> 1306057 | L13: ='1. Sales'!P294+'1. Sales'!P317 -> 870704.64 | M13: ='1. Sales'!Q294+'1. Sales'!Q317 -> 1160939.5 | ... Q13: ='1. Sales'!U294+'1. Sales'!U317 -> 3436099.1
B14: 2. 기타 매출 | C14: 2. Other sales | D14: =SUM(F14:Q14) -> 1530000 | F14: =SUM(F15:F18) -> 0 | G14: =SUM(G15:G18) -> 0 | H14: =SUM(H15:H18) -> 0 | I14: =SUM(I15:I18) -> 0 | J14: =SUM(J15:J18) -> 0 | K14: =SUM(K15:K18) -> 0 | L14: =SUM(L15:L18) -> 0 | M14: =SUM(M15:M18) -> 0 | ... Q14: =SUM(Q15:Q18) -> 1530000
B15: └ scrap | C15: └ Scrap | D15: =SUM(F15:Q15) -> 0
B16: └ Test Parts | C16: └ Test Parts | D16: =SUM(F16:Q16) -> 0
B17: └ 기타 | C17: └ Other | D17: =SUM(F17:Q17) -> 1530000 | Q17: =30000*'Exchange Rate'!D14 -> 1530000 | U17: 30000 | V17: BEV-H RESIDENCE Q.C Contract
B18: └ 기타(투자비) | C18: └ Investment | D18: =SUM(F18:Q18) -> 0
D19: =+D20/D5 -> 0.78991526 | F19: =IFERROR(F20/F5,"") -> 0.76682497 | G19: =IFERROR(G20/G5,"") -> 0.76611273 | H19: =IFERROR(H20/H5,"") -> 0.76564981 | I19: =IFERROR(I20/I5,"") -> 0.76475524 | J19: =IFERROR(J20/J5,"") -> 0.76203145 | K19: =IFERROR(K20/K5,"") -> 0.76557737 | L19: =IFERROR(L20/L5,"") -> 0.7644828 | M19: =IFERROR(M20/M5,"") -> 0.76573661 | ... Q19: =IFERROR(Q20/Q5,"") -> 0.85133274 | U19: EV-V4 10월 양산반영(수익율 2% 저하요인)
B20: Ⅱ. 매출원가 | C20: Ⅱ. COST OF SALES | D20: =SUM(F20:Q20) -> 1.466262e+09 | F20: =+F21+F27 -> 71721958 | G20: =+G21+G27 -> 89422523 | H20: =+H21+H27 -> 1.2720976e+08 | I20: =+I21+I27 -> 1.0599332e+08 | J20: =+J21+J27 -> 96644431 | K20: =+K21+K27 -> 1.4794106e+08 | L20: =+L21+L27 -> 90434637 | M20: =+M21+M27 -> 1.3487313e+08 | ... Q20: =+Q21+Q27 -> 1.4339128e+08
B21: 상품매출원가 | C21: Cost of merchandise sold | D21: =SUM(F21:Q21) -> 1.466262e+09 | F21: =+F22+F23+F24-F25-F26 -> 71721958 | G21: =+G22+G23+G24-G25-G26 -> 89422523 | H21: =+H22+H23+H24-H25-H26 -> 1.2720976e+08 | I21: =+I22+I23+I24-I25-I26 -> 1.0599332e+08 | J21: =+J22+J23+J24-J25-J26 -> 96644431 | K21: =+K22+K23+K24-K25-K26 -> 1.4794106e+08 | L21: =+L22+L23+L24-L25-L26 -> 90434637 | M21: =+M22+M23+M24-M25-M26 -> 1.3487313e+08 | ... Q21: =+Q22+Q23+Q24-Q25-Q26 -> 1.4339128e+08
B22: 1.기초 상품재고 | C22: 1. Beginning Merchandise | D22: =+F22 -> 0
B23: 2.당기 상품매입원가 | C23: 2. Cost of Merchandise | D23: =SUM(F23:Q23) -> 1.466262e+09 | F23: ='1. Sales'!J559 -> 71721958 | G23: ='1. Sales'!K559 -> 89422523 | H23: ='1. Sales'!L559 -> 1.2720976e+08 | I23: ='1. Sales'!M559 -> 1.0599332e+08 | J23: ='1. Sales'!N559 -> 96644431 | K23: ='1. Sales'!O559 -> 1.4794106e+08 | L23: ='1. Sales'!P559 -> 90434637 | M23: ='1. Sales'!Q559 -> 1.3487313e+08 | ... Q23: ='1. Sales'!U559 -> 1.4339128e+08
B24: 3.타계정전입 (+) | C24: 3. Transferred from other accounts | D24: =SUM(F24:Q24) -> 0
B25: 4.타계정대체 (-) | C25: 4. Transferred to other accounts | D25: =SUM(F25:Q25) -> 0
B26: 5.기말 상품재고 | C26: 5. Ending Merchandise | D26: =SUM(F26:Q26) -> 0
B27: 기타매출원가 | C27: Cost of other sold | D27: =SUM(F27:Q27) -> 0 | F27: =SUM(F28:F31) -> 0 | G27: =SUM(G28:G31) -> 0 | H27: =SUM(H28:H31) -> 0 | I27: =SUM(I28:I31) -> 0 | J27: =SUM(J28:J31) -> 0 | K27: =SUM(K28:K31) -> 0 | L27: =SUM(L28:L31) -> 0 | M27: =SUM(M28:M31) -> 0 | ... Q27: =SUM(Q28:Q31) -> 0
B28: 원재료 매출원가 | C28: Raw material | D28: =SUM(F28:Q28) -> 0
B29: 반제품 매출원가 | C29: Halb | D29: =SUM(F29:Q29) -> 0
B30: 기타 | C30: Other | D30: =SUM(F30:Q30) -> 0
B31: 기타(투자비) | C31: Investment | D31: =SUM(F31:Q31) -> 0
B32: Ⅲ. 매출총이익 | C32: Ⅲ. GROSS PROFIT (or GROSS LOSS) | D32: =SUM(F32:Q32) -> 3.8996495e+08 | F32: =+F5-F20 -> 21809110 | G32: =+G5-G20 -> 27299886 | H32: =+H5-H20 -> 38936379 | I32: =+I5-I20 -> 32604383 | J32: =+J5-J20 -> 30180296 | K32: =+K5-K20 -> 45300103 | L32: =+L5-L20 -> 27860551 | M32: =+M5-M20 -> 41262017 | ... Q32: =+Q5-Q20 -> 25040255
B33: (이익률) | C33: (Rate) | D33: =+IFERROR(D32/D5,) -> 0.21008474 | F33: =+IFERROR(F32/F5,) -> 0.23317503 | G33: =+IFERROR(G32/G5,) -> 0.23388727 | H33: =+IFERROR(H32/H5,) -> 0.23435019 | I33: =+IFERROR(I32/I5,) -> 0.23524476 | J33: =+IFERROR(J32/J5,) -> 0.23796855 | K33: =+IFERROR(K32/K5,) -> 0.23442263 | L33: =+IFERROR(L32/L5,) -> 0.2355172 | M33: =+IFERROR(M32/M5,) -> 0.23426339 | ... Q33: =+IFERROR(Q32/Q5,) -> 0.14866726
B34: Ⅳ.판매관리비 | C34: SELLING AND MARKETING EXPENSES | D34: =SUM(F34:Q34) -> 32457954 | E34: =E35+E36+E37+E38+E39+E40+E41 -> 0 | F34: =SUM(F35:F42) -> 1864869.9 | G34: =SUM(G35:G42) -> 2111319.2 | H34: =SUM(H35:H42) -> 2624130.2 | I34: =SUM(I35:I42) -> 2295347.5 | J34: =SUM(J35:J42) -> 4211534.9 | K34: =SUM(K35:K42) -> 2905578.6 | L34: =SUM(L35:L42) -> 2097975.2 | M34: =SUM(M35:M42) -> 2807689.8 | ... Q34: =SUM(Q35:Q42) -> 2745091.2
C35: Export Expenses | D35: =SUM(F35:Q35) -> 1628307.2 | F35: =+'26 Detail'!B3 -> 95782.779 | G35: =+'26 Detail'!C3 -> 95782.779 | H35: =+'26 Detail'!D3 -> 95782.779 | I35: =+'26 Detail'!E3 -> 95782.779 | J35: =+'26 Detail'!F3 -> 95782.779 | K35: =+'26 Detail'!G3 -> 95782.779 | L35: =+'26 Detail'!H3 -> 95782.779 | M35: =+'26 Detail'!I3 -> 191565.56 | ... Q35: =+'26 Detail'!M3 -> 191565.56
C36: Import Expenses | D36: =SUM(F36:Q36) -> 334367.46 | F36: =+'26 Detail'!B11 -> 20897.966 | G36: =+'26 Detail'!C11 -> 20897.966 | H36: =+'26 Detail'!D11 -> 20897.966 | I36: =+'26 Detail'!E11 -> 20897.966 | J36: =+'26 Detail'!F11 -> 20897.966 | K36: =+'26 Detail'!G11 -> 20897.966 | L36: =+'26 Detail'!H11 -> 20897.966 | M36: =+'26 Detail'!I11 -> 20897.966 | ... Q36: =+'26 Detail'!M11 -> 41795.933
C37: Domestic Transportation Expenses | D37: =SUM(F37:Q37) -> 6658033.8 | F37: =+'26 Detail'!B20 -> 554836.15 | G37: =+'26 Detail'!C20 -> 554836.15 | H37: =+'26 Detail'!D20 -> 554836.15 | I37: =+'26 Detail'!E20 -> 554836.15 | J37: =+'26 Detail'!F20 -> 554836.15 | K37: =+'26 Detail'!G20 -> 554836.15 | L37: =+'26 Detail'!H20 -> 554836.15 | M37: =+'26 Detail'!I20 -> 554836.15 | ... Q37: =+'26 Detail'!M20 -> 554836.15
C38: Sales Return costs | D38: =SUM(F38:Q38) -> 0
C39: Product Sample Expenses | D39: =SUM(F39:Q39) -> 496289.82 | F39: =+'26 Detail'!B27 -> 41357.485 | G39: =+'26 Detail'!C27 -> 41357.485 | H39: =+'26 Detail'!D27 -> 41357.485 | I39: =+'26 Detail'!E27 -> 41357.485 | J39: =+'26 Detail'!F27 -> 41357.485 | K39: =+'26 Detail'!G27 -> 41357.485 | L39: =+'26 Detail'!H27 -> 41357.485 | M39: =+'26 Detail'!I27 -> 41357.485 | ... Q39: =+'26 Detail'!M27 -> 41357.485
C40: Rental Expenses(Boxes) | D40: =SUM(F40:Q40) -> 1457627.6 | F40: =+'26 Detail'!B32 -> 106596.59 | G40: =+'26 Detail'!C32 -> 121132.49 | H40: =+'26 Detail'!D32 -> 139706.13 | I40: =+'26 Detail'!E32 -> 86407.841 | J40: =+'26 Detail'!F32 -> 120324.94 | K40: =+'26 Detail'!G32 -> 150204.28 | L40: =+'26 Detail'!H32 -> 92060.69 | M40: =+'26 Detail'!I32 -> 127592.89 | ... Q40: =+'26 Detail'!M32 -> 121132.49
C41: Other Expenses | D41: =SUM(F41:Q41) -> 3321059.4 | F41: =+'26 Detail'!B35 -> 110088.28 | G41: =+'26 Detail'!C35 -> 110088.28 | H41: =+'26 Detail'!D35 -> 110088.28 | I41: =+'26 Detail'!E35 -> 110088.28 | J41: =+'26 Detail'!F35 -> 2110088.3 | K41: =+'26 Detail'!G35 -> 110088.28 | L41: =+'26 Detail'!H35 -> 110088.28 | M41: =+'26 Detail'!I35 -> 110088.28 | ... Q41: =+'26 Detail'!M35 -> 110088.28
...

Sheet 26 Detail
B1: 1 | C1: 2 | D1: 3 | E1: 4 | F1: 5 | G1: 6 | H1: 7 | I1: 8 | J1: 9 | K1: 10 | L1: 11 | M1: 12
A2: Ⅳ.판매관리비 _ SELLING AND MARKETING EXPENSES | R2: double check
A3: Export Expenses | B3: =SUM(B4:B9) -> 95782.779 | C3: =SUM(C4:C9) -> 95782.779 | D3: =SUM(D4:D9) -> 95782.779 | E3: =SUM(E4:E9) -> 95782.779 | F3: =SUM(F4:F9) -> 95782.779 | G3: =SUM(G4:G9) -> 95782.779 | H3: =SUM(H4:H9) -> 95782.779 | I3: =SUM(I4:I9) -> 191565.56 | ... M3: =SUM(M4:M9) -> 191565.56 | R3: =+SUM(B3:M3) -> 1628307.2
A4: Shipping Expenses | B4: ='8. Export, Import1'!C6 -> 23901.116 | C4: ='8. Export, Import1'!D6 -> 23901.116 | D4: ='8. Export, Import1'!E6 -> 23901.116 | E4: ='8. Export, Import1'!F6 -> 23901.116 | F4: ='8. Export, Import1'!G6 -> 23901.116 | G4: ='8. Export, Import1'!H6 -> 23901.116 | H4: ='8. Export, Import1'!I6 -> 23901.116 | I4: ='8. Export, Import1'!J6 -> 47802.232 | ... M4: ='8. Export, Import1'!N6 -> 47802.232 | O4: Shipping Expenses 390 TL., Handling Service 3,900 TL one time, EV-V4 (Part Export `26.08~) | P4: 30% Increased | R4: =+R3-SUM(B4:M9) -> 0
A5: Export Charges | B5: ='8. Export, Import1'!C7 -> 0 | C5: ='8. Export, Import1'!D7 -> 0 | D5: ='8. Export, Import1'!E7 -> 0 | E5: ='8. Export, Import1'!F7 -> 0 | F5: ='8. Export, Import1'!G7 -> 0 | G5: ='8. Export, Import1'!H7 -> 0 | H5: ='8. Export, Import1'!I7 -> 0 | I5: ='8. Export, Import1'!J7 -> 0 | ... M5: ='8. Export, Import1'!N7 -> 0
A6: Warehouse Charges | B6: ='8. Export, Import1'!C8 -> 8755.676 | C6: ='8. Export, Import1'!D8 -> 8755.676 | D6: ='8. Export, Import1'!E8 -> 8755.676 | E6: ='8. Export, Import1'!F8 -> 8755.676 | F6: ='8. Export, Import1'!G8 -> 8755.676 | G6: ='8. Export, Import1'!H8 -> 8755.676 | H6: ='8. Export, Import1'!I8 -> 8755.676 | I6: ='8. Export, Import1'!J8 -> 17511.352 | ... M6: ='8. Export, Import1'!N8 -> 17511.352 | O6: Warehouse charges 5,213 TL one time, EV-V4 (Part Export `26.08~) | P6: 30% Increased
A7: Transport labour | B7: ='8. Export, Import1'!C9 -> 32447.412 | C7: ='8. Export, Import1'!D9 -> 32447.412 | D7: ='8. Export, Import1'!E9 -> 32447.412 | E7: ='8. Export, Import1'!F9 -> 32447.412 | F7: ='8. Export, Import1'!G9 -> 32447.412 | G7: ='8. Export, Import1'!H9 -> 32447.412 | H7: ='8. Export, Import1'!I9 -> 32447.412 | I7: ='8. Export, Import1'!J9 -> 64894.825 | ... M7: ='8. Export, Import1'!N9 -> 64894.825 | O7: Security X-Ray, Customs, Declaration, Certificate of Origin, EV-V4 (Part Export `26.08~) | P7: 30% Increased
A8: Other Export Expenses | B8: ='8. Export, Import1'!C10 -> 17133.943 | C8: ='8. Export, Import1'!D10 -> 17133.943 | D8: ='8. Export, Import1'!E10 -> 17133.943 | E8: ='8. Export, Import1'!F10 -> 17133.943 | F8: ='8. Export, Import1'!G10 -> 17133.943 | G8: ='8. Export, Import1'!H10 -> 17133.943 | H8: ='8. Export, Import1'!I10 -> 17133.943 | I8: ='8. Export, Import1'!J10 -> 34267.886 | ... M8: ='8. Export, Import1'!N10 -> 34267.886 | P8: 30% Increased
A9: Other Tax | B9: ='8. Export, Import1'!C11 -> 13544.631 | C9: ='8. Export, Import1'!D11 -> 13544.631 | D9: ='8. Export, Import1'!E11 -> 13544.631 | E9: ='8. Export, Import1'!F11 -> 13544.631 | F9: ='8. Export, Import1'!G11 -> 13544.631 | G9: ='8. Export, Import1'!H11 -> 13544.631 | H9: ='8. Export, Import1'!I11 -> 13544.631 | I9: ='8. Export, Import1'!J11 -> 27089.262 | ... M9: ='8. Export, Import1'!N11 -> 27089.262 | O9: EV-V4 (Part Export `26.08~) | P9: 30% Increased
A11: Import Expenses | B11: =SUM(B12:B18) -> 20897.966 | C11: =SUM(C12:C18) -> 20897.966 | D11: =SUM(D12:D18) -> 20897.966 | E11: =SUM(E12:E18) -> 20897.966 | F11: =SUM(F12:F18) -> 20897.966 | G11: =SUM(G12:G18) -> 20897.966 | H11: =SUM(H12:H18) -> 20897.966 | I11: =SUM(I12:I18) -> 20897.966 | ... M11: =SUM(M12:M18) -> 41795.933 | R11: =+SUM(B11:M11) -> 334367.46
A12: Shipping Expenses | B12: ='8. Export, Import1'!C40 -> 3260.9471 | C12: ='8. Export, Import1'!D40 -> 3260.9471 | D12: ='8. Export, Import1'!E40 -> 3260.9471 | E12: ='8. Export, Import1'!F40 -> 3260.9471 | F12: ='8. Export, Import1'!G40 -> 3260.9471 | G12: ='8. Export, Import1'!H40 -> 3260.9471 | H12: ='8. Export, Import1'!I40 -> 3260.9471 | I12: ='8. Export, Import1'!J40 -> 3260.9471 | ... M12: ='8. Export, Import1'!N40 -> 6521.8942 | O12: - Ev-v4 will start on september | P12: 30% Increased | R12: =+R11-SUM(B12:M18) -> 0
A13: Export Charges | B13: ='8. Export, Import1'!C41 -> 0 | C13: ='8. Export, Import1'!D41 -> 0 | D13: ='8. Export, Import1'!E41 -> 0 | E13: ='8. Export, Import1'!F41 -> 0 | F13: ='8. Export, Import1'!G41 -> 0 | G13: ='8. Export, Import1'!H41 -> 0 | H13: ='8. Export, Import1'!I41 -> 0 | I13: ='8. Export, Import1'!J41 -> 0 | ... M13: ='8. Export, Import1'!N41 -> 0
A14: Warehouse Charges | B14: ='8. Export, Import1'!C42 -> 2443.8245 | C14: ='8. Export, Import1'!D42 -> 2443.8245 | D14: ='8. Export, Import1'!E42 -> 2443.8245 | E14: ='8. Export, Import1'!F42 -> 2443.8245 | F14: ='8. Export, Import1'!G42 -> 2443.8245 | G14: ='8. Export, Import1'!H42 -> 2443.8245 | H14: ='8. Export, Import1'!I42 -> 2443.8245 | I14: ='8. Export, Import1'!J42 -> 2443.8245 | ... M14: ='8. Export, Import1'!N42 -> 4887.649 | P14: 30% Increased
A15: Transport labour | B15: ='8. Export, Import1'!C43 -> 3286.6121 | C15: ='8. Export, Import1'!D43 -> 3286.6121 | D15: ='8. Export, Import1'!E43 -> 3286.6121 | E15: ='8. Export, Import1'!F43 -> 3286.6121 | F15: ='8. Export, Import1'!G43 -> 3286.6121 | G15: ='8. Export, Import1'!H43 -> 3286.6121 | H15: ='8. Export, Import1'!I43 -> 3286.6121 | I15: ='8. Export, Import1'!J43 -> 3286.6121 | ... M15: ='8. Export, Import1'!N43 -> 6573.2242 | P15: 30% Increased
A16: Other Export Expenses | B16: ='8. Export, Import1'!C44 -> 2469.1258 | C16: ='8. Export, Import1'!D44 -> 2469.1258 | D16: ='8. Export, Import1'!E44 -> 2469.1258 | E16: ='8. Export, Import1'!F44 -> 2469.1258 | F16: ='8. Export, Import1'!G44 -> 2469.1258 | G16: ='8. Export, Import1'!H44 -> 2469.1258 | H16: ='8. Export, Import1'!I44 -> 2469.1258 | I16: ='8. Export, Import1'!J44 -> 2469.1258 | ... M16: ='8. Export, Import1'!N44 -> 4938.2515 | P16: 30% Increased
A17: Custom Tax | B17: ='8. Export, Import1'!C45 -> 8320.6184 | C17: ='8. Export, Import1'!D45 -> 8320.6184 | D17: ='8. Export, Import1'!E45 -> 8320.6184 | E17: ='8. Export, Import1'!F45 -> 8320.6184 | F17: ='8. Export, Import1'!G45 -> 8320.6184 | G17: ='8. Export, Import1'!H45 -> 8320.6184 | H17: ='8. Export, Import1'!I45 -> 8320.6184 | I17: ='8. Export, Import1'!J45 -> 8320.6184 | ... M17: ='8. Export, Import1'!N45 -> 16641.237 | P17: 30% Increased
A18: Other Tax | B18: ='8. Export, Import1'!C46 -> 1116.8384 | C18: ='8. Export, Import1'!D46 -> 1116.8384 | D18: ='8. Export, Import1'!E46 -> 1116.8384 | E18: ='8. Export, Import1'!F46 -> 1116.8384 | F18: ='8. Export, Import1'!G46 -> 1116.8384 | G18: ='8. Export, Import1'!H46 -> 1116.8384 | H18: ='8. Export, Import1'!I46 -> 1116.8384 | I18: ='8. Export, Import1'!J46 -> 1116.8384 | ... M18: ='8. Export, Import1'!N46 -> 2233.6769 | P18: 30% Increased
A20: Domestic Transportation Expenses | B20: =SUM(B21) -> 554836.15 | C20: =SUM(C21) -> 554836.15 | D20: =SUM(D21) -> 554836.15 | E20: =SUM(E21) -> 554836.15 | F20: =SUM(F21) -> 554836.15 | G20: =SUM(G21) -> 554836.15 | H20: =SUM(H21) -> 554836.15 | I20: =SUM(I21) -> 554836.15 | ... M20: =SUM(M21) -> 554836.15 | R20: =+SUM(B20:M20) -> 6658033.8
A21: Transportation Expenses | B21: ='9.Transportation'!C5 -> 554836.15 | C21: ='9.Transportation'!D5 -> 554836.15 | D21: ='9.Transportation'!E5 -> 554836.15 | E21: ='9.Transportation'!F5 -> 554836.15 | F21: ='9.Transportation'!G5 -> 554836.15 | G21: ='9.Transportation'!H5 -> 554836.15 | H21: ='9.Transportation'!I5 -> 554836.15 | I21: ='9.Transportation'!J5 -> 554836.15 | ... M21: ='9.Transportation'!N5 -> 554836.15 | O21: Ford-KCTR direct delivery manage `25 performance | P21: 30% Increased | R21: =+R20-SUM(B21:M21) -> 0
A23: Sales Return costs | B23: =SUM(B24:B25) -> 0 | C23: =SUM(C24:C25) -> 0 | D23: =SUM(D24:D25) -> 0 | E23: =SUM(E24:E25) -> 0 | F23: =SUM(F24:F25) -> 0 | G23: =SUM(G24:G25) -> 0 | H23: =SUM(H24:H25) -> 0 | I23: =SUM(I24:I25) -> 0 | ... M23: =SUM(M24:M25) -> 0 | R23: =+SUM(B23:M23) -> 0
A24: Return Material Transportation Expenses | B24: - | C24: - | D24: - | E24: - | F24: - | G24: - | H24: - | I24: - | J24: - | K24: - | L24: - | M24: - | O24: Already applied to shipping expense | R24: =+R23-SUM(B24:M25) -> 0
A25: Other Expenses | B25: - | C25: - | D25: - | E25: - | F25: - | G25: - | H25: - | I25: - | J25: - | K25: - | L25: - | M25: - | O25: Already applied to shipping expense
A27: Product Sample Expenses | B27: =SUM(B28:B30) -> 41357.485 | C27: =SUM(C28:C30) -> 41357.485 | D27: =SUM(D28:D30) -> 41357.485 | E27: =SUM(E28:E30) -> 41357.485 | F27: =SUM(F28:F30) -> 41357.485 | G27: =SUM(G28:G30) -> 41357.485 | H27: =SUM(H28:H30) -> 41357.485 | I27: =SUM(I28:I30) -> 41357.485 | ... M27: =SUM(M28:M30) -> 41357.485 | R27: =+SUM(B27:M27) -> 496289.82
A28: Domestic Sample Expenses | B28: ='9.Transportation'!C28 -> 6790.5596 | C28: ='9.Transportation'!D28 -> 6790.5596 | D28: ='9.Transportation'!E28 -> 6790.5596 | E28: ='9.Transportation'!F28 -> 6790.5596 | F28: ='9.Transportation'!G28 -> 6790.5596 | G28: ='9.Transportation'!H28 -> 6790.5596 | H28: ='9.Transportation'!I28 -> 6790.5596 | I28: ='9.Transportation'!J28 -> 6790.5596 | ... M28: ='9.Transportation'!N28 -> 6790.5596 | O28: Urgent delivery to supplier | P28: 30% Increased | R28: =+R27-SUM(B28:M30) -> 0
A29: Export Sample Expenses | B29: ='9.Transportation'!C29 -> 3457.4614 | C29: ='9.Transportation'!D29 -> 3457.4614 | D29: ='9.Transportation'!E29 -> 3457.4614 | E29: ='9.Transportation'!F29 -> 3457.4614 | F29: ='9.Transportation'!G29 -> 3457.4614 | G29: ='9.Transportation'!H29 -> 3457.4614 | H29: ='9.Transportation'!I29 -> 3457.4614 | I29: ='9.Transportation'!J29 -> 3457.4614 | ... M29: ='9.Transportation'!N29 -> 3457.4614 | O29: Ford Overseas Product Shipping | P29: 30% Increased
A30: Other Sample Expenses | B30: ='9.Transportation'!C30 -> 31109.464 | C30: ='9.Transportation'!D30 -> 31109.464 | D30: ='9.Transportation'!E30 -> 31109.464 | E30: ='9.Transportation'!F30 -> 31109.464 | F30: ='9.Transportation'!G30 -> 31109.464 | G30: ='9.Transportation'!H30 -> 31109.464 | H30: ='9.Transportation'!I30 -> 31109.464 | I30: ='9.Transportation'!J30 -> 31109.464 | ... M30: ='9.Transportation'!N30 -> 31109.464 | O30: Urgent delivery to supplier KSC / KSCE | P30: 30% Increased
A32: Rental Expenses | B32: =SUM(B33) -> 106596.59 | C32: =SUM(C33) -> 121132.49 | D32: =SUM(D33) -> 139706.13 | E32: =SUM(E33) -> 86407.841 | F32: =SUM(F33) -> 120324.94 | G32: =SUM(G33) -> 150204.28 | H32: =SUM(H33) -> 92060.69 | I32: =SUM(I33) -> 127592.89 | ... M32: =SUM(M33) -> 121132.49 | R32: =+SUM(B32:M32) -> 1457627.6
A33: Box Rental Expenses | B33: =SUM('10. Warehouse'!E24,'10. Warehouse'!E26) -> 106596.59 | C33: =SUM('10. Warehouse'!F24,'10. Warehouse'!F26) -> 121132.49 | D33: =SUM('10. Warehouse'!G24,'10. Warehouse'!G26) -> 139706.13 | E33: =SUM('10. Warehouse'!H24,'10. Warehouse'!H26) -> 86407.841 | F33: =SUM('10. Warehouse'!I24,'10. Warehouse'!I26) -> 120324.94 | G33: =SUM('10. Warehouse'!J24,'10. Warehouse'!J26) -> 150204.28 | H33: =SUM('10. Warehouse'!K24,'10. Warehouse'!K26) -> 92060.69 | I33: =SUM('10. Warehouse'!L24,'10. Warehouse'!L26) -> 127592.89 | ... M33: =SUM('10. Warehouse'!P24,'10. Warehouse'!P26) -> 121132.49 | O33: BEV-M Rent/Issue Fee Box payment | P33: 30% Increased | R33: =+R32-SUM(B33:M33) -> 0
A35: Other Expenses | B35: =SUM(B36:B38) -> 110088.28 | C35: =SUM(C36:C38) -> 110088.28 | D35: =SUM(D36:D38) -> 110088.28 | E35: =SUM(E36:E38) -> 110088.28 | F35: =SUM(F36:F38) -> 2110088.3 | G35: =SUM(G36:G38) -> 110088.28 | H35: =SUM(H36:H38) -> 110088.28 | I35: =SUM(I36:I38) -> 110088.28 | ... M35: =SUM(M36:M38) -> 110088.28 | R35: =+SUM(B35:M35) -> 3321059.4
A36: Packaging-Label Expenses | R36: =+R35-SUM(B36:M38) -> 0
A37: Returnable Box Purchasing Expenses | B37: ='10. Warehouse'!E27 -> 110088.28 | C37: ='10. Warehouse'!F27 -> 110088.28 | D37: ='10. Warehouse'!G27 -> 110088.28 | E37: ='10. Warehouse'!H27 -> 110088.28 | F37: ='10. Warehouse'!I27 -> 110088.28 | G37: ='10. Warehouse'!J27 -> 110088.28 | H37: ='10. Warehouse'!K27 -> 110088.28 | I37: ='10. Warehouse'!L27 -> 110088.28 | ... M37: ='10. Warehouse'!P27 -> 110088.28 | O37: PHEV-E (P703) 101,620TL/month | P37: 30% Increased
A38: Annual DV/PV Test | B38: ='15. Test, Royalty '!D6 -> - | C38: ='15. Test, Royalty '!E6 -> - | D38: ='15. Test, Royalty '!F6 -> - | E38: ='15. Test, Royalty '!G6 -> - | F38: ='15. Test, Royalty '!H6 -> 2000000 | G38: ='15. Test, Royalty '!I6 -> - | H38: ='15. Test, Royalty '!J6 -> - | I38: ='15. Test, Royalty '!K6 -> - | ... M38: ='15. Test, Royalty '!O6 -> - | O38: Project DV/PV Test
A40: Sorting&Rework Expenses | B40: =SUM(B41:B44) -> 935310.68 | C40: =SUM(C41:C44) -> 1167224.1 | D40: =SUM(D41:D44) -> 1661461.4 | E40: =SUM(E41:E44) -> 1385977 | F40: =SUM(F41:F44) -> 1268247.3 | G40: =SUM(G41:G44) -> 1932411.7 | H40: =SUM(H41:H44) -> 1182951.9 | I40: =SUM(I41:I44) -> 1761351.5 | ... M40: =SUM(M41:M44) -> 1684315.3 | R40: =+SUM(B40:M40) -> 18562269
A41: Sorting&Rework Expenses | B41: =Summary!F5*0.01 -> 935310.68 | C41: =Summary!G5*0.01 -> 1167224.1 | D41: =Summary!H5*0.01 -> 1661461.4 | E41: =Summary!I5*0.01 -> 1385977 | F41: =Summary!J5*0.01 -> 1268247.3 | G41: =Summary!K5*0.01 -> 1932411.7 | H41: =Summary!L5*0.01 -> 1182951.9 | I41: =Summary!M5*0.01 -> 1761351.5 | ... M41: =Summary!Q5*0.01 -> 1684315.3 | O41: QC sorting Payment | R41: =+R40-SUM(B41:M41) -> 0
A43: Ⅳ.판매관리비 _ GENERAL ADMINISTRATION EXPENSES
A44: Personnel Expenses
A45: Executive Expenses | B45: =+SUM(B46:B51) -> 1197719.5 | C45: =+SUM(C46:C51) -> 1770719.5 | D45: =+SUM(D46:D51) -> 1197719.5 | E45: =+SUM(E46:E51) -> 2997719.5 | F45: =+SUM(F46:F51) -> 1197719.5 | G45: =+SUM(G46:G51) -> 4077719.5 | H45: =+SUM(H46:H51) -> 1865901.2 | I45: =+SUM(I46:I51) -> 1994901.2 | ... M45: =+SUM(M46:M51) -> 1667101.2 | R45: =+SUM(B45:M45) -> 23327078
A46: GROSS SALARIES | B46: ='4. Salary'!H46+'7. Commucation '!E46 -> 1109399 | C46: ='4. Salary'!I46+'7. Commucation '!F46 -> 1553399 | D46: ='4. Salary'!J46+'7. Commucation '!G46 -> 1109399 | E46: ='4. Salary'!K46+'7. Commucation '!H46 -> 2909399 | F46: ='4. Salary'!L46+'7. Commucation '!I46 -> 1109399 | G46: ='4. Salary'!M46+'7. Commucation '!J46 -> 3989399 | H46: ='4. Salary'!N46+'7. Commucation '!K46 -> 1529790.4 | I46: ='4. Salary'!O46+'7. Commucation '!L46 -> 1529790.4 | ... M46: ='4. Salary'!S46+'7. Commucation '!P46 -> 1529790.4 | O46: 26.07 Cost division Executive (Esti.) | R46: =+R45-SUM(B46:M51) -> 0
A47: SSI EMPLOYER PREMIUM SHARE | B47: ='4. Salary'!H47 -> 65338.86 | C47: ='4. Salary'!I47 -> 65338.86 | D47: ='4. Salary'!J47 -> 65338.86 | E47: ='4. Salary'!K47 -> 65338.86 | F47: ='4. Salary'!L47 -> 65338.86 | G47: ='4. Salary'!M47 -> 65338.86 | H47: ='4. Salary'!N47 -> 98008.29 | I47: ='4. Salary'!O47 -> 98008.29 | ... M47: ='4. Salary'!S47 -> 98008.29 | O47: 26.07 Cost division Executive (Esti.)
A48: EMPLOYER UNEMPLOYMENT PREMIUM SHARE | B48: ='4. Salary'!H48 -> 7801.66 | C48: ='4. Salary'!I48 -> 7801.66 | D48: ='4. Salary'!J48 -> 7801.66 | E48: ='4. Salary'!K48 -> 7801.66 | F48: ='4. Salary'!L48 -> 7801.66 | G48: ='4. Salary'!M48 -> 7801.66 | H48: ='4. Salary'!N48 -> 11702.49 | I48: ='4. Salary'!O48 -> 11702.49 | ... M48: ='4. Salary'!S48 -> 11702.49 | O48: 26.07 Cost division Executive (Esti.)
...

Sheet 1. Sales
A1: ▣ 상품 매출액 | G1: EV-V4 매입가 비율 | H1: 0.98 | J1: USD/EUR | K1: ='Exchange Rate'!$D$6/'Exchange Rate'!$D$4 -> 1.1851852
A2: 1. 매출수량 | W2: 단위 : 대
A3: 구분 | B3: 차종 | C3: LEVEL | F3: 아이템 | G3: 품번 | H3: U/S | I3: 비고 | J3: 매출 계획 (EA) | W3: 비고 | X3: 연결매출 연간 수량 | Y3: 차이
C4: 1 | D4: 2 | E4: 3 | J4: 1월 | K4: 2월 | L4: 3월 | M4: 4월 | N4: 5월 | O4: 6월 | P4: 7월 | Q4: 8월 | R4: 9월 | S4: 10월 | T4: 11월 | U4: 12월 | V4: TOTAL | X4: (영업팀)
A5: Battery | B5: FORD PHEV-E | C5: ● | F5: MAIN W/H | G5: PZ38-10B694-AC | H5: 1 | I5: 터키 현지 외주 | J5: 3040 | K5: 3300 | L5: 3940 | M5: 2880 | N5: 2380 | O5: 4960 | P5: 2740 | Q5: 4460 | R5: 4360 | S5: 3392 | T5: 3716 | U5: 3938 | V5: =SUM(J5:U5) -> 43106 | W5: ▶ 유럽 向 | X5: 43106 | Y5: =V5-X5 -> 0 | Z5: 43106 | AA5: =+Z5*H5 -> 43106
A6: Pack | B6: Ford Otosan | C6: ● | F6: BEC to ISC Conn (JUMPER) | G6: PZ38-14B252-AB | H6: 1 | I6: 터키 현지 외주 | J6: 3040 | K6: 3300 | L6: 3940 | M6: 2880 | N6: 2380 | O6: 4960 | P6: 2740 | Q6: 4460 | R6: 4360 | S6: 3392 | T6: 3716 | U6: 3938 | V6: =SUM(J6:U6) -> 43106 | W6: ↑ | X6: 43106 | Y6: =V6-X6 -> 0 | Z6: 43106 | AA6: =+Z6*H6 -> 43106
C7: ● | F7: BUSBAR - Array to Array (short) | G7: PZ38-14A033-AB | H7: 3 | I7: 터키 현지 외주 | J7: 9120 | K7: 9900 | L7: 11820 | M7: 8640 | N7: 7140 | O7: 14880 | P7: 8220 | Q7: 13380 | R7: 13080 | S7: 10176 | T7: 11148 | U7: 11814 | V7: =SUM(J7:U7) -> 129318 | W7: ↑ | X7: 129318 | Y7: =V7-X7 -> 0 | Z7: 43106 | AA7: =+Z7*H7 -> 129318
C8: ● | F8: BUSBAR - Array to Array (long) | G8: PZ38-14A033-BB | H8: 3 | I8: 터키 현지 외주 | J8: 9120 | K8: 9900 | L8: 11820 | M8: 8640 | N8: 7140 | O8: 14880 | P8: 8220 | Q8: 13380 | R8: 13080 | S8: 10176 | T8: 11148 | U8: 11814 | V8: =SUM(J8:U8) -> 129318 | W8: ↑ | X8: 129318 | Y8: =V8-X8 -> 0 | Z8: 43106 | AA8: =+Z8*H8 -> 129318
C9: ● | F9: BUSBAR - Array 3 to 4 | G9: PZ38-14A033-CB | H9: 1 | I9: 터키 현지 외주 | J9: 3040 | K9: 3300 | L9: 3940 | M9: 2880 | N9: 2380 | O9: 4960 | P9: 2740 | Q9: 4460 | R9: 4360 | S9: 3392 | T9: 3716 | U9: 3938 | V9: =SUM(J9:U9) -> 43106 | W9: ↑ | X9: 43106 | Y9: =V9-X9 -> 0 | Z9: 43106 | AA9: =+Z9*H9 -> 43106
B10: FORD PHEV-E | C10: ● | F10: MAIN W/H | G10: PZ38-10B694-AC | H10: 1 | I10: 터키 현지 외주 | J10: 1520 | K10: 1360 | L10: 1680 | M10: 1680 | N10: 1840 | O10: 2480 | P10: 1760 | Q10: 1800 | R10: 1874 | S10: 1906 | T10: 1944 | U10: 1961 | V10: =SUM(J10:U10) -> 21805 | W10: ▶ 아프리카 向 * P703 Forecast 8월부터 이전 6개월 평균 계산 | X10: 21805 | Y10: =V10-X10 -> 0 | Z10: 21805 | AA10: =+Z10*H10 -> 21805
B11: S/Africa | C11: ● | F11: BEC to ISC Conn (JUMPER) | G11: PZ38-14B252-AB | H11: 1 | I11: 터키 현지 외주 | J11: 1520 | K11: 1360 | L11: 1680 | M11: 1680 | N11: 1840 | O11: 2480 | P11: 1760 | Q11: 1800 | R11: 1874 | S11: 1906 | T11: 1944 | U11: 1961 | V11: =SUM(J11:U11) -> 21805 | W11: ↑ | X11: 21805 | Y11: =V11-X11 -> 0 | Z11: 21805 | AA11: =+Z11*H11 -> 21805
C12: ● | F12: BUSBAR - Array to Array (short) | G12: PZ38-14A033-AB | H12: 3 | I12: 터키 현지 외주 | J12: 4560 | K12: 4080 | L12: 5040 | M12: 5040 | N12: 5520 | O12: 7440 | P12: 5280 | Q12: 5400 | R12: 5622 | S12: 5718 | T12: 5832 | U12: 5883 | V12: =SUM(J12:U12) -> 65415 | W12: ↑ | X12: 65415 | Y12: =V12-X12 -> 0 | Z12: 21805 | AA12: =+Z12*H12 -> 65415
C13: ● | F13: BUSBAR - Array to Array (long) | G13: PZ38-14A033-BB | H13: 3 | I13: 터키 현지 외주 | J13: 4560 | K13: 4080 | L13: 5040 | M13: 5040 | N13: 5520 | O13: 7440 | P13: 5280 | Q13: 5400 | R13: 5622 | S13: 5718 | T13: 5832 | U13: 5883 | V13: =SUM(J13:U13) -> 65415 | W13: ↑ | X13: 65415 | Y13: =V13-X13 -> 0 | Z13: 21805 | AA13: =+Z13*H13 -> 65415
C14: ● | F14: BUSBAR - Array 3 to 4 | G14: PZ38-14A033-CB | H14: 1 | I14: 터키 현지 외주 | J14: 1520 | K14: 1360 | L14: 1680 | M14: 1680 | N14: 1840 | O14: 2480 | P14: 1760 | Q14: 1800 | R14: 1874 | S14: 1906 | T14: 1944 | U14: 1961 | V14: =SUM(J14:U14) -> 21805 | W14: ↑ | X14: 21805 | Y14: =V14-X14 -> 0 | Z14: 21805 | AA14: =+Z14*H14 -> 21805
B15: FORD BEV-E1 RWD | C15: ● | F15: MAIN W/H RWD | G15: TZ38-10B694-DB | H15: 1 | I15: 터키 현지 외주 | J15: 2004 | K15: 2059 | L15: 3966 | M15: 3354 | N15: 2679 | O15: 4244 | P15: 2581 | Q15: 4082 | R15: 3401 | S15: 3205 | T15: 0 | U15: 0 | V15: =SUM(J15:U15) -> 31575 | W15: * RWD 10월 단산 | X15: 31019 | Y15: =V15-X15 -> 556 | Z15: 31019 | AA15: =+Z15*H15 -> 31019
C16: ● | F16: CONN ASSY (PDU) | G16: TZ38-14B680-BB | H16: 1 | I16: 터키 현지 외주 | J16: 2004 | K16: 2059 | L16: 3966 | M16: 3354 | N16: 2679 | O16: 4244 | P16: 2581 | Q16: 4082 | R16: 3401 | S16: 3205 | T16: 0 | U16: 0 | V16: =SUM(J16:U16) -> 31575 | X16: 31019 | Y16: =V16-X16 -> 556 | Z16: 31019 | AA16: =+Z16*H16 -> 31019
C17: ● | F17: BUSBAR - Array to Array (Straight)_Insert | G17: TZ38-14A033-FA | H17: 1 | I17: 터키 현지 외주 | J17: 2004 | K17: 2059 | L17: 3966 | M17: 3354 | N17: 2679 | O17: 4244 | P17: 2581 | Q17: 4082 | R17: 3401 | S17: 3205 | T17: 0 | U17: 0 | V17: =SUM(J17:U17) -> 31575 | X17: 31019 | Y17: =V17-X17 -> 556 | Z17: 31019 | AA17: =+Z17*H17 -> 31019
C18: ● | F18: BUSBAR - Array to Array (Angled)_Insert | G18: TZ38-14A033-HB | H18: 3 | I18: 터키 현지 외주 | J18: 6012 | K18: 6177 | L18: 11898 | M18: 10062 | N18: 8037 | O18: 12732 | P18: 7743 | Q18: 12246 | R18: 10203 | S18: 9615 | T18: 0 | U18: 0 | V18: =SUM(J18:U18) -> 94725 | X18: 93057 | Y18: =V18-X18 -> 1668 | Z18: 31019 | AA18: =+Z18*H18 -> 93057
C19: ● | F19: BUSBAR - Array 1 to Neg BEC_Insert | G19: TZ38-14A033-SA | H19: 1 | I19: 터키 현지 외주 | J19: 2004 | K19: 2059 | L19: 3966 | M19: 3354 | N19: 2679 | O19: 4244 | P19: 2581 | Q19: 4082 | R19: 3401 | S19: 3205 | T19: 0 | U19: 0 | V19: =SUM(J19:U19) -> 31575 | X19: 31019 | Y19: =V19-X19 -> 556 | Z19: 31019 | AA19: =+Z19*H19 -> 31019
C20: ● | F20: BUSBAR - Array4 to Array 5_Insert | G20: PZ38-14A033-HF | H20: 1 | I20: 터키 현지 외주 | J20: 2004 | K20: 2059 | L20: 3966 | M20: 3354 | N20: 2679 | O20: 4244 | P20: 2581 | Q20: 4082 | R20: 3401 | S20: 3205 | T20: 0 | U20: 0 | V20: =SUM(J20:U20) -> 31575 | X20: 31019 | Y20: =V20-X20 -> 556 | Z20: 31019 | AA20: =+Z20*H20 -> 31019
C21: ● | F21: BUSBAR - Array 8 to Array 9_Insert | G21: TZ38-14A033-JB | H21: 1 | I21: 터키 현지 외주 | J21: 2004 | K21: 2059 | L21: 3966 | M21: 3354 | N21: 2679 | O21: 4244 | P21: 2581 | Q21: 4082 | R21: 3401 | S21: 3205 | T21: 0 | U21: 0 | V21: =SUM(J21:U21) -> 31575 | X21: 31019 | Y21: =V21-X21 -> 556 | Z21: 31019 | AA21: =+Z21*H21 -> 31019
C22: ● | F22: BUSBAR - Array 9 to Pos BEC_Insert | G22: PZ38-14A033-LF | H22: 1 | I22: 터키 현지 외주 | J22: 2004 | K22: 2059 | L22: 3966 | M22: 3354 | N22: 2679 | O22: 4244 | P22: 2581 | Q22: 4082 | R22: 3401 | S22: 3205 | T22: 0 | U22: 0 | V22: =SUM(J22:U22) -> 31575 | X22: 31019 | Y22: =V22-X22 -> 556 | Z22: 31019 | AA22: =+Z22*H22 -> 31019
C23: ● | F23: BUSBAR - Pos BEC to DCFC_Protector | G23: PZ38-14A033-MC | H23: 1 | I23: 터키 현지 외주 | J23: 2004 | K23: 2059 | L23: 3966 | M23: 3354 | N23: 2679 | O23: 4244 | P23: 2581 | Q23: 4082 | R23: 3401 | S23: 3205 | T23: 0 | U23: 0 | V23: =SUM(J23:U23) -> 31575 | X23: 31019 | Y23: =V23-X23 -> 556 | Z23: 31019 | AA23: =+Z23*H23 -> 31019
C24: ● | F24: BUSBAR - Neg BEC to DCFC_Protector | G24: TZ38-14A033-NA | H24: 1 | I24: 터키 현지 외주 | J24: 2004 | K24: 2059 | L24: 3966 | M24: 3354 | N24: 2679 | O24: 4244 | P24: 2581 | Q24: 4082 | R24: 3401 | S24: 3205 | T24: 0 | U24: 0 | V24: =SUM(J24:U24) -> 31575 | X24: 31019 | Y24: =V24-X24 -> 556 | Z24: 31019 | AA24: =+Z24*H24 -> 31019
C25: ● | F25: BUSBAR - CIRCUIT BREAKER_A_Insert | G25: TZ38-14A033-PB | H25: 1 | I25: 터키 현지 외주 | J25: 2004 | K25: 2059 | L25: 3966 | M25: 3354 | N25: 2679 | O25: 4244 | P25: 2581 | Q25: 4082 | R25: 3401 | S25: 3205 | T25: 0 | U25: 0 | V25: =SUM(J25:U25) -> 31575 | X25: 31019 | Y25: =V25-X25 -> 556 | Z25: 31019 | AA25: =+Z25*H25 -> 31019
C26: ● | F26: BUSBAR - CIRCUIT BREAKER_B_Insert | G26: TZ38-14A033-RB | H26: 1 | I26: 터키 현지 외주 | J26: 2004 | K26: 2059 | L26: 3966 | M26: 3354 | N26: 2679 | O26: 4244 | P26: 2581 | Q26: 4082 | R26: 3401 | S26: 3205 | T26: 0 | U26: 0 | V26: =SUM(J26:U26) -> 31575 | X26: 31019 | Y26: =V26-X26 -> 556 | Z26: 31019 | AA26: =+Z26*H26 -> 31019
C27: ● | F27: BUSBAR - Array to Array (Straight)_Insert | G27: PZ38-14A033-FD | H27: 1 | I27: 터키 현지 외주 | J27: 2004 | K27: 2059 | L27: 3966 | M27: 3354 | N27: 2679 | O27: 4244 | P27: 2581 | Q27: 4082 | R27: 3401 | S27: 3205 | T27: 0 | U27: 0 | V27: =SUM(J27:U27) -> 31575 | X27: 31019 | Y27: =V27-X27 -> 556 | Z27: 31019 | AA27: =+Z27*H27 -> 31019
B28: FORD BEV-E1 AWD | C28: ● | F28: BUSBAR - Array to Array (Straight)_Insert | G28: PZ38-14A033-FD | H28: 1 | I28: 터키 현지 외주 | J28: 65 | K28: 558 | L28: 980 | M28: 783 | N28: 588 | O28: 1004 | P28: 552 | Q28: 940 | R28: 766 | S28: 777 | T28: 0 | U28: 0 | V28: =SUM(J28:U28) -> 7013 | W28: * AWD 10월 단산 | X28: 7013 | Y28: =V28-X28 -> 0 | Z28: 7013 | AA28: =+Z28*H28 -> 7013
C29: ● | F29: CONN ASSY (PDU) | G29: TZ38-14B680-BB | H29: 1 | I29: 터키 현지 외주 | J29: 65 | K29: 558 | L29: 980 | M29: 783 | N29: 588 | O29: 1004 | P29: 552 | Q29: 940 | R29: 766 | S29: 777 | T29: 0 | U29: 0 | V29: =SUM(J29:U29) -> 7013 | X29: 7013 | Y29: =V29-X29 -> 0 | Z29: 7013 | AA29: =+Z29*H29 -> 7013
C30: ● | F30: BUSBAR - Array to Array (Straight)_Insert | G30: TZ38-14A033-FA | H30: 1 | I30: 터키 현지 외주 | J30: 65 | K30: 558 | L30: 980 | M30: 783 | N30: 588 | O30: 1004 | P30: 552 | Q30: 940 | R30: 766 | S30: 777 | T30: 0 | U30: 0 | V30: =SUM(J30:U30) -> 7013 | X30: 7013 | Y30: =V30-X30 -> 0 | Z30: 7013 | AA30: =+Z30*H30 -> 7013
C31: ● | F31: BUSBAR - Array to Array (Angled)_Insert | G31: TZ38-14A033-HB | H31: 3 | I31: 터키 현지 외주 | J31: 195 | K31: 1674 | L31: 2940 | M31: 2349 | N31: 1764 | O31: 3012 | P31: 1656 | Q31: 2820 | R31: 2298 | S31: 2331 | T31: 0 | U31: 0 | V31: =SUM(J31:U31) -> 21039 | X31: 21039 | Y31: =V31-X31 -> 0 | Z31: 7013 | AA31: =+Z31*H31 -> 21039
C32: ● | F32: BUSBAR - Array 1 to Neg BEC_Insert | G32: TZ38-14A033-SA | H32: 1 | I32: 터키 현지 외주 | J32: 65 | K32: 558 | L32: 980 | M32: 783 | N32: 588 | O32: 1004 | P32: 552 | Q32: 940 | R32: 766 | S32: 777 | T32: 0 | U32: 0 | V32: =SUM(J32:U32) -> 7013 | X32: 7013 | Y32: =V32-X32 -> 0 | Z32: 7013 | AA32: =+Z32*H32 -> 7013
C33: ● | F33: BUSBAR - Array4 to Array 5_Insert | G33: PZ38-14A033-HF | H33: 1 | I33: 터키 현지 외주 | J33: 65 | K33: 558 | L33: 980 | M33: 783 | N33: 588 | O33: 1004 | P33: 552 | Q33: 940 | R33: 766 | S33: 777 | T33: 0 | U33: 0 | V33: =SUM(J33:U33) -> 7013 | X33: 7013 | Y33: =V33-X33 -> 0 | Z33: 7013 | AA33: =+Z33*H33 -> 7013
C34: ● | F34: BUSBAR - Array 8 to Array 9_Insert | G34: TZ38-14A033-JB | H34: 1 | I34: 터키 현지 외주 | J34: 65 | K34: 558 | L34: 980 | M34: 783 | N34: 588 | O34: 1004 | P34: 552 | Q34: 940 | R34: 766 | S34: 777 | T34: 0 | U34: 0 | V34: =SUM(J34:U34) -> 7013 | X34: 7013 | Y34: =V34-X34 -> 0 | Z34: 7013 | AA34: =+Z34*H34 -> 7013
C35: ● | F35: BUSBAR - Array 9 to Pos BEC_Insert | G35: PZ38-14A033-LF | H35: 1 | I35: 터키 현지 외주 | J35: 65 | K35: 558 | L35: 980 | M35: 783 | N35: 588 | O35: 1004 | P35: 552 | Q35: 940 | R35: 766 | S35: 777 | T35: 0 | U35: 0 | V35: =SUM(J35:U35) -> 7013 | X35: 7013 | Y35: =V35-X35 -> 0 | Z35: 7013 | AA35: =+Z35*H35 -> 7013
C36: ● | F36: BUSBAR - Pos BEC to DCFC_Protector | G36: PZ38-14A033-MC | H36: 1 | I36: 터키 현지 외주 | J36: 65 | K36: 558 | L36: 980 | M36: 783 | N36: 588 | O36: 1004 | P36: 552 | Q36: 940 | R36: 766 | S36: 777 | T36: 0 | U36: 0 | V36: =SUM(J36:U36) -> 7013 | X36: 7013 | Y36: =V36-X36 -> 0 | Z36: 7013 | AA36: =+Z36*H36 -> 7013
C37: ● | F37: BUSBAR - Neg BEC to DCFC_Protector | G37: TZ38-14A033-NA | H37: 1 | I37: 터키 현지 외주 | J37: 65 | K37: 558 | L37: 980 | M37: 783 | N37: 588 | O37: 1004 | P37: 552 | Q37: 940 | R37: 766 | S37: 777 | T37: 0 | U37: 0 | V37: =SUM(J37:U37) -> 7013 | X37: 7013 | Y37: =V37-X37 -> 0 | Z37: 7013 | AA37: =+Z37*H37 -> 7013
C38: ● | F38: BUSBAR - CIRCUIT BREAKER_A_Insert | G38: TZ38-14A033-PB | H38: 1 | I38: 터키 현지 외주 | J38: 65 | K38: 558 | L38: 980 | M38: 783 | N38: 588 | O38: 1004 | P38: 552 | Q38: 940 | R38: 766 | S38: 777 | T38: 0 | U38: 0 | V38: =SUM(J38:U38) -> 7013 | X38: 7013 | Y38: =V38-X38 -> 0 | Z38: 7013 | AA38: =+Z38*H38 -> 7013
C39: ● | F39: BUSBAR - CIRCUIT BREAKER_B_Insert | G39: TZ38-14A033-RB | H39: 1 | I39: 터키 현지 외주 | J39: 65 | K39: 558 | L39: 980 | M39: 783 | N39: 588 | O39: 1004 | P39: 552 | Q39: 940 | R39: 766 | S39: 777 | T39: 0 | U39: 0 | V39: =SUM(J39:U39) -> 7013 | X39: 7013 | Y39: =V39-X39 -> 0 | Z39: 7013 | AA39: =+Z39*H39 -> 7013
C40: ● | F40: BUSBAR - Array to Array (Straight)_Insert | G40: PZ38-14A033-FD | H40: 1 | I40: 터키 현지 외주 | J40: 65 | K40: 558 | L40: 980 | M40: 783 | N40: 588 | O40: 1004 | P40: 552 | Q40: 940 | R40: 766 | S40: 777 | V40: =SUM(J40:U40) -> 7013 | X40: 7013 | Y40: =V40-X40 -> 0 | Z40: 7013 | AA40: =+Z40*H40 -> 7013
...

Sheet 2. Service
B1: ▣ Service sumarry
B4: Service Companies | D4: Jan | E4: Feb | F4: Mar | G4: Apr | H4: May | I4: Jun | J4: Jul | K4: Aug | L4: Sep | M4: Oct | N4: Nov | O4: Dec | P4: Total | Q4: Remark | R4: Remark
B5: Tax Accounting & Audit (VDY) | C5: Consultancy | D5: =+D60 -> 121232 | E5: =+E60 -> 121232 | F5: =+F60 -> 121232 | G5: =+G60 -> 121232 | H5: =+H60 -> 121232 | I5: =+I60 -> 121232 | J5: =+J60 -> 121232 | K5: =+K60 -> 121232 | ... O5: =+O60 -> 121232 | P5: =SUM(D5:O5) -> 1454784
B6: Legal Advice Service (Tao-r) | C6: Account | D6: 35512.634 | E6: 35512.634 | F6: 35512.634 | G6: 35512.634 | H6: 35512.634 | I6: 35512.634 | J6: 35512.634 | K6: 35512.634 | L6: 35512.634 | M6: 35512.634 | N6: 35512.634 | O6: 35512.634 | P6: =SUM(D6:O6) -> 426151.61
B7: Notary / Translation expenses | D7: 6000 | E7: - | F7: - | G7: 6000 | H7: - | I7: - | J7: 6000 | K7: - | L7: - | M7: 6000 | N7: - | O7: - | P7: =SUM(D7:O7) -> 24000 | Q7: 4회/년 | R7: Notery payment
B8: Cargo Expenses for urgent service | D8: 5000 | E8: 5000 | F8: 5000 | G8: 5000 | H8: 5000 | I8: 5000 | J8: 5000 | K8: 5000 | L8: 5000 | M8: 5000 | N8: 5000 | O8: 5000 | P8: =SUM(D8:O8) -> 60000
B9: 총합 | C9: - | D9: =SUM(D5:D7) -> 162744.63 | E9: =SUM(E5:E7) -> 156744.63 | F9: =SUM(F5:F7) -> 156744.63 | G9: =SUM(G5:G7) -> 162744.63 | H9: =SUM(H5:H7) -> 156744.63 | I9: =SUM(I5:I7) -> 156744.63 | J9: =SUM(J5:J7) -> 162744.63 | K9: =SUM(K5:K7) -> 156744.63 | ... P9: =SUM(P5:P7) -> 1904935.6
B12: ▣ IT Service
B15: 2025
B16: Company | C16: Detail | D16: Payment Status | E16: Jan | F16: Jan | G16: Feb | H16: Feb | I16: Mar | J16: Mar | K16: Apr | L16: Apr | M16: May | N16: May | O16: Jun | P16: Jun | Q16: July | R16: July | S16: Aug | T16: Aug | U16: Sept | V16: Sept | W16: Oct | X16: Oct | Y16: Nov | Z16: Nov | AA16: Dec | AB16: Dec | AC16: Yearly Avarage | AD16: Contact
E17: USD | F17: TL | G17: USD | H17: TL | I17: USD | J17: TL | K17: USD | L17: TL | M17: USD | N17: TL | O17: USD | P17: TL | Q17: USD | R17: TL | S17: USD | T17: TL | U17: USD | V17: TL | W17: USD | X17: TL | Y17: USD | Z17: TL | AA17: USD | AB17: TL | AD17: 2024.6~2025.6
E18: 35.52 | G18: 36.17 | I18: 37.09 | K18: 38.13 | M18: 38.83 | O18: 39.48 | Q18: 40.24 | S18: 40.86 | U18: 41.35 | W18: 41.85 | Y18: 42.18
B19: RINT | C19: DATA CENTER | D19: Montly | E19: 653.22269 | F19: 23202.47 | G19: 641.48383 | H19: 23202.47 | I19: 625.57212 | J19: 23202.47 | K19: 608.50957 | L19: 23202.47 | M19: 597.53979 | N19: 23202.47 | O19: 587.70187 | P19: 23202.47 | Q19: 576.60214 | R19: 23202.47 | S19: 567.85291 | T19: 23202.47 | U19: 565.34921 | V19: 23202.47 | W19: 562.76965 | X19: 23202.47 | Y19: 562.50901 | Z19: 23202.47 | AA19: 562.50901 | AB19: 23202.47 | AC19: =SUM(F19,H19,J19,L19,N19,P19,R19,T19,V19,X19,Z19,AB19) -> 278429.64
C20: SQL SERVICE | D20: Montly | F20: 6800.79 | H20: 6800.79 | J20: 6800.79 | L20: 6800.79 | N20: 6800.79 | P20: 6800.79 | R20: 6800.79 | T20: 6800.79 | U20: 164.46892 | V20: 6800.79 | X20: 6800.79 | Z20: 6800.79 | AB20: 6800.79 | AC20: =SUM(F20,H20,J20,L20,N20,P20,R20,T20,V20,X20,Z20,AB20) -> 81609.48
B21: Proser | C21: Fortigate | D21: YEARLY | U21: 1100 | V21: 54710 | AC21: =SUM(F21,H21,J21,L21,N21,P21,R21,T21,V21,X21,Z21,AB21) -> 54710
C22: Fortilogger | D22: YEARLY | AC22: =SUM(F22,H22,J22,L22,N22,P22,R22,T22,V22,X22,Z22,AB22) -> 0
C23: IT SERVICE FEE | D23: Montly | O23: 577.5076 | P23: 22800 | Q23: 566.6004 | R23: 22800 | S23: 558.00294 | T23: 22800 | U23: 551.39057 | V23: 22800 | W23: 544.80287 | X23: 22800 | Y23: 540.54054 | Z23: 22800 | AA23: 540.54054 | AB23: 22800 | AC23: =SUM(F23,H23,J23,L23,N23,P23,R23,T23,V23,X23,Z23,AB23) -> 159600
B24: Chip Computer | C24: LICENCE LOGO | D24: YEARLY | M24: 3862.9925 | N24: 150000 | W24: 3022.9746 | X24: 125000 | AC24: =SUM(F24,H24,J24,L24,N24,P24,R24,T24,V24,X24,Z24,AB24) -> 275000
C25: LEM LICENCE | D25: YEARLY | U25: 725.51391 | V25: 30000 | W25: 716.84588 | X25: 30000 | Y25: 711.23755 | Z25: 30000 | AB25: 30000 | AC25: =SUM(F25,H25,J25,L25,N25,P25,R25,T25,V25,X25,Z25,AB25) -> 120000
C26: LOGO TIGER | D26: YEARLY | M26: 2034.5094 | N26: 79000 | AC26: =SUM(F26,H26,J26,L26,N26,P26,R26,T26,V26,X26,Z26,AB26) -> 79000
B27: HRSI (KOLAY İK) | D27: YEARLY | AB27: 26006 | AC27: =AB27 -> 26006
AC28: =SUM(AC19:AC27) -> 1074355.1
B29: 2026
B30: Company | C30: Detail | D30: Payment Status | E30: Jan | F30: Jan | G30: Feb | H30: Feb | I30: Mar | J30: Mar | K30: Apr | L30: Apr | M30: May | N30: May | O30: Jun | P30: Jun | Q30: July | R30: July | S30: Aug | T30: Aug | U30: Sept | V30: Sept | W30: Oct | X30: Oct | Y30: Nov | Z30: Nov | AA30: Dec | AB30: Dec | AC30: Yearly Avarage
E31: USD | F31: TL | G31: USD | H31: TL | I31: USD | J31: TL | K31: USD | L31: TL | M31: USD | N31: TL | O31: USD | P31: TL | Q31: USD | R31: TL | S31: USD | T31: TL | U31: USD | V31: TL | W31: USD | X31: TL | Y31: USD | Z31: TL | AA31: USD | AB31: TL
B33: RINT | C33: DATA CENTER | D33: Montly | F33: =23202.47*1.3 -> 30163.211 | H33: =23202.47*1.3 -> 30163.211 | J33: =23202.47*1.3 -> 30163.211 | L33: =23202.47*1.3 -> 30163.211 | M33: - | N33: =23202.47*1.3 -> 30163.211 | P33: =23202.47*1.3 -> 30163.211 | R33: =23202.47*1.3 -> 30163.211 | T33: =23202.47*1.3 -> 30163.211 | V33: =23202.47*1.3 -> 30163.211 | X33: =23202.47*1.3 -> 30163.211 | Z33: =23202.47*1.3 -> 30163.211 | AB33: =23202.47*1.3 -> 30163.211 | AC33: =SUM(F33,H33,J33,L33,N33,P33,R33,T33,V33,X33,Z33,AB33) -> 361958.53
C34: SQL SERVICE | D34: Montly | F34: =6800.79*1.3 -> 8841.027 | H34: =6800.79*1.3 -> 8841.027 | J34: =6800.79*1.3 -> 8841.027 | L34: =6800.79*1.3 -> 8841.027 | N34: =6800.79*1.3 -> 8841.027 | P34: =6800.79*1.3 -> 8841.027 | R34: =6800.79*1.3 -> 8841.027 | T34: =6800.79*1.3 -> 8841.027 | V34: =6800.79*1.3 -> 8841.027 | X34: =6800.79*1.3 -> 8841.027 | Z34: =6800.79*1.3 -> 8841.027 | AB34: =6800.79*1.3 -> 8841.027 | AC34: =SUM(F34,H34,J34,L34,N34,P34,R34,T34,V34,X34,Z34,AB34) -> 106092.32
B35: Proser | C35: FORTIGATE | D35: YEARLY | F35: - | V35: =54582*1.3 -> 70956.6 | AC35: =SUM(F35,H35,J35,L35,N35,P35,R35,T35,V35,X35,Z35,AB35) -> 70956.6
C36: Fortigate | D36: YEARLY | F36: - | AC36: =SUM(F36,H36,J36,L36,N36,P36,R36,T36,V36,X36,Z36,AB36) -> 0
C37: IT SERVICE FEE | D37: Montly | F37: 22800 | H37: 22800 | J37: 22800 | L37: 22800 | N37: 22800 | P37: 22800 | R37: =P37*1.3 -> 29640 | T37: 29640 | V37: 29640 | X37: 29640 | Z37: 29640 | AB37: 29640 | AC37: =SUM(F37,H37,J37,L37,N37,P37,R37,T37,V37,X37,Z37,AB37) -> 314640 | AD37: 30th Jun 2025 ~ 30th Jun 2026 ~
B38: Chip Computer | C38: LICENCE LOGO | D38: YEARLY | N38: 198000 | AC38: =SUM(F38,H38,J38,L38,N38,P38,R38,T38,V38,X38,Z38,AB38) -> 198000
C39: LEM LICENCE | D39: YEARLY | F39: 39600 | H39: 39600 | J39: 39600 | L39: 39600 | N39: 39600 | P39: 39600 | R39: 39600 | T39: 39600 | V39: 39600 | X39: 39600 | Z39: 39600 | AB39: 39600 | AC39: =SUM(F39,H39,J39,L39,N39,P39,R39,T39,V39,X39,Z39,AB39) -> 475200
C40: Logo system update | D40: YEARLY | AB40: 182378 | AC40: =SUM(F40,H40,J40,L40,N40,P40,R40,T40,V40,X40,Z40,AB40) -> 182378
C41: LOGO TIGER | D41: YEARLY | F41: 182378.4 | AC41: =SUM(F41,H41,J41,L41,N41,P41,R41,T41,V41,X41,Z41,AB41) -> 182378.4
B42: HRSI (KOLAY İK) | D42: YEARLY | M42: - | O42: - | Q42: - | AB42: 34328.448 | AC42: =SUM(F42,H42,J42,L42,N42,P42,R42,T42,V42,X42,Z42,AB42) -> 34328.448
AC43: =SUM(AC32:AC42) -> 1925932.3
D46: IT service | E46: Jan | F46: Feb | G46: Mar | H46: Apr | I46: May | J46: Jun | K46: Jul | L46: Aug | M46: Sep | N46: Oct | O46: Nov | P46: Dec | Q46: Total
D47: Total | E47: =SUM(F33:F42) -> 283782.64 | F47: =SUM(H33:H42) -> 101404.24 | G47: =SUM(J33:J42) -> 101404.24 | H47: =SUM(L33:L42) -> 101404.24 | I47: =SUM(N33:N42) -> 299404.24 | J47: =SUM(P33:P42) -> 101404.24 | K47: =SUM(R33:R42) -> 108244.24 | L47: =SUM(T33:T42) -> 108244.24 | M47: =SUM(V33:V42) -> 179200.84 | N47: =SUM(X33:X42) -> 108244.24 | O47: =SUM(Z33:Z42) -> 108244.24 | P47: =SUM(AB33:AB42) -> 324950.69 | Q47: =SUM(E47:P47) -> 1925932.3
B50: ▣ Tax Accounting & Audit (VDY)
B53: Service Companies | C53: Frequency | D53: Jan | E53: Feb | F53: Mar | G53: Apr | H53: May | I53: Jun | J53: Jul | K53: Aug | L53: Sep | M53: Oct | N53: Nov | O53: Dec | P53: Total
...

Sheet 3. HR
E1: 26 KCTR H/R Plan
A6: Month | E6: Jan | F6: Feb | G6: Mar | H6: Apr | I6: May | J6: Jun | K6: Jul | L6: Aug | M6: Sept | N6: Oct | O6: Nov | P6: Dec
A7: Total Number of employees | E7: =SUM(E9:E11) -> 23 | F7: =SUM(F9:F11) -> 24 | G7: =SUM(G9:G11) -> 24 | H7: =SUM(H9:H11) -> 24 | I7: =SUM(I9:I11) -> 24 | J7: =SUM(J9:J11) -> 24 | K7: =SUM(K9:K11) -> 25 | L7: =SUM(L9:L11) -> 27 | ... P7: =SUM(P9:P11) -> 27
A8: New employees | E8: 1 | F8: 1 | K8: 1 | L8: 2
A9: 주재원 | E9: =SUM(E13,E14,E36) -> 2 | F9: =SUM(F13,F14,F36) -> 2 | G9: =SUM(G13,G14,G36) -> 2 | H9: =SUM(H13,H14,H36) -> 2 | I9: =SUM(I13,I14,I36) -> 2 | J9: =SUM(J13,J14,J36) -> 2 | K9: =SUM(K13,K14,K36) -> 3 | L9: =SUM(L13,L14,L36) -> 3 | ... P9: =SUM(P13,P14,P36) -> 3
A10: Accounting-Finance Personel | E10: =SUM(E15:E23)+SUM(E37,E38) -> 10 | F10: =SUM(F15:F23)+SUM(F37,F38) -> 11 | G10: =SUM(G15:G23)+SUM(G37,G38) -> 11 | H10: =SUM(H15:H23)+SUM(H37,H38) -> 11 | I10: =SUM(I15:I23)+SUM(I37,I38) -> 11 | J10: =SUM(J15:J23)+SUM(J37,J38) -> 11 | K10: =SUM(K15:K23)+SUM(K37,K38) -> 11 | L10: =SUM(L15:L23)+SUM(L37,L38) -> 11 | ... P10: =SUM(P15:P23)+SUM(P37,P38) -> 11
A11: Manufacturing Personel | E11: =SUM(E24:E34)+SUM(E39,E40) -> 11 | F11: =SUM(F24:F34)+SUM(F39,F40) -> 11 | G11: =SUM(G24:G34)+SUM(G39,G40) -> 11 | H11: =SUM(H24:H34)+SUM(H39,H40) -> 11 | I11: =SUM(I24:I34)+SUM(I39,I40) -> 11 | J11: =SUM(J24:J34)+SUM(J39,J40) -> 11 | K11: =SUM(K24:K34)+SUM(K39,K40) -> 11 | L11: =SUM(L24:L34)+SUM(L39,L40) -> 13 | ... P11: =SUM(P24:P34)+SUM(P39,P40) -> 13
A13: 2026년 계획 | B13: General Manager | C13: HM CHO | D13: 주재원 | E13: 1 | F13: 1 | G13: 1 | H13: 1 | I13: 1 | J13: 1 | K13: 1 | L13: 1 | M13: 1 | N13: 1 | O13: 1 | P13: 1
B14: D. General Manager | C14: SH LEE | D14: 주재원 | E14: 1 | F14: 1 | G14: 1 | H14: 1 | I14: 1 | J14: 1 | K14: 1 | L14: 1 | M14: 1 | N14: 1 | O14: 1 | P14: 1
B15: HR/General Affairs | C15: MERVE | D15: Manager | E15: 1 | F15: 1 | G15: 1 | H15: 1 | I15: 1 | J15: 1 | K15: 1 | L15: 1 | M15: 1 | N15: 1 | O15: 1 | P15: 1
C16: Kübra Ceren | D16: Specialist | E16: 1 | F16: 1 | G16: 1 | H16: 1 | I16: 1 | J16: 1 | K16: 1 | L16: 1 | M16: 1 | N16: 1 | O16: 1 | P16: 1
C17: GÜLSÜM | D17: Technician | E17: 1 | F17: 1 | G17: 1 | H17: 1 | I17: 1 | J17: 1 | K17: 1 | L17: 1 | M17: 1 | N17: 1 | O17: 1 | P17: 1
B18: Finance/Account | C18: Özge | D18: Supervisor | E18: 1 | F18: 1 | G18: 1 | H18: 1 | I18: 1 | J18: 1 | K18: 1 | L18: 1 | M18: 1 | N18: 1 | O18: 1 | P18: 1
C19: ÇAĞLA | D19: Specialist | E19: 1 | F19: 1 | G19: 1 | H19: 1 | I19: 1 | J19: 1 | K19: 1 | L19: 1 | M19: 1 | N19: 1 | O19: 1 | P19: 1
C20: Haticenur | D20: Assistant Specialist | E20: 1 | F20: 1 | G20: 1 | H20: 1 | I20: 1 | J20: 1 | K20: 1 | L20: 1 | M20: 1 | N20: 1 | O20: 1 | P20: 1
B21: Sales/Procurement | C21: Melis | D21: Specialist | E21: 1 | F21: 1 | G21: 1 | H21: 1 | I21: 1 | J21: 1 | K21: 1 | L21: 1 | M21: 1 | N21: 1 | O21: 1 | P21: 1
C22: Cagatay | D22: Assistant Specialist | E22: 1 | F22: 1 | G22: 1 | H22: 1 | I22: 1 | J22: 1 | K22: 1 | L22: 1 | M22: 1 | N22: 1 | O22: 1 | P22: 1
C23: Sonbahar | D23: Supervisor | E23: 1 | F23: 1 | G23: 1 | H23: 1 | I23: 1 | J23: 1 | K23: 1 | L23: 1 | M23: 1 | N23: 1 | O23: 1 | P23: 1
B24: MP&L | C24: OZNUR | D24: Manager | E24: 1 | F24: 1 | G24: 1 | H24: 1 | I24: 1 | J24: 1 | K24: 1 | L24: 1 | M24: 1 | N24: 1 | O24: 1 | P24: 1
C25: Murat Öze | D25: Supervisor | E25: 1 | F25: 1 | G25: 1 | H25: 1 | I25: 1 | J25: 1 | K25: 1 | L25: 1 | M25: 1 | N25: 1 | O25: 1 | P25: 1
C26: MERİÇ | D26: Assistant Specialist | E26: 1 | F26: 1 | G26: 1 | H26: 1 | I26: 1 | J26: 1 | K26: 1 | L26: 1 | M26: 1 | N26: 1 | O26: 1 | P26: 1
C27: Tugay | D27: Engineer | E27: 1 | F27: 1 | G27: 1 | H27: 1 | I27: 1 | J27: 1 | K27: 1 | L27: 1 | M27: 1 | N27: 1 | O27: 1 | P27: 1
B28: P/M | C28: Akin | D28: Supervisor | E28: 1 | F28: 1 | G28: 1 | H28: 1 | I28: 1 | J28: 1 | K28: 1 | L28: 1 | M28: 1 | N28: 1 | O28: 1 | P28: 1
C29: CH Park | D29: Specialist | E29: 1 | F29: 1 | G29: 1 | H29: 1 | I29: 1 | J29: 1 | K29: 1 | L29: 1 | M29: 1 | N29: 1 | O29: 1 | P29: 1
B30: Q.C. | C30: CEREN | D30: Manager | E30: 1 | F30: 1 | G30: 1 | H30: 1 | I30: 1 | J30: 1 | K30: 1 | L30: 1 | M30: 1 | N30: 1 | O30: 1 | P30: 1
C31: Sevde | D31: Engineer | E31: 1 | F31: 1 | G31: 1 | H31: 1 | I31: 1 | J31: 1 | K31: 1 | L31: 1 | M31: 1 | N31: 1 | O31: 1 | P31: 1
C32: MUZAFFER(Residents Otosan) | D32: Technician | E32: 1 | F32: 1 | G32: 1 | H32: 1 | I32: 1 | J32: 1 | K32: 1 | L32: 1 | M32: 1 | N32: 1 | O32: 1 | P32: 1
C33: BAHADIR (Residents Nursan) | D33: Technician | E33: 1 | F33: 1 | G33: 1 | H33: 1 | I33: 1 | J33: 1 | K33: 1 | L33: 1 | M33: 1 | N33: 1 | O33: 1 | P33: 1
C34: İBRAHIM (Residents Takosan) | D34: Technician | E34: 1 | F34: 1 | G34: 1 | H34: 1 | I34: 1 | J34: 1 | K34: 1 | L34: 1 | M34: 1 | N34: 1 | O34: 1 | P34: 1
A36: 2026년 중장기 운영 계획 | B36: 영업 (예상) | C36: Korean Manager | D36: Manager | K36: 1 | L36: 1 | M36: 1 | N36: 1 | O36: 1 | P36: 1
B37: Sales | C37: TBD | D37: Engineer | F37: 1 | G37: 1 | H37: 1 | I37: 1 | J37: 1 | K37: 1 | L37: 1 | M37: 1 | N37: 1 | O37: 1 | P37: 1
B38: Purchasing | C38: TBD | D38: Engineer | E38: 1 | F38: 1 | G38: 1 | H38: 1 | I38: 1 | J38: 1 | K38: 1 | L38: 1 | M38: 1 | N38: 1 | O38: 1 | P38: 1
B39: MP&L | C39: TBD | D39: Engineer | L39: 1 | M39: 1 | N39: 1 | O39: 1 | P39: 1
B40: MP&L | C40: TBD | D40: Engineer | L40: 1 | M40: 1 | N40: 1 | O40: 1 | P40: 1
B42: ※ EV-V4 포장사양 협의결과에 따라 변동(KCTR 포장사양 변경시 2명 충원예정) | H42: 총인원 | J42: 주재원 | K42: Manager | L42: Supervisor | M42: Specialist | N42: Engineer | O42: Technician | P42: Total
H43: ‘25.12 | J43: 2 | K43: 2 | L43: 4 | M43: 5 | N43: 5 | O43: 4 | P43: =SUM(J43:O43) -> 22
H44: 26.01 | J44: 2 | K44: 3 | L44: 4 | M44: 4 | N44: 5 | O44: 4 | P44: =SUM(J44:O44) -> 22
H45: `26 long term ('26.12) | J45: 3 | K45: 3 | L45: 4 | M45: 4 | N45: 9 | O45: 4 | P45: =SUM(J45:O45) -> 27

Sheet 4. Salary
B1: ▣ `26 Salary
O4: SGK 총급여의 약 37%
P5: SGK | V5: INCOME TAX
P6: 4대보험 | R6: 실업급여 | V6: 소득세 | W6: 인지세
P7: 근로자 | Q7: 고용주 | R7: 근로자 | S7: 고용주 | V7: 세금 | W7: 세금
B8: Current Employee
B9: Department | C9: Employee | D9: Position | F9: Title | G9: Gender | H9: Age | I9: Start Date | J9: 근속년수 (26년1월 기준) | K9: MONTHLY (NET) $ | L9: MONTHLY (NET) TL | M9: REMARK | N9: GROSS(MONTH) | O9: GROSS(YEAR) | P9: SSI Ee | Q9: SSI Er | R9: UEe | S9: UEr | T9: CITB | U9: ITB | V9: Income Tax | W9: Stamp Tax | X9: MLA | Y9: Net(MONTH) | Z9: Net(YEAR) | AA9: NET
C10: HM.CHO | D10: GENERAL MANAGER | E10: 주재원 | F10: 정규 | I10: 2022.05 | K10: 8800 | L10: 0 | M10: 0 | N10: 679907.49 | O10: =N10*12 -> 8158889.9 | P10: 27305.8 | Q10: 32669.43 | R10: 1950.41 | S10: 3900.83 | U10: 0 | V10: 141360.15 | W10: 4963.12 | Y10: =L10 -> 0 | Z10: =Y10*12 -> 0
C11: SH.LEE | D11: D.GENERAL MANAGER | E11: 주재원 | F11: 정규 | I11: 2024.07 | K11: 7460 | L11: 0 | M11: 0 | N11: 420391.48 | O11: =N11*12 -> 5044697.8 | P11: 27305.8 | Q11: 32669.43 | R11: 1950.41 | S11: 3900.83 | T11: 0 | U11: 0 | V11: 71290.82 | W11: 2993.39 | Y11: =L11 -> 0 | Z11: =Y11*12 -> 0
B12: HR/GA | C12: MERVE GÜNDÜZ | D12: MANAGER | E12: Accounting-Affair Personel | F12: Team Leader | G12: Female | H12: 36 | I12: 44769 | J12: 3.4356164 | L12: 92000 | M12: 0 | N12: 123773.5 | O12: =N12*12 -> 1485282 | P12: 17328.29 | Q12: 20732.06 | R12: 1237.74 | S12: 2475.47 | T12: 0 | U12: 0 | V12: 12465.42 | W12: 742.06 | Y12: =L12 -> 92000 | Z12: =Y12*12 -> 1104000
B13: QC | C13: CEREN KARAKOÇUM | D13: MANAGER | E13: Manufacturing Personel | F13: Team Leader | G13: Female | H13: 35 | I13: 44823 | J13: 3.290411 | L13: 92000 | M13: 0 | N13: 123773.5 | O13: =N13*12 -> 1485282 | P13: 17328.29 | Q13: 20732.06 | R13: 1237.74 | S13: 2475.47 | T13: 0 | U13: 0 | V13: 12465.42 | W13: 742.06 | Y13: =L13 -> 92000 | Z13: =Y13*12 -> 1104000
B14: MP&L | C14: ÖZNUR KOCAMAN | D14: MANAGER | E14: Manufacturing Personel | F14: Team Leader | G14: Female | H14: 34 | I14: 45152 | J14: 2.3917808 | L14: 92000 | M14: 0 | N14: 123773.5 | O14: =N14*12 -> 1485282 | P14: 17328.29 | Q14: 20732.06 | R14: 1237.74 | S14: 2475.47 | T14: 0 | U14: 0 | V14: 12465.42 | W14: 742.06 | Y14: =L14 -> 92000 | Z14: =Y14*12 -> 1104000
B15: F/A | C15: OZGE REÇBER | D15: SUPERVISOR | E15: Accounting-Affair Personel | F15: Team Leader | G15: Female | H15: 34 | I15: 45356 | J15: 1.8356164 | L15: 86000 | M15: 0 | N15: 115380.84 | O15: =N15*12 -> 1384570.1 | P15: 16153.32 | Q15: 19326.29 | R15: 1153.81 | S15: 2307.62 | T15: 0 | U15: 0 | V15: 11395.36 | W15: 678.36 | Y15: =L15 -> 86000 | Z15: =Y15*12 -> 1032000
B16: MP&L | C16: MURAT ÖZEN | D16: SUPERVISOR | E16: Manufacturing Personel | G16: Male | H16: 32 | I16: 45446 | J16: 1.5917808 | L16: 86000 | M16: 0 | N16: 115380.84 | O16: =N16*12 -> 1384570.1 | P16: 16153.32 | Q16: 19326.29 | R16: 1153.81 | S16: 2307.62 | T16: 0 | U16: 0 | V16: 11395.36 | W16: 678.36 | Y16: =L16 -> 86000 | Z16: =Y16*12 -> 1032000
B17: MP&L | C17: TUGAY BİRBEN | D17: ENGINEER | E17: Accounting-Affair Personel | G17: Male | H17: 32 | I17: 45518 | J17: 1.4 | L17: 60000 | M17: 0 | N17: 79012.63 | O17: =N17*12 -> 948151.56 | P17: 11061.77 | Q17: 13234.62 | R17: 790.13 | S17: 1580.25 | T17: 0 | U17: 0 | V17: 6758.41 | W17: 402.32 | Y17: =L17 -> 60000 | Z17: =Y17*12 -> 720000
B18: HR/GA | C18: KÜBRA CEREN ÖZEN | D18: SPECIALIST | E18: Accounting-Affair Personel | G18: Female | H18: 29 | I18: 45544 | J18: 1.3315068 | L18: 65000 | M18: 0 | N18: 86006.52 | O18: =N18*12 -> 1032078.2 | P18: 12040.91 | Q18: 14406.09 | R18: 860.07 | S18: 1720.13 | T18: 0 | U18: 0 | V18: 7650.13 | W18: 455.41 | Y18: =L18 -> 65000 | Z18: =Y18*12 -> 780000
B19: PM | C19: AKIN ILGAZ | D19: SUPERVISOR | E19: Manufacturing Personel | F19: Team Leader | G19: Male | H19: 29 | I19: 45597 | J19: 1.1890411 | L19: 80000 | M19: 0 | N19: 115380.84 | O19: =N19*12 -> 1384570.1 | P19: 16153.32 | Q19: 19326.29 | R19: 1153.81 | S19: 2307.62 | T19: 0 | U19: 0 | V19: 11395.36 | W19: 678.36 | Y19: =L19 -> 80000 | Z19: =Y19*12 -> 960000
B20: QC | C20: MUZAFFER TÜRK | D20: TECHNICIAN | E20: Manufacturing Personel | G20: Male | H20: 33 | I20: 45629 | J20: 1.1041096 | L20: 60000 | M20: 0 | N20: 79012.63 | O20: =N20*12 -> 948151.56 | P20: 11061.77 | Q20: 13234.62 | R20: 790.13 | S20: 1580.25 | T20: 0 | U20: 0 | V20: 6758.41 | W20: 402.32 | Y20: =L20 -> 60000 | Z20: =Y20*12 -> 720000
B21: QC | C21: İBRAHIM OSMANLI | D21: TECHNICIAN | E21: Manufacturing Personel | G21: Male | H21: 33 | I21: 45635 | J21: 1.090411 | L21: 60000 | M21: 0 | N21: 79012.63 | O21: =N21*12 -> 948151.56 | P21: 11061.77 | Q21: 13234.62 | R21: 790.13 | S21: 1580.25 | T21: 0 | U21: 0 | V21: 6758.41 | W21: 402.32 | Y21: =L21 -> 60000 | Z21: =Y21*12 -> 720000
B22: COST | C22: MELİS BİÇER YILDIZ | D22: SPECIALIST | E22: Accounting-Affair Personel | G22: Female | H22: 29 | I22: 45726 | J22: 0.84383562 | L22: 75000 | M22: 0 | N22: 99994.29 | O22: =N22*12 -> 1199931.5 | P22: 13999.2 | Q22: 16749.04 | R22: 999.94 | S22: 1999.89 | T22: 0 | U22: 0 | V22: 9433.57 | W22: 561.57 | Y22: =L22 -> 75000 | Z22: =Y22*12 -> 900000
B23: F/A | C23: ELİF ÇAĞLA KARAGÖL | D23: SPECIALIST | E23: Accounting-Affair Personel | G23: Female | H23: 32 | I23: 45824 | J23: 0.57808219 | L23: 75000 | M23: 0 | N23: 99994.29 | O23: =N23*12 -> 1199931.5 | P23: 13999.2 | Q23: 16749.04 | R23: 999.94 | S23: 1999.89 | T23: 0 | U23: 0 | V23: 9433.57 | W23: 561.57 | Y23: =L23 -> 75000 | Z23: =Y23*12 -> 900000
