Workbook

Sheet 1. 경신전선 요약
C4: 1. 월 손익/원가 요약 | P4: (단위:백만원)
C5: 구 분 | D5: 2026년 계 획 | E5: 년계획 진척률 | F5: 누 계 계 획 | G5: 누 계 실 적 | H5: 달성률 | I5: 전 월 실 적 | J5: 매 출 구성비 | K5: 당 월 계 획 | L5: 매 출 구성비 | M5: 당 월 실 적 | N5: 매 출 구성비 | O5: 전 월 대 비 | P5: 계 획 대 비
C6: Ⅰ. 매출액 | D6: =+'2. 손익계산서'!C6/1000000 -> 47498.576 | E6: =+'2. 손익계산서'!D6 -> 0 | F6: =+'2. 손익계산서'!E6/1000000 -> 1801.9737 | G6: =+'2. 손익계산서'!F6/1000000 -> 0 | H6: =+'2. 손익계산서'!G6 -> 0 | I6: =+'2. 손익계산서'!H6/1000000 -> 0 | J6: =+'2. 손익계산서'!I6 -> 0 | K6: =+'2. 손익계산서'!J6/1000000 -> 1801.9737 | L6: =+'2. 손익계산서'!K6 -> 1 | M6: =+'2. 손익계산서'!L6/1000000 -> 0 | N6: =+'2. 손익계산서'!M6 -> 0 | O6: =+'2. 손익계산서'!N6 -> 0 | P6: =+'2. 손익계산서'!O6 -> 0
C7: W/H | D7: =+'2. 손익계산서'!C7/1000000 -> 0 | E7: =+'2. 손익계산서'!D7 -> 0 | F7: =+'2. 손익계산서'!E7/1000000 -> 0 | G7: =+'2. 손익계산서'!F7/1000000 -> 0 | H7: =+'2. 손익계산서'!G7 -> 0 | I7: =+'2. 손익계산서'!H7/1000000 -> 0 | J7: =+'2. 손익계산서'!I7 -> 0 | K7: =+'2. 손익계산서'!J7/1000000 -> 0 | L7: =+'2. 손익계산서'!K7 -> 0 | M7: =+'2. 손익계산서'!L7/1000000 -> 0 | N7: =+'2. 손익계산서'!M7 -> 0 | O7: =+'2. 손익계산서'!N7 -> 0 | P7: =+'2. 손익계산서'!O7 -> 0 | Z7: =M7-K7 -> 0 | AA7: =M7-I7 -> 0
C8: 상품 | D8: =+'2. 손익계산서'!C8/1000000 -> 9059.1683 | E8: =+'2. 손익계산서'!D8 -> 0 | F8: =+'2. 손익계산서'!E8/1000000 -> 268.009 | G8: =+'2. 손익계산서'!F8/1000000 -> 0 | H8: =+'2. 손익계산서'!G8 -> 0 | I8: =+'2. 손익계산서'!H8/1000000 -> 0 | J8: =+'2. 손익계산서'!I8 -> 0 | K8: =+'2. 손익계산서'!J8/1000000 -> 268.009 | L8: =+'2. 손익계산서'!K8 -> 0.1487308 | M8: =+'2. 손익계산서'!L8/1000000 -> 0 | N8: =+'2. 손익계산서'!M8 -> 0 | O8: =+'2. 손익계산서'!N8 -> 0 | P8: =+'2. 손익계산서'!O8 -> 0 | Z8: =M8-K8 -> -268.009 | AA8: =M8-I8 -> 0
C9: 부품 | D9: =+'2. 손익계산서'!C9/1000000 -> 22049.85 | E9: =+'2. 손익계산서'!D9 -> 0 | F9: =+'2. 손익계산서'!E9/1000000 -> 1533.9647 | G9: =+'2. 손익계산서'!F9/1000000 -> 0 | H9: =+'2. 손익계산서'!G9 -> 0 | I9: =+'2. 손익계산서'!H9/1000000 -> 0 | J9: =+'2. 손익계산서'!I9 -> 0 | K9: =+'2. 손익계산서'!J9/1000000 -> 1533.9647 | L9: =+'2. 손익계산서'!K9 -> 0.8512692 | M9: =+'2. 손익계산서'!L9/1000000 -> 0 | N9: =+'2. 손익계산서'!M9 -> 0 | O9: =+'2. 손익계산서'!N9 -> 0 | P9: =+'2. 손익계산서'!O9 -> 0 | Z9: =M9-K9 -> -1533.9647 | AA9: =M9-I9 -> 0
C10: 기타 | D10: =+'2. 손익계산서'!C10/1000000 -> 16389.558 | E10: =+'2. 손익계산서'!D10 -> 0 | F10: =+'2. 손익계산서'!E10/1000000 -> 0 | G10: =+'2. 손익계산서'!F10/1000000 -> 0 | H10: =+'2. 손익계산서'!G10 -> 0 | I10: =+'2. 손익계산서'!H10/1000000 -> 0 | J10: =+'2. 손익계산서'!I10 -> 0 | K10: =+'2. 손익계산서'!J10/1000000 -> 0 | L10: =+'2. 손익계산서'!K10 -> 0 | M10: =+'2. 손익계산서'!L10/1000000 -> 0 | N10: =+'2. 손익계산서'!M10 -> 0 | O10: =+'2. 손익계산서'!N10 -> 0 | P10: =+'2. 손익계산서'!O10 -> 0 | Z10: =M10-K10 -> 0 | AA10: =M10-I10 -> 0
C11: Ⅱ. 매출원가 | D11: =+'2. 손익계산서'!C11/1000000 -> 40951.464 | E11: =+'2. 손익계산서'!D11 -> 0 | F11: =+'2. 손익계산서'!E11/1000000 -> 1646.3422 | G11: =+'2. 손익계산서'!F11/1000000 -> 0 | H11: =+'2. 손익계산서'!G11 -> 0 | I11: =+'2. 손익계산서'!H11/1000000 -> 0 | J11: =+'2. 손익계산서'!I11 -> 0 | K11: =+'2. 손익계산서'!J11/1000000 -> 1646.3422 | L11: =+'2. 손익계산서'!K11 -> 0.91363274 | M11: =+'2. 손익계산서'!L11/1000000 -> 0 | N11: =+'2. 손익계산서'!M11 -> 0 | O11: =+'2. 손익계산서'!N11 -> 0 | P11: =+'2. 손익계산서'!O11 -> 0
C12: W/H | D12: =+'2. 손익계산서'!C12/1000000 -> 0 | E12: =+'2. 손익계산서'!D12 -> 0 | F12: =+'2. 손익계산서'!E12/1000000 -> 0 | G12: =+'2. 손익계산서'!F12/1000000 -> 0 | H12: =+'2. 손익계산서'!G12 -> 0 | I12: =+'2. 손익계산서'!H12/1000000 -> 0 | J12: =+'2. 손익계산서'!I12 -> 0 | K12: =+'2. 손익계산서'!J12/1000000 -> 0 | L12: =+IFERROR(K12/K7,) -> 0 | M12: =+'2. 손익계산서'!L12/1000000 -> 0 | N12: =+IFERROR(M12/M7,) -> 0 | O12: =+'2. 손익계산서'!N12 -> 0 | P12: =+'2. 손익계산서'!O12 -> 0 | R12: =(I9)*95%-(I14) -> 0 | S12: =+R12/(I14) -> #DIV/0! | T12: =K7-K12 -> 0 | U12: =M7-M12 -> 0 | W12: =+I7-I12 -> 0
C13: 상품 | D13: =+'2. 손익계산서'!C13/1000000 -> 5125.883 | E13: =+'2. 손익계산서'!D13 -> 0 | F13: =+'2. 손익계산서'!E13/1000000 -> 154.7585 | G13: =+'2. 손익계산서'!F13/1000000 -> 0 | H13: =+'2. 손익계산서'!G13 -> 0 | I13: =+'2. 손익계산서'!H13/1000000 -> 0 | J13: =+'2. 손익계산서'!I13 -> 0 | K13: =+'2. 손익계산서'!J13/1000000 -> 154.7585 | L13: =+IFERROR(K13/K8,) -> 0.5774377 | M13: =+'2. 손익계산서'!L13/1000000 -> 0 | N13: =+IFERROR(M13/M8,) -> 0 | O13: =+'2. 손익계산서'!N13 -> 0 | P13: =+'2. 손익계산서'!O13 -> 0 | R13: =(M9)*95%-(M14) -> 0 | S13: =+R13/(M14) -> #DIV/0! | T13: =K8-K13 -> 113.2505 | U13: =M8-M13 -> 0 | W13: =+I8-I13 -> 0
C14: 부품 | D14: =+'2. 손익계산서'!C14/1000000 -> 21403.973 | E14: =+'2. 손익계산서'!D14 -> 0 | F14: =+'2. 손익계산서'!E14/1000000 -> 1489.1561 | G14: =+'2. 손익계산서'!F14/1000000 -> 0 | H14: =+'2. 손익계산서'!G14 -> 0 | I14: =+'2. 손익계산서'!H14/1000000 -> 0 | J14: =+'2. 손익계산서'!I14 -> #DIV/0! | K14: =+'2. 손익계산서'!J14/1000000 -> 1489.1561 | L14: =+IFERROR(K14/K9,) -> 0.97078902 | M14: =+'2. 손익계산서'!L14/1000000 -> 0 | N14: =+IFERROR(M14/M9,) -> 0 | O14: =+'2. 손익계산서'!N14 -> 0 | P14: =+'2. 손익계산서'!O14 -> 0 | T14: =K9-K14 -> 44.808614 | U14: =M9-M14 -> 0 | W14: =+I9-I14 -> 0
C15: 기타 | D15: =+'2. 손익계산서'!C15/1000000 -> 14421.608 | E15: =+'2. 손익계산서'!D15 -> 0 | F15: =+'2. 손익계산서'!E15/1000000 -> 2.4275724 | G15: =+'2. 손익계산서'!F15/1000000 -> 0 | H15: =+'2. 손익계산서'!G15 -> 0 | I15: =+'2. 손익계산서'!H15/1000000 -> 0 | J15: =+'2. 손익계산서'!I15 -> #DIV/0! | K15: =+'2. 손익계산서'!J15/1000000 -> 2.4275724 | L15: =+IFERROR(K15/K10,) -> 0 | M15: =+'2. 손익계산서'!L15/1000000 -> 0 | N15: =+IFERROR(M15/M10,) -> 0 | O15: =+'2. 손익계산서'!N15 -> 0 | P15: =+'2. 손익계산서'!O15 -> 0 | T15: =K10-K15 -> -2.4275724 | U15: =M10-M15 -> 0 | V15: =+U15-T15 -> 2.4275724 | W15: =+I10-I15 -> 0 | X15: =+U15-W15 -> 0
C16: Ⅲ. 매출총이익 | D16: =+'2. 손익계산서'!C16/1000000 -> 6547.1122 | E16: =+'2. 손익계산서'!D16 -> 0 | F16: =+'2. 손익계산서'!E16/1000000 -> 155.63154 | G16: =+'2. 손익계산서'!F16/1000000 -> 0 | H16: =+'2. 손익계산서'!G16 -> 0 | I16: =+'2. 손익계산서'!H16/1000000 -> 0 | J16: =+'2. 손익계산서'!I16 -> 0 | K16: =+'2. 손익계산서'!J16/1000000 -> 155.63154 | L16: =+'2. 손익계산서'!K16 -> 0.086367264 | M16: =+'2. 손익계산서'!L16/1000000 -> 0 | N16: =+'2. 손익계산서'!M16 -> 0 | O16: =+'2. 손익계산서'!N16 -> - | P16: =+'2. 손익계산서'!O16 -> 0 | V16: 계획비 | X16: 전월비
C17: (이익률) | D17: =+'2. 손익계산서'!C17 -> 0.13783807 | F17: =+'2. 손익계산서'!E17 -> 0.086367264 | G17: =+'2. 손익계산서'!F17 -> 0 | I17: =+'2. 손익계산서'!H17 -> 0 | K17: =+'2. 손익계산서'!J17 -> 0.086367264 | M17: =+'2. 손익계산서'!L17 -> 0 | R17: 계획 | S17: =+M22-K22 -> 1212.2964
C18: Ⅳ.판매관리비 | D18: =+'2. 손익계산서'!C18/1000000 -> 16095.021 | E18: =+'2. 손익계산서'!D18 -> 0 | F18: =+'2. 손익계산서'!E18/1000000 -> 1367.928 | G18: =+'2. 손익계산서'!F18/1000000 -> 0 | H18: =+'2. 손익계산서'!G18 -> 0 | I18: =+'2. 손익계산서'!H18/1000000 -> 0 | J18: =+'2. 손익계산서'!I18 -> 0 | K18: =+'2. 손익계산서'!J18/1000000 -> 1367.928 | L18: =+'2. 손익계산서'!K18 -> 0.75912758 | M18: =+'2. 손익계산서'!L18/1000000 -> 0 | N18: =+'2. 손익계산서'!M18 -> 0 | O18: =+'2. 손익계산서'!N18 -> 0 | P18: =+'2. 손익계산서'!O18 -> 0 | R18: 전월 | S18: =+M22-I22 -> 0
C19: [판매비] | D19: =+'2. 손익계산서'!C19/1000000 -> 1617.6997 | E19: =+'2. 손익계산서'!D19 -> 0 | F19: =+'2. 손익계산서'!E19/1000000 -> 141.5064 | G19: =+'2. 손익계산서'!F19/1000000 -> 0 | H19: =+'2. 손익계산서'!G19 -> 0 | I19: =+'2. 손익계산서'!H19/1000000 -> 0 | J19: =+'2. 손익계산서'!I19 -> 0 | K19: =+'2. 손익계산서'!J19/1000000 -> 141.5064 | L19: =+'2. 손익계산서'!K19 -> 0.07852856 | M19: =+'2. 손익계산서'!L19/1000000 -> 0 | N19: =+'2. 손익계산서'!M19 -> 0 | O19: =+'2. 손익계산서'!N19 -> 0 | P19: =+'2. 손익계산서'!O19 -> 0
C20: [관리비] | D20: =+'2. 손익계산서'!C35/1000000 -> 8903.3639 | E20: =+'2. 손익계산서'!D35 -> 0 | F20: =+'2. 손익계산서'!E35/1000000 -> 731.65943 | G20: =+'2. 손익계산서'!F35/1000000 -> 0 | H20: =+'2. 손익계산서'!G35 -> 0 | I20: =+'2. 손익계산서'!H35/1000000 -> 0 | J20: =+'2. 손익계산서'!I35 -> 0 | K20: =+'2. 손익계산서'!J35/1000000 -> 731.65943 | L20: =+'2. 손익계산서'!K35 -> 0.40603224 | M20: =+'2. 손익계산서'!L35/1000000 -> 0 | N20: =+'2. 손익계산서'!M35 -> 0 | O20: =+'2. 손익계산서'!N35 -> 0 | P20: =+'2. 손익계산서'!O35 -> 0
C21: [연구개발비] | D21: =+'2. 손익계산서'!C53/1000000 -> 5573.9576 | E21: =+'2. 손익계산서'!D53 -> 0 | F21: =+'2. 손익계산서'!E53/1000000 -> 494.76213 | G21: =+'2. 손익계산서'!F53/1000000 -> 0 | H21: =+'2. 손익계산서'!G53 -> 0 | I21: =+'2. 손익계산서'!H53/1000000 -> 0 | J21: =+'2. 손익계산서'!I53 -> 0 | K21: =+'2. 손익계산서'!J53/1000000 -> 494.76213 | L21: =+'2. 손익계산서'!K53 -> 0.27456678 | M21: =+'2. 손익계산서'!L53/1000000 -> 0 | N21: =+'2. 손익계산서'!M53 -> 0 | O21: =+'2. 손익계산서'!N53 -> 0 | P21: =+'2. 손익계산서'!O53 -> 0 | R21: 인건비
C22: Ⅴ.영업이익 | D22: =+'2. 손익계산서'!C68/1000000 -> -9547.9091 | F22: =+'2. 손익계산서'!E68/1000000 -> -1212.2964 | G22: =+'2. 손익계산서'!F68/1000000 -> 0 | I22: =+'2. 손익계산서'!H68/1000000 -> 0 | J22: =+'2. 손익계산서'!I68 -> 0 | K22: =+'2. 손익계산서'!J68/1000000 -> -1212.2964 | L22: =+'2. 손익계산서'!K68 -> -0.67276031 | M22: =+'2. 손익계산서'!L68/1000000 -> 0 | N22: =+'2. 손익계산서'!M68 -> 0 | O22: =+'2. 손익계산서'!N68 -> - | P22: =+'2. 손익계산서'!O68 -> - | R22: 해외출장비 | Z22: =M22-K22 -> 1212.2964 | AA22: =M22-I22 -> 0
C23: (이익률) | D23: =+'2. 손익계산서'!C69 -> -0.20101464 | F23: =+'2. 손익계산서'!E69 -> -0.67276031 | G23: =+'2. 손익계산서'!F69 -> 0 | I23: =+'2. 손익계산서'!H69 -> 0 | K23: =+'2. 손익계산서'!J69 -> -0.67276031 | M23: =+'2. 손익계산서'!L69 -> 0 | R23: 시험/평가비
R24: 용역
C25: 구 분 | D25: 2025년 계 획 | E25: 년계획 진척률 | F25: 누 계 계 획 | G25: 누계 실적 | H25: 달성률 | I25: 전 월 실 적 | J25: 원 가 구성비 | K25: 당 월 계 획 | L25: 원 가 구성비 | M25: 당 월 실 적 | N25: 원 가 구성비 | O25: 전 월 대 비 | P25: 계 획 대 비
C26: Ⅰ. 재료비
C27: Ⅱ. 노무비
C28: Ⅲ. 경비
C29: Ⅳ. 당기총제조비용
C30: Ⅴ. 당기제품제조원가
C31: ▣ 관리지표
C32: 항공운송비
C33: 컨테이너 효율
C34: 품질비용(대체출고) | D34: - | I34: 3.2 | K34: - | M34: 3.2
C35: ▣ 당월 주요 손익증감 내역
C36: - 해외법인 부품 C/C | D36: -
C37: - 제품폐기 | D37: -
C38: - 기타매출 이익 | D38: - | I38: =I10-I15 -> 0 | K38: =+K10-K15 -> -2.4275724 | M38: =+M10-M15 -> 0
C39: - 운반비 | D39: - | I39: ='2. 손익계산서'!H24/1000000 -> 0 | M39: ='2. 손익계산서'!L24/1000000 -> 0

Sheet 2. 손익계산서
B3: Plofit and Loss statement FY 2026
B4: MONTH | C4: 1 | O4: (단위:원)
B5: 구 분 | C5: 2026년 계 획 | D5: 년계획 진척률 | E5: 누 계 계 획 | F5: 누 계 실 적 | G5: 달성률 | H5: 전 월 실 적 | I5: 매 출 구성비 | J5: 당 월 계 획 | K5: 매 출 구성비 | L5: 당 월 실 적 | M5: 매 출 구성비 | N5: 전 월 대 비 | O5: 계 획 대 비
B6: Ⅰ. 매출액 | C6: =+'(계획)손익계산서 월별계획'!C6 -> 4.7498576e+10 | D6: =+IFERROR(F6/C6,) -> 0 | E6: =SUM(E7:E10) -> 1.8019737e+09 | F6: =SUM(F7:F10) -> 0 | G6: =+IFERROR(F6/E6,) -> 0 | H6: =SUM(H7:H10) -> 0 | I6: =+IFERROR(H6/$H$6,) -> 0 | J6: =SUM(J7:J10) -> 1.8019737e+09 | K6: =+IFERROR(J6/$J$6,) -> 1 | L6: =SUM(L7:L10) -> 0 | M6: =+IFERROR(L6/$L$6,) -> 0 | N6: =+IFERROR(L6/H6,) -> 0 | O6: =+IFERROR(L6/J6,) -> 0 | Q6: 당월실적 | S6: 당월계획 | U6: 전월실적
B7: W/H | C7: =+'(계획)손익계산서 월별계획'!C7 -> 0 | D7: =+IFERROR(F7/C7,) -> 0 | E7: =SUM('(계획)손익계산서 월별계획'!E7:OFFSET('(계획)손익계산서 월별계획'!E7,0,$C$4-1)) -> 0 | F7: =SUM('3. 손익계산서 월별실적'!E7:OFFSET('3. 손익계산서 월별실적'!E7,0,$C$4-1)) -> 0 | G7: =+IFERROR(F7/E7,) -> 0 | H7: =OFFSET('3. 손익계산서 월별실적'!E7,0,$C$4-2) -> 0 | I7: =+IFERROR(H7/$H$6,) -> 0 | J7: =OFFSET('(계획)손익계산서 월별계획'!E7,0,$C$4-1) -> 0 | K7: =+IFERROR(J7/$J$6,) -> 0 | L7: =OFFSET('3. 손익계산서 월별실적'!E7,0,$C$4-1) -> 0 | M7: =+IFERROR(L7/$L$6,) -> 0 | N7: =+IFERROR(L7/H7,) -> 0 | O7: =+IFERROR(L7/J7,) -> 0 | S7: =+Q8-S8 -> -113250500 | U7: =+Q8-U8 -> 0
B8: 상품 | C8: =+'(계획)손익계산서 월별계획'!C8 -> 9059168350 | D8: =+IFERROR(F8/C8,) -> 0 | E8: =SUM('(계획)손익계산서 월별계획'!E8:OFFSET('(계획)손익계산서 월별계획'!E8,0,$C$4-1)) -> 268009000 | F8: =SUM('3. 손익계산서 월별실적'!E8:OFFSET('3. 손익계산서 월별실적'!E8,0,$C$4-1)) -> 0 | G8: =+IFERROR(F8/E8,) -> 0 | H8: =OFFSET('3. 손익계산서 월별실적'!E8,0,$C$4-2) -> 0 | I8: =+IFERROR(H8/$H$6,) -> 0 | J8: =OFFSET('(계획)손익계산서 월별계획'!E8,0,$C$4-1) -> 268009000 | K8: =+IFERROR(J8/$J$6,) -> 0.1487308 | L8: =OFFSET('3. 손익계산서 월별실적'!E8,0,$C$4-1) -> 0 | M8: =+IFERROR(L8/$L$6,) -> 0 | N8: =+IFERROR(L8/H8,) -> 0 | O8: =+IFERROR(L8/J8,) -> 0 | Q8: =+L8-L13 -> 0 | R8: =+Q8/L8 -> #DIV/0! | S8: =+J8-J13 -> 113250500 | T8: =+S8/J8 -> 0.4225623 | U8: =+H8-H13 -> 0 | V8: =+U8/H8 -> #DIV/0!
B9: 부품 | C9: =+'(계획)손익계산서 월별계획'!C9 -> 2.204985e+10 | D9: =+IFERROR(F9/C9,) -> 0 | E9: =SUM('(계획)손익계산서 월별계획'!E9:OFFSET('(계획)손익계산서 월별계획'!E9,0,$C$4-1)) -> 1.5339647e+09 | F9: =SUM('3. 손익계산서 월별실적'!E9:OFFSET('3. 손익계산서 월별실적'!E9,0,$C$4-1)) -> 0 | G9: =+IFERROR(F9/E9,) -> 0 | H9: =OFFSET('3. 손익계산서 월별실적'!E9,0,$C$4-2) -> 0 | I9: =+IFERROR(H9/$H$6,) -> 0 | J9: =OFFSET('(계획)손익계산서 월별계획'!E9,0,$C$4-1) -> 1.5339647e+09 | K9: =+IFERROR(J9/$J$6,) -> 0.8512692 | L9: =OFFSET('3. 손익계산서 월별실적'!E9,0,$C$4-1) -> 0 | M9: =+IFERROR(L9/$L$6,) -> 0 | N9: =+IFERROR(L9/H9,) -> 0 | O9: =+IFERROR(L9/J9,) -> 0 | Q9: =+L9-L14 -> 0 | R9: =+Q9/L9 -> #DIV/0! | S9: =+J9-J14 -> 44808614 | T9: =+S9/J9 -> 0.02921098 | U9: =+H9-H14 -> 0 | V9: =+U9/H9 -> #DIV/0!
B10: 기타 | C10: =+'(계획)손익계산서 월별계획'!C10 -> 16389558229 | D10: =+IFERROR(F10/C10,) -> 0 | E10: =SUM('(계획)손익계산서 월별계획'!E10:OFFSET('(계획)손익계산서 월별계획'!E10,0,$C$4-1)) -> 0 | F10: =SUM('3. 손익계산서 월별실적'!E10:OFFSET('3. 손익계산서 월별실적'!E10,0,$C$4-1)) -> 0 | G10: =+IFERROR(F10/E10,) -> 0 | H10: =OFFSET('3. 손익계산서 월별실적'!E10,0,$C$4-2) -> 0 | I10: =+IFERROR(H10/$H$6,) -> 0 | J10: =OFFSET('(계획)손익계산서 월별계획'!E10,0,$C$4-1) -> 0 | K10: =+IFERROR(J10/$J$6,) -> 0 | L10: =OFFSET('3. 손익계산서 월별실적'!E10,0,$C$4-1) -> 0 | M10: =+IFERROR(L10/$L$6,) -> 0 | N10: =+IFERROR(L10/H10,) -> 0 | O10: =+IFERROR(L10/J10,) -> 0 | Q10: =+L10-L15 -> 0 | R10: =+Q10/L10 -> #DIV/0! | S10: =+J10-J15 -> -2427572.4 | T10: =+S10/J10 -> #DIV/0! | U10: =+H10-H15 -> 0 | V10: =+U10/H10 -> #DIV/0!
B11: Ⅱ. 매출원가 | C11: =+'(계획)손익계산서 월별계획'!C11 -> 4.0951464e+10 | D11: =+IFERROR(F11/C11,) -> 0 | E11: =SUM(E12:E15) -> 1.6463422e+09 | F11: =SUM(F12:F15) -> 0 | G11: =+IFERROR(F11/E11,) -> 0 | H11: =SUM(H12:H15) -> 0 | I11: =+IFERROR(H11/$H$6,) -> 0 | J11: =SUM(J12:J15) -> 1.6463422e+09 | K11: =+IFERROR(J11/$J$6,) -> 0.91363274 | L11: =SUM(L12:L15) -> 0 | M11: =+IFERROR(L11/$L$6,) -> 0 | N11: =+IFERROR(L11/H11,) -> 0 | O11: =+IFERROR(L11/J11,) -> 0 | S11: =+Q10-S10 -> 2427572.4 | U11: =+Q10-U10 -> 0
B12: W/H | C12: =+'(계획)손익계산서 월별계획'!C12 -> 0 | D12: =+IFERROR(F12/C12,) -> 0 | E12: =SUM('(계획)손익계산서 월별계획'!E12:OFFSET('(계획)손익계산서 월별계획'!E12,0,$C$4-1)) -> 0 | F12: =SUM('3. 손익계산서 월별실적'!E12:OFFSET('3. 손익계산서 월별실적'!E12,0,$C$4-1)) -> 0 | G12: =+IFERROR(F12/E12,) -> 0 | H12: =OFFSET('3. 손익계산서 월별실적'!E12,0,$C$4-2) -> 0 | I12: =IFERROR(H12/H7,0) -> 0 | J12: =OFFSET('(계획)손익계산서 월별계획'!E12,0,$C$4-1) -> 0 | K12: =IFERROR(J12/J7,0) -> 0 | L12: =OFFSET('3. 손익계산서 월별실적'!E12,0,$C$4-1) -> 0 | M12: =IFERROR(L12/L7,0) -> 0 | N12: =+IFERROR(L12/H12,) -> 0 | O12: =+IFERROR(L12/J12,) -> 0
B13: 상품 | C13: =+'(계획)손익계산서 월별계획'!C13 -> 5125883039 | D13: =+IFERROR(F13/C13,) -> 0 | E13: =SUM('(계획)손익계산서 월별계획'!E13:OFFSET('(계획)손익계산서 월별계획'!E13,0,$C$4-1)) -> 154758500 | F13: =SUM('3. 손익계산서 월별실적'!E13:OFFSET('3. 손익계산서 월별실적'!E13,0,$C$4-1)) -> 0 | G13: =+IFERROR(F13/E13,) -> 0 | H13: =OFFSET('3. 손익계산서 월별실적'!E13,0,$C$4-2) -> 0 | I13: =IFERROR(H13/H8,0) -> 0 | J13: =OFFSET('(계획)손익계산서 월별계획'!E13,0,$C$4-1) -> 154758500 | K13: =+J13/J8 -> 0.5774377 | L13: =OFFSET('3. 손익계산서 월별실적'!E13,0,$C$4-1) -> 0 | M13: =IFERROR(L13/L8,0) -> 0 | N13: =+IFERROR(L13/H13,) -> 0 | O13: =+IFERROR(L13/J13,) -> 0
B14: 부품 | C14: =+'(계획)손익계산서 월별계획'!C14 -> 2.1403973e+10 | D14: =+IFERROR(F14/C14,) -> 0 | E14: =SUM('(계획)손익계산서 월별계획'!E14:OFFSET('(계획)손익계산서 월별계획'!E14,0,$C$4-1)) -> 1.4891561e+09 | F14: =SUM('3. 손익계산서 월별실적'!E14:OFFSET('3. 손익계산서 월별실적'!E14,0,$C$4-1)) -> 0 | G14: =+IFERROR(F14/E14,) -> 0 | H14: =OFFSET('3. 손익계산서 월별실적'!E14,0,$C$4-2) -> 0 | I14: =+H14/H9 -> #DIV/0! | J14: =OFFSET('(계획)손익계산서 월별계획'!E14,0,$C$4-1) -> 1.4891561e+09 | K14: =+J14/J9 -> 0.97078902 | L14: =OFFSET('3. 손익계산서 월별실적'!E14,0,$C$4-1) -> 0 | M14: =+L14/L9 -> #DIV/0! | N14: =+IFERROR(L14/H14,) -> 0 | O14: =+IFERROR(L14/J14,) -> 0
B15: 기타 | C15: =+'(계획)손익계산서 월별계획'!C15 -> 1.4421608e+10 | D15: =+IFERROR(F15/C15,) -> 0 | E15: =SUM('(계획)손익계산서 월별계획'!E15:OFFSET('(계획)손익계산서 월별계획'!E15,0,$C$4-1)) -> 2427572.4 | F15: =SUM('3. 손익계산서 월별실적'!E15:OFFSET('3. 손익계산서 월별실적'!E15,0,$C$4-1)) -> 0 | G15: =+IFERROR(F15/E15,) -> 0 | H15: =OFFSET('3. 손익계산서 월별실적'!E15,0,$C$4-2) -> 0 | I15: =+H15/H10 -> #DIV/0! | J15: =OFFSET('(계획)손익계산서 월별계획'!E15,0,$C$4-1) -> 2427572.4 | K15: =+J15/J10 -> #DIV/0! | L15: =OFFSET('3. 손익계산서 월별실적'!E15,0,$C$4-1) -> 0 | M15: =+L15/L10 -> #DIV/0! | N15: =+IFERROR(L15/H15,) -> 0 | O15: =+IFERROR(L15/J15,) -> 0
B16: Ⅲ. 매출총이익 | C16: =+'(계획)손익계산서 월별계획'!C16 -> 6.5471122e+09 | D16: =+IFERROR(F16/C16,) -> 0 | E16: =+E6-E11 -> 1.5563154e+08 | F16: =+F6-F11 -> 0 | G16: =+IFERROR(F16/E16,) -> 0 | H16: =+H6-H11 -> 0 | I16: =+IFERROR(H16/$H$6,) -> 0 | J16: =+J6-J11 -> 1.5563154e+08 | K16: =+IFERROR(J16/$J$6,) -> 0.086367264 | L16: =+L6-L11 -> 0 | M16: =+IFERROR(L16/$L$6,) -> 0 | N16: =+IF(AND(H16>0,L16>0),L16/H16,"-") -> - | O16: =+IF(AND(J16>0,N16>0),L16/J16,"-") -> 0
B17: (이익률) | C17: =+'(계획)손익계산서 월별계획'!C17 -> 0.13783807 | E17: =+IFERROR(E16/E6,) -> 0.086367264 | F17: =+IFERROR(F16/F6,) -> 0 | H17: =+IFERROR(H16/H6,) -> 0 | J17: =+IFERROR(J16/J6,) -> 0.086367264 | L17: =+IFERROR(L16/L6,) -> 0
B18: Ⅳ.판매관리비 | C18: =+'(계획)손익계산서 월별계획'!C18 -> 1.6095021e+10 | D18: =+IFERROR(F18/C18,) -> 0 | E18: =+E19+E35+E53 -> 1.367928e+09 | F18: =+F19+F35+F53 -> 0 | G18: =+IFERROR(F18/E18,) -> 0 | H18: =+H19+H35+H53 -> 0 | I18: =+IFERROR(H18/$L$6,) -> 0 | J18: =+J19+J35+J53 -> 1.367928e+09 | K18: =+IFERROR(J18/$J$6,) -> 0.75912758 | L18: =+L19+L35+L53 -> 0 | M18: =+IFERROR(L18/$L$6,) -> 0 | N18: =+IFERROR(L18/H18,) -> 0 | O18: =+IFERROR(L18/J18,) -> 0 | Q18: =+L18-J18 -> -1.367928e+09 | R18: =+L18-H18 -> 0
B19: [판매비] | C19: =+'(계획)손익계산서 월별계획'!C19 -> 1.6176997e+09 | D19: =+IFERROR(F19/C19,) -> 0 | E19: =SUM(E20:E34) -> 1.415064e+08 | F19: =SUM(F20:F34) -> 0 | G19: =+IFERROR(F19/E19,) -> 0 | H19: =SUM(H20:H34) -> 0 | I19: =+IFERROR(H19/$H$6,) -> 0 | J19: =SUM(J20:J34) -> 1.415064e+08 | K19: =+IFERROR(J19/$J$6,) -> 0.07852856 | L19: =SUM(L20:L34) -> 0 | M19: =+IFERROR(L19/$L$6,) -> 0 | N19: =+IFERROR(L19/H19,) -> 0 | O19: =+IFERROR(L19/J19,) -> 0 | R19: 누계 계획 | S19: 누계 실적
B20: 인건비 | C20: =+'(계획)손익계산서 월별계획'!C20 -> 7.1526467e+08 | D20: =+IFERROR(F20/C20,) -> 0 | E20: =SUM('(계획)손익계산서 월별계획'!E20:OFFSET('(계획)손익계산서 월별계획'!E20,0,$C$4-1)) -> 56724044 | F20: =SUM('3. 손익계산서 월별실적'!E20:OFFSET('3. 손익계산서 월별실적'!E20,0,$C$4-1)) -> 0 | G20: =+IFERROR(F20/E20,) -> 0 | H20: =OFFSET('3. 손익계산서 월별실적'!E20,0,$C$4-2) -> 0 | I20: =+IFERROR(H20/$H$6,) -> 0 | J20: =OFFSET('(계획)손익계산서 월별계획'!E20,0,$C$4-1) -> 56724044 | K20: =+IFERROR(J20/$J$6,) -> 0.03147884 | L20: =OFFSET('3. 손익계산서 월별실적'!E20,0,$C$4-1) -> 0 | M20: =+IFERROR(L20/$L$6,) -> 0 | N20: =+IFERROR(L20/H20,) -> 0 | O20: =+IFERROR(L20/J20,) -> 0 | Q20: 인건비 | R20: =+E20+E36+E54 -> 6.9951538e+08 | S20: =+F20+F36+F54 -> 0 | T20: =+S20/R20 -> 0
B21: 유지비용 | C21: =+'(계획)손익계산서 월별계획'!C21 -> 12041448 | D21: =+IFERROR(F21/C21,) -> 0 | E21: =SUM('(계획)손익계산서 월별계획'!E21:OFFSET('(계획)손익계산서 월별계획'!E21,0,$C$4-1)) -> 1003454 | F21: =SUM('3. 손익계산서 월별실적'!E21:OFFSET('3. 손익계산서 월별실적'!E21,0,$C$4-1)) -> 0 | G21: =+IFERROR(F21/E21,) -> 0 | H21: =OFFSET('3. 손익계산서 월별실적'!E21,0,$C$4-2) -> 0 | I21: =+IFERROR(H21/$H$6,) -> 0 | J21: =OFFSET('(계획)손익계산서 월별계획'!E21,0,$C$4-1) -> 1003454 | K21: =+IFERROR(J21/$J$6,) -> 0.00055686383 | L21: =OFFSET('3. 손익계산서 월별실적'!E21,0,$C$4-1) -> 0 | M21: =+IFERROR(L21/$L$6,) -> 0 | N21: =+IFERROR(L21/H21,) -> 0 | O21: =+IFERROR(L21/J21,) -> 0 | Q21: 지급수수료비 | R21: =SUM(E27,E43,E61) -> 1.6637885e+08 | S21: =SUM(F27,F43,F61) -> 0 | T21: =+S21/R21 -> 0
B22: 세금,보험 | C22: =+'(계획)손익계산서 월별계획'!C22 -> 60201580 | D22: =+IFERROR(F22/C22,) -> 0 | E22: =SUM('(계획)손익계산서 월별계획'!E22:OFFSET('(계획)손익계산서 월별계획'!E22,0,$C$4-1)) -> 4668588 | F22: =SUM('3. 손익계산서 월별실적'!E22:OFFSET('3. 손익계산서 월별실적'!E22,0,$C$4-1)) -> 0 | G22: =+IFERROR(F22/E22,) -> 0 | H22: =OFFSET('3. 손익계산서 월별실적'!E22,0,$C$4-2) -> 0 | I22: =+IFERROR(H22/$H$6,) -> 0 | J22: =OFFSET('(계획)손익계산서 월별계획'!E22,0,$C$4-1) -> 4668588 | K22: =+IFERROR(J22/$J$6,) -> 0.0025908191 | L22: =OFFSET('3. 손익계산서 월별실적'!E22,0,$C$4-1) -> 0 | M22: =+IFERROR(L22/$L$6,) -> 0 | N22: =+IFERROR(L22/H22,) -> 0 | O22: =+IFERROR(L22/J22,) -> 0 | Q22: 개발비 | R22: =SUM(E30,E46,E64) -> 165990000 | S22: =SUM(F30,F46,F64) -> 0 | T22: =+S22/R22 -> 0
B23: 복리후생비 | C23: =+'(계획)손익계산서 월별계획'!C23 -> 60289269 | D23: =+IFERROR(F23/C23,) -> 0 | E23: =SUM('(계획)손익계산서 월별계획'!E23:OFFSET('(계획)손익계산서 월별계획'!E23,0,$C$4-1)) -> 2095697.4 | F23: =SUM('3. 손익계산서 월별실적'!E23:OFFSET('3. 손익계산서 월별실적'!E23,0,$C$4-1)) -> 0 | G23: =+IFERROR(F23/E23,) -> 0 | H23: =OFFSET('3. 손익계산서 월별실적'!E23,0,$C$4-2) -> 0 | I23: =+IFERROR(H23/$H$6,) -> 0 | J23: =OFFSET('(계획)손익계산서 월별계획'!E23,0,$C$4-1) -> 2095697.4 | K23: =+IFERROR(J23/$J$6,) -> 0.0011630011 | L23: =OFFSET('3. 손익계산서 월별실적'!E23,0,$C$4-1) -> 0 | M23: =+IFERROR(L23/$L$6,) -> 0 | N23: =+IFERROR(L23/H23,) -> 0 | O23: =+IFERROR(L23/J23,) -> 0
B24: 운반비 | C24: =+'(계획)손익계산서 월별계획'!C24 -> 6.2254697e+08 | D24: =+IFERROR(F24/C24,) -> 0 | E24: =SUM('(계획)손익계산서 월별계획'!E24:OFFSET('(계획)손익계산서 월별계획'!E24,0,$C$4-1)) -> 64761640 | F24: =SUM('3. 손익계산서 월별실적'!E24:OFFSET('3. 손익계산서 월별실적'!E24,0,$C$4-1)) -> 0 | G24: =+IFERROR(F24/E24,) -> 0 | H24: =OFFSET('3. 손익계산서 월별실적'!E24,0,$C$4-2) -> 0 | I24: =+IFERROR(H24/$H$6,) -> 0 | J24: =OFFSET('(계획)손익계산서 월별계획'!E24,0,$C$4-1) -> 64761640 | K24: =+IFERROR(J24/$J$6,) -> 0.035939281 | L24: =OFFSET('3. 손익계산서 월별실적'!E24,0,$C$4-1) -> 0 | M24: =+IFERROR(L24/$L$6,) -> 0 | N24: =+IFERROR(L24/H24,) -> 0 | O24: =+IFERROR(L24/J24,) -> 0
B25: 포장비 | C25: =+'(계획)손익계산서 월별계획'!C25 -> 0 | D25: =+IFERROR(F25/C25,) -> 0 | E25: =SUM('(계획)손익계산서 월별계획'!E25:OFFSET('(계획)손익계산서 월별계획'!E25,0,$C$4-1)) -> 0 | F25: =SUM('3. 손익계산서 월별실적'!E25:OFFSET('3. 손익계산서 월별실적'!E25,0,$C$4-1)) -> 0 | G25: =+IFERROR(F25/E25,) -> 0 | H25: =OFFSET('3. 손익계산서 월별실적'!E25,0,$C$4-2) -> 0 | I25: =+IFERROR(H25/$H$6,) -> 0 | J25: =OFFSET('(계획)손익계산서 월별계획'!E25,0,$C$4-1) -> 0 | K25: =+IFERROR(J25/$J$6,) -> 0 | L25: =OFFSET('3. 손익계산서 월별실적'!E25,0,$C$4-1) -> 0 | M25: =+IFERROR(L25/$L$6,) -> 0 | N25: =+IFERROR(L25/H25,) -> 0 | O25: =+IFERROR(L25/J25,) -> 0
B26: 광고선전비 | C26: =+'(계획)손익계산서 월별계획'!C26 -> 0 | D26: =+IFERROR(F26/C26,) -> 0 | E26: =SUM('(계획)손익계산서 월별계획'!E26:OFFSET('(계획)손익계산서 월별계획'!E26,0,$C$4-1)) -> 0 | F26: =SUM('3. 손익계산서 월별실적'!E26:OFFSET('3. 손익계산서 월별실적'!E26,0,$C$4-1)) -> 0 | G26: =+IFERROR(F26/E26,) -> 0 | H26: =OFFSET('3. 손익계산서 월별실적'!E26,0,$C$4-2) -> 0 | I26: =+IFERROR(H26/$H$6,) -> 0 | J26: =OFFSET('(계획)손익계산서 월별계획'!E26,0,$C$4-1) -> 0 | K26: =+IFERROR(J26/$J$6,) -> 0 | L26: =OFFSET('3. 손익계산서 월별실적'!E26,0,$C$4-1) -> 0 | M26: =+IFERROR(L26/$L$6,) -> 0 | N26: =+IFERROR(L26/H26,) -> 0 | O26: =+IFERROR(L26/J26,) -> 0
B27: 지급수수료 | C27: =+'(계획)손익계산서 월별계획'!C27 -> 2304000 | D27: =+IFERROR(F27/C27,) -> 0 | E27: =SUM('(계획)손익계산서 월별계획'!E27:OFFSET('(계획)손익계산서 월별계획'!E27,0,$C$4-1)) -> 192000 | F27: =SUM('3. 손익계산서 월별실적'!E27:OFFSET('3. 손익계산서 월별실적'!E27,0,$C$4-1)) -> 0 | G27: =+IFERROR(F27/E27,) -> 0 | H27: =OFFSET('3. 손익계산서 월별실적'!E27,0,$C$4-2) -> 0 | I27: =+IFERROR(H27/$H$6,) -> 0 | J27: =OFFSET('(계획)손익계산서 월별계획'!E27,0,$C$4-1) -> 192000 | K27: =+IFERROR(J27/$J$6,) -> 0.00010654983 | L27: =OFFSET('3. 손익계산서 월별실적'!E27,0,$C$4-1) -> 0 | M27: =+IFERROR(L27/$L$6,) -> 0 | N27: =+IFERROR(L27/H27,) -> 0 | O27: =+IFERROR(L27/J27,) -> 0
B28: 여비교통비 | C28: =+'(계획)손익계산서 월별계획'!C28 -> 1.17625e+08 | D28: =+IFERROR(F28/C28,) -> 0 | E28: =SUM('(계획)손익계산서 월별계획'!E28:OFFSET('(계획)손익계산서 월별계획'!E28,0,$C$4-1)) -> 9802083.3 | F28: =SUM('3. 손익계산서 월별실적'!E28:OFFSET('3. 손익계산서 월별실적'!E28,0,$C$4-1)) -> 0 | G28: =+IFERROR(F28/E28,) -> 0 | H28: =OFFSET('3. 손익계산서 월별실적'!E28,0,$C$4-2) -> 0 | I28: =+IFERROR(H28/$H$6,) -> 0 | J28: =OFFSET('(계획)손익계산서 월별계획'!E28,0,$C$4-1) -> 9802083.3 | K28: =+IFERROR(J28/$J$6,) -> 0.0054396372 | L28: =OFFSET('3. 손익계산서 월별실적'!E28,0,$C$4-1) -> 0 | M28: =+IFERROR(L28/$L$6,) -> 0 | N28: =+IFERROR(L28/H28,) -> 0 | O28: =+IFERROR(L28/J28,) -> 0
B29: 감가상각비 | C29: =+'(계획)손익계산서 월별계획'!C29 -> 0 | D29: =+IFERROR(F29/C29,) -> 0 | E29: =SUM('(계획)손익계산서 월별계획'!E29:OFFSET('(계획)손익계산서 월별계획'!E29,0,$C$4-1)) -> 0 | F29: =SUM('3. 손익계산서 월별실적'!E29:OFFSET('3. 손익계산서 월별실적'!E29,0,$C$4-1)) -> 0 | G29: =+IFERROR(F29/E29,) -> 0 | H29: =OFFSET('3. 손익계산서 월별실적'!E29,0,$C$4-2) -> 0 | I29: =+IFERROR(H29/$H$6,) -> 0 | J29: =OFFSET('(계획)손익계산서 월별계획'!E29,0,$C$4-1) -> 0 | K29: =+IFERROR(J29/$J$6,) -> 0 | L29: =OFFSET('3. 손익계산서 월별실적'!E29,0,$C$4-1) -> 0 | M29: =+IFERROR(L29/$L$6,) -> 0 | N29: =+IFERROR(L29/H29,) -> 0 | O29: =+IFERROR(L29/J29,) -> 0
B30: 개발비 | C30: =+'(계획)손익계산서 월별계획'!C30 -> 0 | D30: =+IFERROR(F30/C30,) -> 0 | E30: =SUM('(계획)손익계산서 월별계획'!E30:OFFSET('(계획)손익계산서 월별계획'!E30,0,$C$4-1)) -> 0 | F30: =SUM('3. 손익계산서 월별실적'!E30:OFFSET('3. 손익계산서 월별실적'!E30,0,$C$4-1)) -> 0 | G30: =+IFERROR(F30/E30,) -> 0 | H30: =OFFSET('3. 손익계산서 월별실적'!E30,0,$C$4-2) -> 0 | I30: =+IFERROR(H30/$H$6,) -> 0 | J30: =OFFSET('(계획)손익계산서 월별계획'!E30,0,$C$4-1) -> 0 | K30: =+IFERROR(J30/$J$6,) -> 0 | L30: =OFFSET('3. 손익계산서 월별실적'!E30,0,$C$4-1) -> 0 | M30: =+IFERROR(L30/$L$6,) -> 0 | N30: =+IFERROR(L30/H30,) -> 0 | O30: =+IFERROR(L30/J30,) -> 0
B31: 충당비용 | C31: =+'(계획)손익계산서 월별계획'!C31 -> 0 | D31: =+IFERROR(F31/C31,) -> 0 | E31: =SUM('(계획)손익계산서 월별계획'!E31:OFFSET('(계획)손익계산서 월별계획'!E31,0,$C$4-1)) -> 0 | F31: =SUM('3. 손익계산서 월별실적'!E31:OFFSET('3. 손익계산서 월별실적'!E31,0,$C$4-1)) -> 0 | G31: =+IFERROR(F31/E31,) -> 0 | H31: =OFFSET('3. 손익계산서 월별실적'!E31,0,$C$4-2) -> 0 | I31: =+IFERROR(H31/$H$6,) -> 0 | J31: =OFFSET('(계획)손익계산서 월별계획'!E31,0,$C$4-1) -> 0 | K31: =+IFERROR(J31/$J$6,) -> 0 | L31: =OFFSET('3. 손익계산서 월별실적'!E31,0,$C$4-1) -> 0 | M31: =+IFERROR(L31/$L$6,) -> 0 | N31: =+IFERROR(L31/H31,) -> 0 | O31: =+IFERROR(L31/J31,) -> 0
B32: 외주비 | C32: =+'(계획)손익계산서 월별계획'!C32 -> 0 | D32: =+IFERROR(F32/C32,) -> 0 | E32: =SUM('(계획)손익계산서 월별계획'!E32:OFFSET('(계획)손익계산서 월별계획'!E32,0,$C$4-1)) -> 0 | F32: =SUM('3. 손익계산서 월별실적'!E32:OFFSET('3. 손익계산서 월별실적'!E32,0,$C$4-1)) -> 0 | G32: =+IFERROR(F32/E32,) -> 0 | H32: =OFFSET('3. 손익계산서 월별실적'!E32,0,$C$4-2) -> 0 | I32: =+IFERROR(H32/$H$6,) -> 0 | J32: =OFFSET('(계획)손익계산서 월별계획'!E32,0,$C$4-1) -> 0 | K32: =+IFERROR(J32/$J$6,) -> 0 | L32: =OFFSET('3. 손익계산서 월별실적'!E32,0,$C$4-1) -> 0 | M32: =+IFERROR(L32/$L$6,) -> 0 | N32: =+IFERROR(L32/H32,) -> 0 | O32: =+IFERROR(L32/J32,) -> 0
B33: 기타비용 | C33: =+'(계획)손익계산서 월별계획'!C33 -> 27426755 | D33: =+IFERROR(F33/C33,) -> 0 | E33: =SUM('(계획)손익계산서 월별계획'!E33:OFFSET('(계획)손익계산서 월별계획'!E33,0,$C$4-1)) -> 2258896.2 | F33: =SUM('3. 손익계산서 월별실적'!E33:OFFSET('3. 손익계산서 월별실적'!E33,0,$C$4-1)) -> 0 | G33: =+IFERROR(F33/E33,) -> 0 | H33: =OFFSET('3. 손익계산서 월별실적'!E33,0,$C$4-2) -> 0 | I33: =+IFERROR(H33/$H$6,) -> 0 | J33: =OFFSET('(계획)손익계산서 월별계획'!E33,0,$C$4-1) -> 2258896.2 | K33: =+IFERROR(J33/$J$6,) -> 0.0012535678 | L33: =OFFSET('3. 손익계산서 월별실적'!E33,0,$C$4-1) -> 0 | M33: =+IFERROR(L33/$L$6,) -> 0 | N33: =+IFERROR(L33/H33,) -> 0 | O33: =+IFERROR(L33/J33,) -> 0
B35: [관리비] | C35: =+'(계획)손익계산서 월별계획'!C35 -> 8.9033639e+09 | D35: =+IFERROR(F35/C35,) -> 0 | E35: =SUM(E36:E51) -> 7.3165943e+08 | F35: =SUM(F36:F51) -> 0 | G35: =+IFERROR(F35/E35,) -> 0 | H35: =SUM(H36:H51) -> 0 | I35: =+IFERROR(H35/$H$6,) -> 0 | J35: =SUM(J36:J51) -> 7.3165943e+08 | K35: =+IFERROR(J35/$J$6,) -> 0.40603224 | L35: =SUM(L36:L51) -> 0 | M35: =+IFERROR(L35/$L$6,) -> 0 | N35: =+IFERROR(L35/H35,) -> 0 | O35: =+IFERROR(L35/J35,) -> 0
B36: 인건비 | C36: =+'(계획)손익계산서 월별계획'!C36 -> 5.1840452e+09 | D36: =+IFERROR(F36/C36,) -> 0 | E36: =SUM('(계획)손익계산서 월별계획'!E36:OFFSET('(계획)손익계산서 월별계획'!E36,0,$C$4-1)) -> 4.0722025e+08 | F36: =SUM('3. 손익계산서 월별실적'!E36:OFFSET('3. 손익계산서 월별실적'!E36,0,$C$4-1)) -> 0 | G36: =+IFERROR(F36/E36,) -> 0 | H36: =OFFSET('3. 손익계산서 월별실적'!E36,0,$C$4-2) -> 0 | I36: =+IFERROR(H36/$H$6,) -> 0 | J36: =OFFSET('(계획)손익계산서 월별계획'!E36,0,$C$4-1) -> 4.0722025e+08 | K36: =+IFERROR(J36/$J$6,) -> 0.22598567 | L36: =OFFSET('3. 손익계산서 월별실적'!E36,0,$C$4-1) -> 0 | M36: =+IFERROR(L36/$L$6,) -> 0 | N36: =+IFERROR(L36/H36,) -> 0 | O36: =+IFERROR(L36/J36,) -> 0
B37: 유지비용 | C37: =+'(계획)손익계산서 월별계획'!C37 -> 4.4378742e+08 | D37: =+IFERROR(F37/C37,) -> 0 | E37: =SUM('(계획)손익계산서 월별계획'!E37:OFFSET('(계획)손익계산서 월별계획'!E37,0,$C$4-1)) -> 26650202 | F37: =SUM('3. 손익계산서 월별실적'!E37:OFFSET('3. 손익계산서 월별실적'!E37,0,$C$4-1)) -> 0 | G37: =+IFERROR(F37/E37,) -> 0 | H37: =OFFSET('3. 손익계산서 월별실적'!E37,0,$C$4-2) -> 0 | I37: =+IFERROR(H37/$H$6,) -> 0 | J37: =OFFSET('(계획)손익계산서 월별계획'!E37,0,$C$4-1) -> 26650202 | K37: =+IFERROR(J37/$J$6,) -> 0.014789451 | L37: =OFFSET('3. 손익계산서 월별실적'!E37,0,$C$4-1) -> 0 | M37: =+IFERROR(L37/$L$6,) -> 0 | N37: =+IFERROR(L37/H37,) -> 0 | O37: =+IFERROR(L37/J37,) -> 0
B38: 세금,보험 | C38: =+'(계획)손익계산서 월별계획'!C38 -> 4.7398803e+08 | D38: =+IFERROR(F38/C38,) -> 0 | E38: =SUM('(계획)손익계산서 월별계획'!E38:OFFSET('(계획)손익계산서 월별계획'!E38,0,$C$4-1)) -> 38314585 | F38: =SUM('3. 손익계산서 월별실적'!E38:OFFSET('3. 손익계산서 월별실적'!E38,0,$C$4-1)) -> 0 | G38: =+IFERROR(F38/E38,) -> 0 | H38: =OFFSET('3. 손익계산서 월별실적'!E38,0,$C$4-2) -> 0 | I38: =+IFERROR(H38/$H$6,) -> 0 | J38: =OFFSET('(계획)손익계산서 월별계획'!E38,0,$C$4-1) -> 38314585 | K38: =+IFERROR(J38/$J$6,) -> 0.021262566 | L38: =OFFSET('3. 손익계산서 월별실적'!E38,0,$C$4-1) -> 0 | M38: =+IFERROR(L38/$L$6,) -> 0 | N38: =+IFERROR(L38/H38,) -> 0 | O38: =+IFERROR(L38/J38,) -> 0
B39: 복리후생비 | C39: =+'(계획)손익계산서 월별계획'!C39 -> 3.7167399e+08 | D39: =+IFERROR(F39/C39,) -> 0 | E39: =SUM('(계획)손익계산서 월별계획'!E39:OFFSET('(계획)손익계산서 월별계획'!E39,0,$C$4-1)) -> 17105492 | F39: =SUM('3. 손익계산서 월별실적'!E39:OFFSET('3. 손익계산서 월별실적'!E39,0,$C$4-1)) -> 0 | G39: =+IFERROR(F39/E39,) -> 0 | H39: =OFFSET('3. 손익계산서 월별실적'!E39,0,$C$4-2) -> 0 | I39: =+IFERROR(H39/$H$6,) -> 0 | J39: =OFFSET('(계획)손익계산서 월별계획'!E39,0,$C$4-1) -> 17105492 | K39: =+IFERROR(J39/$J$6,) -> 0.0094926422 | L39: =OFFSET('3. 손익계산서 월별실적'!E39,0,$C$4-1) -> 0 | M39: =+IFERROR(L39/$L$6,) -> 0 | N39: =+IFERROR(L39/H39,) -> 0 | O39: =+IFERROR(L39/J39,) -> 0
B40: 운반비 | C40: =+'(계획)손익계산서 월별계획'!C40 -> 0 | D40: =+IFERROR(F40/C40,) -> 0 | E40: =SUM('(계획)손익계산서 월별계획'!E40:OFFSET('(계획)손익계산서 월별계획'!E40,0,$C$4-1)) -> 0 | F40: =SUM('3. 손익계산서 월별실적'!E40:OFFSET('3. 손익계산서 월별실적'!E40,0,$C$4-1)) -> 0 | G40: =+IFERROR(F40/E40,) -> 0 | H40: =OFFSET('3. 손익계산서 월별실적'!E40,0,$C$4-2) -> 0 | I40: =+IFERROR(H40/$H$6,) -> 0 | J40: =OFFSET('(계획)손익계산서 월별계획'!E40,0,$C$4-1) -> 0 | K40: =+IFERROR(J40/$J$6,) -> 0 | L40: =OFFSET('3. 손익계산서 월별실적'!E40,0,$C$4-1) -> 0 | M40: =+IFERROR(L40/$L$6,) -> 0 | N40: =+IFERROR(L40/H40,) -> 0 | O40: =+IFERROR(L40/J40,) -> 0
B41: 포장비 | C41: =+'(계획)손익계산서 월별계획'!C41 -> 0 | D41: =+IFERROR(F41/C41,) -> 0 | E41: =SUM('(계획)손익계산서 월별계획'!E41:OFFSET('(계획)손익계산서 월별계획'!E41,0,$C$4-1)) -> 0 | F41: =SUM('3. 손익계산서 월별실적'!E41:OFFSET('3. 손익계산서 월별실적'!E41,0,$C$4-1)) -> 0 | G41: =+IFERROR(F41/E41,) -> 0 | H41: =OFFSET('3. 손익계산서 월별실적'!E41,0,$C$4-2) -> 0 | I41: =+IFERROR(H41/$H$6,) -> 0 | J41: =OFFSET('(계획)손익계산서 월별계획'!E41,0,$C$4-1) -> 0 | K41: =+IFERROR(J41/$J$6,) -> 0 | L41: =OFFSET('3. 손익계산서 월별실적'!E41,0,$C$4-1) -> 0 | M41: =+IFERROR(L41/$L$6,) -> 0 | N41: =+IFERROR(L41/H41,) -> 0 | O41: =+IFERROR(L41/J41,) -> 0
B42: 광고선전비 | C42: =+'(계획)손익계산서 월별계획'!C42 -> 0 | D42: =+IFERROR(F42/C42,) -> 0 | E42: =SUM('(계획)손익계산서 월별계획'!E42:OFFSET('(계획)손익계산서 월별계획'!E42,0,$C$4-1)) -> 0 | F42: =SUM('3. 손익계산서 월별실적'!E42:OFFSET('3. 손익계산서 월별실적'!E42,0,$C$4-1)) -> 0 | G42: =+IFERROR(F42/E42,) -> 0 | H42: =OFFSET('3. 손익계산서 월별실적'!E42,0,$C$4-2) -> 0 | I42: =+IFERROR(H42/$H$6,) -> 0 | J42: =OFFSET('(계획)손익계산서 월별계획'!E42,0,$C$4-1) -> 0 | K42: =+IFERROR(J42/$J$6,) -> 0 | L42: =OFFSET('3. 손익계산서 월별실적'!E42,0,$C$4-1) -> 0 | M42: =+IFERROR(L42/$L$6,) -> 0 | N42: =+IFERROR(L42/H42,) -> 0 | O42: =+IFERROR(L42/J42,) -> 0
B43: 지급수수료 | C43: =+'(계획)손익계산서 월별계획'!C43 -> 1.3008292e+09 | D43: =+IFERROR(F43/C43,) -> 0 | E43: =SUM('(계획)손익계산서 월별계획'!E43:OFFSET('(계획)손익계산서 월별계획'!E43,0,$C$4-1)) -> 1.2236385e+08 | F43: =SUM('3. 손익계산서 월별실적'!E43:OFFSET('3. 손익계산서 월별실적'!E43,0,$C$4-1)) -> 0 | G43: =+IFERROR(F43/E43,) -> 0 | H43: =OFFSET('3. 손익계산서 월별실적'!E43,0,$C$4-2) -> 0 | I43: =+IFERROR(H43/$H$6,) -> 0 | J43: =OFFSET('(계획)손익계산서 월별계획'!E43,0,$C$4-1) -> 1.2236385e+08 | K43: =+IFERROR(J43/$J$6,) -> 0.067905456 | L43: =OFFSET('3. 손익계산서 월별실적'!E43,0,$C$4-1) -> 0 | M43: =+IFERROR(L43/$L$6,) -> 0 | N43: =+IFERROR(L43/H43,) -> 0 | O43: =+IFERROR(L43/J43,) -> 0
...

Sheet 3. 손익계산서 월별실적
B3: Plofit and Loss statement FY 2026
P4: (단위:원)
B5: 구분 | C5: 년계 | D5: 12. lst y | E5: 1월 | F5: 2월 | G5: 3월 | H5: 4월 | I5: 5월 | J5: 6월 | K5: 7월 | L5: 8월 | M5: 9월 | N5: 10월 | O5: 11월 | P5: 12월
B6: Ⅰ. 매출액 | C6: =SUM(C7:C10) -> 0 | E6: =SUM(E7:E10) -> 0 | F6: =SUM(F7:F10) -> 0 | G6: =SUM(G7:G10) -> 0 | H6: =SUM(H7:H10) -> 0 | I6: =SUM(I7:I10) -> 0 | J6: =SUM(J7:J10) -> 0 | K6: =SUM(K7:K10) -> 0 | L6: =SUM(L7:L10) -> 0 | ... P6: =SUM(P7:P10) -> 0
B7: W/H | C7: =SUM(E7:P7) -> 0
B8: 상품 | C8: =SUM(E8:P8) -> 0
B9: 부품 | C9: =SUM(E9:P9) -> 0
B10: 기타 | C10: =SUM(E10:P10) -> 0
B11: Ⅱ. 매출원가 | C11: =SUM(C12:C15) -> 0 | E11: =SUM(E12:E15) -> 0 | F11: =SUM(F12:F15) -> 0 | G11: =SUM(G12:G15) -> 0 | H11: =SUM(H12:H15) -> 0 | I11: =SUM(I12:I15) -> 0 | J11: =SUM(J12:J15) -> 0 | K11: =SUM(K12:K15) -> 0 | L11: =SUM(L12:L15) -> 0 | ... P11: =SUM(P12:P15) -> 0
B12: W/H | C12: =SUM(E12:P12) -> 0
B13: 상품 | C13: =SUM(E13:P13) -> 0
B14: 부품 | C14: =SUM(E14:P14) -> 0
B15: 기타 | C15: =SUM(E15:P15) -> 0
B16: Ⅲ. 매출총이익 | C16: =+C6-C11 -> 0 | E16: =+E6-E11 -> 0 | F16: =+F6-F11 -> 0 | G16: =+G6-G11 -> 0 | H16: =+H6-H11 -> 0 | I16: =+I6-I11 -> 0 | J16: =+J6-J11 -> 0 | K16: =+K6-K11 -> 0 | L16: =+L6-L11 -> 0 | ... P16: =+P6-P11 -> 0
B17: (이익률) | C17: =+IFERROR(C16/C6,) -> 0 | E17: =+IFERROR(E16/E6,) -> 0 | F17: =+IFERROR(F16/F6,) -> 0 | G17: =+IFERROR(G16/G6,) -> 0 | H17: =+IFERROR(H16/H6,) -> 0 | I17: =+IFERROR(I16/I6,) -> 0 | J17: =+IFERROR(J16/J6,) -> 0 | K17: =+IFERROR(K16/K6,) -> 0 | L17: =+IFERROR(L16/L6,) -> 0 | ... P17: =+IFERROR(P16/P6,) -> 0
B18: Ⅳ.판매관리비 | C18: =SUM(E18:P18) -> 0 | E18: =+E19+E35+E53 -> 0 | F18: =+F19+F35+F53 -> 0 | G18: =+G19+G35+G53 -> 0 | H18: =+H19+H35+H53 -> 0 | I18: =+I19+I35+I53 -> 0 | J18: =+J19+J35+J53 -> 0 | K18: =+K19+K35+K53 -> 0 | L18: =+L19+L35+L53 -> 0 | ... P18: =+P19+P35+P53 -> 0
B19: [판매비] | C19: =SUM(E19:P19) -> 0 | E19: =SUM(E20:E33) -> 0 | F19: =SUM(F20:F33) -> 0 | G19: =SUM(G20:G33) -> 0 | H19: =SUM(H20:H33) -> 0 | I19: =SUM(I20:I33) -> 0 | J19: =SUM(J20:J33) -> 0 | K19: =SUM(K20:K33) -> 0 | L19: =SUM(L20:L33) -> 0 | ... P19: =SUM(P20:P33) -> 0
B20: 인건비 | C20: =SUM(E20:P20) -> 0
B21: 유지비용 | C21: =SUM(E21:P21) -> 0
B22: 세금,보험 | C22: =SUM(E22:P22) -> 0
B23: 복리후생비 | C23: =SUM(E23:P23) -> 0
B24: 운반비 | C24: =SUM(E24:P24) -> 0
B25: 포장비 | C25: =SUM(E25:P25) -> 0
B26: 광고선전비 | C26: =SUM(E26:P26) -> 0
B27: 지급수수료 | C27: =SUM(E27:P27) -> 0
B28: 여비교통비 | C28: =SUM(E28:P28) -> 0
B29: 감가상각비 | C29: =SUM(E29:P29) -> 0
B30: 개발비 | C30: =SUM(E30:P30) -> 0
B31: 충당비용 | C31: =SUM(E31:P31) -> 0
... B33: 기타비용 | C33: =SUM(E33:P33) -> 0
B35: [관리비] | C35: =SUM(E35:P35) -> 0 | E35: =SUM(E36:E51) -> 0 | F35: =SUM(F36:F51) -> 0 | G35: =SUM(G36:G51) -> 0 | H35: =SUM(H36:H51) -> 0 | I35: =SUM(I36:I51) -> 0 | J35: =SUM(J36:J51) -> 0 | K35: =SUM(K36:K51) -> 0 | L35: =SUM(L36:L51) -> 0 | ... P35: =SUM(P36:P51) -> 0
B36: 인건비 | C36: =SUM(E36:P36) -> 0
B37: 유지비용 | C37: =SUM(E37:P37) -> 0
B38: 세금,보험 | C38: =SUM(E38:P38) -> 0
B39: 복리후생비 | C39: =SUM(E39:P39) -> 0
B40: 운반비 | C40: =SUM(E40:P40) -> 0
B41: 포장비 | C41: =SUM(E41:P41) -> 0
B42: 광고선전비 | C42: =SUM(E42:P42) -> 0
B43: 지급수수료 | C43: =SUM(E43:P43) -> 0
B44: 여비교통비 | C44: =SUM(E44:P44) -> 0
...

Sheet 4. PA요약
B2: 고객별 손익요약 | G2: (단위 : 원)
B3: 행 레이블 | C3: 합계 : 매출액 합계 | D3: 합계 : 매출총이익 | E3: 합계 : 매출총이익율 | F3: 합계 : 영업이익 | G3: 합계 : 영업이익율
B4: (주)엘지에너지솔루션 | C4: 749784620 | D4: 319781480 | E4: 0.42649779 | F4: 24632639 | G4: 0.032852954
B5: Kyungshin Cable Euro | C5: 1550103155 | D5: 55597728 | E5: 0.035867115 | F5: -5.5459237e+08 | G5: -0.35777772
B6: Kyungshin Cable Inte | C6: 1125573567 | D6: 76877048 | E6: 0.068300332 | F6: -3.6619917e+08 | G6: -0.3253445
B7: CHANGZHOU KYUNGSHIN | C7: 5948688 | D7: 5948688 | E7: 1 | F7: 3607017.7 | G7: 0.60635517
B8: POWERLOGICS BATHIEN | C8: 1803028 | D8: 874477 | E8: 0.48500467 | F8: 164724.35 | G8: 0.091359838
B9: ㈜ 파워로직스 | C9: 16090410 | D9: 6804900 | E9: 0.42291651 | F9: 470993.26 | G9: 0.029271675
B10: 총합계 | C10: 3449303468 | D10: 465884321 | E10: 0.1350662 | F10: -891916163 | G10: -0.25857863
B21: 제품군별 손익요약 | G21: (단위 : 원)
B22: 행 레이블 | C22: 합계 : 매출액 합계 | D22: 합계 : 매출총이익 | E22: 합계 : 매출총이익율 | F22: 합계 : 영업이익 | G22: 합계 : 영업이익율
B23: 부품 | C23: 2644329659 | D23: 129205182 | E23: 0.048861223 | F23: -9.1172152e+08 | G23: -0.34478361
B24: 기타 | C24: 38675751 | D24: 9218282 | E24: 0.23834785 | F24: -6006227.5 | G24: -0.15529698
B25: 상품 | C25: 766298058 | D25: 327460857 | E25: 0.42732831 | F25: 25811587 | G25: 0.033683482
B26: 총합계 | C26: 3449303468 | D26: 465884321 | E26: 0.1350662 | F26: -8.9191616e+08 | G26: -0.25857863
E30: 값 | N30: 구분 | O30: 고객명 | P30: 제품명 | Q30: 매출액 | R30: 매출원가 | S30: 매출총이익 | T30: 매출총이익률 | U30: 판관비 | V30: 영업이익 | W30: 영업이익률
B31: 구분 | C31: 고객명 | D31: 제품명 | E31: 합계 : 매출액 합계 | F31: 합계 : 매출원가 합계 | G31: 합계 : 매출총이익 | H31: 합계 : 매출총이익율 | I31: 합계 : 총판관비 | J31: 합계 : 영업이익 | K31: 합계 : 영업이익율 | N31: 부품 | O31: KSCE | Q31: 1519907606 | R31: 1466427958 | S31: 53479648 | T31: 0.035186118 | U31: 5.9830377e+08 | V31: -5.4482413e+08 | W31: -0.35845871
B32: 부품 | C32: Kyungshin Cable Euro | E32: 1519907606 | F32: 1466427958 | G32: 53479648 | H32: 0.035186118 | I32: 5.9830377e+08 | J32: -5.4482413e+08 | K32: -0.35845871 | O32: KSCI | Q32: 1124422053 | R32: 1048696519 | S32: 75725534 | T32: 0.067346184 | U32: 4.4262293e+08 | V32: -3.668974e+08 | W32: -0.32629865
C33: Kyungshin Cable Inte | E33: 1124422053 | F33: 1048696519 | G33: 75725534 | H33: 0.067346184 | I33: 4.4262293e+08 | J33: -3.668974e+08 | K33: -0.32629865
B34: 부품 요약 | E34: 2644329659 | F34: 2515124477 | G34: 129205182 | H34: 0.048861223 | I34: 1.0409267e+09 | J34: -9.1172152e+08 | K34: -0.34478361
B35: 기타 | C35: Kyungshin Cable Euro | E35: 30195549 | F35: 28077469 | G35: 2118080 | H35: 0.070145438 | I35: 11886322 | J35: -9768241.8 | K35: -0.32349939 | N35: 부품 요약 | Q35: 2644329659 | R35: 2515124477 | S35: 129205182 | T35: 0.048861223 | U35: 1.0409267e+09 | V35: -9.1172152e+08 | W35: -0.34478361
C36: (주)엘지에너지솔루션 | E36: 1380000 | F36: 1380000 | G36: 0 | H36: 0 | I36: 543229.87 | J36: -543229.87 | K36: -0.39364483 | N36: 기타 | O36: KSCE | Q36: 30195549 | R36: 28077469 | S36: 2118080 | T36: 0.070145438 | U36: 11886322 | V36: -9768241.8 | W36: -0.32349939
C37: Kyungshin Cable Inte | E37: 1151514 | F37: 0 | G37: 1151514 | H37: 1 | I37: 453287.54 | J37: 698226.46 | K37: 0.60635517 | O37: (주)엘지에너지솔루션 | Q37: 1380000 | R37: 1380000 | S37: 0 | T37: 0 | U37: 543229.87 | V37: -543229.87 | W37: -0.39364483
C38: CHANGZHOU KYUNGSHIN | E38: 5948688 | F38: 0 | G38: 5948688 | H38: 1 | I38: 2341670.3 | J38: 3607017.7 | K38: 0.60635517 | O38: KSCI | Q38: 1151514 | R38: 0 | S38: 1151514 | T38: 1 | U38: 453287.54 | V38: 698226.46 | W38: 0.60635517
B39: 기타 요약 | E39: 38675751 | F39: 29457469 | G39: 9218282 | H39: 0.23834785 | I39: 15224510 | J39: -6006227.5 | K39: -0.15529698 | O39: KSCCZ | Q39: 5948688 | R39: 0 | S39: 5948688 | T39: 1 | U39: 2341670.3 | V39: 3607017.7 | W39: 0.60635517
B40: 상품 | C40: (주)엘지에너지솔루션 | E40: 748404620 | F40: 428623140 | G40: 319781480 | H40: 0.42728421 | I40: 2.9460561e+08 | J40: 25175869 | K40: 0.033639382
C41: POWERLOGICS BATHIEN | E41: 1803028 | F41: 928551 | G41: 874477 | H41: 0.48500467 | I41: 709752.65 | J41: 164724.35 | K41: 0.091359838
C42: ㈜ 파워로직스 | D42: PBMS | E42: 16090410 | F42: 9285510 | G42: 6804900 | H42: 0.42291651 | I42: 6333906.7 | J42: 470993.26 | K42: 0.029271675
B43: 상품 요약 | E43: 766298058 | F43: 438837201 | G43: 327460857 | H43: 0.42732831 | I43: 3.0164927e+08 | J43: 25811587 | K43: 0.033683482 | N43: 기타 요약 | Q43: 38675751 | R43: 29457469 | S43: 9218282 | T43: 0.23834785 | U43: 15224510 | V43: -6006227.5 | W43: -0.15529698
B44: 총합계 | E44: 3449303468 | F44: 2983419147 | G44: 465884321 | H44: 0.1350662 | I44: 1.3578005e+09 | J44: -891916163 | K44: -0.25857863 | N44: 상품 | O44: (주)엘지에너지솔루션 | Q44: 748404620 | R44: 428623140 | S44: 319781480 | T44: 0.42728421 | U44: 2.9460561e+08 | V44: 25175869 | W44: 0.033639382
O45: POWERLOGICS BATHIEN | Q45: 1803028 | R45: 928551 | S45: 874477 | T45: 0.48500467 | U45: 709752.65 | V45: 164724.35 | W45: 0.091359838
O46: ㈜ 파워로직스 | Q46: 16090410 | R46: 9285510 | S46: 6804900 | T46: 0.42291651 | U46: 6333906.7 | V46: 470993.26 | W46: 0.029271675
N47: 상품 요약 | Q47: 766298058 | R47: 438837201 | S47: 327460857 | T47: 0.42732831 | U47: 3.0164927e+08 | V47: 25811587 | W47: 0.033683482
N48: 총합계 | Q48: 3449303468 | R48: 2983419147 | S48: 465884321 | T48: 0.1350662 | U48: 1.3578005e+09 | V48: -891916163 | W48: -0.25857863

Sheet pa data(26년1월)
E1: WH제품 | F1: =SUMIF($C$9:$C$974,$E1,F$9:F$974) -> 0 | G1: =SUMIF($C$9:$C$974,$E1,G$9:G$974) -> 0 | H1: =SUMIF($C$9:$C$974,$E1,H$9:H$974) -> 0 | Q1: 3105328928 | R1: =+F7 -> 0 | T1: EBA02150AD | U1: =SUMIF(D:D,$T1,F:F)+SUMIF(D:D,$W1,F:F) -> 0 | V1: =SUMIF(D:D,$T1,H:H)+SUMIF(D:D,$W1,H:H) -> 0 | W1: EBA02150AF
E2: 상품 | F2: =SUMIF($C$9:$C$974,$E2,F$9:F$974) -> 0 | G2: =SUMIF($C$9:$C$974,$E2,G$9:G$974) -> 0 | H2: =SUMIF($C$9:$C$974,$E2,H$9:H$974) -> 0 | Q2: 1867677336 | R2: =+H7 -> 0 | S2: =+Q2-R2 -> 1867677336 | T2: EEA00597AB | U2: =SUMIF(D:D,$T2,F:F) -> 0 | V2: =SUMIF(D:D,$T2,H:H)+SUMIF(D:D,$W2,H:H) -> 0
E3: 부품 | F3: =SUMIF($C$9:$C$974,$E3,F$9:F$974) -> 0 | G3: =SUMIF($C$9:$C$974,$E3,G$9:G$974) -> 0 | H3: =SUMIF($C$9:$C$974,$E3,H$9:H$974) -> 0 | J3: 미이관예상 | Q3: 1498140440 | R3: =+J7 -> #DIV/0! | S3: =+Q3-R3 -> #DIV/0! | T3: EEA00596AB | U3: =SUMIF(D:D,$T3,F:F) -> 0 | V3: =SUMIF(D:D,$T3,H:H)+SUMIF(D:D,$W3,H:H) -> 0
E4: 기타 | F4: =SUMIF($C$9:$C$974,$E4,F$9:F$974) -> 0 | G4: =SUMIF($C$9:$C$974,$E4,G$9:G$974) -> 0 | H4: =SUMIF($C$9:$C$974,$E4,H$9:H$974) -> 0 | K4: 전체 운반비 | L4: 31405400 | Q4: =+Q1-Q2-Q3 -> -260488848 | R4: =+R1-R2-R3 -> #DIV/0! | T4: EEA00595AB | U4: =SUMIF(D:D,$T4,F:F) -> 0 | V4: =SUMIF(D:D,$T4,H:H)+SUMIF(D:D,$W4,H:H) -> 0
F5: =SUM(F1:F4) -> 0 | G5: =SUM(G1:G4) -> 0 | H5: =SUM(H1:H4) -> 0 | K5: 매출액 | L5: =+F7 -> 0 | Q5: fi | R5: co | T5: EBA02112AF | U5: =SUMIF(D:D,$T5,F:F) -> 0 | V5: =SUMIF(D:D,$T5,H:H)+SUMIF(D:D,$W5,H:H) -> 0
F6: 3494964112 | G6: 7328641 | H6: 2690181483 | I6: =+F6-H6 -> 804782629 | J6: 1433155682 | K6: =J6-L6 -> 1382534625 | L6: =47873947+2747110 -> 50621057 | M6: =I6-J6 -> -628373053 | Q6: =+Q4-R4 -> #DIV/0! | U6: =SUM(U1:U5) -> 0 | V6: =SUM(V1:V5) -> 0
F7: =SUM(F9:F974) -> 0 | G7: =SUM(G9:G974) -> 0 | H7: =SUM(H9:H974) -> 0 | I7: =SUM(I9:I974) -> 0 | J7: =SUM(J9:J974) -> #DIV/0! | K7: =SUM(K9:K974) -> #DIV/0! | L7: =SUM(L9:L974) -> #DIV/0! | M7: =SUM(M9:M974) -> #DIV/0!
A8: 고객 | B8: 고객명 | C8: 구분 | D8: 제품코드 | E8: 제품명 | F8: 매출액 합계 | G8: 매출수량 | H8: 매출원가 합계 | I8: 매출총이익 | J8: 총판관비 | K8: 기타 판관비 | L8: 운반비 | M8: 영업이익
I9: =+F9-H9 -> 0 | J9: =SUM(K9:L9) -> #DIV/0! | K9: =+F9/$F$7*$K$6 -> #DIV/0! | L9: =+F9/$F$7*$L$6 -> #DIV/0! | M9: =+I9-J9 -> #DIV/0!
I10: =+F10-H10 -> 0 | J10: =SUM(K10:L10) -> #DIV/0! | K10: =+F10/$F$7*$K$6 -> #DIV/0! | L10: =+F10/$F$7*$L$6 -> #DIV/0! | M10: =+I10-J10 -> #DIV/0!
I11: =+F11-H11 -> 0 | J11: =SUM(K11:L11) -> #DIV/0! | K11: =+F11/$F$7*$K$6 -> #DIV/0! | L11: =+F11/$F$7*$L$6 -> #DIV/0! | M11: =+I11-J11 -> #DIV/0!
I12: =+F12-H12 -> 0 | J12: =SUM(K12:L12) -> #DIV/0! | K12: =+F12/$F$7*$K$6 -> #DIV/0! | L12: =+F12/$F$7*$L$6 -> #DIV/0! | M12: =+I12-J12 -> #DIV/0!
I13: =+F13-H13 -> 0 | J13: =SUM(K13:L13) -> #DIV/0! | K13: =+F13/$F$7*$K$6 -> #DIV/0! | L13: =+F13/$F$7*$L$6 -> #DIV/0! | M13: =+I13-J13 -> #DIV/0!
I14: =+F14-H14 -> 0 | J14: =SUM(K14:L14) -> #DIV/0! | K14: =+F14/$F$7*$K$6 -> #DIV/0! | L14: =+F14/$F$7*$L$6 -> #DIV/0! | M14: =+I14-J14 -> #DIV/0!
I15: =+F15-H15 -> 0 | J15: =SUM(K15:L15) -> #DIV/0! | K15: =+F15/$F$7*$K$6 -> #DIV/0! | L15: =+F15/$F$7*$L$6 -> #DIV/0! | M15: =+I15-J15 -> #DIV/0!
I16: =+F16-H16 -> 0 | J16: =SUM(K16:L16) -> #DIV/0! | K16: =+F16/$F$7*$K$6 -> #DIV/0! | L16: =+F16/$F$7*$L$6 -> #DIV/0! | M16: =+I16-J16 -> #DIV/0!
I17: =+F17-H17 -> 0 | J17: =SUM(K17:L17) -> #DIV/0! | K17: =+F17/$F$7*$K$6 -> #DIV/0! | L17: =+F17/$F$7*$L$6 -> #DIV/0! | M17: =+I17-J17 -> #DIV/0!
I18: =+F18-H18 -> 0 | J18: =SUM(K18:L18) -> #DIV/0! | K18: =+F18/$F$7*$K$6 -> #DIV/0! | L18: =+F18/$F$7*$L$6 -> #DIV/0! | M18: =+I18-J18 -> #DIV/0!
I19: =+F19-H19 -> 0 | J19: =SUM(K19:L19) -> #DIV/0! | K19: =+F19/$F$7*$K$6 -> #DIV/0! | L19: =+F19/$F$7*$L$6 -> #DIV/0! | M19: =+I19-J19 -> #DIV/0!
I20: =+F20-H20 -> 0 | J20: =SUM(K20:L20) -> #DIV/0! | K20: =+F20/$F$7*$K$6 -> #DIV/0! | L20: =+F20/$F$7*$L$6 -> #DIV/0! | M20: =+I20-J20 -> #DIV/0!
... I160: =+F160-H160 -> 0 | J160: =SUM(K160:L160) -> #DIV/0! | K160: =+F160/$F$7*$K$6 -> #DIV/0! | L160: =+F160/$F$7*$L$6 -> #DIV/0! | M160: =+I160-J160 -> #DIV/0!

Sheet (계획)손익계산서 월별계획
B3: Plofit and Loss statement Plan FY 2026
P4: (단위:원)
B5: 구 분 | C5: F Y | D5: 12. lst y | E5: 1월 | F5: 2월 | G5: 3월 | H5: 4월 | I5: 5월 | J5: 6월 | K5: 7월 | L5: 8월 | M5: 9월 | N5: 10월 | O5: 11월 | P5: 12월
B6: Ⅰ. 매출액 | C6: =SUM(E6:P6) -> 4.7498576e+10 | D6: 0 | E6: =SUM(E7:E10) -> 1.8019737e+09 | F6: =SUM(F7:F10) -> 2.2671711e+09 | G6: =SUM(G7:G10) -> 3.2136919e+09 | H6: =SUM(H7:H10) -> 5.8756726e+09 | I6: =SUM(I7:I10) -> 3.0360047e+09 | J6: =SUM(J7:J10) -> 4.3987402e+09 | K6: =SUM(K7:K10) -> 4.1798454e+09 | L6: =SUM(L7:L10) -> 2.1316705e+09 | ... P6: =SUM(P7:P10) -> 1.262006e+10
B7: W/H | C7: =SUM(E7:P7) -> 0 | E7: =SUMIFS('(계획)26년 매출매입 월별계획'!E:E,'(계획)26년 매출매입 월별계획'!$T:$T,$B7,'(계획)26년 매출매입 월별계획'!$V:$V,"매출") -> 0 | F7: =SUMIFS('(계획)26년 매출매입 월별계획'!F:F,'(계획)26년 매출매입 월별계획'!$T:$T,$B7,'(계획)26년 매출매입 월별계획'!$V:$V,"매출") -> 0 | G7: =SUMIFS('(계획)26년 매출매입 월별계획'!G:G,'(계획)26년 매출매입 월별계획'!$T:$T,$B7,'(계획)26년 매출매입 월별계획'!$V:$V,"매출") -> 0 | H7: =SUMIFS('(계획)26년 매출매입 월별계획'!H:H,'(계획)26년 매출매입 월별계획'!$T:$T,$B7,'(계획)26년 매출매입 월별계획'!$V:$V,"매출") -> 0 | I7: =SUMIFS('(계획)26년 매출매입 월별계획'!I:I,'(계획)26년 매출매입 월별계획'!$T:$T,$B7,'(계획)26년 매출매입 월별계획'!$V:$V,"매출") -> 0 | J7: =SUMIFS('(계획)26년 매출매입 월별계획'!J:J,'(계획)26년 매출매입 월별계획'!$T:$T,$B7,'(계획)26년 매출매입 월별계획'!$V:$V,"매출") -> 0 | K7: =SUMIFS('(계획)26년 매출매입 월별계획'!K:K,'(계획)26년 매출매입 월별계획'!$T:$T,$B7,'(계획)26년 매출매입 월별계획'!$V:$V,"매출") -> 0 | L7: =SUMIFS('(계획)26년 매출매입 월별계획'!L:L,'(계획)26년 매출매입 월별계획'!$T:$T,$B7,'(계획)26년 매출매입 월별계획'!$V:$V,"매출") -> 0 | M7: =SUMIFS('(계획)26년 매출매입 월별계획'!M:M,'(계획)26년 매출매입 월별계획'!$T:$T,$B7,'(계획)26년 매출매입 월별계획'!$V:$V,"매출") -> 0 | N7: =SUMIFS('(계획)26년 매출매입 월별계획'!N:N,'(계획)26년 매출매입 월별계획'!$T:$T,$B7,'(계획)26년 매출매입 월별계획'!$V:$V,"매출") -> 0 | O7: =SUMIFS('(계획)26년 매출매입 월별계획'!O:O,'(계획)26년 매출매입 월별계획'!$T:$T,$B7,'(계획)26년 매출매입 월별계획'!$V:$V,"매출") -> 0 | P7: =SUMIFS('(계획)26년 매출매입 월별계획'!P:P,'(계획)26년 매출매입 월별계획'!$T:$T,$B7,'(계획)26년 매출매입 월별계획'!$V:$V,"매출") -> 0
B8: 상품 | C8: =SUM(E8:P8) -> 9059168350 | E8: =SUMIFS('(계획)26년 매출매입 월별계획'!E:E,'(계획)26년 매출매입 월별계획'!$T:$T,$B8,'(계획)26년 매출매입 월별계획'!$V:$V,"매출") -> 268009000 | F8: =SUMIFS('(계획)26년 매출매입 월별계획'!F:F,'(계획)26년 매출매입 월별계획'!$T:$T,$B8,'(계획)26년 매출매입 월별계획'!$V:$V,"매출") -> 470499568 | G8: =SUMIFS('(계획)26년 매출매입 월별계획'!G:G,'(계획)26년 매출매입 월별계획'!$T:$T,$B8,'(계획)26년 매출매입 월별계획'!$V:$V,"매출") -> 581814052 | H8: =SUMIFS('(계획)26년 매출매입 월별계획'!H:H,'(계획)26년 매출매입 월별계획'!$T:$T,$B8,'(계획)26년 매출매입 월별계획'!$V:$V,"매출") -> 916682560 | I8: =SUMIFS('(계획)26년 매출매입 월별계획'!I:I,'(계획)26년 매출매입 월별계획'!$T:$T,$B8,'(계획)26년 매출매입 월별계획'!$V:$V,"매출") -> 897375852 | J8: =SUMIFS('(계획)26년 매출매입 월별계획'!J:J,'(계획)26년 매출매입 월별계획'!$T:$T,$B8,'(계획)26년 매출매입 월별계획'!$V:$V,"매출") -> 903742952 | K8: =SUMIFS('(계획)26년 매출매입 월별계획'!K:K,'(계획)26년 매출매입 월별계획'!$T:$T,$B8,'(계획)26년 매출매입 월별계획'!$V:$V,"매출") -> 1032380066 | L8: =SUMIFS('(계획)26년 매출매입 월별계획'!L:L,'(계획)26년 매출매입 월별계획'!$T:$T,$B8,'(계획)26년 매출매입 월별계획'!$V:$V,"매출") -> 832505164 | M8: =SUMIFS('(계획)26년 매출매입 월별계획'!M:M,'(계획)26년 매출매입 월별계획'!$T:$T,$B8,'(계획)26년 매출매입 월별계획'!$V:$V,"매출") -> 841903084 | N8: =SUMIFS('(계획)26년 매출매입 월별계획'!N:N,'(계획)26년 매출매입 월별계획'!$T:$T,$B8,'(계획)26년 매출매입 월별계획'!$V:$V,"매출") -> 771418684 | O8: =SUMIFS('(계획)26년 매출매입 월별계획'!O:O,'(계획)26년 매출매입 월별계획'!$T:$T,$B8,'(계획)26년 매출매입 월별계획'!$V:$V,"매출") -> 771418684 | P8: =SUMIFS('(계획)26년 매출매입 월별계획'!P:P,'(계획)26년 매출매입 월별계획'!$T:$T,$B8,'(계획)26년 매출매입 월별계획'!$V:$V,"매출") -> 771418684
B9: 부품 | C9: =SUM(E9:P9) -> 2.204985e+10 | E9: =SUMIFS('(계획)26년 매출매입 월별계획'!E:E,'(계획)26년 매출매입 월별계획'!$T:$T,$B9,'(계획)26년 매출매입 월별계획'!$V:$V,"매출") -> 1.5339647e+09 | F9: =SUMIFS('(계획)26년 매출매입 월별계획'!F:F,'(계획)26년 매출매입 월별계획'!$T:$T,$B9,'(계획)26년 매출매입 월별계획'!$V:$V,"매출") -> 1.7966715e+09 | G9: =SUMIFS('(계획)26년 매출매입 월별계획'!G:G,'(계획)26년 매출매입 월별계획'!$T:$T,$B9,'(계획)26년 매출매입 월별계획'!$V:$V,"매출") -> 2.1252148e+09 | H9: =SUMIFS('(계획)26년 매출매입 월별계획'!H:H,'(계획)26년 매출매입 월별계획'!$T:$T,$B9,'(계획)26년 매출매입 월별계획'!$V:$V,"매출") -> 1.966594e+09 | I9: =SUMIFS('(계획)26년 매출매입 월별계획'!I:I,'(계획)26년 매출매입 월별계획'!$T:$T,$B9,'(계획)26년 매출매입 월별계획'!$V:$V,"매출") -> 2.0665289e+09 | J9: =SUMIFS('(계획)26년 매출매입 월별계획'!J:J,'(계획)26년 매출매입 월별계획'!$T:$T,$B9,'(계획)26년 매출매입 월별계획'!$V:$V,"매출") -> 2.1590029e+09 | K9: =SUMIFS('(계획)26년 매출매입 월별계획'!K:K,'(계획)26년 매출매입 월별계획'!$T:$T,$B9,'(계획)26년 매출매입 월별계획'!$V:$V,"매출") -> 1.7007817e+09 | L9: =SUMIFS('(계획)26년 매출매입 월별계획'!L:L,'(계획)26년 매출매입 월별계획'!$T:$T,$B9,'(계획)26년 매출매입 월별계획'!$V:$V,"매출") -> 1.2991653e+09 | M9: =SUMIFS('(계획)26년 매출매입 월별계획'!M:M,'(계획)26년 매출매입 월별계획'!$T:$T,$B9,'(계획)26년 매출매입 월별계획'!$V:$V,"매출") -> 1.7509651e+09 | N9: =SUMIFS('(계획)26년 매출매입 월별계획'!N:N,'(계획)26년 매출매입 월별계획'!$T:$T,$B9,'(계획)26년 매출매입 월별계획'!$V:$V,"매출") -> 1.8953783e+09 | O9: =SUMIFS('(계획)26년 매출매입 월별계획'!O:O,'(계획)26년 매출매입 월별계획'!$T:$T,$B9,'(계획)26년 매출매입 월별계획'!$V:$V,"매출") -> 1.7841573e+09 | P9: =SUMIFS('(계획)26년 매출매입 월별계획'!P:P,'(계획)26년 매출매입 월별계획'!$T:$T,$B9,'(계획)26년 매출매입 월별계획'!$V:$V,"매출") -> 1.971425e+09
B10: 기타 | C10: =SUM(E10:P10) -> 16389558229 | E10: =SUMIFS('(계획)26년 매출매입 월별계획'!E:E,'(계획)26년 매출매입 월별계획'!$R:$R,'(계획)손익계산서 월별계획'!$B$10,'(계획)26년 매출매입 월별계획'!$V:$V,"매출") -> 0 | F10: =SUMIFS('(계획)26년 매출매입 월별계획'!F:F,'(계획)26년 매출매입 월별계획'!$R:$R,'(계획)손익계산서 월별계획'!$B$10,'(계획)26년 매출매입 월별계획'!$V:$V,"매출") -> 0 | G10: =SUMIFS('(계획)26년 매출매입 월별계획'!G:G,'(계획)26년 매출매입 월별계획'!$R:$R,'(계획)손익계산서 월별계획'!$B$10,'(계획)26년 매출매입 월별계획'!$V:$V,"매출") -> 506663000 | H10: =SUMIFS('(계획)26년 매출매입 월별계획'!H:H,'(계획)26년 매출매입 월별계획'!$R:$R,'(계획)손익계산서 월별계획'!$B$10,'(계획)26년 매출매입 월별계획'!$V:$V,"매출") -> 2992396000 | I10: =SUMIFS('(계획)26년 매출매입 월별계획'!I:I,'(계획)26년 매출매입 월별계획'!$R:$R,'(계획)손익계산서 월별계획'!$B$10,'(계획)26년 매출매입 월별계획'!$V:$V,"매출") -> 72100000 | J10: =SUMIFS('(계획)26년 매출매입 월별계획'!J:J,'(계획)26년 매출매입 월별계획'!$R:$R,'(계획)손익계산서 월별계획'!$B$10,'(계획)26년 매출매입 월별계획'!$V:$V,"매출") -> 1335994400 | K10: =SUMIFS('(계획)26년 매출매입 월별계획'!K:K,'(계획)26년 매출매입 월별계획'!$R:$R,'(계획)손익계산서 월별계획'!$B$10,'(계획)26년 매출매입 월별계획'!$V:$V,"매출") -> 1446683600 | L10: =SUMIFS('(계획)26년 매출매입 월별계획'!L:L,'(계획)26년 매출매입 월별계획'!$R:$R,'(계획)손익계산서 월별계획'!$B$10,'(계획)26년 매출매입 월별계획'!$V:$V,"매출") -> 0 | M10: =SUMIFS('(계획)26년 매출매입 월별계획'!M:M,'(계획)26년 매출매입 월별계획'!$R:$R,'(계획)손익계산서 월별계획'!$B$10,'(계획)26년 매출매입 월별계획'!$V:$V,"매출") -> 158505000 | N10: =SUMIFS('(계획)26년 매출매입 월별계획'!N:N,'(계획)26년 매출매입 월별계획'!$R:$R,'(계획)손익계산서 월별계획'!$B$10,'(계획)26년 매출매입 월별계획'!$V:$V,"매출") -> 0 | O10: =SUMIFS('(계획)26년 매출매입 월별계획'!O:O,'(계획)26년 매출매입 월별계획'!$R:$R,'(계획)손익계산서 월별계획'!$B$10,'(계획)26년 매출매입 월별계획'!$V:$V,"매출") -> 0 | P10: =SUMIFS('(계획)26년 매출매입 월별계획'!P:P,'(계획)26년 매출매입 월별계획'!$R:$R,'(계획)손익계산서 월별계획'!$B$10,'(계획)26년 매출매입 월별계획'!$V:$V,"매출") -> 9877216229
B11: Ⅱ. 매출원가 | C11: =SUM(E11:P11) -> 4.0951464e+10 | E11: =SUM(E12:E15) -> 1.6463422e+09 | F11: =SUM(F12:F15) -> 2.0091019e+09 | G11: =SUM(G12:G15) -> 2.5235449e+09 | H11: =SUM(H12:H15) -> 5.3849733e+09 | I11: =SUM(I12:I15) -> 2.5856495e+09 | J11: =SUM(J12:J15) -> 2.9354813e+09 | K11: =SUM(K12:K15) -> 3.6868062e+09 | L11: =SUM(L12:L15) -> 1.7355754e+09 | ... P11: =SUM(P12:P15) -> 1.1654289e+10
B12: W/H | C12: =SUM(E12:P12) -> 0 | E12: =SUMIFS('(계획)26년 매출매입 월별계획'!E:E,'(계획)26년 매출매입 월별계획'!$T:$T,$B12,'(계획)26년 매출매입 월별계획'!$V:$V,"매입") -> 0 | F12: =SUMIFS('(계획)26년 매출매입 월별계획'!F:F,'(계획)26년 매출매입 월별계획'!$T:$T,$B12,'(계획)26년 매출매입 월별계획'!$V:$V,"매입") -> 0 | G12: =SUMIFS('(계획)26년 매출매입 월별계획'!G:G,'(계획)26년 매출매입 월별계획'!$T:$T,$B12,'(계획)26년 매출매입 월별계획'!$V:$V,"매입") -> 0 | H12: =SUMIFS('(계획)26년 매출매입 월별계획'!H:H,'(계획)26년 매출매입 월별계획'!$T:$T,$B12,'(계획)26년 매출매입 월별계획'!$V:$V,"매입") -> 0 | I12: =SUMIFS('(계획)26년 매출매입 월별계획'!I:I,'(계획)26년 매출매입 월별계획'!$T:$T,$B12,'(계획)26년 매출매입 월별계획'!$V:$V,"매입") -> 0 | J12: =SUMIFS('(계획)26년 매출매입 월별계획'!J:J,'(계획)26년 매출매입 월별계획'!$T:$T,$B12,'(계획)26년 매출매입 월별계획'!$V:$V,"매입") -> 0 | K12: =SUMIFS('(계획)26년 매출매입 월별계획'!K:K,'(계획)26년 매출매입 월별계획'!$T:$T,$B12,'(계획)26년 매출매입 월별계획'!$V:$V,"매입") -> 0 | L12: =SUMIFS('(계획)26년 매출매입 월별계획'!L:L,'(계획)26년 매출매입 월별계획'!$T:$T,$B12,'(계획)26년 매출매입 월별계획'!$V:$V,"매입") -> 0 | M12: =SUMIFS('(계획)26년 매출매입 월별계획'!M:M,'(계획)26년 매출매입 월별계획'!$T:$T,$B12,'(계획)26년 매출매입 월별계획'!$V:$V,"매입") -> 0 | N12: =SUMIFS('(계획)26년 매출매입 월별계획'!N:N,'(계획)26년 매출매입 월별계획'!$T:$T,$B12,'(계획)26년 매출매입 월별계획'!$V:$V,"매입") -> 0 | O12: =SUMIFS('(계획)26년 매출매입 월별계획'!O:O,'(계획)26년 매출매입 월별계획'!$T:$T,$B12,'(계획)26년 매출매입 월별계획'!$V:$V,"매입") -> 0 | P12: =SUMIFS('(계획)26년 매출매입 월별계획'!P:P,'(계획)26년 매출매입 월별계획'!$T:$T,$B12,'(계획)26년 매출매입 월별계획'!$V:$V,"매입") -> 0
B13: 상품 | C13: =SUM(E13:P13) -> 5125883039 | D13: 0 | E13: =SUMIFS('(계획)26년 매출매입 월별계획'!E:E,'(계획)26년 매출매입 월별계획'!$T:$T,$B13,'(계획)26년 매출매입 월별계획'!$V:$V,"매입") -> 154758500 | F13: =SUMIFS('(계획)26년 매출매입 월별계획'!F:F,'(계획)26년 매출매입 월별계획'!$T:$T,$B13,'(계획)26년 매출매입 월별계획'!$V:$V,"매입") -> 261536528 | G13: =SUMIFS('(계획)26년 매출매입 월별계획'!G:G,'(계획)26년 매출매입 월별계획'!$T:$T,$B13,'(계획)26년 매출매입 월별계획'!$V:$V,"매입") -> 3.205398e+08 | H13: =SUMIFS('(계획)26년 매출매입 월별계획'!H:H,'(계획)26년 매출매입 월별계획'!$T:$T,$B13,'(계획)26년 매출매입 월별계획'!$V:$V,"매입") -> 517598810 | I13: =SUMIFS('(계획)26년 매출매입 월별계획'!I:I,'(계획)26년 매출매입 월별계획'!$T:$T,$B13,'(계획)26년 매출매입 월별계획'!$V:$V,"매입") -> 506557096 | J13: =SUMIFS('(계획)26년 매출매입 월별계획'!J:J,'(계획)26년 매출매입 월별계획'!$T:$T,$B13,'(계획)26년 매출매입 월별계획'!$V:$V,"매입") -> 510213692 | K13: =SUMIFS('(계획)26년 매출매입 월별계획'!K:K,'(계획)26년 매출매입 월별계획'!$T:$T,$B13,'(계획)26년 매출매입 월별계획'!$V:$V,"매입") -> 5.8745998e+08 | L13: =SUMIFS('(계획)26년 매출매입 월별계획'!L:L,'(계획)26년 매출매입 월별계획'!$T:$T,$B13,'(계획)26년 매출매입 월별계획'!$V:$V,"매입") -> 4.7283164e+08 | M13: =SUMIFS('(계획)26년 매출매입 월별계획'!M:M,'(계획)26년 매출매입 월별계획'!$T:$T,$B13,'(계획)26년 매출매입 월별계획'!$V:$V,"매입") -> 4.7807161e+08 | N13: =SUMIFS('(계획)26년 매출매입 월별계획'!N:N,'(계획)26년 매출매입 월별계획'!$T:$T,$B13,'(계획)26년 매출매입 월별계획'!$V:$V,"매입") -> 4.3877179e+08 | O13: =SUMIFS('(계획)26년 매출매입 월별계획'!O:O,'(계획)26년 매출매입 월별계획'!$T:$T,$B13,'(계획)26년 매출매입 월별계획'!$V:$V,"매입") -> 4.3877179e+08 | P13: =SUMIFS('(계획)26년 매출매입 월별계획'!P:P,'(계획)26년 매출매입 월별계획'!$T:$T,$B13,'(계획)26년 매출매입 월별계획'!$V:$V,"매입") -> 4.3877179e+08
B14: 부품 | C14: =SUM(E14:P14) -> 2.1403973e+10 | E14: =SUMIFS('(계획)26년 매출매입 월별계획'!E:E,'(계획)26년 매출매입 월별계획'!$T:$T,$B14,'(계획)26년 매출매입 월별계획'!$V:$V,"매입") -> 1.4891561e+09 | F14: =SUMIFS('(계획)26년 매출매입 월별계획'!F:F,'(계획)26년 매출매입 월별계획'!$T:$T,$B14,'(계획)26년 매출매입 월별계획'!$V:$V,"매입") -> 1.7451378e+09 | G14: =SUMIFS('(계획)26년 매출매입 월별계획'!G:G,'(계획)26년 매출매입 월별계획'!$T:$T,$B14,'(계획)26년 매출매입 월별계획'!$V:$V,"매입") -> 2.0645775e+09 | H14: =SUMIFS('(계획)26년 매출매입 월별계획'!H:H,'(계획)26년 매출매입 월별계획'!$T:$T,$B14,'(계획)26년 매출매입 월별계획'!$V:$V,"매입") -> 1.9100469e+09 | I14: =SUMIFS('(계획)26년 매출매입 월별계획'!I:I,'(계획)26년 매출매입 월별계획'!$T:$T,$B14,'(계획)26년 매출매입 월별계획'!$V:$V,"매입") -> 2.0066648e+09 | J14: =SUMIFS('(계획)26년 매출매입 월별계획'!J:J,'(계획)26년 매출매입 월별계획'!$T:$T,$B14,'(계획)26년 매출매입 월별계획'!$V:$V,"매입") -> 2.0955401e+09 | K14: =SUMIFS('(계획)26년 매출매입 월별계획'!K:K,'(계획)26년 매출매입 월별계획'!$T:$T,$B14,'(계획)26년 매출매입 월별계획'!$V:$V,"매입") -> 1.6502351e+09 | L14: =SUMIFS('(계획)26년 매출매입 월별계획'!L:L,'(계획)26년 매출매입 월별계획'!$T:$T,$B14,'(계획)26년 매출매입 월별계획'!$V:$V,"매입") -> 1.2603162e+09 | M14: =SUMIFS('(계획)26년 매출매입 월별계획'!M:M,'(계획)26년 매출매입 월별계획'!$T:$T,$B14,'(계획)26년 매출매입 월별계획'!$V:$V,"매입") -> 1.6989568e+09 | N14: =SUMIFS('(계획)26년 매출매입 월별계획'!N:N,'(계획)26년 매출매입 월별계획'!$T:$T,$B14,'(계획)26년 매출매입 월별계획'!$V:$V,"매입") -> 1.8391638e+09 | O14: =SUMIFS('(계획)26년 매출매입 월별계획'!O:O,'(계획)26년 매출매입 월별계획'!$T:$T,$B14,'(계획)26년 매출매입 월별계획'!$V:$V,"매입") -> 1.7311822e+09 | P14: =SUMIFS('(계획)26년 매출매입 월별계획'!P:P,'(계획)26년 매출매입 월별계획'!$T:$T,$B14,'(계획)26년 매출매입 월별계획'!$V:$V,"매입") -> 1.9129955e+09
B15: 기타 | C15: =SUM(E15:P15) -> 1.4421608e+10 | E15: =SUMIFS('(계획)26년 매출매입 월별계획'!E:E,'(계획)26년 매출매입 월별계획'!$R:$R,'(계획)손익계산서 월별계획'!$B$15,'(계획)26년 매출매입 월별계획'!$V:$V,"매입") -> 2427572.4 | F15: =SUMIFS('(계획)26년 매출매입 월별계획'!F:F,'(계획)26년 매출매입 월별계획'!$R:$R,'(계획)손익계산서 월별계획'!$B$15,'(계획)26년 매출매입 월별계획'!$V:$V,"매입") -> 2427572.4 | G15: =SUMIFS('(계획)26년 매출매입 월별계획'!G:G,'(계획)26년 매출매입 월별계획'!$R:$R,'(계획)손익계산서 월별계획'!$B$15,'(계획)26년 매출매입 월별계획'!$V:$V,"매입") -> 1.3842757e+08 | H15: =SUMIFS('(계획)26년 매출매입 월별계획'!H:H,'(계획)26년 매출매입 월별계획'!$R:$R,'(계획)손익계산서 월별계획'!$B$15,'(계획)26년 매출매입 월별계획'!$V:$V,"매입") -> 2.9573276e+09 | I15: =SUMIFS('(계획)26년 매출매입 월별계획'!I:I,'(계획)26년 매출매입 월별계획'!$R:$R,'(계획)손익계산서 월별계획'!$B$15,'(계획)26년 매출매입 월별계획'!$V:$V,"매입") -> 72427572 | J15: =SUMIFS('(계획)26년 매출매입 월별계획'!J:J,'(계획)26년 매출매입 월별계획'!$R:$R,'(계획)손익계산서 월별계획'!$B$15,'(계획)26년 매출매입 월별계획'!$V:$V,"매입") -> 3.2972757e+08 | K15: =SUMIFS('(계획)26년 매출매입 월별계획'!K:K,'(계획)26년 매출매입 월별계획'!$R:$R,'(계획)손익계산서 월별계획'!$B$15,'(계획)26년 매출매입 월별계획'!$V:$V,"매입") -> 1.4491112e+09 | L15: =SUMIFS('(계획)26년 매출매입 월별계획'!L:L,'(계획)26년 매출매입 월별계획'!$R:$R,'(계획)손익계산서 월별계획'!$B$15,'(계획)26년 매출매입 월별계획'!$V:$V,"매입") -> 2427572.4 | M15: =SUMIFS('(계획)26년 매출매입 월별계획'!M:M,'(계획)26년 매출매입 월별계획'!$R:$R,'(계획)손익계산서 월별계획'!$B$15,'(계획)26년 매출매입 월별계획'!$V:$V,"매입") -> 1.5992757e+08 | N15: =SUMIFS('(계획)26년 매출매입 월별계획'!N:N,'(계획)26년 매출매입 월별계획'!$R:$R,'(계획)손익계산서 월별계획'!$B$15,'(계획)26년 매출매입 월별계획'!$V:$V,"매입") -> 2427572.4 | O15: =SUMIFS('(계획)26년 매출매입 월별계획'!O:O,'(계획)26년 매출매입 월별계획'!$R:$R,'(계획)손익계산서 월별계획'!$B$15,'(계획)26년 매출매입 월별계획'!$V:$V,"매입") -> 2427572.4 | P15: =SUMIFS('(계획)26년 매출매입 월별계획'!P:P,'(계획)26년 매출매입 월별계획'!$R:$R,'(계획)손익계산서 월별계획'!$B$15,'(계획)26년 매출매입 월별계획'!$V:$V,"매입") -> 9.3025212e+09
B16: Ⅲ. 매출총이익 | C16: =SUM(E16:P16) -> 6.5471122e+09 | D16: 0 | E16: =+E6-E11 -> 1.5563154e+08 | F16: =+F6-F11 -> 2.5806917e+08 | G16: =+G6-G11 -> 6.9014697e+08 | H16: =+H6-H11 -> 4.9069924e+08 | I16: =+I6-I11 -> 4.5035521e+08 | J16: =+J6-J11 -> 1.4632589e+09 | K16: =+K6-K11 -> 4.9303919e+08 | L16: =+L6-L11 -> 3.9609506e+08 | ... P16: =+P6-P11 -> 9.6577141e+08
B17: (이익률) | C17: =IFERROR(C16/C6,0) -> 0.13783807 | D17: 0 | E17: =IFERROR(E16/E6,0) -> 0.086367264 | F17: =IFERROR(F16/F6,0) -> 0.11382872 | G17: =IFERROR(G16/G6,0) -> 0.21475207 | H17: =IFERROR(H16/H6,0) -> 0.083513715 | I17: =IFERROR(I16/I6,0) -> 0.14833811 | J17: =IFERROR(J16/J6,0) -> 0.33265408 | K17: =IFERROR(K16/K6,0) -> 0.11795632 | L17: =IFERROR(L16/L6,0) -> 0.1858144 | ... P17: =IFERROR(P16/P6,0) -> 0.07652669
B18: Ⅳ.판매관리비 | C18: =SUM(E18:P18) -> 1.6095021e+10 | E18: =SUM(E19,E35,E53) -> 1.367928e+09 | F18: =SUM(F19,F35,F53) -> 1.5471097e+09 | G18: =SUM(G19,G35,G53) -> 1.4827872e+09 | H18: =SUM(H19,H35,H53) -> 1.350987e+09 | I18: =SUM(I19,I35,I53) -> 1.1967927e+09 | J18: =SUM(J19,J35,J53) -> 1.3688464e+09 | K18: =SUM(K19,K35,K53) -> 1.291439e+09 | L18: =SUM(L19,L35,L53) -> 1.2417071e+09 | ... P18: =SUM(P19,P35,P53) -> 1.4385923e+09
B19: [판매비] | C19: =SUM(E19:P19) -> 1.6176997e+09 | E19: =SUM(E20:E33) -> 1.415064e+08 | F19: =SUM(F20:F33) -> 1.3831112e+08 | G19: =SUM(G20:G33) -> 1.3316199e+08 | H19: =SUM(H20:H33) -> 1.3375119e+08 | I19: =SUM(I20:I33) -> 1.1364247e+08 | J19: =SUM(J20:J33) -> 1.4080895e+08 | K19: =SUM(K20:K33) -> 1.1933504e+08 | L19: =SUM(L20:L33) -> 1.3302336e+08 | ... P19: =SUM(P20:P33) -> 1.5510538e+08
B20: 인건비 | C20: =SUM(E20:P20) -> 7.1526467e+08 | E20: =SUMIFS('(계획)비용계획 상세_26년'!K:K,'(계획)비용계획 상세_26년'!$I:$I,'(계획)손익계산서 월별계획'!$B$19,'(계획)비용계획 상세_26년'!$B:$B,'(계획)손익계산서 월별계획'!$B20) -> 56724044 | F20: =SUMIFS('(계획)비용계획 상세_26년'!L:L,'(계획)비용계획 상세_26년'!$I:$I,'(계획)손익계산서 월별계획'!$B$19,'(계획)비용계획 상세_26년'!$B:$B,'(계획)손익계산서 월별계획'!$B20) -> 65666944 | G20: =SUMIFS('(계획)비용계획 상세_26년'!M:M,'(계획)비용계획 상세_26년'!$I:$I,'(계획)손익계산서 월별계획'!$B$19,'(계획)비용계획 상세_26년'!$B:$B,'(계획)손익계산서 월별계획'!$B20) -> 55820911 | H20: =SUMIFS('(계획)비용계획 상세_26년'!N:N,'(계획)비용계획 상세_26년'!$I:$I,'(계획)손익계산서 월별계획'!$B$19,'(계획)비용계획 상세_26년'!$B:$B,'(계획)손익계산서 월별계획'!$B20) -> 60638160 | I20: =SUMIFS('(계획)비용계획 상세_26년'!O:O,'(계획)비용계획 상세_26년'!$I:$I,'(계획)손익계산서 월별계획'!$B$19,'(계획)비용계획 상세_26년'!$B:$B,'(계획)손익계산서 월별계획'!$B20) -> 50594871 | J20: =SUMIFS('(계획)비용계획 상세_26년'!P:P,'(계획)비용계획 상세_26년'!$I:$I,'(계획)손익계산서 월별계획'!$B$19,'(계획)비용계획 상세_26년'!$B:$B,'(계획)손익계산서 월별계획'!$B20) -> 62780442 | K20: =SUMIFS('(계획)비용계획 상세_26년'!Q:Q,'(계획)비용계획 상세_26년'!$I:$I,'(계획)손익계산서 월별계획'!$B$19,'(계획)비용계획 상세_26년'!$B:$B,'(계획)손익계산서 월별계획'!$B20) -> 59413755 | L20: =SUMIFS('(계획)비용계획 상세_26년'!R:R,'(계획)비용계획 상세_26년'!$I:$I,'(계획)손익계산서 월별계획'!$B$19,'(계획)비용계획 상세_26년'!$B:$B,'(계획)손익계산서 월별계획'!$B20) -> 56282442 | M20: =SUMIFS('(계획)비용계획 상세_26년'!S:S,'(계획)비용계획 상세_26년'!$I:$I,'(계획)손익계산서 월별계획'!$B$19,'(계획)비용계획 상세_26년'!$B:$B,'(계획)손익계산서 월별계획'!$B20) -> 56219110 | N20: =SUMIFS('(계획)비용계획 상세_26년'!T:T,'(계획)비용계획 상세_26년'!$I:$I,'(계획)손익계산서 월별계획'!$B$19,'(계획)비용계획 상세_26년'!$B:$B,'(계획)손익계산서 월별계획'!$B20) -> 60387440 | O20: =SUMIFS('(계획)비용계획 상세_26년'!U:U,'(계획)비용계획 상세_26년'!$I:$I,'(계획)손익계산서 월별계획'!$B$19,'(계획)비용계획 상세_26년'!$B:$B,'(계획)손익계산서 월별계획'!$B20) -> 63091228 | P20: =SUMIFS('(계획)비용계획 상세_26년'!V:V,'(계획)비용계획 상세_26년'!$I:$I,'(계획)손익계산서 월별계획'!$B$19,'(계획)비용계획 상세_26년'!$B:$B,'(계획)손익계산서 월별계획'!$B20) -> 67645323
