Workbook

Sheet 변경사항
A1: REV. | B1: Date | C1: Update | D1: Note | E1: change | G1: change | I1: change | K1: Basic price
A2: R1 | B2: 45983 | C2: Sales price change from KSCP on APR(CR) | D2: EV2020 | E2: 16.92 | F2: usd | G2: =E2*RSDUSD25 -> 1692 | H2: rsd | I2: =G2*KRWRSD25 -> 23688 | J2: krw | K2: 17.44
C3: Sales price change from KSCP on JUN(AS price) | D3: PSA SDN | E3: 144.4 | F3: usd | G3: =E3*RSDUSD25 -> 14440 | H3: rsd | I3: =G3*KRWRSD25 -> 202160 | J3: krw | K3: 98.23
C4: exchange rate for 2026 | D4: PL/MC in KRW
C5: labor change 10% | D5: All
A6: R2 | B6: 45986 | C6: Decrease direct worker | D6: 11 People
C7: Decrease Korean | D7: 2 people from Apr
A8: R3 | B8: 45987 | C8: EV-V4 volume change and decrease direct wokers | D8: EV-V4
A9: R4 | B9: 46013 | C9: LG 2026Y price apply
A10: Final | B10: 46035 | C10: EV-V4 Price Update | D10: EV-V4

Sheet Work Calendar
H2: CY2026 | J2: Jan | L2: Feb | N2: Mar | P2: Apr | R2: May | T2: Jun | V2: Jul | X2: Aug | Z2: Sep | AB2: Oct | AD2: Nov | AF2: Dec
C3: Calendar Days | H3: =SUM(J3:AG3) -> 365 | J3: 31 | L3: 28 | N3: 31 | P3: 30 | R3: 31 | T3: 30 | V3: 31 | X3: 31 | Z3: 30 | AB3: 31 | AD3: 30 | AF3: 31
C4: Working days | H4: =SUM(J4:AG4) -> 240 | J4: 17 | L4: 18 | N4: 22 | P4: 20 | R4: 20 | T4: 22 | V4: 18 | X4: 16 | Z4: 22 | AB4: 22 | AD4: 20 | AF4: 23
C5: Non-working days | H5: =SUM(J5:AG5) -> 125 | J5: 14 | L5: 10 | N5: 9 | P5: 10 | R5: 11 | T5: 8 | V5: 13 | X5: 15 | Z5: 8 | AB5: 9 | AD5: 10 | AF5: 8
C7: WORK Calendar of KSCE | AD7: 2026
C9: January | K9: February | S9: March | AA9: April
C10: Su | D10: Mo | E10: Tu | F10: We | G10: Th | H10: Fr | I10: Sa | K10: Su | L10: Mo | M10: Tu | N10: We | O10: Th | P10: Fr | Q10: Sa | S10: Su | T10: Mo | U10: Tu | V10: We | W10: Th | X10: Fr | Y10: Sa | AA10: Su | AB10: Mo | AC10: Tu | AD10: We | AE10: Th | AF10: Fr | AG10: Sa
B11: CW1 | C11: =IF(DAY(JanSun1)=1,"",IF(AND(YEAR(JanSun1+1)=CalendarYear,MONTH(JanSun1+1)=1),JanSun1+1,"")) | D11: =IF(DAY(JanSun1)=1,"",IF(AND(YEAR(JanSun1+2)=CalendarYear,MONTH(JanSun1+2)=1),JanSun1+2,"")) | E11: =IF(DAY(JanSun1)=1,"",IF(AND(YEAR(JanSun1+3)=CalendarYear,MONTH(JanSun1+3)=1),JanSun1+3,"")) | F11: =IF(DAY(JanSun1)=1,"",IF(AND(YEAR(JanSun1+4)=CalendarYear,MONTH(JanSun1+4)=1),JanSun1+4,"")) | G11: =IF(DAY(JanSun1)=1,"",IF(AND(YEAR(JanSun1+5)=CalendarYear,MONTH(JanSun1+5)=1),JanSun1+5,"")) -> 46023 | H11: =IF(DAY(JanSun1)=1,"",IF(AND(YEAR(JanSun1+6)=CalendarYear,MONTH(JanSun1+6)=1),JanSun1+6,"")) -> 46024 | I11: =IF(DAY(JanSun1)=1,IF(AND(YEAR(JanSun1)=CalendarYear,MONTH(JanSun1)=1),JanSun1,""),IF(AND(YEAR(JanSun1+7)=CalendarYear,MONTH(JanSun1+7)=1),JanSun1+7,"")) -> 46025 | J11: CW5 | K11: =IF(DAY(FebSun1)=1,"",IF(AND(YEAR(FebSun1+1)=CalendarYear,MONTH(FebSun1+1)=2),FebSun1+1,"")) -> 46054 | L11: =IF(DAY(FebSun1)=1,"",IF(AND(YEAR(FebSun1+2)=CalendarYear,MONTH(FebSun1+2)=2),FebSun1+2,"")) -> 46055 | M11: =IF(DAY(FebSun1)=1,"",IF(AND(YEAR(FebSun1+3)=CalendarYear,MONTH(FebSun1+3)=2),FebSun1+3,"")) -> 46056 | N11: =IF(DAY(FebSun1)=1,"",IF(AND(YEAR(FebSun1+4)=CalendarYear,MONTH(FebSun1+4)=2),FebSun1+4,"")) -> 46057 | O11: =IF(DAY(FebSun1)=1,"",IF(AND(YEAR(FebSun1+5)=CalendarYear,MONTH(FebSun1+5)=2),FebSun1+5,"")) -> 46058 | P11: =IF(DAY(FebSun1)=1,"",IF(AND(YEAR(FebSun1+6)=CalendarYear,MONTH(FebSun1+6)=2),FebSun1+6,"")) -> 46059 | Q11: =IF(DAY(FebSun1)=1,IF(AND(YEAR(FebSun1)=CalendarYear,MONTH(FebSun1)=2),FebSun1,""),IF(AND(YEAR(FebSun1+7)=CalendarYear,MONTH(FebSun1+7)=2),FebSun1+7,"")) -> 46060 | R11: CW9 | S11: =IF(DAY(MarSun1)=1,"",IF(AND(YEAR(MarSun1+1)=CalendarYear,MONTH(MarSun1+1)=3),MarSun1+1,"")) -> 46082 | T11: =IF(DAY(MarSun1)=1,"",IF(AND(YEAR(MarSun1+2)=CalendarYear,MONTH(MarSun1+2)=3),MarSun1+2,"")) -> 46083 | U11: =IF(DAY(MarSun1)=1,"",IF(AND(YEAR(MarSun1+3)=CalendarYear,MONTH(MarSun1+3)=3),MarSun1+3,"")) -> 46084 | V11: =IF(DAY(MarSun1)=1,"",IF(AND(YEAR(MarSun1+4)=CalendarYear,MONTH(MarSun1+4)=3),MarSun1+4,"")) -> 46085 | W11: =IF(DAY(MarSun1)=1,"",IF(AND(YEAR(MarSun1+5)=CalendarYear,MONTH(MarSun1+5)=3),MarSun1+5,"")) -> 46086 | X11: =IF(DAY(MarSun1)=1,"",IF(AND(YEAR(MarSun1+6)=CalendarYear,MONTH(MarSun1+6)=3),MarSun1+6,"")) -> 46087 | Y11: =IF(DAY(MarSun1)=1,IF(AND(YEAR(MarSun1)=CalendarYear,MONTH(MarSun1)=3),MarSun1,""),IF(AND(YEAR(MarSun1+7)=CalendarYear,MONTH(MarSun1+7)=3),MarSun1+7,"")) -> 46088 | Z11: CW14 | AA11: =IF(DAY(AprSun1)=1,"",IF(AND(YEAR(AprSun1+1)=CalendarYear,MONTH(AprSun1+1)=4),AprSun1+1,"")) | AB11: =IF(DAY(AprSun1)=1,"",IF(AND(YEAR(AprSun1+2)=CalendarYear,MONTH(AprSun1+2)=4),AprSun1+2,"")) | AC11: =IF(DAY(AprSun1)=1,"",IF(AND(YEAR(AprSun1+3)=CalendarYear,MONTH(AprSun1+3)=4),AprSun1+3,"")) | AD11: =IF(DAY(AprSun1)=1,"",IF(AND(YEAR(AprSun1+4)=CalendarYear,MONTH(AprSun1+4)=4),AprSun1+4,"")) -> 46113 | AE11: =IF(DAY(AprSun1)=1,"",IF(AND(YEAR(AprSun1+5)=CalendarYear,MONTH(AprSun1+5)=4),AprSun1+5,"")) -> 46114 | AF11: =IF(DAY(AprSun1)=1,"",IF(AND(YEAR(AprSun1+6)=CalendarYear,MONTH(AprSun1+6)=4),AprSun1+6,"")) -> 46115 | AG11: =IF(DAY(AprSun1)=1,IF(AND(YEAR(AprSun1)=CalendarYear,MONTH(AprSun1)=4),AprSun1,""),IF(AND(YEAR(AprSun1+7)=CalendarYear,MONTH(AprSun1+7)=4),AprSun1+7,"")) -> 46116
B12: CW2 | C12: =IF(DAY(JanSun1)=1,IF(AND(YEAR(JanSun1+1)=CalendarYear,MONTH(JanSun1+1)=1),JanSun1+1,""),IF(AND(YEAR(JanSun1+8)=CalendarYear,MONTH(JanSun1+8)=1),JanSun1+8,"")) -> 46026 | D12: =IF(DAY(JanSun1)=1,IF(AND(YEAR(JanSun1+2)=CalendarYear,MONTH(JanSun1+2)=1),JanSun1+2,""),IF(AND(YEAR(JanSun1+9)=CalendarYear,MONTH(JanSun1+9)=1),JanSun1+9,"")) -> 46027 | E12: =IF(DAY(JanSun1)=1,IF(AND(YEAR(JanSun1+3)=CalendarYear,MONTH(JanSun1+3)=1),JanSun1+3,""),IF(AND(YEAR(JanSun1+10)=CalendarYear,MONTH(JanSun1+10)=1),JanSun1+10,"")) -> 46028 | F12: =IF(DAY(JanSun1)=1,IF(AND(YEAR(JanSun1+4)=CalendarYear,MONTH(JanSun1+4)=1),JanSun1+4,""),IF(AND(YEAR(JanSun1+11)=CalendarYear,MONTH(JanSun1+11)=1),JanSun1+11,"")) -> 46029 | G12: =IF(DAY(JanSun1)=1,IF(AND(YEAR(JanSun1+5)=CalendarYear,MONTH(JanSun1+5)=1),JanSun1+5,""),IF(AND(YEAR(JanSun1+12)=CalendarYear,MONTH(JanSun1+12)=1),JanSun1+12,"")) -> 46030 | H12: =IF(DAY(JanSun1)=1,IF(AND(YEAR(JanSun1+6)=CalendarYear,MONTH(JanSun1+6)=1),JanSun1+6,""),IF(AND(YEAR(JanSun1+13)=CalendarYear,MONTH(JanSun1+13)=1),JanSun1+13,"")) -> 46031 | I12: =IF(DAY(JanSun1)=1,IF(AND(YEAR(JanSun1+7)=CalendarYear,MONTH(JanSun1+7)=1),JanSun1+7,""),IF(AND(YEAR(JanSun1+14)=CalendarYear,MONTH(JanSun1+14)=1),JanSun1+14,"")) -> 46032 | J12: CW6 | K12: =IF(DAY(FebSun1)=1,IF(AND(YEAR(FebSun1+1)=CalendarYear,MONTH(FebSun1+1)=2),FebSun1+1,""),IF(AND(YEAR(FebSun1+8)=CalendarYear,MONTH(FebSun1+8)=2),FebSun1+8,"")) -> 46061 | L12: =IF(DAY(FebSun1)=1,IF(AND(YEAR(FebSun1+2)=CalendarYear,MONTH(FebSun1+2)=2),FebSun1+2,""),IF(AND(YEAR(FebSun1+9)=CalendarYear,MONTH(FebSun1+9)=2),FebSun1+9,"")) -> 46062 | M12: =IF(DAY(FebSun1)=1,IF(AND(YEAR(FebSun1+3)=CalendarYear,MONTH(FebSun1+3)=2),FebSun1+3,""),IF(AND(YEAR(FebSun1+10)=CalendarYear,MONTH(FebSun1+10)=2),FebSun1+10,"")) -> 46063 | N12: =IF(DAY(FebSun1)=1,IF(AND(YEAR(FebSun1+4)=CalendarYear,MONTH(FebSun1+4)=2),FebSun1+4,""),IF(AND(YEAR(FebSun1+11)=CalendarYear,MONTH(FebSun1+11)=2),FebSun1+11,"")) -> 46064 | O12: =IF(DAY(FebSun1)=1,IF(AND(YEAR(FebSun1+5)=CalendarYear,MONTH(FebSun1+5)=2),FebSun1+5,""),IF(AND(YEAR(FebSun1+12)=CalendarYear,MONTH(FebSun1+12)=2),FebSun1+12,"")) -> 46065 | P12: =IF(DAY(FebSun1)=1,IF(AND(YEAR(FebSun1+6)=CalendarYear,MONTH(FebSun1+6)=2),FebSun1+6,""),IF(AND(YEAR(FebSun1+13)=CalendarYear,MONTH(FebSun1+13)=2),FebSun1+13,"")) -> 46066 | Q12: =IF(DAY(FebSun1)=1,IF(AND(YEAR(FebSun1+7)=CalendarYear,MONTH(FebSun1+7)=2),FebSun1+7,""),IF(AND(YEAR(FebSun1+14)=CalendarYear,MONTH(FebSun1+14)=2),FebSun1+14,"")) -> 46067 | R12: CW10 | S12: =IF(DAY(MarSun1)=1,IF(AND(YEAR(MarSun1+1)=CalendarYear,MONTH(MarSun1+1)=3),MarSun1+1,""),IF(AND(YEAR(MarSun1+8)=CalendarYear,MONTH(MarSun1+8)=3),MarSun1+8,"")) -> 46089 | T12: =IF(DAY(MarSun1)=1,IF(AND(YEAR(MarSun1+2)=CalendarYear,MONTH(MarSun1+2)=3),MarSun1+2,""),IF(AND(YEAR(MarSun1+9)=CalendarYear,MONTH(MarSun1+9)=3),MarSun1+9,"")) -> 46090 | U12: =IF(DAY(MarSun1)=1,IF(AND(YEAR(MarSun1+3)=CalendarYear,MONTH(MarSun1+3)=3),MarSun1+3,""),IF(AND(YEAR(MarSun1+10)=CalendarYear,MONTH(MarSun1+10)=3),MarSun1+10,"")) -> 46091 | V12: =IF(DAY(MarSun1)=1,IF(AND(YEAR(MarSun1+4)=CalendarYear,MONTH(MarSun1+4)=3),MarSun1+4,""),IF(AND(YEAR(MarSun1+11)=CalendarYear,MONTH(MarSun1+11)=3),MarSun1+11,"")) -> 46092 | W12: =IF(DAY(MarSun1)=1,IF(AND(YEAR(MarSun1+5)=CalendarYear,MONTH(MarSun1+5)=3),MarSun1+5,""),IF(AND(YEAR(MarSun1+12)=CalendarYear,MONTH(MarSun1+12)=3),MarSun1+12,"")) -> 46093 | X12: =IF(DAY(MarSun1)=1,IF(AND(YEAR(MarSun1+6)=CalendarYear,MONTH(MarSun1+6)=3),MarSun1+6,""),IF(AND(YEAR(MarSun1+13)=CalendarYear,MONTH(MarSun1+13)=3),MarSun1+13,"")) -> 46094 | Y12: =IF(DAY(MarSun1)=1,IF(AND(YEAR(MarSun1+7)=CalendarYear,MONTH(MarSun1+7)=3),MarSun1+7,""),IF(AND(YEAR(MarSun1+14)=CalendarYear,MONTH(MarSun1+14)=3),MarSun1+14,"")) -> 46095 | Z12: CW15 | AA12: =IF(DAY(AprSun1)=1,IF(AND(YEAR(AprSun1+1)=CalendarYear,MONTH(AprSun1+1)=4),AprSun1+1,""),IF(AND(YEAR(AprSun1+8)=CalendarYear,MONTH(AprSun1+8)=4),AprSun1+8,"")) -> 46117 | AB12: =IF(DAY(AprSun1)=1,IF(AND(YEAR(AprSun1+2)=CalendarYear,MONTH(AprSun1+2)=4),AprSun1+2,""),IF(AND(YEAR(AprSun1+9)=CalendarYear,MONTH(AprSun1+9)=4),AprSun1+9,"")) -> 46118 | AC12: =IF(DAY(AprSun1)=1,IF(AND(YEAR(AprSun1+3)=CalendarYear,MONTH(AprSun1+3)=4),AprSun1+3,""),IF(AND(YEAR(AprSun1+10)=CalendarYear,MONTH(AprSun1+10)=4),AprSun1+10,"")) -> 46119 | AD12: =IF(DAY(AprSun1)=1,IF(AND(YEAR(AprSun1+4)=CalendarYear,MONTH(AprSun1+4)=4),AprSun1+4,""),IF(AND(YEAR(AprSun1+11)=CalendarYear,MONTH(AprSun1+11)=4),AprSun1+11,"")) -> 46120 | AE12: =IF(DAY(AprSun1)=1,IF(AND(YEAR(AprSun1+5)=CalendarYear,MONTH(AprSun1+5)=4),AprSun1+5,""),IF(AND(YEAR(AprSun1+12)=CalendarYear,MONTH(AprSun1+12)=4),AprSun1+12,"")) -> 46121 | AF12: =IF(DAY(AprSun1)=1,IF(AND(YEAR(AprSun1+6)=CalendarYear,MONTH(AprSun1+6)=4),AprSun1+6,""),IF(AND(YEAR(AprSun1+13)=CalendarYear,MONTH(AprSun1+13)=4),AprSun1+13,"")) -> 46122 | AG12: =IF(DAY(AprSun1)=1,IF(AND(YEAR(AprSun1+7)=CalendarYear,MONTH(AprSun1+7)=4),AprSun1+7,""),IF(AND(YEAR(AprSun1+14)=CalendarYear,MONTH(AprSun1+14)=4),AprSun1+14,"")) -> 46123
B13: CW3 | C13: =IF(DAY(JanSun1)=1,IF(AND(YEAR(JanSun1+8)=CalendarYear,MONTH(JanSun1+8)=1),JanSun1+8,""),IF(AND(YEAR(JanSun1+15)=CalendarYear,MONTH(JanSun1+15)=1),JanSun1+15,"")) -> 46033 | D13: =IF(DAY(JanSun1)=1,IF(AND(YEAR(JanSun1+9)=CalendarYear,MONTH(JanSun1+9)=1),JanSun1+9,""),IF(AND(YEAR(JanSun1+16)=CalendarYear,MONTH(JanSun1+16)=1),JanSun1+16,"")) -> 46034 | E13: =IF(DAY(JanSun1)=1,IF(AND(YEAR(JanSun1+10)=CalendarYear,MONTH(JanSun1+10)=1),JanSun1+10,""),IF(AND(YEAR(JanSun1+17)=CalendarYear,MONTH(JanSun1+17)=1),JanSun1+17,"")) -> 46035 | F13: =IF(DAY(JanSun1)=1,IF(AND(YEAR(JanSun1+11)=CalendarYear,MONTH(JanSun1+11)=1),JanSun1+11,""),IF(AND(YEAR(JanSun1+18)=CalendarYear,MONTH(JanSun1+18)=1),JanSun1+18,"")) -> 46036 | G13: =IF(DAY(JanSun1)=1,IF(AND(YEAR(JanSun1+12)=CalendarYear,MONTH(JanSun1+12)=1),JanSun1+12,""),IF(AND(YEAR(JanSun1+19)=CalendarYear,MONTH(JanSun1+19)=1),JanSun1+19,"")) -> 46037 | H13: =IF(DAY(JanSun1)=1,IF(AND(YEAR(JanSun1+13)=CalendarYear,MONTH(JanSun1+13)=1),JanSun1+13,""),IF(AND(YEAR(JanSun1+20)=CalendarYear,MONTH(JanSun1+20)=1),JanSun1+20,"")) -> 46038 | I13: =IF(DAY(JanSun1)=1,IF(AND(YEAR(JanSun1+14)=CalendarYear,MONTH(JanSun1+14)=1),JanSun1+14,""),IF(AND(YEAR(JanSun1+21)=CalendarYear,MONTH(JanSun1+21)=1),JanSun1+21,"")) -> 46039 | J13: CW7 | K13: =IF(DAY(FebSun1)=1,IF(AND(YEAR(FebSun1+8)=CalendarYear,MONTH(FebSun1+8)=2),FebSun1+8,""),IF(AND(YEAR(FebSun1+15)=CalendarYear,MONTH(FebSun1+15)=2),FebSun1+15,"")) -> 46068 | L13: =IF(DAY(FebSun1)=1,IF(AND(YEAR(FebSun1+9)=CalendarYear,MONTH(FebSun1+9)=2),FebSun1+9,""),IF(AND(YEAR(FebSun1+16)=CalendarYear,MONTH(FebSun1+16)=2),FebSun1+16,"")) -> 46069 | M13: =IF(DAY(FebSun1)=1,IF(AND(YEAR(FebSun1+10)=CalendarYear,MONTH(FebSun1+10)=2),FebSun1+10,""),IF(AND(YEAR(FebSun1+17)=CalendarYear,MONTH(FebSun1+17)=2),FebSun1+17,"")) -> 46070 | N13: =IF(DAY(FebSun1)=1,IF(AND(YEAR(FebSun1+11)=CalendarYear,MONTH(FebSun1+11)=2),FebSun1+11,""),IF(AND(YEAR(FebSun1+18)=CalendarYear,MONTH(FebSun1+18)=2),FebSun1+18,"")) -> 46071 | O13: =IF(DAY(FebSun1)=1,IF(AND(YEAR(FebSun1+12)=CalendarYear,MONTH(FebSun1+12)=2),FebSun1+12,""),IF(AND(YEAR(FebSun1+19)=CalendarYear,MONTH(FebSun1+19)=2),FebSun1+19,"")) -> 46072 | P13: =IF(DAY(FebSun1)=1,IF(AND(YEAR(FebSun1+13)=CalendarYear,MONTH(FebSun1+13)=2),FebSun1+13,""),IF(AND(YEAR(FebSun1+20)=CalendarYear,MONTH(FebSun1+20)=2),FebSun1+20,"")) -> 46073 | Q13: =IF(DAY(FebSun1)=1,IF(AND(YEAR(FebSun1+14)=CalendarYear,MONTH(FebSun1+14)=2),FebSun1+14,""),IF(AND(YEAR(FebSun1+21)=CalendarYear,MONTH(FebSun1+21)=2),FebSun1+21,"")) -> 46074 | R13: CW11 | S13: =IF(DAY(MarSun1)=1,IF(AND(YEAR(MarSun1+8)=CalendarYear,MONTH(MarSun1+8)=3),MarSun1+8,""),IF(AND(YEAR(MarSun1+15)=CalendarYear,MONTH(MarSun1+15)=3),MarSun1+15,"")) -> 46096 | T13: =IF(DAY(MarSun1)=1,IF(AND(YEAR(MarSun1+9)=CalendarYear,MONTH(MarSun1+9)=3),MarSun1+9,""),IF(AND(YEAR(MarSun1+16)=CalendarYear,MONTH(MarSun1+16)=3),MarSun1+16,"")) -> 46097 | U13: =IF(DAY(MarSun1)=1,IF(AND(YEAR(MarSun1+10)=CalendarYear,MONTH(MarSun1+10)=3),MarSun1+10,""),IF(AND(YEAR(MarSun1+17)=CalendarYear,MONTH(MarSun1+17)=3),MarSun1+17,"")) -> 46098 | V13: =IF(DAY(MarSun1)=1,IF(AND(YEAR(MarSun1+11)=CalendarYear,MONTH(MarSun1+11)=3),MarSun1+11,""),IF(AND(YEAR(MarSun1+18)=CalendarYear,MONTH(MarSun1+18)=3),MarSun1+18,"")) -> 46099 | W13: =IF(DAY(MarSun1)=1,IF(AND(YEAR(MarSun1+12)=CalendarYear,MONTH(MarSun1+12)=3),MarSun1+12,""),IF(AND(YEAR(MarSun1+19)=CalendarYear,MONTH(MarSun1+19)=3),MarSun1+19,"")) -> 46100 | X13: =IF(DAY(MarSun1)=1,IF(AND(YEAR(MarSun1+13)=CalendarYear,MONTH(MarSun1+13)=3),MarSun1+13,""),IF(AND(YEAR(MarSun1+20)=CalendarYear,MONTH(MarSun1+20)=3),MarSun1+20,"")) -> 46101 | Y13: =IF(DAY(MarSun1)=1,IF(AND(YEAR(MarSun1+14)=CalendarYear,MONTH(MarSun1+14)=3),MarSun1+14,""),IF(AND(YEAR(MarSun1+21)=CalendarYear,MONTH(MarSun1+21)=3),MarSun1+21,"")) -> 46102 | Z13: CW16 | AA13: =IF(DAY(AprSun1)=1,IF(AND(YEAR(AprSun1+8)=CalendarYear,MONTH(AprSun1+8)=4),AprSun1+8,""),IF(AND(YEAR(AprSun1+15)=CalendarYear,MONTH(AprSun1+15)=4),AprSun1+15,"")) -> 46124 | AB13: =IF(DAY(AprSun1)=1,IF(AND(YEAR(AprSun1+9)=CalendarYear,MONTH(AprSun1+9)=4),AprSun1+9,""),IF(AND(YEAR(AprSun1+16)=CalendarYear,MONTH(AprSun1+16)=4),AprSun1+16,"")) -> 46125 | AC13: =IF(DAY(AprSun1)=1,IF(AND(YEAR(AprSun1+10)=CalendarYear,MONTH(AprSun1+10)=4),AprSun1+10,""),IF(AND(YEAR(AprSun1+17)=CalendarYear,MONTH(AprSun1+17)=4),AprSun1+17,"")) -> 46126 | AD13: =IF(DAY(AprSun1)=1,IF(AND(YEAR(AprSun1+11)=CalendarYear,MONTH(AprSun1+11)=4),AprSun1+11,""),IF(AND(YEAR(AprSun1+18)=CalendarYear,MONTH(AprSun1+18)=4),AprSun1+18,"")) -> 46127 | AE13: =IF(DAY(AprSun1)=1,IF(AND(YEAR(AprSun1+12)=CalendarYear,MONTH(AprSun1+12)=4),AprSun1+12,""),IF(AND(YEAR(AprSun1+19)=CalendarYear,MONTH(AprSun1+19)=4),AprSun1+19,"")) -> 46128 | AF13: =IF(DAY(AprSun1)=1,IF(AND(YEAR(AprSun1+13)=CalendarYear,MONTH(AprSun1+13)=4),AprSun1+13,""),IF(AND(YEAR(AprSun1+20)=CalendarYear,MONTH(AprSun1+20)=4),AprSun1+20,"")) -> 46129 | AG13: =IF(DAY(AprSun1)=1,IF(AND(YEAR(AprSun1+14)=CalendarYear,MONTH(AprSun1+14)=4),AprSun1+14,""),IF(AND(YEAR(AprSun1+21)=CalendarYear,MONTH(AprSun1+21)=4),AprSun1+21,"")) -> 46130
B14: CW4 | C14: =IF(DAY(JanSun1)=1,IF(AND(YEAR(JanSun1+15)=CalendarYear,MONTH(JanSun1+15)=1),JanSun1+15,""),IF(AND(YEAR(JanSun1+22)=CalendarYear,MONTH(JanSun1+22)=1),JanSun1+22,"")) -> 46040 | D14: =IF(DAY(JanSun1)=1,IF(AND(YEAR(JanSun1+16)=CalendarYear,MONTH(JanSun1+16)=1),JanSun1+16,""),IF(AND(YEAR(JanSun1+23)=CalendarYear,MONTH(JanSun1+23)=1),JanSun1+23,"")) -> 46041 | E14: =IF(DAY(JanSun1)=1,IF(AND(YEAR(JanSun1+17)=CalendarYear,MONTH(JanSun1+17)=1),JanSun1+17,""),IF(AND(YEAR(JanSun1+24)=CalendarYear,MONTH(JanSun1+24)=1),JanSun1+24,"")) -> 46042 | F14: =IF(DAY(JanSun1)=1,IF(AND(YEAR(JanSun1+18)=CalendarYear,MONTH(JanSun1+18)=1),JanSun1+18,""),IF(AND(YEAR(JanSun1+25)=CalendarYear,MONTH(JanSun1+25)=1),JanSun1+25,"")) -> 46043 | G14: =IF(DAY(JanSun1)=1,IF(AND(YEAR(JanSun1+19)=CalendarYear,MONTH(JanSun1+19)=1),JanSun1+19,""),IF(AND(YEAR(JanSun1+26)=CalendarYear,MONTH(JanSun1+26)=1),JanSun1+26,"")) -> 46044 | H14: =IF(DAY(JanSun1)=1,IF(AND(YEAR(JanSun1+20)=CalendarYear,MONTH(JanSun1+20)=1),JanSun1+20,""),IF(AND(YEAR(JanSun1+27)=CalendarYear,MONTH(JanSun1+27)=1),JanSun1+27,"")) -> 46045 | I14: =IF(DAY(JanSun1)=1,IF(AND(YEAR(JanSun1+21)=CalendarYear,MONTH(JanSun1+21)=1),JanSun1+21,""),IF(AND(YEAR(JanSun1+28)=CalendarYear,MONTH(JanSun1+28)=1),JanSun1+28,"")) -> 46046 | J14: CW8 | K14: =IF(DAY(FebSun1)=1,IF(AND(YEAR(FebSun1+15)=CalendarYear,MONTH(FebSun1+15)=2),FebSun1+15,""),IF(AND(YEAR(FebSun1+22)=CalendarYear,MONTH(FebSun1+22)=2),FebSun1+22,"")) -> 46075 | L14: =IF(DAY(FebSun1)=1,IF(AND(YEAR(FebSun1+16)=CalendarYear,MONTH(FebSun1+16)=2),FebSun1+16,""),IF(AND(YEAR(FebSun1+23)=CalendarYear,MONTH(FebSun1+23)=2),FebSun1+23,"")) -> 46076 | M14: =IF(DAY(FebSun1)=1,IF(AND(YEAR(FebSun1+17)=CalendarYear,MONTH(FebSun1+17)=2),FebSun1+17,""),IF(AND(YEAR(FebSun1+24)=CalendarYear,MONTH(FebSun1+24)=2),FebSun1+24,"")) -> 46077 | N14: =IF(DAY(FebSun1)=1,IF(AND(YEAR(FebSun1+18)=CalendarYear,MONTH(FebSun1+18)=2),FebSun1+18,""),IF(AND(YEAR(FebSun1+25)=CalendarYear,MONTH(FebSun1+25)=2),FebSun1+25,"")) -> 46078 | O14: =IF(DAY(FebSun1)=1,IF(AND(YEAR(FebSun1+19)=CalendarYear,MONTH(FebSun1+19)=2),FebSun1+19,""),IF(AND(YEAR(FebSun1+26)=CalendarYear,MONTH(FebSun1+26)=2),FebSun1+26,"")) -> 46079 | P14: =IF(DAY(FebSun1)=1,IF(AND(YEAR(FebSun1+20)=CalendarYear,MONTH(FebSun1+20)=2),FebSun1+20,""),IF(AND(YEAR(FebSun1+27)=CalendarYear,MONTH(FebSun1+27)=2),FebSun1+27,"")) -> 46080 | Q14: =IF(DAY(FebSun1)=1,IF(AND(YEAR(FebSun1+21)=CalendarYear,MONTH(FebSun1+21)=2),FebSun1+21,""),IF(AND(YEAR(FebSun1+28)=CalendarYear,MONTH(FebSun1+28)=2),FebSun1+28,"")) -> 46081 | R14: CW12 | S14: =IF(DAY(MarSun1)=1,IF(AND(YEAR(MarSun1+15)=CalendarYear,MONTH(MarSun1+15)=3),MarSun1+15,""),IF(AND(YEAR(MarSun1+22)=CalendarYear,MONTH(MarSun1+22)=3),MarSun1+22,"")) -> 46103 | T14: =IF(DAY(MarSun1)=1,IF(AND(YEAR(MarSun1+16)=CalendarYear,MONTH(MarSun1+16)=3),MarSun1+16,""),IF(AND(YEAR(MarSun1+23)=CalendarYear,MONTH(MarSun1+23)=3),MarSun1+23,"")) -> 46104 | U14: =IF(DAY(MarSun1)=1,IF(AND(YEAR(MarSun1+17)=CalendarYear,MONTH(MarSun1+17)=3),MarSun1+17,""),IF(AND(YEAR(MarSun1+24)=CalendarYear,MONTH(MarSun1+24)=3),MarSun1+24,"")) -> 46105 | V14: =IF(DAY(MarSun1)=1,IF(AND(YEAR(MarSun1+18)=CalendarYear,MONTH(MarSun1+18)=3),MarSun1+18,""),IF(AND(YEAR(MarSun1+25)=CalendarYear,MONTH(MarSun1+25)=3),MarSun1+25,"")) -> 46106 | W14: =IF(DAY(MarSun1)=1,IF(AND(YEAR(MarSun1+19)=CalendarYear,MONTH(MarSun1+19)=3),MarSun1+19,""),IF(AND(YEAR(MarSun1+26)=CalendarYear,MONTH(MarSun1+26)=3),MarSun1+26,"")) -> 46107 | X14: =IF(DAY(MarSun1)=1,IF(AND(YEAR(MarSun1+20)=CalendarYear,MONTH(MarSun1+20)=3),MarSun1+20,""),IF(AND(YEAR(MarSun1+27)=CalendarYear,MONTH(MarSun1+27)=3),MarSun1+27,"")) -> 46108 | Y14: =IF(DAY(MarSun1)=1,IF(AND(YEAR(MarSun1+21)=CalendarYear,MONTH(MarSun1+21)=3),MarSun1+21,""),IF(AND(YEAR(MarSun1+28)=CalendarYear,MONTH(MarSun1+28)=3),MarSun1+28,"")) -> 46109 | Z14: CW17 | AA14: =IF(DAY(AprSun1)=1,IF(AND(YEAR(AprSun1+15)=CalendarYear,MONTH(AprSun1+15)=4),AprSun1+15,""),IF(AND(YEAR(AprSun1+22)=CalendarYear,MONTH(AprSun1+22)=4),AprSun1+22,"")) -> 46131 | AB14: =IF(DAY(AprSun1)=1,IF(AND(YEAR(AprSun1+16)=CalendarYear,MONTH(AprSun1+16)=4),AprSun1+16,""),IF(AND(YEAR(AprSun1+23)=CalendarYear,MONTH(AprSun1+23)=4),AprSun1+23,"")) -> 46132 | AC14: =IF(DAY(AprSun1)=1,IF(AND(YEAR(AprSun1+17)=CalendarYear,MONTH(AprSun1+17)=4),AprSun1+17,""),IF(AND(YEAR(AprSun1+24)=CalendarYear,MONTH(AprSun1+24)=4),AprSun1+24,"")) -> 46133 | AD14: =IF(DAY(AprSun1)=1,IF(AND(YEAR(AprSun1+18)=CalendarYear,MONTH(AprSun1+18)=4),AprSun1+18,""),IF(AND(YEAR(AprSun1+25)=CalendarYear,MONTH(AprSun1+25)=4),AprSun1+25,"")) -> 46134 | AE14: =IF(DAY(AprSun1)=1,IF(AND(YEAR(AprSun1+19)=CalendarYear,MONTH(AprSun1+19)=4),AprSun1+19,""),IF(AND(YEAR(AprSun1+26)=CalendarYear,MONTH(AprSun1+26)=4),AprSun1+26,"")) -> 46135 | AF14: =IF(DAY(AprSun1)=1,IF(AND(YEAR(AprSun1+20)=CalendarYear,MONTH(AprSun1+20)=4),AprSun1+20,""),IF(AND(YEAR(AprSun1+27)=CalendarYear,MONTH(AprSun1+27)=4),AprSun1+27,"")) -> 46136 | AG14: =IF(DAY(AprSun1)=1,IF(AND(YEAR(AprSun1+21)=CalendarYear,MONTH(AprSun1+21)=4),AprSun1+21,""),IF(AND(YEAR(AprSun1+28)=CalendarYear,MONTH(AprSun1+28)=4),AprSun1+28,"")) -> 46137
B15: CW5 | C15: =IF(DAY(JanSun1)=1,IF(AND(YEAR(JanSun1+22)=CalendarYear,MONTH(JanSun1+22)=1),JanSun1+22,""),IF(AND(YEAR(JanSun1+29)=CalendarYear,MONTH(JanSun1+29)=1),JanSun1+29,"")) -> 46047 | D15: =IF(DAY(JanSun1)=1,IF(AND(YEAR(JanSun1+23)=CalendarYear,MONTH(JanSun1+23)=1),JanSun1+23,""),IF(AND(YEAR(JanSun1+30)=CalendarYear,MONTH(JanSun1+30)=1),JanSun1+30,"")) -> 46048 | E15: =IF(DAY(JanSun1)=1,IF(AND(YEAR(JanSun1+24)=CalendarYear,MONTH(JanSun1+24)=1),JanSun1+24,""),IF(AND(YEAR(JanSun1+31)=CalendarYear,MONTH(JanSun1+31)=1),JanSun1+31,"")) -> 46049 | F15: =IF(DAY(JanSun1)=1,IF(AND(YEAR(JanSun1+25)=CalendarYear,MONTH(JanSun1+25)=1),JanSun1+25,""),IF(AND(YEAR(JanSun1+32)=CalendarYear,MONTH(JanSun1+32)=1),JanSun1+32,"")) -> 46050 | G15: =IF(DAY(JanSun1)=1,IF(AND(YEAR(JanSun1+26)=CalendarYear,MONTH(JanSun1+26)=1),JanSun1+26,""),IF(AND(YEAR(JanSun1+33)=CalendarYear,MONTH(JanSun1+33)=1),JanSun1+33,"")) -> 46051 | H15: =IF(DAY(JanSun1)=1,IF(AND(YEAR(JanSun1+27)=CalendarYear,MONTH(JanSun1+27)=1),JanSun1+27,""),IF(AND(YEAR(JanSun1+34)=CalendarYear,MONTH(JanSun1+34)=1),JanSun1+34,"")) -> 46052 | I15: =IF(DAY(JanSun1)=1,IF(AND(YEAR(JanSun1+28)=CalendarYear,MONTH(JanSun1+28)=1),JanSun1+28,""),IF(AND(YEAR(JanSun1+35)=CalendarYear,MONTH(JanSun1+35)=1),JanSun1+35,"")) -> 46053 | J15: CW9 | K15: =IF(DAY(FebSun1)=1,IF(AND(YEAR(FebSun1+22)=CalendarYear,MONTH(FebSun1+22)=2),FebSun1+22,""),IF(AND(YEAR(FebSun1+29)=CalendarYear,MONTH(FebSun1+29)=2),FebSun1+29,"")) | L15: =IF(DAY(FebSun1)=1,IF(AND(YEAR(FebSun1+23)=CalendarYear,MONTH(FebSun1+23)=2),FebSun1+23,""),IF(AND(YEAR(FebSun1+30)=CalendarYear,MONTH(FebSun1+30)=2),FebSun1+30,"")) | M15: =IF(DAY(FebSun1)=1,IF(AND(YEAR(FebSun1+24)=CalendarYear,MONTH(FebSun1+24)=2),FebSun1+24,""),IF(AND(YEAR(FebSun1+31)=CalendarYear,MONTH(FebSun1+31)=2),FebSun1+31,"")) | N15: =IF(DAY(FebSun1)=1,IF(AND(YEAR(FebSun1+25)=CalendarYear,MONTH(FebSun1+25)=2),FebSun1+25,""),IF(AND(YEAR(FebSun1+32)=CalendarYear,MONTH(FebSun1+32)=2),FebSun1+32,"")) | O15: =IF(DAY(FebSun1)=1,IF(AND(YEAR(FebSun1+26)=CalendarYear,MONTH(FebSun1+26)=2),FebSun1+26,""),IF(AND(YEAR(FebSun1+33)=CalendarYear,MONTH(FebSun1+33)=2),FebSun1+33,"")) | P15: =IF(DAY(FebSun1)=1,IF(AND(YEAR(FebSun1+27)=CalendarYear,MONTH(FebSun1+27)=2),FebSun1+27,""),IF(AND(YEAR(FebSun1+34)=CalendarYear,MONTH(FebSun1+34)=2),FebSun1+34,"")) | Q15: =IF(DAY(FebSun1)=1,IF(AND(YEAR(FebSun1+28)=CalendarYear,MONTH(FebSun1+28)=2),FebSun1+28,""),IF(AND(YEAR(FebSun1+35)=CalendarYear,MONTH(FebSun1+35)=2),FebSun1+35,"")) | R15: CW13 | S15: =IF(DAY(MarSun1)=1,IF(AND(YEAR(MarSun1+22)=CalendarYear,MONTH(MarSun1+22)=3),MarSun1+22,""),IF(AND(YEAR(MarSun1+29)=CalendarYear,MONTH(MarSun1+29)=3),MarSun1+29,"")) -> 46110 | T15: =IF(DAY(MarSun1)=1,IF(AND(YEAR(MarSun1+23)=CalendarYear,MONTH(MarSun1+23)=3),MarSun1+23,""),IF(AND(YEAR(MarSun1+30)=CalendarYear,MONTH(MarSun1+30)=3),MarSun1+30,"")) -> 46111 | U15: =IF(DAY(MarSun1)=1,IF(AND(YEAR(MarSun1+24)=CalendarYear,MONTH(MarSun1+24)=3),MarSun1+24,""),IF(AND(YEAR(MarSun1+31)=CalendarYear,MONTH(MarSun1+31)=3),MarSun1+31,"")) -> 46112 | V15: =IF(DAY(MarSun1)=1,IF(AND(YEAR(MarSun1+25)=CalendarYear,MONTH(MarSun1+25)=3),MarSun1+25,""),IF(AND(YEAR(MarSun1+32)=CalendarYear,MONTH(MarSun1+32)=3),MarSun1+32,"")) | W15: =IF(DAY(MarSun1)=1,IF(AND(YEAR(MarSun1+26)=CalendarYear,MONTH(MarSun1+26)=3),MarSun1+26,""),IF(AND(YEAR(MarSun1+33)=CalendarYear,MONTH(MarSun1+33)=3),MarSun1+33,"")) | X15: =IF(DAY(MarSun1)=1,IF(AND(YEAR(MarSun1+27)=CalendarYear,MONTH(MarSun1+27)=3),MarSun1+27,""),IF(AND(YEAR(MarSun1+34)=CalendarYear,MONTH(MarSun1+34)=3),MarSun1+34,"")) | Y15: =IF(DAY(MarSun1)=1,IF(AND(YEAR(MarSun1+28)=CalendarYear,MONTH(MarSun1+28)=3),MarSun1+28,""),IF(AND(YEAR(MarSun1+35)=CalendarYear,MONTH(MarSun1+35)=3),MarSun1+35,"")) | Z15: CW18 | AA15: =IF(DAY(AprSun1)=1,IF(AND(YEAR(AprSun1+22)=CalendarYear,MONTH(AprSun1+22)=4),AprSun1+22,""),IF(AND(YEAR(AprSun1+29)=CalendarYear,MONTH(AprSun1+29)=4),AprSun1+29,"")) -> 46138 | AB15: =IF(DAY(AprSun1)=1,IF(AND(YEAR(AprSun1+23)=CalendarYear,MONTH(AprSun1+23)=4),AprSun1+23,""),IF(AND(YEAR(AprSun1+30)=CalendarYear,MONTH(AprSun1+30)=4),AprSun1+30,"")) -> 46139 | AC15: =IF(DAY(AprSun1)=1,IF(AND(YEAR(AprSun1+24)=CalendarYear,MONTH(AprSun1+24)=4),AprSun1+24,""),IF(AND(YEAR(AprSun1+31)=CalendarYear,MONTH(AprSun1+31)=4),AprSun1+31,"")) -> 46140 | AD15: =IF(DAY(AprSun1)=1,IF(AND(YEAR(AprSun1+25)=CalendarYear,MONTH(AprSun1+25)=4),AprSun1+25,""),IF(AND(YEAR(AprSun1+32)=CalendarYear,MONTH(AprSun1+32)=4),AprSun1+32,"")) -> 46141 | AE15: =IF(DAY(AprSun1)=1,IF(AND(YEAR(AprSun1+26)=CalendarYear,MONTH(AprSun1+26)=4),AprSun1+26,""),IF(AND(YEAR(AprSun1+33)=CalendarYear,MONTH(AprSun1+33)=4),AprSun1+33,"")) -> 46142 | AF15: =IF(DAY(AprSun1)=1,IF(AND(YEAR(AprSun1+27)=CalendarYear,MONTH(AprSun1+27)=4),AprSun1+27,""),IF(AND(YEAR(AprSun1+34)=CalendarYear,MONTH(AprSun1+34)=4),AprSun1+34,"")) | AG15: =IF(DAY(AprSun1)=1,IF(AND(YEAR(AprSun1+28)=CalendarYear,MONTH(AprSun1+28)=4),AprSun1+28,""),IF(AND(YEAR(AprSun1+35)=CalendarYear,MONTH(AprSun1+35)=4),AprSun1+35,""))
C16: =IF(DAY(JanSun1)=1,IF(AND(YEAR(JanSun1+29)=CalendarYear,MONTH(JanSun1+29)=1),JanSun1+29,""),IF(AND(YEAR(JanSun1+36)=CalendarYear,MONTH(JanSun1+36)=1),JanSun1+36,"")) | D16: =IF(DAY(JanSun1)=1,IF(AND(YEAR(JanSun1+30)=CalendarYear,MONTH(JanSun1+30)=1),JanSun1+30,""),IF(AND(YEAR(JanSun1+37)=CalendarYear,MONTH(JanSun1+37)=1),JanSun1+37,"")) | E16: =IF(DAY(JanSun1)=1,IF(AND(YEAR(JanSun1+31)=CalendarYear,MONTH(JanSun1+31)=1),JanSun1+31,""),IF(AND(YEAR(JanSun1+38)=CalendarYear,MONTH(JanSun1+38)=1),JanSun1+38,"")) | F16: =IF(DAY(JanSun1)=1,IF(AND(YEAR(JanSun1+32)=CalendarYear,MONTH(JanSun1+32)=1),JanSun1+32,""),IF(AND(YEAR(JanSun1+39)=CalendarYear,MONTH(JanSun1+39)=1),JanSun1+39,"")) | G16: =IF(DAY(JanSun1)=1,IF(AND(YEAR(JanSun1+33)=CalendarYear,MONTH(JanSun1+33)=1),JanSun1+33,""),IF(AND(YEAR(JanSun1+40)=CalendarYear,MONTH(JanSun1+40)=1),JanSun1+40,"")) | H16: =IF(DAY(JanSun1)=1,IF(AND(YEAR(JanSun1+34)=CalendarYear,MONTH(JanSun1+34)=1),JanSun1+34,""),IF(AND(YEAR(JanSun1+41)=CalendarYear,MONTH(JanSun1+41)=1),JanSun1+41,"")) | I16: =IF(DAY(JanSun1)=1,IF(AND(YEAR(JanSun1+35)=CalendarYear,MONTH(JanSun1+35)=1),JanSun1+35,""),IF(AND(YEAR(JanSun1+42)=CalendarYear,MONTH(JanSun1+42)=1),JanSun1+42,"")) | K16: =IF(DAY(FebSun1)=1,IF(AND(YEAR(FebSun1+29)=CalendarYear,MONTH(FebSun1+29)=2),FebSun1+29,""),IF(AND(YEAR(FebSun1+36)=CalendarYear,MONTH(FebSun1+36)=2),FebSun1+36,"")) | L16: =IF(DAY(FebSun1)=1,IF(AND(YEAR(FebSun1+30)=CalendarYear,MONTH(FebSun1+30)=2),FebSun1+30,""),IF(AND(YEAR(FebSun1+37)=CalendarYear,MONTH(FebSun1+37)=2),FebSun1+37,"")) | M16: =IF(DAY(FebSun1)=1,IF(AND(YEAR(FebSun1+31)=CalendarYear,MONTH(FebSun1+31)=2),FebSun1+31,""),IF(AND(YEAR(FebSun1+38)=CalendarYear,MONTH(FebSun1+38)=2),FebSun1+38,"")) | N16: =IF(DAY(FebSun1)=1,IF(AND(YEAR(FebSun1+32)=CalendarYear,MONTH(FebSun1+32)=2),FebSun1+32,""),IF(AND(YEAR(FebSun1+39)=CalendarYear,MONTH(FebSun1+39)=2),FebSun1+39,"")) | O16: =IF(DAY(FebSun1)=1,IF(AND(YEAR(FebSun1+33)=CalendarYear,MONTH(FebSun1+33)=2),FebSun1+33,""),IF(AND(YEAR(FebSun1+40)=CalendarYear,MONTH(FebSun1+40)=2),FebSun1+40,"")) | P16: =IF(DAY(FebSun1)=1,IF(AND(YEAR(FebSun1+34)=CalendarYear,MONTH(FebSun1+34)=2),FebSun1+34,""),IF(AND(YEAR(FebSun1+41)=CalendarYear,MONTH(FebSun1+41)=2),FebSun1+41,"")) | Q16: =IF(DAY(FebSun1)=1,IF(AND(YEAR(FebSun1+35)=CalendarYear,MONTH(FebSun1+35)=2),FebSun1+35,""),IF(AND(YEAR(FebSun1+42)=CalendarYear,MONTH(FebSun1+42)=2),FebSun1+42,"")) | R16: CW14 | S16: =IF(DAY(MarSun1)=1,IF(AND(YEAR(MarSun1+29)=CalendarYear,MONTH(MarSun1+29)=3),MarSun1+29,""),IF(AND(YEAR(MarSun1+36)=CalendarYear,MONTH(MarSun1+36)=3),MarSun1+36,"")) | T16: =IF(DAY(MarSun1)=1,IF(AND(YEAR(MarSun1+30)=CalendarYear,MONTH(MarSun1+30)=3),MarSun1+30,""),IF(AND(YEAR(MarSun1+37)=CalendarYear,MONTH(MarSun1+37)=3),MarSun1+37,"")) | U16: =IF(DAY(MarSun1)=1,IF(AND(YEAR(MarSun1+31)=CalendarYear,MONTH(MarSun1+31)=3),MarSun1+31,""),IF(AND(YEAR(MarSun1+38)=CalendarYear,MONTH(MarSun1+38)=3),MarSun1+38,"")) | V16: =IF(DAY(MarSun1)=1,IF(AND(YEAR(MarSun1+32)=CalendarYear,MONTH(MarSun1+32)=3),MarSun1+32,""),IF(AND(YEAR(MarSun1+39)=CalendarYear,MONTH(MarSun1+39)=3),MarSun1+39,"")) | W16: =IF(DAY(MarSun1)=1,IF(AND(YEAR(MarSun1+33)=CalendarYear,MONTH(MarSun1+33)=3),MarSun1+33,""),IF(AND(YEAR(MarSun1+40)=CalendarYear,MONTH(MarSun1+40)=3),MarSun1+40,"")) | X16: =IF(DAY(MarSun1)=1,IF(AND(YEAR(MarSun1+34)=CalendarYear,MONTH(MarSun1+34)=3),MarSun1+34,""),IF(AND(YEAR(MarSun1+41)=CalendarYear,MONTH(MarSun1+41)=3),MarSun1+41,"")) | Y16: =IF(DAY(MarSun1)=1,IF(AND(YEAR(MarSun1+35)=CalendarYear,MONTH(MarSun1+35)=3),MarSun1+35,""),IF(AND(YEAR(MarSun1+42)=CalendarYear,MONTH(MarSun1+42)=3),MarSun1+42,"")) | AA16: =IF(DAY(AprSun1)=1,IF(AND(YEAR(AprSun1+29)=CalendarYear,MONTH(AprSun1+29)=4),AprSun1+29,""),IF(AND(YEAR(AprSun1+36)=CalendarYear,MONTH(AprSun1+36)=4),AprSun1+36,"")) | AB16: =IF(DAY(AprSun1)=1,IF(AND(YEAR(AprSun1+30)=CalendarYear,MONTH(AprSun1+30)=4),AprSun1+30,""),IF(AND(YEAR(AprSun1+37)=CalendarYear,MONTH(AprSun1+37)=4),AprSun1+37,"")) | AC16: =IF(DAY(AprSun1)=1,IF(AND(YEAR(AprSun1+31)=CalendarYear,MONTH(AprSun1+31)=4),AprSun1+31,""),IF(AND(YEAR(AprSun1+38)=CalendarYear,MONTH(AprSun1+38)=4),AprSun1+38,"")) | AD16: =IF(DAY(AprSun1)=1,IF(AND(YEAR(AprSun1+32)=CalendarYear,MONTH(AprSun1+32)=4),AprSun1+32,""),IF(AND(YEAR(AprSun1+39)=CalendarYear,MONTH(AprSun1+39)=4),AprSun1+39,"")) | AE16: =IF(DAY(AprSun1)=1,IF(AND(YEAR(AprSun1+33)=CalendarYear,MONTH(AprSun1+33)=4),AprSun1+33,""),IF(AND(YEAR(AprSun1+40)=CalendarYear,MONTH(AprSun1+40)=4),AprSun1+40,"")) | AF16: =IF(DAY(AprSun1)=1,IF(AND(YEAR(AprSun1+34)=CalendarYear,MONTH(AprSun1+34)=4),AprSun1+34,""),IF(AND(YEAR(AprSun1+41)=CalendarYear,MONTH(AprSun1+41)=4),AprSun1+41,"")) | AG16: =IF(DAY(AprSun1)=1,IF(AND(YEAR(AprSun1+35)=CalendarYear,MONTH(AprSun1+35)=4),AprSun1+35,""),IF(AND(YEAR(AprSun1+42)=CalendarYear,MONTH(AprSun1+42)=4),AprSun1+42,""))
C17: * New year(1st-2nd) | G17: *Big 5 Slava | K17: * Statehood Day(15th-16th) | S17: * Women’s day(8th) | AA17: * Easter (10th-13st)
C18: * Collective leave (3rd,6th) | K18: * Replacement(17th)
C19: * Christmas(7th)
C21: May | K21: June | S21: July | AA21: August
C22: Su | D22: Mo | E22: Tu | F22: We | G22: Th | H22: Fr | I22: Sa | K22: Su | L22: Mo | M22: Tu | N22: We | O22: Th | P22: Fr | Q22: Sa | S22: Su | T22: Mo | U22: Tu | V22: We | W22: Th | X22: Fr | Y22: Sa | AA22: Su | AB22: Mo | AC22: Tu | AD22: We | AE22: Th | AF22: Fr | AG22: Sa
B23: CW18 | C23: =IF(DAY(MaySun1)=1,"",IF(AND(YEAR(MaySun1+1)=CalendarYear,MONTH(MaySun1+1)=5),MaySun1+1,"")) | D23: =IF(DAY(MaySun1)=1,"",IF(AND(YEAR(MaySun1+2)=CalendarYear,MONTH(MaySun1+2)=5),MaySun1+2,"")) | E23: =IF(DAY(MaySun1)=1,"",IF(AND(YEAR(MaySun1+3)=CalendarYear,MONTH(MaySun1+3)=5),MaySun1+3,"")) | F23: =IF(DAY(MaySun1)=1,"",IF(AND(YEAR(MaySun1+4)=CalendarYear,MONTH(MaySun1+4)=5),MaySun1+4,"")) | G23: =IF(DAY(MaySun1)=1,"",IF(AND(YEAR(MaySun1+5)=CalendarYear,MONTH(MaySun1+5)=5),MaySun1+5,"")) | H23: =IF(DAY(MaySun1)=1,"",IF(AND(YEAR(MaySun1+6)=CalendarYear,MONTH(MaySun1+6)=5),MaySun1+6,"")) -> 46143 | I23: =IF(DAY(MaySun1)=1,IF(AND(YEAR(MaySun1)=CalendarYear,MONTH(MaySun1)=5),MaySun1,""),IF(AND(YEAR(MaySun1+7)=CalendarYear,MONTH(MaySun1+7)=5),MaySun1+7,"")) -> 46144 | J23: CW22 | K23: =IF(DAY(JunSun1)=1,"",IF(AND(YEAR(JunSun1+1)=CalendarYear,MONTH(JunSun1+1)=6),JunSun1+1,"")) | L23: =IF(DAY(JunSun1)=1,"",IF(AND(YEAR(JunSun1+2)=CalendarYear,MONTH(JunSun1+2)=6),JunSun1+2,"")) -> 46174 | M23: =IF(DAY(JunSun1)=1,"",IF(AND(YEAR(JunSun1+3)=CalendarYear,MONTH(JunSun1+3)=6),JunSun1+3,"")) -> 46175 | N23: =IF(DAY(JunSun1)=1,"",IF(AND(YEAR(JunSun1+4)=CalendarYear,MONTH(JunSun1+4)=6),JunSun1+4,"")) -> 46176 | O23: =IF(DAY(JunSun1)=1,"",IF(AND(YEAR(JunSun1+5)=CalendarYear,MONTH(JunSun1+5)=6),JunSun1+5,"")) -> 46177 | P23: =IF(DAY(JunSun1)=1,"",IF(AND(YEAR(JunSun1+6)=CalendarYear,MONTH(JunSun1+6)=6),JunSun1+6,"")) -> 46178 | Q23: =IF(DAY(JunSun1)=1,IF(AND(YEAR(JunSun1)=CalendarYear,MONTH(JunSun1)=6),JunSun1,""),IF(AND(YEAR(JunSun1+7)=CalendarYear,MONTH(JunSun1+7)=6),JunSun1+7,"")) -> 46179 | R23: CW27 | S23: =IF(DAY(JulSun1)=1,"",IF(AND(YEAR(JulSun1+1)=CalendarYear,MONTH(JulSun1+1)=7),JulSun1+1,"")) | T23: =IF(DAY(JulSun1)=1,"",IF(AND(YEAR(JulSun1+2)=CalendarYear,MONTH(JulSun1+2)=7),JulSun1+2,"")) | U23: =IF(DAY(JulSun1)=1,"",IF(AND(YEAR(JulSun1+3)=CalendarYear,MONTH(JulSun1+3)=7),JulSun1+3,"")) | V23: =IF(DAY(JulSun1)=1,"",IF(AND(YEAR(JulSun1+4)=CalendarYear,MONTH(JulSun1+4)=7),JulSun1+4,"")) -> 46204 | W23: =IF(DAY(JulSun1)=1,"",IF(AND(YEAR(JulSun1+5)=CalendarYear,MONTH(JulSun1+5)=7),JulSun1+5,"")) -> 46205 | X23: =IF(DAY(JulSun1)=1,"",IF(AND(YEAR(JulSun1+6)=CalendarYear,MONTH(JulSun1+6)=7),JulSun1+6,"")) -> 46206 | Y23: =IF(DAY(JulSun1)=1,IF(AND(YEAR(JulSun1)=CalendarYear,MONTH(JulSun1)=7),JulSun1,""),IF(AND(YEAR(JulSun1+7)=CalendarYear,MONTH(JulSun1+7)=7),JulSun1+7,"")) -> 46207 | Z23: CW31 | AA23: =IF(DAY(AugSun1)=1,"",IF(AND(YEAR(AugSun1+1)=CalendarYear,MONTH(AugSun1+1)=8),AugSun1+1,"")) | AB23: =IF(DAY(AugSun1)=1,"",IF(AND(YEAR(AugSun1+2)=CalendarYear,MONTH(AugSun1+2)=8),AugSun1+2,"")) | AC23: =IF(DAY(AugSun1)=1,"",IF(AND(YEAR(AugSun1+3)=CalendarYear,MONTH(AugSun1+3)=8),AugSun1+3,"")) | AD23: =IF(DAY(AugSun1)=1,"",IF(AND(YEAR(AugSun1+4)=CalendarYear,MONTH(AugSun1+4)=8),AugSun1+4,"")) | AE23: =IF(DAY(AugSun1)=1,"",IF(AND(YEAR(AugSun1+5)=CalendarYear,MONTH(AugSun1+5)=8),AugSun1+5,"")) | AF23: =IF(DAY(AugSun1)=1,"",IF(AND(YEAR(AugSun1+6)=CalendarYear,MONTH(AugSun1+6)=8),AugSun1+6,"")) | AG23: =IF(DAY(AugSun1)=1,IF(AND(YEAR(AugSun1)=CalendarYear,MONTH(AugSun1)=8),AugSun1,""),IF(AND(YEAR(AugSun1+7)=CalendarYear,MONTH(AugSun1+7)=8),AugSun1+7,"")) -> 46235
B24: CW19 | C24: =IF(DAY(MaySun1)=1,IF(AND(YEAR(MaySun1+1)=CalendarYear,MONTH(MaySun1+1)=5),MaySun1+1,""),IF(AND(YEAR(MaySun1+8)=CalendarYear,MONTH(MaySun1+8)=5),MaySun1+8,"")) -> 46145 | D24: =IF(DAY(MaySun1)=1,IF(AND(YEAR(MaySun1+2)=CalendarYear,MONTH(MaySun1+2)=5),MaySun1+2,""),IF(AND(YEAR(MaySun1+9)=CalendarYear,MONTH(MaySun1+9)=5),MaySun1+9,"")) -> 46146 | E24: =IF(DAY(MaySun1)=1,IF(AND(YEAR(MaySun1+3)=CalendarYear,MONTH(MaySun1+3)=5),MaySun1+3,""),IF(AND(YEAR(MaySun1+10)=CalendarYear,MONTH(MaySun1+10)=5),MaySun1+10,"")) -> 46147 | F24: =IF(DAY(MaySun1)=1,IF(AND(YEAR(MaySun1+4)=CalendarYear,MONTH(MaySun1+4)=5),MaySun1+4,""),IF(AND(YEAR(MaySun1+11)=CalendarYear,MONTH(MaySun1+11)=5),MaySun1+11,"")) -> 46148 | G24: =IF(DAY(MaySun1)=1,IF(AND(YEAR(MaySun1+5)=CalendarYear,MONTH(MaySun1+5)=5),MaySun1+5,""),IF(AND(YEAR(MaySun1+12)=CalendarYear,MONTH(MaySun1+12)=5),MaySun1+12,"")) -> 46149 | H24: =IF(DAY(MaySun1)=1,IF(AND(YEAR(MaySun1+6)=CalendarYear,MONTH(MaySun1+6)=5),MaySun1+6,""),IF(AND(YEAR(MaySun1+13)=CalendarYear,MONTH(MaySun1+13)=5),MaySun1+13,"")) -> 46150 | I24: =IF(DAY(MaySun1)=1,IF(AND(YEAR(MaySun1+7)=CalendarYear,MONTH(MaySun1+7)=5),MaySun1+7,""),IF(AND(YEAR(MaySun1+14)=CalendarYear,MONTH(MaySun1+14)=5),MaySun1+14,"")) -> 46151 | J24: CW23 | K24: =IF(DAY(JunSun1)=1,IF(AND(YEAR(JunSun1+1)=CalendarYear,MONTH(JunSun1+1)=6),JunSun1+1,""),IF(AND(YEAR(JunSun1+8)=CalendarYear,MONTH(JunSun1+8)=6),JunSun1+8,"")) -> 46180 | L24: =IF(DAY(JunSun1)=1,IF(AND(YEAR(JunSun1+2)=CalendarYear,MONTH(JunSun1+2)=6),JunSun1+2,""),IF(AND(YEAR(JunSun1+9)=CalendarYear,MONTH(JunSun1+9)=6),JunSun1+9,"")) -> 46181 | M24: =IF(DAY(JunSun1)=1,IF(AND(YEAR(JunSun1+3)=CalendarYear,MONTH(JunSun1+3)=6),JunSun1+3,""),IF(AND(YEAR(JunSun1+10)=CalendarYear,MONTH(JunSun1+10)=6),JunSun1+10,"")) -> 46182 | N24: =IF(DAY(JunSun1)=1,IF(AND(YEAR(JunSun1+4)=CalendarYear,MONTH(JunSun1+4)=6),JunSun1+4,""),IF(AND(YEAR(JunSun1+11)=CalendarYear,MONTH(JunSun1+11)=6),JunSun1+11,"")) -> 46183 | O24: =IF(DAY(JunSun1)=1,IF(AND(YEAR(JunSun1+5)=CalendarYear,MONTH(JunSun1+5)=6),JunSun1+5,""),IF(AND(YEAR(JunSun1+12)=CalendarYear,MONTH(JunSun1+12)=6),JunSun1+12,"")) -> 46184 | P24: =IF(DAY(JunSun1)=1,IF(AND(YEAR(JunSun1+6)=CalendarYear,MONTH(JunSun1+6)=6),JunSun1+6,""),IF(AND(YEAR(JunSun1+13)=CalendarYear,MONTH(JunSun1+13)=6),JunSun1+13,"")) -> 46185 | Q24: =IF(DAY(JunSun1)=1,IF(AND(YEAR(JunSun1+7)=CalendarYear,MONTH(JunSun1+7)=6),JunSun1+7,""),IF(AND(YEAR(JunSun1+14)=CalendarYear,MONTH(JunSun1+14)=6),JunSun1+14,"")) -> 46186 | R24: CW28 | S24: =IF(DAY(JulSun1)=1,IF(AND(YEAR(JulSun1+1)=CalendarYear,MONTH(JulSun1+1)=7),JulSun1+1,""),IF(AND(YEAR(JulSun1+8)=CalendarYear,MONTH(JulSun1+8)=7),JulSun1+8,"")) -> 46208 | T24: =IF(DAY(JulSun1)=1,IF(AND(YEAR(JulSun1+2)=CalendarYear,MONTH(JulSun1+2)=7),JulSun1+2,""),IF(AND(YEAR(JulSun1+9)=CalendarYear,MONTH(JulSun1+9)=7),JulSun1+9,"")) -> 46209 | U24: =IF(DAY(JulSun1)=1,IF(AND(YEAR(JulSun1+3)=CalendarYear,MONTH(JulSun1+3)=7),JulSun1+3,""),IF(AND(YEAR(JulSun1+10)=CalendarYear,MONTH(JulSun1+10)=7),JulSun1+10,"")) -> 46210 | V24: =IF(DAY(JulSun1)=1,IF(AND(YEAR(JulSun1+4)=CalendarYear,MONTH(JulSun1+4)=7),JulSun1+4,""),IF(AND(YEAR(JulSun1+11)=CalendarYear,MONTH(JulSun1+11)=7),JulSun1+11,"")) -> 46211 | W24: =IF(DAY(JulSun1)=1,IF(AND(YEAR(JulSun1+5)=CalendarYear,MONTH(JulSun1+5)=7),JulSun1+5,""),IF(AND(YEAR(JulSun1+12)=CalendarYear,MONTH(JulSun1+12)=7),JulSun1+12,"")) -> 46212 | X24: =IF(DAY(JulSun1)=1,IF(AND(YEAR(JulSun1+6)=CalendarYear,MONTH(JulSun1+6)=7),JulSun1+6,""),IF(AND(YEAR(JulSun1+13)=CalendarYear,MONTH(JulSun1+13)=7),JulSun1+13,"")) -> 46213 | Y24: =IF(DAY(JulSun1)=1,IF(AND(YEAR(JulSun1+7)=CalendarYear,MONTH(JulSun1+7)=7),JulSun1+7,""),IF(AND(YEAR(JulSun1+14)=CalendarYear,MONTH(JulSun1+14)=7),JulSun1+14,"")) -> 46214 | Z24: CW32 | AA24: =IF(DAY(AugSun1)=1,IF(AND(YEAR(AugSun1+1)=CalendarYear,MONTH(AugSun1+1)=8),AugSun1+1,""),IF(AND(YEAR(AugSun1+8)=CalendarYear,MONTH(AugSun1+8)=8),AugSun1+8,"")) -> 46236 | AB24: =IF(DAY(AugSun1)=1,IF(AND(YEAR(AugSun1+2)=CalendarYear,MONTH(AugSun1+2)=8),AugSun1+2,""),IF(AND(YEAR(AugSun1+9)=CalendarYear,MONTH(AugSun1+9)=8),AugSun1+9,"")) -> 46237 | AC24: =IF(DAY(AugSun1)=1,IF(AND(YEAR(AugSun1+3)=CalendarYear,MONTH(AugSun1+3)=8),AugSun1+3,""),IF(AND(YEAR(AugSun1+10)=CalendarYear,MONTH(AugSun1+10)=8),AugSun1+10,"")) -> 46238 | AD24: =IF(DAY(AugSun1)=1,IF(AND(YEAR(AugSun1+4)=CalendarYear,MONTH(AugSun1+4)=8),AugSun1+4,""),IF(AND(YEAR(AugSun1+11)=CalendarYear,MONTH(AugSun1+11)=8),AugSun1+11,"")) -> 46239 | AE24: =IF(DAY(AugSun1)=1,IF(AND(YEAR(AugSun1+5)=CalendarYear,MONTH(AugSun1+5)=8),AugSun1+5,""),IF(AND(YEAR(AugSun1+12)=CalendarYear,MONTH(AugSun1+12)=8),AugSun1+12,"")) -> 46240 | AF24: =IF(DAY(AugSun1)=1,IF(AND(YEAR(AugSun1+6)=CalendarYear,MONTH(AugSun1+6)=8),AugSun1+6,""),IF(AND(YEAR(AugSun1+13)=CalendarYear,MONTH(AugSun1+13)=8),AugSun1+13,"")) -> 46241 | AG24: =IF(DAY(AugSun1)=1,IF(AND(YEAR(AugSun1+7)=CalendarYear,MONTH(AugSun1+7)=8),AugSun1+7,""),IF(AND(YEAR(AugSun1+14)=CalendarYear,MONTH(AugSun1+14)=8),AugSun1+14,"")) -> 46242
B25: CW20 | C25: =IF(DAY(MaySun1)=1,IF(AND(YEAR(MaySun1+8)=CalendarYear,MONTH(MaySun1+8)=5),MaySun1+8,""),IF(AND(YEAR(MaySun1+15)=CalendarYear,MONTH(MaySun1+15)=5),MaySun1+15,"")) -> 46152 | D25: =IF(DAY(MaySun1)=1,IF(AND(YEAR(MaySun1+9)=CalendarYear,MONTH(MaySun1+9)=5),MaySun1+9,""),IF(AND(YEAR(MaySun1+16)=CalendarYear,MONTH(MaySun1+16)=5),MaySun1+16,"")) -> 46153 | E25: =IF(DAY(MaySun1)=1,IF(AND(YEAR(MaySun1+10)=CalendarYear,MONTH(MaySun1+10)=5),MaySun1+10,""),IF(AND(YEAR(MaySun1+17)=CalendarYear,MONTH(MaySun1+17)=5),MaySun1+17,"")) -> 46154 | F25: =IF(DAY(MaySun1)=1,IF(AND(YEAR(MaySun1+11)=CalendarYear,MONTH(MaySun1+11)=5),MaySun1+11,""),IF(AND(YEAR(MaySun1+18)=CalendarYear,MONTH(MaySun1+18)=5),MaySun1+18,"")) -> 46155 | G25: =IF(DAY(MaySun1)=1,IF(AND(YEAR(MaySun1+12)=CalendarYear,MONTH(MaySun1+12)=5),MaySun1+12,""),IF(AND(YEAR(MaySun1+19)=CalendarYear,MONTH(MaySun1+19)=5),MaySun1+19,"")) -> 46156 | H25: =IF(DAY(MaySun1)=1,IF(AND(YEAR(MaySun1+13)=CalendarYear,MONTH(MaySun1+13)=5),MaySun1+13,""),IF(AND(YEAR(MaySun1+20)=CalendarYear,MONTH(MaySun1+20)=5),MaySun1+20,"")) -> 46157 | I25: =IF(DAY(MaySun1)=1,IF(AND(YEAR(MaySun1+14)=CalendarYear,MONTH(MaySun1+14)=5),MaySun1+14,""),IF(AND(YEAR(MaySun1+21)=CalendarYear,MONTH(MaySun1+21)=5),MaySun1+21,"")) -> 46158 | J25: CW24 | K25: =IF(DAY(JunSun1)=1,IF(AND(YEAR(JunSun1+8)=CalendarYear,MONTH(JunSun1+8)=6),JunSun1+8,""),IF(AND(YEAR(JunSun1+15)=CalendarYear,MONTH(JunSun1+15)=6),JunSun1+15,"")) -> 46187 | L25: =IF(DAY(JunSun1)=1,IF(AND(YEAR(JunSun1+9)=CalendarYear,MONTH(JunSun1+9)=6),JunSun1+9,""),IF(AND(YEAR(JunSun1+16)=CalendarYear,MONTH(JunSun1+16)=6),JunSun1+16,"")) -> 46188 | M25: =IF(DAY(JunSun1)=1,IF(AND(YEAR(JunSun1+10)=CalendarYear,MONTH(JunSun1+10)=6),JunSun1+10,""),IF(AND(YEAR(JunSun1+17)=CalendarYear,MONTH(JunSun1+17)=6),JunSun1+17,"")) -> 46189 | N25: =IF(DAY(JunSun1)=1,IF(AND(YEAR(JunSun1+11)=CalendarYear,MONTH(JunSun1+11)=6),JunSun1+11,""),IF(AND(YEAR(JunSun1+18)=CalendarYear,MONTH(JunSun1+18)=6),JunSun1+18,"")) -> 46190 | O25: =IF(DAY(JunSun1)=1,IF(AND(YEAR(JunSun1+12)=CalendarYear,MONTH(JunSun1+12)=6),JunSun1+12,""),IF(AND(YEAR(JunSun1+19)=CalendarYear,MONTH(JunSun1+19)=6),JunSun1+19,"")) -> 46191 | P25: =IF(DAY(JunSun1)=1,IF(AND(YEAR(JunSun1+13)=CalendarYear,MONTH(JunSun1+13)=6),JunSun1+13,""),IF(AND(YEAR(JunSun1+20)=CalendarYear,MONTH(JunSun1+20)=6),JunSun1+20,"")) -> 46192 | Q25: =IF(DAY(JunSun1)=1,IF(AND(YEAR(JunSun1+14)=CalendarYear,MONTH(JunSun1+14)=6),JunSun1+14,""),IF(AND(YEAR(JunSun1+21)=CalendarYear,MONTH(JunSun1+21)=6),JunSun1+21,"")) -> 46193 | R25: CW29 | S25: =IF(DAY(JulSun1)=1,IF(AND(YEAR(JulSun1+8)=CalendarYear,MONTH(JulSun1+8)=7),JulSun1+8,""),IF(AND(YEAR(JulSun1+15)=CalendarYear,MONTH(JulSun1+15)=7),JulSun1+15,"")) -> 46215 | T25: =IF(DAY(JulSun1)=1,IF(AND(YEAR(JulSun1+9)=CalendarYear,MONTH(JulSun1+9)=7),JulSun1+9,""),IF(AND(YEAR(JulSun1+16)=CalendarYear,MONTH(JulSun1+16)=7),JulSun1+16,"")) -> 46216 | U25: =IF(DAY(JulSun1)=1,IF(AND(YEAR(JulSun1+10)=CalendarYear,MONTH(JulSun1+10)=7),JulSun1+10,""),IF(AND(YEAR(JulSun1+17)=CalendarYear,MONTH(JulSun1+17)=7),JulSun1+17,"")) -> 46217 | V25: =IF(DAY(JulSun1)=1,IF(AND(YEAR(JulSun1+11)=CalendarYear,MONTH(JulSun1+11)=7),JulSun1+11,""),IF(AND(YEAR(JulSun1+18)=CalendarYear,MONTH(JulSun1+18)=7),JulSun1+18,"")) -> 46218 | W25: =IF(DAY(JulSun1)=1,IF(AND(YEAR(JulSun1+12)=CalendarYear,MONTH(JulSun1+12)=7),JulSun1+12,""),IF(AND(YEAR(JulSun1+19)=CalendarYear,MONTH(JulSun1+19)=7),JulSun1+19,"")) -> 46219 | X25: =IF(DAY(JulSun1)=1,IF(AND(YEAR(JulSun1+13)=CalendarYear,MONTH(JulSun1+13)=7),JulSun1+13,""),IF(AND(YEAR(JulSun1+20)=CalendarYear,MONTH(JulSun1+20)=7),JulSun1+20,"")) -> 46220 | Y25: =IF(DAY(JulSun1)=1,IF(AND(YEAR(JulSun1+14)=CalendarYear,MONTH(JulSun1+14)=7),JulSun1+14,""),IF(AND(YEAR(JulSun1+21)=CalendarYear,MONTH(JulSun1+21)=7),JulSun1+21,"")) -> 46221 | Z25: CW33 | AA25: =IF(DAY(AugSun1)=1,IF(AND(YEAR(AugSun1+8)=CalendarYear,MONTH(AugSun1+8)=8),AugSun1+8,""),IF(AND(YEAR(AugSun1+15)=CalendarYear,MONTH(AugSun1+15)=8),AugSun1+15,"")) -> 46243 | AB25: =IF(DAY(AugSun1)=1,IF(AND(YEAR(AugSun1+9)=CalendarYear,MONTH(AugSun1+9)=8),AugSun1+9,""),IF(AND(YEAR(AugSun1+16)=CalendarYear,MONTH(AugSun1+16)=8),AugSun1+16,"")) -> 46244 | AC25: =IF(DAY(AugSun1)=1,IF(AND(YEAR(AugSun1+10)=CalendarYear,MONTH(AugSun1+10)=8),AugSun1+10,""),IF(AND(YEAR(AugSun1+17)=CalendarYear,MONTH(AugSun1+17)=8),AugSun1+17,"")) -> 46245 | AD25: =IF(DAY(AugSun1)=1,IF(AND(YEAR(AugSun1+11)=CalendarYear,MONTH(AugSun1+11)=8),AugSun1+11,""),IF(AND(YEAR(AugSun1+18)=CalendarYear,MONTH(AugSun1+18)=8),AugSun1+18,"")) -> 46246 | AE25: =IF(DAY(AugSun1)=1,IF(AND(YEAR(AugSun1+12)=CalendarYear,MONTH(AugSun1+12)=8),AugSun1+12,""),IF(AND(YEAR(AugSun1+19)=CalendarYear,MONTH(AugSun1+19)=8),AugSun1+19,"")) -> 46247 | AF25: =IF(DAY(AugSun1)=1,IF(AND(YEAR(AugSun1+13)=CalendarYear,MONTH(AugSun1+13)=8),AugSun1+13,""),IF(AND(YEAR(AugSun1+20)=CalendarYear,MONTH(AugSun1+20)=8),AugSun1+20,"")) -> 46248 | AG25: =IF(DAY(AugSun1)=1,IF(AND(YEAR(AugSun1+14)=CalendarYear,MONTH(AugSun1+14)=8),AugSun1+14,""),IF(AND(YEAR(AugSun1+21)=CalendarYear,MONTH(AugSun1+21)=8),AugSun1+21,"")) -> 46249
B26: CW21 | C26: =IF(DAY(MaySun1)=1,IF(AND(YEAR(MaySun1+15)=CalendarYear,MONTH(MaySun1+15)=5),MaySun1+15,""),IF(AND(YEAR(MaySun1+22)=CalendarYear,MONTH(MaySun1+22)=5),MaySun1+22,"")) -> 46159 | D26: =IF(DAY(MaySun1)=1,IF(AND(YEAR(MaySun1+16)=CalendarYear,MONTH(MaySun1+16)=5),MaySun1+16,""),IF(AND(YEAR(MaySun1+23)=CalendarYear,MONTH(MaySun1+23)=5),MaySun1+23,"")) -> 46160 | E26: =IF(DAY(MaySun1)=1,IF(AND(YEAR(MaySun1+17)=CalendarYear,MONTH(MaySun1+17)=5),MaySun1+17,""),IF(AND(YEAR(MaySun1+24)=CalendarYear,MONTH(MaySun1+24)=5),MaySun1+24,"")) -> 46161 | F26: =IF(DAY(MaySun1)=1,IF(AND(YEAR(MaySun1+18)=CalendarYear,MONTH(MaySun1+18)=5),MaySun1+18,""),IF(AND(YEAR(MaySun1+25)=CalendarYear,MONTH(MaySun1+25)=5),MaySun1+25,"")) -> 46162 | G26: =IF(DAY(MaySun1)=1,IF(AND(YEAR(MaySun1+19)=CalendarYear,MONTH(MaySun1+19)=5),MaySun1+19,""),IF(AND(YEAR(MaySun1+26)=CalendarYear,MONTH(MaySun1+26)=5),MaySun1+26,"")) -> 46163 | H26: =IF(DAY(MaySun1)=1,IF(AND(YEAR(MaySun1+20)=CalendarYear,MONTH(MaySun1+20)=5),MaySun1+20,""),IF(AND(YEAR(MaySun1+27)=CalendarYear,MONTH(MaySun1+27)=5),MaySun1+27,"")) -> 46164 | I26: =IF(DAY(MaySun1)=1,IF(AND(YEAR(MaySun1+21)=CalendarYear,MONTH(MaySun1+21)=5),MaySun1+21,""),IF(AND(YEAR(MaySun1+28)=CalendarYear,MONTH(MaySun1+28)=5),MaySun1+28,"")) -> 46165 | J26: CW25 | K26: =IF(DAY(JunSun1)=1,IF(AND(YEAR(JunSun1+15)=CalendarYear,MONTH(JunSun1+15)=6),JunSun1+15,""),IF(AND(YEAR(JunSun1+22)=CalendarYear,MONTH(JunSun1+22)=6),JunSun1+22,"")) -> 46194 | L26: =IF(DAY(JunSun1)=1,IF(AND(YEAR(JunSun1+16)=CalendarYear,MONTH(JunSun1+16)=6),JunSun1+16,""),IF(AND(YEAR(JunSun1+23)=CalendarYear,MONTH(JunSun1+23)=6),JunSun1+23,"")) -> 46195 | M26: =IF(DAY(JunSun1)=1,IF(AND(YEAR(JunSun1+17)=CalendarYear,MONTH(JunSun1+17)=6),JunSun1+17,""),IF(AND(YEAR(JunSun1+24)=CalendarYear,MONTH(JunSun1+24)=6),JunSun1+24,"")) -> 46196 | N26: =IF(DAY(JunSun1)=1,IF(AND(YEAR(JunSun1+18)=CalendarYear,MONTH(JunSun1+18)=6),JunSun1+18,""),IF(AND(YEAR(JunSun1+25)=CalendarYear,MONTH(JunSun1+25)=6),JunSun1+25,"")) -> 46197 | O26: =IF(DAY(JunSun1)=1,IF(AND(YEAR(JunSun1+19)=CalendarYear,MONTH(JunSun1+19)=6),JunSun1+19,""),IF(AND(YEAR(JunSun1+26)=CalendarYear,MONTH(JunSun1+26)=6),JunSun1+26,"")) -> 46198 | P26: =IF(DAY(JunSun1)=1,IF(AND(YEAR(JunSun1+20)=CalendarYear,MONTH(JunSun1+20)=6),JunSun1+20,""),IF(AND(YEAR(JunSun1+27)=CalendarYear,MONTH(JunSun1+27)=6),JunSun1+27,"")) -> 46199 | Q26: =IF(DAY(JunSun1)=1,IF(AND(YEAR(JunSun1+21)=CalendarYear,MONTH(JunSun1+21)=6),JunSun1+21,""),IF(AND(YEAR(JunSun1+28)=CalendarYear,MONTH(JunSun1+28)=6),JunSun1+28,"")) -> 46200 | R26: CW30 | S26: =IF(DAY(JulSun1)=1,IF(AND(YEAR(JulSun1+15)=CalendarYear,MONTH(JulSun1+15)=7),JulSun1+15,""),IF(AND(YEAR(JulSun1+22)=CalendarYear,MONTH(JulSun1+22)=7),JulSun1+22,"")) -> 46222 | T26: =IF(DAY(JulSun1)=1,IF(AND(YEAR(JulSun1+16)=CalendarYear,MONTH(JulSun1+16)=7),JulSun1+16,""),IF(AND(YEAR(JulSun1+23)=CalendarYear,MONTH(JulSun1+23)=7),JulSun1+23,"")) -> 46223 | U26: =IF(DAY(JulSun1)=1,IF(AND(YEAR(JulSun1+17)=CalendarYear,MONTH(JulSun1+17)=7),JulSun1+17,""),IF(AND(YEAR(JulSun1+24)=CalendarYear,MONTH(JulSun1+24)=7),JulSun1+24,"")) -> 46224 | V26: =IF(DAY(JulSun1)=1,IF(AND(YEAR(JulSun1+18)=CalendarYear,MONTH(JulSun1+18)=7),JulSun1+18,""),IF(AND(YEAR(JulSun1+25)=CalendarYear,MONTH(JulSun1+25)=7),JulSun1+25,"")) -> 46225 | W26: =IF(DAY(JulSun1)=1,IF(AND(YEAR(JulSun1+19)=CalendarYear,MONTH(JulSun1+19)=7),JulSun1+19,""),IF(AND(YEAR(JulSun1+26)=CalendarYear,MONTH(JulSun1+26)=7),JulSun1+26,"")) -> 46226 | X26: =IF(DAY(JulSun1)=1,IF(AND(YEAR(JulSun1+20)=CalendarYear,MONTH(JulSun1+20)=7),JulSun1+20,""),IF(AND(YEAR(JulSun1+27)=CalendarYear,MONTH(JulSun1+27)=7),JulSun1+27,"")) -> 46227 | Y26: =IF(DAY(JulSun1)=1,IF(AND(YEAR(JulSun1+21)=CalendarYear,MONTH(JulSun1+21)=7),JulSun1+21,""),IF(AND(YEAR(JulSun1+28)=CalendarYear,MONTH(JulSun1+28)=7),JulSun1+28,"")) -> 46228 | Z26: CW34 | AA26: =IF(DAY(AugSun1)=1,IF(AND(YEAR(AugSun1+15)=CalendarYear,MONTH(AugSun1+15)=8),AugSun1+15,""),IF(AND(YEAR(AugSun1+22)=CalendarYear,MONTH(AugSun1+22)=8),AugSun1+22,"")) -> 46250 | AB26: =IF(DAY(AugSun1)=1,IF(AND(YEAR(AugSun1+16)=CalendarYear,MONTH(AugSun1+16)=8),AugSun1+16,""),IF(AND(YEAR(AugSun1+23)=CalendarYear,MONTH(AugSun1+23)=8),AugSun1+23,"")) -> 46251 | AC26: =IF(DAY(AugSun1)=1,IF(AND(YEAR(AugSun1+17)=CalendarYear,MONTH(AugSun1+17)=8),AugSun1+17,""),IF(AND(YEAR(AugSun1+24)=CalendarYear,MONTH(AugSun1+24)=8),AugSun1+24,"")) -> 46252 | AD26: =IF(DAY(AugSun1)=1,IF(AND(YEAR(AugSun1+18)=CalendarYear,MONTH(AugSun1+18)=8),AugSun1+18,""),IF(AND(YEAR(AugSun1+25)=CalendarYear,MONTH(AugSun1+25)=8),AugSun1+25,"")) -> 46253 | AE26: =IF(DAY(AugSun1)=1,IF(AND(YEAR(AugSun1+19)=CalendarYear,MONTH(AugSun1+19)=8),AugSun1+19,""),IF(AND(YEAR(AugSun1+26)=CalendarYear,MONTH(AugSun1+26)=8),AugSun1+26,"")) -> 46254 | AF26: =IF(DAY(AugSun1)=1,IF(AND(YEAR(AugSun1+20)=CalendarYear,MONTH(AugSun1+20)=8),AugSun1+20,""),IF(AND(YEAR(AugSun1+27)=CalendarYear,MONTH(AugSun1+27)=8),AugSun1+27,"")) -> 46255 | AG26: =IF(DAY(AugSun1)=1,IF(AND(YEAR(AugSun1+21)=CalendarYear,MONTH(AugSun1+21)=8),AugSun1+21,""),IF(AND(YEAR(AugSun1+28)=CalendarYear,MONTH(AugSun1+28)=8),AugSun1+28,"")) -> 46256
B27: CW22 | C27: =IF(DAY(MaySun1)=1,IF(AND(YEAR(MaySun1+22)=CalendarYear,MONTH(MaySun1+22)=5),MaySun1+22,""),IF(AND(YEAR(MaySun1+29)=CalendarYear,MONTH(MaySun1+29)=5),MaySun1+29,"")) -> 46166 | D27: =IF(DAY(MaySun1)=1,IF(AND(YEAR(MaySun1+23)=CalendarYear,MONTH(MaySun1+23)=5),MaySun1+23,""),IF(AND(YEAR(MaySun1+30)=CalendarYear,MONTH(MaySun1+30)=5),MaySun1+30,"")) -> 46167 | E27: =IF(DAY(MaySun1)=1,IF(AND(YEAR(MaySun1+24)=CalendarYear,MONTH(MaySun1+24)=5),MaySun1+24,""),IF(AND(YEAR(MaySun1+31)=CalendarYear,MONTH(MaySun1+31)=5),MaySun1+31,"")) -> 46168 | F27: =IF(DAY(MaySun1)=1,IF(AND(YEAR(MaySun1+25)=CalendarYear,MONTH(MaySun1+25)=5),MaySun1+25,""),IF(AND(YEAR(MaySun1+32)=CalendarYear,MONTH(MaySun1+32)=5),MaySun1+32,"")) -> 46169 | G27: =IF(DAY(MaySun1)=1,IF(AND(YEAR(MaySun1+26)=CalendarYear,MONTH(MaySun1+26)=5),MaySun1+26,""),IF(AND(YEAR(MaySun1+33)=CalendarYear,MONTH(MaySun1+33)=5),MaySun1+33,"")) -> 46170 | H27: =IF(DAY(MaySun1)=1,IF(AND(YEAR(MaySun1+27)=CalendarYear,MONTH(MaySun1+27)=5),MaySun1+27,""),IF(AND(YEAR(MaySun1+34)=CalendarYear,MONTH(MaySun1+34)=5),MaySun1+34,"")) -> 46171 | I27: =IF(DAY(MaySun1)=1,IF(AND(YEAR(MaySun1+28)=CalendarYear,MONTH(MaySun1+28)=5),MaySun1+28,""),IF(AND(YEAR(MaySun1+35)=CalendarYear,MONTH(MaySun1+35)=5),MaySun1+35,"")) -> 46172 | J27: CW26 | K27: =IF(DAY(JunSun1)=1,IF(AND(YEAR(JunSun1+22)=CalendarYear,MONTH(JunSun1+22)=6),JunSun1+22,""),IF(AND(YEAR(JunSun1+29)=CalendarYear,MONTH(JunSun1+29)=6),JunSun1+29,"")) -> 46201 | L27: =IF(DAY(JunSun1)=1,IF(AND(YEAR(JunSun1+23)=CalendarYear,MONTH(JunSun1+23)=6),JunSun1+23,""),IF(AND(YEAR(JunSun1+30)=CalendarYear,MONTH(JunSun1+30)=6),JunSun1+30,"")) -> 46202 | M27: =IF(DAY(JunSun1)=1,IF(AND(YEAR(JunSun1+24)=CalendarYear,MONTH(JunSun1+24)=6),JunSun1+24,""),IF(AND(YEAR(JunSun1+31)=CalendarYear,MONTH(JunSun1+31)=6),JunSun1+31,"")) -> 46203 | N27: =IF(DAY(JunSun1)=1,IF(AND(YEAR(JunSun1+25)=CalendarYear,MONTH(JunSun1+25)=6),JunSun1+25,""),IF(AND(YEAR(JunSun1+32)=CalendarYear,MONTH(JunSun1+32)=6),JunSun1+32,"")) | O27: =IF(DAY(JunSun1)=1,IF(AND(YEAR(JunSun1+26)=CalendarYear,MONTH(JunSun1+26)=6),JunSun1+26,""),IF(AND(YEAR(JunSun1+33)=CalendarYear,MONTH(JunSun1+33)=6),JunSun1+33,"")) | P27: =IF(DAY(JunSun1)=1,IF(AND(YEAR(JunSun1+27)=CalendarYear,MONTH(JunSun1+27)=6),JunSun1+27,""),IF(AND(YEAR(JunSun1+34)=CalendarYear,MONTH(JunSun1+34)=6),JunSun1+34,"")) | Q27: =IF(DAY(JunSun1)=1,IF(AND(YEAR(JunSun1+28)=CalendarYear,MONTH(JunSun1+28)=6),JunSun1+28,""),IF(AND(YEAR(JunSun1+35)=CalendarYear,MONTH(JunSun1+35)=6),JunSun1+35,"")) | R27: CW31 | S27: =IF(DAY(JulSun1)=1,IF(AND(YEAR(JulSun1+22)=CalendarYear,MONTH(JulSun1+22)=7),JulSun1+22,""),IF(AND(YEAR(JulSun1+29)=CalendarYear,MONTH(JulSun1+29)=7),JulSun1+29,"")) -> 46229 | T27: =IF(DAY(JulSun1)=1,IF(AND(YEAR(JulSun1+23)=CalendarYear,MONTH(JulSun1+23)=7),JulSun1+23,""),IF(AND(YEAR(JulSun1+30)=CalendarYear,MONTH(JulSun1+30)=7),JulSun1+30,"")) -> 46230 | U27: =IF(DAY(JulSun1)=1,IF(AND(YEAR(JulSun1+24)=CalendarYear,MONTH(JulSun1+24)=7),JulSun1+24,""),IF(AND(YEAR(JulSun1+31)=CalendarYear,MONTH(JulSun1+31)=7),JulSun1+31,"")) -> 46231 | V27: =IF(DAY(JulSun1)=1,IF(AND(YEAR(JulSun1+25)=CalendarYear,MONTH(JulSun1+25)=7),JulSun1+25,""),IF(AND(YEAR(JulSun1+32)=CalendarYear,MONTH(JulSun1+32)=7),JulSun1+32,"")) -> 46232 | W27: =IF(DAY(JulSun1)=1,IF(AND(YEAR(JulSun1+26)=CalendarYear,MONTH(JulSun1+26)=7),JulSun1+26,""),IF(AND(YEAR(JulSun1+33)=CalendarYear,MONTH(JulSun1+33)=7),JulSun1+33,"")) -> 46233 | X27: =IF(DAY(JulSun1)=1,IF(AND(YEAR(JulSun1+27)=CalendarYear,MONTH(JulSun1+27)=7),JulSun1+27,""),IF(AND(YEAR(JulSun1+34)=CalendarYear,MONTH(JulSun1+34)=7),JulSun1+34,"")) -> 46234 | Y27: =IF(DAY(JulSun1)=1,IF(AND(YEAR(JulSun1+28)=CalendarYear,MONTH(JulSun1+28)=7),JulSun1+28,""),IF(AND(YEAR(JulSun1+35)=CalendarYear,MONTH(JulSun1+35)=7),JulSun1+35,"")) | Z27: CW35 | AA27: =IF(DAY(AugSun1)=1,IF(AND(YEAR(AugSun1+22)=CalendarYear,MONTH(AugSun1+22)=8),AugSun1+22,""),IF(AND(YEAR(AugSun1+29)=CalendarYear,MONTH(AugSun1+29)=8),AugSun1+29,"")) -> 46257 | AB27: =IF(DAY(AugSun1)=1,IF(AND(YEAR(AugSun1+23)=CalendarYear,MONTH(AugSun1+23)=8),AugSun1+23,""),IF(AND(YEAR(AugSun1+30)=CalendarYear,MONTH(AugSun1+30)=8),AugSun1+30,"")) -> 46258 | AC27: =IF(DAY(AugSun1)=1,IF(AND(YEAR(AugSun1+24)=CalendarYear,MONTH(AugSun1+24)=8),AugSun1+24,""),IF(AND(YEAR(AugSun1+31)=CalendarYear,MONTH(AugSun1+31)=8),AugSun1+31,"")) -> 46259 | AD27: =IF(DAY(AugSun1)=1,IF(AND(YEAR(AugSun1+25)=CalendarYear,MONTH(AugSun1+25)=8),AugSun1+25,""),IF(AND(YEAR(AugSun1+32)=CalendarYear,MONTH(AugSun1+32)=8),AugSun1+32,"")) -> 46260 | AE27: =IF(DAY(AugSun1)=1,IF(AND(YEAR(AugSun1+26)=CalendarYear,MONTH(AugSun1+26)=8),AugSun1+26,""),IF(AND(YEAR(AugSun1+33)=CalendarYear,MONTH(AugSun1+33)=8),AugSun1+33,"")) -> 46261 | AF27: =IF(DAY(AugSun1)=1,IF(AND(YEAR(AugSun1+27)=CalendarYear,MONTH(AugSun1+27)=8),AugSun1+27,""),IF(AND(YEAR(AugSun1+34)=CalendarYear,MONTH(AugSun1+34)=8),AugSun1+34,"")) -> 46262 | AG27: =IF(DAY(AugSun1)=1,IF(AND(YEAR(AugSun1+28)=CalendarYear,MONTH(AugSun1+28)=8),AugSun1+28,""),IF(AND(YEAR(AugSun1+35)=CalendarYear,MONTH(AugSun1+35)=8),AugSun1+35,"")) -> 46263
C28: =IF(DAY(MaySun1)=1,IF(AND(YEAR(MaySun1+29)=CalendarYear,MONTH(MaySun1+29)=5),MaySun1+29,""),IF(AND(YEAR(MaySun1+36)=CalendarYear,MONTH(MaySun1+36)=5),MaySun1+36,"")) -> 46173 | D28: =IF(DAY(MaySun1)=1,IF(AND(YEAR(MaySun1+30)=CalendarYear,MONTH(MaySun1+30)=5),MaySun1+30,""),IF(AND(YEAR(MaySun1+37)=CalendarYear,MONTH(MaySun1+37)=5),MaySun1+37,"")) | E28: =IF(DAY(MaySun1)=1,IF(AND(YEAR(MaySun1+31)=CalendarYear,MONTH(MaySun1+31)=5),MaySun1+31,""),IF(AND(YEAR(MaySun1+38)=CalendarYear,MONTH(MaySun1+38)=5),MaySun1+38,"")) | F28: =IF(DAY(MaySun1)=1,IF(AND(YEAR(MaySun1+32)=CalendarYear,MONTH(MaySun1+32)=5),MaySun1+32,""),IF(AND(YEAR(MaySun1+39)=CalendarYear,MONTH(MaySun1+39)=5),MaySun1+39,"")) | G28: =IF(DAY(MaySun1)=1,IF(AND(YEAR(MaySun1+33)=CalendarYear,MONTH(MaySun1+33)=5),MaySun1+33,""),IF(AND(YEAR(MaySun1+40)=CalendarYear,MONTH(MaySun1+40)=5),MaySun1+40,"")) | H28: =IF(DAY(MaySun1)=1,IF(AND(YEAR(MaySun1+34)=CalendarYear,MONTH(MaySun1+34)=5),MaySun1+34,""),IF(AND(YEAR(MaySun1+41)=CalendarYear,MONTH(MaySun1+41)=5),MaySun1+41,"")) | I28: =IF(DAY(MaySun1)=1,IF(AND(YEAR(MaySun1+35)=CalendarYear,MONTH(MaySun1+35)=5),MaySun1+35,""),IF(AND(YEAR(MaySun1+42)=CalendarYear,MONTH(MaySun1+42)=5),MaySun1+42,"")) | J28: CW27 | K28: =IF(DAY(JunSun1)=1,IF(AND(YEAR(JunSun1+29)=CalendarYear,MONTH(JunSun1+29)=6),JunSun1+29,""),IF(AND(YEAR(JunSun1+36)=CalendarYear,MONTH(JunSun1+36)=6),JunSun1+36,"")) | L28: =IF(DAY(JunSun1)=1,IF(AND(YEAR(JunSun1+30)=CalendarYear,MONTH(JunSun1+30)=6),JunSun1+30,""),IF(AND(YEAR(JunSun1+37)=CalendarYear,MONTH(JunSun1+37)=6),JunSun1+37,"")) | M28: =IF(DAY(JunSun1)=1,IF(AND(YEAR(JunSun1+31)=CalendarYear,MONTH(JunSun1+31)=6),JunSun1+31,""),IF(AND(YEAR(JunSun1+38)=CalendarYear,MONTH(JunSun1+38)=6),JunSun1+38,"")) | N28: =IF(DAY(JunSun1)=1,IF(AND(YEAR(JunSun1+32)=CalendarYear,MONTH(JunSun1+32)=6),JunSun1+32,""),IF(AND(YEAR(JunSun1+39)=CalendarYear,MONTH(JunSun1+39)=6),JunSun1+39,"")) | O28: =IF(DAY(JunSun1)=1,IF(AND(YEAR(JunSun1+33)=CalendarYear,MONTH(JunSun1+33)=6),JunSun1+33,""),IF(AND(YEAR(JunSun1+40)=CalendarYear,MONTH(JunSun1+40)=6),JunSun1+40,"")) | P28: =IF(DAY(JunSun1)=1,IF(AND(YEAR(JunSun1+34)=CalendarYear,MONTH(JunSun1+34)=6),JunSun1+34,""),IF(AND(YEAR(JunSun1+41)=CalendarYear,MONTH(JunSun1+41)=6),JunSun1+41,"")) | Q28: =IF(DAY(JunSun1)=1,IF(AND(YEAR(JunSun1+35)=CalendarYear,MONTH(JunSun1+35)=6),JunSun1+35,""),IF(AND(YEAR(JunSun1+42)=CalendarYear,MONTH(JunSun1+42)=6),JunSun1+42,"")) | S28: =IF(DAY(JulSun1)=1,IF(AND(YEAR(JulSun1+29)=CalendarYear,MONTH(JulSun1+29)=7),JulSun1+29,""),IF(AND(YEAR(JulSun1+36)=CalendarYear,MONTH(JulSun1+36)=7),JulSun1+36,"")) | T28: =IF(DAY(JulSun1)=1,IF(AND(YEAR(JulSun1+30)=CalendarYear,MONTH(JulSun1+30)=7),JulSun1+30,""),IF(AND(YEAR(JulSun1+37)=CalendarYear,MONTH(JulSun1+37)=7),JulSun1+37,"")) | U28: =IF(DAY(JulSun1)=1,IF(AND(YEAR(JulSun1+31)=CalendarYear,MONTH(JulSun1+31)=7),JulSun1+31,""),IF(AND(YEAR(JulSun1+38)=CalendarYear,MONTH(JulSun1+38)=7),JulSun1+38,"")) | V28: =IF(DAY(JulSun1)=1,IF(AND(YEAR(JulSun1+32)=CalendarYear,MONTH(JulSun1+32)=7),JulSun1+32,""),IF(AND(YEAR(JulSun1+39)=CalendarYear,MONTH(JulSun1+39)=7),JulSun1+39,"")) | W28: =IF(DAY(JulSun1)=1,IF(AND(YEAR(JulSun1+33)=CalendarYear,MONTH(JulSun1+33)=7),JulSun1+33,""),IF(AND(YEAR(JulSun1+40)=CalendarYear,MONTH(JulSun1+40)=7),JulSun1+40,"")) | X28: =IF(DAY(JulSun1)=1,IF(AND(YEAR(JulSun1+34)=CalendarYear,MONTH(JulSun1+34)=7),JulSun1+34,""),IF(AND(YEAR(JulSun1+41)=CalendarYear,MONTH(JulSun1+41)=7),JulSun1+41,"")) | Y28: =IF(DAY(JulSun1)=1,IF(AND(YEAR(JulSun1+35)=CalendarYear,MONTH(JulSun1+35)=7),JulSun1+35,""),IF(AND(YEAR(JulSun1+42)=CalendarYear,MONTH(JulSun1+42)=7),JulSun1+42,"")) | AA28: =IF(DAY(AugSun1)=1,IF(AND(YEAR(AugSun1+29)=CalendarYear,MONTH(AugSun1+29)=8),AugSun1+29,""),IF(AND(YEAR(AugSun1+36)=CalendarYear,MONTH(AugSun1+36)=8),AugSun1+36,"")) -> 46264 | AB28: =IF(DAY(AugSun1)=1,IF(AND(YEAR(AugSun1+30)=CalendarYear,MONTH(AugSun1+30)=8),AugSun1+30,""),IF(AND(YEAR(AugSun1+37)=CalendarYear,MONTH(AugSun1+37)=8),AugSun1+37,"")) -> 46265 | AC28: =IF(DAY(AugSun1)=1,IF(AND(YEAR(AugSun1+31)=CalendarYear,MONTH(AugSun1+31)=8),AugSun1+31,""),IF(AND(YEAR(AugSun1+38)=CalendarYear,MONTH(AugSun1+38)=8),AugSun1+38,"")) | AD28: =IF(DAY(AugSun1)=1,IF(AND(YEAR(AugSun1+32)=CalendarYear,MONTH(AugSun1+32)=8),AugSun1+32,""),IF(AND(YEAR(AugSun1+39)=CalendarYear,MONTH(AugSun1+39)=8),AugSun1+39,"")) | AE28: =IF(DAY(AugSun1)=1,IF(AND(YEAR(AugSun1+33)=CalendarYear,MONTH(AugSun1+33)=8),AugSun1+33,""),IF(AND(YEAR(AugSun1+40)=CalendarYear,MONTH(AugSun1+40)=8),AugSun1+40,"")) | AF28: =IF(DAY(AugSun1)=1,IF(AND(YEAR(AugSun1+34)=CalendarYear,MONTH(AugSun1+34)=8),AugSun1+34,""),IF(AND(YEAR(AugSun1+41)=CalendarYear,MONTH(AugSun1+41)=8),AugSun1+41,"")) | AG28: =IF(DAY(AugSun1)=1,IF(AND(YEAR(AugSun1+35)=CalendarYear,MONTH(AugSun1+35)=8),AugSun1+35,""),IF(AND(YEAR(AugSun1+42)=CalendarYear,MONTH(AugSun1+42)=8),AugSun1+42,""))
C29: * Labor day(1st-2nd) | G29: *Big 5 Slava | K29: * KSCE Olympics (13th) | S29: * Collective leave (27st-31st): Summer vacation | AA29: * Collective leave (3st-7th): Summer vacation
C33: September | K33: October | S33: November | AA33: December
C34: Su | D34: Mo | E34: Tu | F34: We | G34: Th | H34: Fr | I34: Sa | K34: Su | L34: Mo | M34: Tu | N34: We | O34: Th | P34: Fr | Q34: Sa | S34: Su | T34: Mo | U34: Tu | V34: We | W34: Th | X34: Fr | Y34: Sa | AA34: Su | AB34: Mo | AC34: Tu | AD34: We | AE34: Th | AF34: Fr | AG34: Sa
