Workbook

Sheet 환율기준
B2: KSCP환율기준
B3: USD/PLN | C3: 1 | D3: 3.6
B4: EUR/PLN | C4: 1 | D4: 4.2
B5: PLN/WON | C5: 1 | D5: 385
B6: WON/USD | C6: 1350 | D6: 1
B7: WON/EUR | C7: 1600 | D7: 1

Sheet 사업계획
A1: 구분 | B1: 년 생산댓수(매출) | E1: 차이 | F1: 1월 | G1: 2월 | H1: 3월 | I1: 4월 | J1: 5월 | K1: 6월 | L1: 7월 | M1: 8월 | N1: 9월 | O1: 10월 | P1: 11월 | Q1: 12월 | R1: Total | S1: 비고
A2: PSA W1 SDN | B2: 2017 | E2: =R2-B2 -> 0 | F2: 900 | G2: 50 | H2: 0 | I2: 570 | J2: 0 | K2: 71 | L2: 71 | M2: 71 | N2: 71 | O2: 71 | P2: 71 | Q2: 71 | R2: =SUM(F2:Q2) -> 2017
A3: PSA W1 SUV | B3: 12618 | E3: =R3-B3 -> 0 | F3: 2140 | G3: 1440 | H3: 660 | I3: 2420 | J3: 960 | K3: 714 | L3: 714 | M3: 714 | N3: 714 | O3: 714 | P3: 714 | Q3: 714 | R3: =SUM(F3:Q3) -> 12618
A4: PSA W2 | B4: 0 | E4: =R4-B4 -> 0 | R4: =SUM(F4:Q4) -> 0
A5: EV2020 | B5: 601518 | E5: =R5-B5 -> 0 | F5: 45170 | G5: 60911 | H5: 62112 | I5: 62162 | J5: 78729 | K5: 55055 | L5: 44244 | M5: 52352 | N5: 34535 | O5: 48248 | P5: 29000 | Q5: 29000 | R5: =SUM(F5:Q5) -> 601518
A6: BMW 12V HAF | B6: 14200 | E6: =R6-B6 -> 0 | F6: 900 | G6: 1200 | H6: 1400 | I6: 1200 | J6: 900 | K6: 1300 | L6: 1000 | M6: 1500 | N6: 1200 | O6: 1200 | P6: 1200 | Q6: 1200 | R6: =SUM(F6:Q6) -> 14200
A8: 구분 | B8: 년 생산댓수(매입) | E8: 차이 | F8: 1월 | G8: 2월 | H8: 3월 | I8: 4월 | J8: 5월 | K8: 6월 | L8: 7월 | M8: 8월 | N8: 9월 | O8: 10월 | P8: 11월 | Q8: 12월 | R8: Total | S8: 비고
A9: EBB00412AC(SDN) | E9: =R9-B9 -> 1000 | H9: 1000 | R9: =SUM(F9:Q9) -> 1000 | S9: 0
A10: EBB00414AE(SDN) | E10: =R10-B10 -> 1200 | H10: 600 | I10: 600 | R10: =SUM(F10:Q10) -> 1200 | S10: 0
A11: ECW01188AD(SDN) | E11: =R11-B11 -> 1988 | F11: 336 | G11: 392 | H11: 420 | I11: 420 | J11: 420 | R11: =SUM(F11:Q11) -> 1988 | S11: 0
A12: EEA00306AC(SDN) | E12: =R12-B12 -> 0 | R12: =SUM(F12:Q12) -> 0 | S12: 0
A13: EEA00308AF(SDN) | E13: =R13-B13 -> 0 | R13: =SUM(F13:Q13) -> 0 | S13: 0
A14: EBB00412AC(SDN)RE | E14: =R14-B14 -> 0 | R14: =SUM(F14:Q14) -> 0 | S14: 단가 인상
A15: EBB00414AE(SDN)RE | E15: =R15-B15 -> 0 | K15: =K14 -> 0 | L15: =L14 -> 0 | M15: =M14 -> 0 | N15: =N14 -> 0 | O15: =O14 -> 0 | P15: =P14 -> 0 | Q15: =Q14 -> 0 | R15: =SUM(F15:Q15) -> 0 | S15: 단가 인상
A16: ECW01188AD(SDN)RE | E16: =R16-B16 -> 3192 | K16: 560 | L16: 420 | M16: 756 | N16: 420 | O16: 560 | P16: 280 | Q16: 196 | R16: =SUM(F16:Q16) -> 3192 | S16: 단가 인상
A17: EEA00306AC(SDN)RE | B17: 2017 | E17: =R17-B17 -> -2017 | K17: =K15 -> 0 | L17: =L15 -> 0 | M17: =M15 -> 0 | N17: =N15 -> 0 | O17: =O15 -> 0 | P17: =P15 -> 0 | Q17: =Q15 -> 0 | R17: =SUM(F17:Q17) -> 0 | S17: 단가 인상
A18: EEA00308AF(SDN)RE | B18: 2017 | E18: =R18-B18 -> -2017 | K18: =K17 -> 0 | L18: =L17 -> 0 | M18: =M17 -> 0 | N18: =N17 -> 0 | O18: =O17 -> 0 | P18: =P17 -> 0 | Q18: =Q17 -> 0 | R18: =SUM(F18:Q18) -> 0 | S18: 단가 인상
A19: EBB00416AC | E19: =R19-B19 -> 0 | R19: =SUM(F19:Q19) -> 0 | S19: 0
A20: EBB00418AC | E20: =R20-B20 -> 15400 | F20: 1000 | J20: 1800 | K20: 1800 | L20: 1800 | M20: 1800 | N20: 1800 | O20: 1800 | P20: 1800 | Q20: 1800 | R20: =SUM(F20:Q20) -> 15400 | S20: 0
A21: EBB00420AD | E21: =R21-B21 -> 16550 | F21: 1000 | G21: 1150 | J21: 1800 | K21: 1800 | L21: 1800 | M21: 1800 | N21: 1800 | O21: 1800 | P21: 1800 | Q21: 1800 | R21: =SUM(F21:Q21) -> 16550 | S21: 0
A22: EBB00422AD | E22: =R22-B22 -> 16400 | F22: 1000 | G22: 1000 | J22: 1800 | K22: 1800 | L22: 1800 | M22: 1800 | N22: 1800 | O22: 1800 | P22: 1800 | Q22: 1800 | R22: =SUM(F22:Q22) -> 16400 | S22: 0
A23: ECW01190AD | E23: =R23-B23 -> 31820 | F23: 2064 | G23: 2408 | H23: 2580 | I23: 2580 | J23: 2580 | K23: 3440 | L23: 2580 | M23: 4644 | N23: 2580 | O23: 3440 | P23: 1720 | Q23: 1204 | R23: =SUM(F23:Q23) -> 31820 | S23: 0
A24: EEA00306AC | E24: =R24-B24 -> 18260 | F24: 1968 | G24: 960 | H24: 932 | J24: 1800 | K24: 1800 | L24: 1800 | M24: 1800 | N24: 1800 | O24: 1800 | P24: 1800 | Q24: 1800 | R24: =SUM(F24:Q24) -> 18260 | S24: 0
A25: EEA00308AF | B25: 2017 | E25: =R25-B25 -> 20113 | F25: 1998 | G25: 2196 | H25: 2400 | I25: 2936 | K25: 1800 | L25: 1800 | M25: 1800 | N25: 1800 | O25: 1800 | P25: 1800 | Q25: 1800 | R25: =SUM(F25:Q25) -> 22130 | S25: 단가 인상
A26: EBB00416AC | B26: 2017 | E26: =R26-B26 -> -2017 | R26: =SUM(F26:Q26) -> 0 | S26: 0
A27: PSA W2 | B27: 0 | E27: =R27-B27 -> 0 | R27: =SUM(F27:Q27) -> 0 | S27: 0
A28: EV2020 | B28: 601518 | E28: =R28-B28 -> 0 | F28: 45170 | G28: 60911 | H28: 62112 | I28: 62162 | J28: 78729 | K28: 55055 | L28: 44244 | M28: 52352 | N28: 34535 | O28: 48248 | P28: 29000 | Q28: 29000 | R28: =SUM(F28:Q28) -> 601518 | S28: 0
A29: BMW 12V HAF | B29: 14200 | E29: =R29-B29 -> 0 | F29: 900 | G29: 1200 | H29: 1400 | I29: 1200 | J29: 900 | K29: 1300 | L29: 1000 | M29: 1500 | N29: 1200 | O29: 1200 | P29: 1200 | Q29: 1200 | R29: =SUM(F29:Q29) -> 14200 | S29: 0
E30: 판가(EUR)
A31: PSA W1 SDN | B31: EBB00412AC(SDN) | C31: ME | E31: =VLOOKUP(B:B,'판매가,매입가'!B:D,3,0) -> 2.35 | F31: =$E$31*F2 -> 2115 | G31: =$E$31*G2 -> 117.5 | H31: =$E$31*H2 -> 0 | I31: =$E$31*I2 -> 1339.5 | J31: =$E$31*J2 -> 0 | R31: =SUM(F31:Q31) -> 3572
A32: PSA W1 SDN | B32: EBB00414AE(SDN) | C32: ME | E32: =VLOOKUP(B:B,'판매가,매입가'!B:D,3,0) -> 7.68 | F32: =$E$32*F2 -> 6912 | G32: =$E$32*G2 -> 384 | H32: =$E$32*H2 -> 0 | I32: =$E$32*I2 -> 4377.6 | J32: =$E$32*J2 -> 0 | R32: =SUM(F32:Q32) -> 11673.6
A33: PSA W1 SDN | B33: ECW01188AD(SDN) | C33: ME | E33: =VLOOKUP(B:B,'판매가,매입가'!B:D,3,0) -> 85.86 | F33: =$E$33*F2 -> 77274 | G33: =$E$33*G2 -> 4293 | H33: =$E$33*H2 -> 0 | I33: =$E$33*I2 -> 48940.2 | J33: =$E$33*J2 -> 0 | R33: =SUM(F33:Q33) -> 130507.2
A34: PSA W1 SDN | B34: EEA00306AC(SDN) | C34: ME | E34: =VLOOKUP(B:B,'판매가,매입가'!B:D,3,0) -> 18.46 | F34: =$E$34*F2 -> 16614 | G34: =$E$34*G2 -> 923 | H34: =$E$34*H2 -> 0 | I34: =$E$34*I2 -> 10522.2 | J34: =$E$34*J2 -> 0 | R34: =SUM(F34:Q34) -> 28059.2
A35: PSA W1 SDN | B35: EEA00308AF(SDN) | C35: ME | E35: =VLOOKUP(B:B,'판매가,매입가'!B:D,3,0) -> 106.61 | F35: =$E$35*F2 -> 95949 | G35: =$E$35*G2 -> 5330.5 | H35: =$E$35*H2 -> 0 | I35: =$E$35*I2 -> 60767.7 | J35: =$E$35*J2 -> 0 | R35: =SUM(F35:Q35) -> 162047.2
A36: PSA W1 SDN | B36: EBB00412AC(SDN)RE | C36: ME | E36: =VLOOKUP(B:B,'판매가,매입가'!B:D,3,0) -> 3.46 | K36: =$E$36*K2 -> 245.66 | L36: =$E$36*L2 -> 245.66 | M36: =$E$36*M2 -> 245.66 | N36: =$E$36*N2 -> 245.66 | O36: =$E$36*O2 -> 245.66 | P36: =$E$36*P2 -> 245.66 | Q36: =$E$36*Q2 -> 245.66 | R36: =SUM(F36:Q36) -> 1719.62
A37: PSA W1 SDN | B37: EBB00414AE(SDN)RE | C37: ME | E37: =VLOOKUP(B:B,'판매가,매입가'!B:D,3,0) -> 11.29 | K37: =$E$37*K2 -> 801.59 | L37: =$E$37*L2 -> 801.59 | M37: =$E$37*M2 -> 801.59 | N37: =$E$37*N2 -> 801.59 | O37: =$E$37*O2 -> 801.59 | P37: =$E$37*P2 -> 801.59 | Q37: =$E$37*Q2 -> 801.59 | R37: =SUM(F37:Q37) -> 5611.13
A38: PSA W1 SDN | B38: ECW01188AD(SDN)RE | C38: ME | E38: =VLOOKUP(B:B,'판매가,매입가'!B:D,3,0) -> 126.26 | K38: =$E$38*K2 -> 8964.46 | L38: =$E$38*L2 -> 8964.46 | M38: =$E$38*M2 -> 8964.46 | N38: =$E$38*N2 -> 8964.46 | O38: =$E$38*O2 -> 8964.46 | P38: =$E$38*P2 -> 8964.46 | Q38: =$E$38*Q2 -> 8964.46 | R38: =SUM(F38:Q38) -> 62751.22
A39: PSA W1 SDN | B39: EEA00306AC(SDN)RE | C39: ME | E39: =VLOOKUP(B:B,'판매가,매입가'!B:D,3,0) -> 27.14 | K39: =$E$39*K2 -> 1926.94 | L39: =$E$39*L2 -> 1926.94 | M39: =$E$39*M2 -> 1926.94 | N39: =$E$39*N2 -> 1926.94 | O39: =$E$39*O2 -> 1926.94 | P39: =$E$39*P2 -> 1926.94 | Q39: =$E$39*Q2 -> 1926.94 | R39: =SUM(F39:Q39) -> 13488.58
A40: PSA W1 SDN | B40: EEA00308AF(SDN)RE | C40: ME | E40: =VLOOKUP(B:B,'판매가,매입가'!B:D,3,0) -> 156.75 | K40: =$E$40*K2 -> 11129.25 | L40: =$E$40*L2 -> 11129.25 | M40: =$E$40*M2 -> 11129.25 | N40: =$E$40*N2 -> 11129.25 | O40: =$E$40*O2 -> 11129.25 | P40: =$E$40*P2 -> 11129.25 | Q40: =$E$40*Q2 -> 11129.25 | R40: =SUM(F40:Q40) -> 77904.75
A41: PSA W1 SDN | B41: EBB00416AC | C41: ME | E41: =VLOOKUP(B:B,'판매가,매입가'!B:D,3,0) -> 0.56 | F41: =$E$41*F2*4 -> 2016 | G41: =$E$41*G2*4 -> 112 | H41: =$E$41*H2*4 -> 0 | I41: =$E$41*I2*4 -> 1276.8 | J41: =$E$41*J2*4 -> 0 | K41: =$E$41*K2*4 -> 159.04 | L41: =$E$41*L2*4 -> 159.04 | M41: =$E$41*M2*4 -> 159.04 | ... Q41: =$E$41*Q2*4 -> 159.04 | R41: =SUM(F41:Q41) -> 4518.08
...

Sheet 노무비,급여(PLN)
A1: 구분 | B1: 중구분 | C1: 소구분 | D1: 이름 | E1: 1월 | F1: 2월 | G1: 3월 | H1: 4월 | I1: 5월 | J1: 6월 | K1: 7월 | L1: 8월 | M1: 9월 | N1: 10월 | O1: 11월 | P1: 12월 | Q1: 비고
A2: 사무직 | B2: AD | C2: 판관 | D2: Yunsung Jung | E2: ='인원급여리스트(PLN)'!I4 -> 4600 | F2: ='인원급여리스트(PLN)'!J4 -> 4600 | G2: ='인원급여리스트(PLN)'!K4 -> 4600 | H2: ='인원급여리스트(PLN)'!L4 -> 4600 | I2: ='인원급여리스트(PLN)'!M4 -> 4600 | J2: ='인원급여리스트(PLN)'!N4 -> 4600 | K2: ='인원급여리스트(PLN)'!O4 -> 4600 | L2: ='인원급여리스트(PLN)'!P4 -> 4600 | ... P2: ='인원급여리스트(PLN)'!T4 -> 4600 | Q2: 최저임금
C3: 판관 | D3: Katarzyna Spiewak | E3: ='인원급여리스트(PLN)'!I5 -> 12555.3 | F3: ='인원급여리스트(PLN)'!J5 -> 12806.06 | G3: ='인원급여리스트(PLN)'!K5 -> 12734.525 | H3: ='인원급여리스트(PLN)'!L5 -> 12608.387 | I3: ='인원급여리스트(PLN)'!M5 -> 12354.804 | J3: ='인원급여리스트(PLN)'!N5 -> 12725.867 | K3: ='인원급여리스트(PLN)'!O5 -> 12025.938 | L3: ='인원급여리스트(PLN)'!P5 -> 12024.519 | ... P3: ='인원급여리스트(PLN)'!T5 -> 13880
C4: 판관 | D4: Anastazja Zagajewska | E4: ='인원급여리스트(PLN)'!I6 -> 7283.293 | F4: ='인원급여리스트(PLN)'!J6 -> 7567.25 | G4: ='인원급여리스트(PLN)'!K6 -> 7394.2585 | H4: ='인원급여리스트(PLN)'!L6 -> 8346.9755 | I4: ='인원급여리스트(PLN)'!M6 -> 7875.8295 | J4: ='인원급여리스트(PLN)'!N6 -> 7381.2149 | K4: ='인원급여리스트(PLN)'!O6 -> 8199.4253 | L4: ='인원급여리스트(PLN)'!P6 -> 8201.2244 | ... P4: ='인원급여리스트(PLN)'!T6 -> 8350
C5: 판관합계(PLN) | E5: =SUM(E2:E4) -> 24438.593 | F5: =SUM(F2:F4) -> 24973.31 | G5: =SUM(G2:G4) -> 24728.784 | H5: =SUM(H2:H4) -> 25555.362 | I5: =SUM(I2:I4) -> 24830.633 | J5: =SUM(J2:J4) -> 24707.082 | K5: =SUM(K2:K4) -> 24825.363 | L5: =SUM(L2:L4) -> 24825.743 | ... P5: =SUM(P2:P4) -> 26830
B6: QC | C6: 제조간접 | D6: Katarzyna Ruminkiewicz | E6: ='인원급여리스트(PLN)'!I7 -> 7269.654 | F6: ='인원급여리스트(PLN)'!J7 -> 9442.7235 | G6: ='인원급여리스트(PLN)'!K7 -> 8293.362 | H6: ='인원급여리스트(PLN)'!L7 -> 8293.362 | I6: ='인원급여리스트(PLN)'!M7 -> 8293.362 | J6: ='인원급여리스트(PLN)'!N7 -> 8293.362 | K6: ='인원급여리스트(PLN)'!O7 -> 0 | L6: ='인원급여리스트(PLN)'!P7 -> 0 | ... P6: ='인원급여리스트(PLN)'!T7 -> 0
B7: LO | C7: 제조간접 | D7: Konrad Janeczek | E7: ='인원급여리스트(PLN)'!I8 -> 11271.153 | F7: ='인원급여리스트(PLN)'!J8 -> 11462.022 | G7: ='인원급여리스트(PLN)'!K8 -> 11866.933 | H7: ='인원급여리스트(PLN)'!L8 -> 11628.436 | I7: ='인원급여리스트(PLN)'!M8 -> 10714.033 | J7: ='인원급여리스트(PLN)'!N8 -> 12123.931 | K7: ='인원급여리스트(PLN)'!O8 -> 12305.518 | L7: ='인원급여리스트(PLN)'!P8 -> 11283.185 | ... P7: ='인원급여리스트(PLN)'!T8 -> 12000
C8: 제조간접 | D8: Robert Lachowicz | E8: ='인원급여리스트(PLN)'!I9 -> 7517.644 | F8: ='인원급여리스트(PLN)'!J9 -> 8083.551 | G8: ='인원급여리스트(PLN)'!K9 -> 8029.392 | H8: ='인원급여리스트(PLN)'!L9 -> 7642.95 | I8: ='인원급여리스트(PLN)'!M9 -> 8127.672 | J8: ='인원급여리스트(PLN)'!N9 -> 8456.68 | K8: ='인원급여리스트(PLN)'!O9 -> 7788.3225 | L8: ='인원급여리스트(PLN)'!P9 -> 8275.849 | ... P8: ='인원급여리스트(PLN)'!T9 -> 8679.6638
C9: 제조간접 | D9: Maciej Przydzial | E9: ='인원급여리스트(PLN)'!I10 -> 8269.654 | F9: ='인원급여리스트(PLN)'!J10 -> 9442.7235 | G9: ='인원급여리스트(PLN)'!K10 -> 9293.362 | H9: ='인원급여리스트(PLN)'!L10 -> 9293.362 | I9: ='인원급여리스트(PLN)'!M10 -> 9293.362 | J9: ='인원급여리스트(PLN)'!N10 -> 9293.362 | K9: ='인원급여리스트(PLN)'!O10 -> 0 | L9: ='인원급여리스트(PLN)'!P10 -> 0 | ... P9: ='인원급여리스트(PLN)'!T10 -> 0
C10: 간접합계(PLN) | E10: =SUM(E6:E9) -> 34328.105 | F10: =SUM(F6:F9) -> 38431.02 | G10: =SUM(G6:G9) -> 37483.049 | H10: =SUM(H6:H9) -> 36858.11 | I10: =SUM(I6:I9) -> 36428.429 | J10: =SUM(J6:J9) -> 38167.335 | K10: =SUM(K6:K9) -> 20093.84 | L10: =SUM(L6:L9) -> 19559.035 | ... P10: =SUM(P6:P9) -> 20679.664
A11: 생산직 | B11: F/W | C11: 제조직접 | D11: Sorting | E11: ='인원급여리스트(PLN)'!I15 -> 52420 | F11: ='인원급여리스트(PLN)'!J15 -> 52420 | G11: ='인원급여리스트(PLN)'!K15 -> 57612 | H11: ='인원급여리스트(PLN)'!L15 -> 55016 | I11: ='인원급여리스트(PLN)'!M15 -> 47228 | J11: ='인원급여리스트(PLN)'!N15 -> 55016 | K11: ='인원급여리스트(PLN)'!O15 -> 60208 | L11: ='인원급여리스트(PLN)'!P15 -> 52420 | ... P11: ='인원급여리스트(PLN)'!T15 -> 57612
C12: 직접합계(PLN) | E12: =SUM(E11:E11) -> 52420 | F12: =SUM(F11:F11) -> 52420 | G12: =SUM(G11:G11) -> 57612 | H12: =SUM(H11:H11) -> 55016 | I12: =SUM(I11:I11) -> 47228 | J12: =SUM(J11:J11) -> 55016 | K12: =SUM(K11:K11) -> 60208 | L12: =SUM(L11:L11) -> 52420 | ... P12: =SUM(P11:P11) -> 57612
A13: 총합계 | C13: PLN | E13: =E5+E10+E12 -> 111186.7 | F13: =F5+F10+F12 -> 115824.33 | G13: =G5+G10+G12 -> 119823.83 | H13: =H5+H10+H12 -> 117429.47 | I13: =I5+I10+I12 -> 108487.06 | J13: =J5+J10+J12 -> 117890.42 | K13: =K5+K10+K12 -> 105127.2 | L13: =L5+L10+L12 -> 96804.778 | ... P13: =P5+P10+P12 -> 105121.66
B15: 2025 | C15: 주재원 | D15: PLN | E15: =+E2 -> 4600 | F15: =+F2 -> 4600 | G15: =+G2 -> 4600 | H15: =+H2 -> 4600 | I15: =+I2 -> 4600 | J15: =+J2 -> 4600 | K15: =+K2 -> 4600 | L15: =+L2 -> 4600 | ... P15: =+P2 -> 4600
C16: 판관 | D16: PLN | E16: =E3+E4 -> 19838.593 | F16: =F3+F4 -> 20373.31 | G16: =G3+G4 -> 20128.783 | H16: =H3+H4 -> 20955.362 | I16: =I3+I4 -> 20230.633 | J16: =J3+J4 -> 20107.082 | K16: =K3+K4 -> 20225.363 | L16: =L3+L4 -> 20225.743 | ... P16: =P3+P4 -> 22230
C17: 사무간접제조 | D17: PLN | E17: =SUM(E10) -> 34328.105 | F17: =SUM(F10) -> 38431.02 | G17: =SUM(G10) -> 37483.049 | H17: =SUM(H10) -> 36858.11 | I17: =SUM(I10) -> 36428.429 | J17: =SUM(J10) -> 38167.335 | K17: =SUM(K10) -> 20093.84 | L17: =SUM(L10) -> 19559.035 | ... P17: =SUM(P10) -> 20679.664
C18: 생산간접제조 | D18: PLN | E18: =SUM(E12) -> 52420 | F18: =SUM(F12) -> 52420 | G18: =SUM(G12) -> 57612 | H18: =SUM(H12) -> 55016 | I18: =SUM(I12) -> 47228 | J18: =SUM(J12) -> 55016 | K18: =SUM(K12) -> 60208 | L18: =SUM(L12) -> 52420 | ... P18: =SUM(P12) -> 57612
C20: 주재원 | D20: Won | E20: =E15*환율기준!$D$5 -> 1771000 | F20: =F15*환율기준!$D$5 -> 1771000 | G20: =G15*환율기준!$D$5 -> 1771000 | H20: =H15*환율기준!$D$5 -> 1771000 | I20: =I15*환율기준!$D$5 -> 1771000 | J20: =J15*환율기준!$D$5 -> 1771000 | K20: =K15*환율기준!$D$5 -> 1771000 | L20: =L15*환율기준!$D$5 -> 1771000 | ... P20: =P15*환율기준!$D$5 -> 1771000
C21: 판관 | D21: Won | E21: =E16*환율기준!$D$5 -> 7637858.3 | F21: =F16*환율기준!$D$5 -> 7843724.3 | G21: =G16*환율기준!$D$5 -> 7749581.6 | H21: =H16*환율기준!$D$5 -> 8067814.6 | I21: =I16*환율기준!$D$5 -> 7788793.9 | J21: =J16*환율기준!$D$5 -> 7741226.5 | K21: =K16*환율기준!$D$5 -> 7786764.9 | L21: =L16*환율기준!$D$5 -> 7786911.2 | ... P21: =P16*환율기준!$D$5 -> 8558550
C22: 사무간접제조 | D22: Won | E22: =E17*환율기준!$D$5 -> 13216320 | F22: =F17*환율기준!$D$5 -> 14795943 | G22: =G17*환율기준!$D$5 -> 14430974 | H22: =H17*환율기준!$D$5 -> 14190372 | I22: =I17*환율기준!$D$5 -> 14024945 | J22: =J17*환율기준!$D$5 -> 14694424 | K22: =K17*환율기준!$D$5 -> 7736128.6 | L22: =L17*환율기준!$D$5 -> 7530228.3 | ... P22: =P17*환율기준!$D$5 -> 7961670.6
C23: 생산간접제조 | D23: Won | E23: =E18*환율기준!$D$5 -> 20181700 | F23: =F18*환율기준!$D$5 -> 20181700 | G23: =G18*환율기준!$D$5 -> 22180620 | H23: =H18*환율기준!$D$5 -> 21181160 | I23: =I18*환율기준!$D$5 -> 18182780 | J23: =J18*환율기준!$D$5 -> 21181160 | K23: =K18*환율기준!$D$5 -> 23180080 | L23: =L18*환율기준!$D$5 -> 20181700 | ... P23: =P18*환율기준!$D$5 -> 22180620

Sheet 임대용역(PLN)
A1: 구분 | B1: 중구분(PLN) | C1: 1월 | D1: 2월 | E1: 3월 | F1: 4월 | G1: 5월 | H1: 6월 | I1: 7월 | J1: 8월 | K1: 9월 | L1: 10월 | M1: 11월 | N1: 12월 | O1: 비고
A2: 임대,용역,리스 | B2: 임대,용역,리스 | C2: =C20 -> 113840.56 | D2: =D20 -> 113840.56 | E2: =E20 -> 113840.56 | F2: =F20 -> 113440.56 | G2: =G20 -> 112940.56 | H2: =H20 -> 112940.56 | I2: =I20 -> 113940.56 | J2: =J20 -> 113940.56 | ... N2: =N20 -> 112340.56 | O2: 임대료, 리스 외(공장임대료,회계 수수료, 안전관리 수수료, 직원 작업복, 주재원 숙소 임대료, 정수기 등)
A3: 세금공과 | B3: 세금공과 | C3: 45000 | D3: =C3 -> 45000 | E3: =D3 -> 45000 | F3: =E3 -> 45000 | G3: =F3 -> 45000 | H3: =G3 -> 45000 | I3: =H3 -> 45000 | J3: =I3 -> 45000 | K3: =J3 -> 45000 | ... N3: =M3 -> 45000 | O3: ZUS, PIT4, PPK, Multy sport
A4: 기타 | B4: 소모품비,운영,부서비 | C4: 4000 | D4: =C4 -> 4000 | E4: =D4 -> 4000 | F4: 3000 | G4: =F4 -> 3000 | H4: =G4 -> 3000 | I4: 4000 | J4: =I4 -> 4000 | K4: =J4 -> 4000 | L4: 3000 | M4: =L4 -> 3000 | N4: =M4 -> 3000 | O4: 부서 운영비(부서비, 소모품비 등)
A5: 기타 | B5: 기타(식대,후생접대 등) | C5: 5000 | D5: =C5 -> 5000 | E5: =5000+80000 -> 85000 | F5: 4000 | G5: =F5 -> 4000 | H5: =G5 -> 4000 | I5: 5000 | J5: 5000 | K5: 5000 | L5: =4000+10800 -> 14800 | M5: =4000+30000 -> 34000 | N5: =4000 -> 4000 | O5: 3월 회계 외부감사 비용, 10월 IATF 심사비용, 11월 이전가격 비용
A6: IT 비용 | B6: 홀딩스 청구 | C6: =C22 -> 3401.2987 | D6: =D22 -> 3401.2987 | E6: =E22 -> 3401.2987 | F6: =F22 -> 3401.2987 | G6: =G22 -> 3401.2987 | H6: =H22 -> 3401.2987 | I6: =I22 -> 3401.2987 | J6: =J22 -> 3401.2987 | ... N6: =N22 -> 3401.2987 | O6: 2025년 상반기 기준
A7: 이자비용 | B7: 이자비용 | C7: 160000 | D7: 160000 | E7: 160000 | F7: 160000 | G7: 160000 | H7: 160000 | I7: 160000 | J7: 160000 | K7: 160000 | L7: 160000 | M7: 160000 | N7: 160000 | O7: 800만 USD 차입기준
C10: PLN
A11: 임대,용역,리스 | B11: 공장 임대료 | C11: =16294*1600/385 -> 67715.325 | D11: =16294*1600/385 -> 67715.325 | E11: =16294*1600/385 -> 67715.325 | F11: =16294*1600/385 -> 67715.325 | G11: =16294*1600/385 -> 67715.325 | H11: =16294*1600/385 -> 67715.325 | I11: =16294*1600/385 -> 67715.325 | J11: =16294*1600/385 -> 67715.325 | ... N11: =16294*1600/385 -> 67715.325
B12: 공장 관리비 | C12: 21725.24 | D12: 21725.24 | E12: 21725.24 | F12: 21725.24 | G12: 21725.24 | H12: 21725.24 | I12: 21725.24 | J12: 21725.24 | K12: 21725.24 | L12: 21725.24 | M12: 21725.24 | N12: 21725.24
B13: 회계 | C13: 7500 | D13: =C13 -> 7500 | E13: =D13 -> 7500 | F13: =E13 -> 7500 | G13: 7000 | H13: =G13 -> 7000 | I13: =H13 -> 7000 | J13: =I13 -> 7000 | K13: =J13 -> 7000 | L13: =K13 -> 7000 | M13: =L13 -> 7000 | N13: =M13 -> 7000
B14: 안전관리 | C14: 1500 | D14: =C14 -> 1500 | E14: =D14 -> 1500 | F14: =E14 -> 1500 | G14: =F14 -> 1500 | H14: =G14 -> 1500 | I14: =H14 -> 1500 | J14: =I14 -> 1500 | K14: =J14 -> 1500 | ... N14: =M14 -> 1500
B15: 정수 임대 | C15: 600 | D15: =C15 -> 600 | E15: =D15 -> 600 | F15: 1200 | G15: =F15 -> 1200 | H15: =G15 -> 1200 | I15: =H15 -> 1200 | J15: =I15 -> 1200 | K15: 1200 | L15: 600 | M15: =L15 -> 600 | N15: =M15 -> 600
B16: 프린터 임대 | C16: 1300 | D16: =C16 -> 1300 | E16: =D16 -> 1300 | F16: =E16 -> 1300 | G16: =F16 -> 1300 | H16: =G16 -> 1300 | I16: =H16 -> 1300 | J16: =I16 -> 1300 | K16: =J16 -> 1300 | ... N16: =M16 -> 1300
B17: 공장 청소 | C17: 6000 | D17: =C17 -> 6000 | E17: =D17 -> 6000 | F17: =E17 -> 6000 | G17: =F17 -> 6000 | H17: =G17 -> 6000 | I17: =H17 -> 6000 | J17: =I17 -> 6000 | K17: =J17 -> 6000 | ... N17: =M17 -> 6000
B18: 차량리스 | C18: 5500 | D18: =C18 -> 5500 | E18: =D18 -> 5500 | F18: =E18 -> 5500 | G18: =F18 -> 5500 | H18: =G18 -> 5500 | I18: =H18 -> 5500 | J18: =I18 -> 5500 | K18: =J18 -> 5500 | ... N18: =M18 -> 5500
B19: 쓰레기 처리 | C19: 2000 | D19: =C19 -> 2000 | E19: =D19 -> 2000 | F19: 1000 | G19: =F19 -> 1000 | H19: =G19 -> 1000 | I19: 2000 | J19: =I19 -> 2000 | K19: =J19 -> 2000 | L19: 1000 | M19: =L19 -> 1000 | N19: =M19 -> 1000
B20: 합계 | C20: =SUM(C11:C19) -> 113840.56 | D20: =SUM(D11:D19) -> 113840.56 | E20: =SUM(E11:E19) -> 113840.56 | F20: =SUM(F11:F19) -> 113440.56 | G20: =SUM(G11:G19) -> 112940.56 | H20: =SUM(H11:H19) -> 112940.56 | I20: =SUM(I11:I19) -> 113940.56 | J20: =SUM(J11:J19) -> 113940.56 | ... N20: =SUM(N11:N19) -> 112340.56
A22: IT 비용 | C22: =970*1350/385 -> 3401.2987 | D22: =970*1350/385 -> 3401.2987 | E22: =970*1350/385 -> 3401.2987 | F22: =970*1350/385 -> 3401.2987 | G22: =970*1350/385 -> 3401.2987 | H22: =970*1350/385 -> 3401.2987 | I22: =970*1350/385 -> 3401.2987 | J22: =970*1350/385 -> 3401.2987 | ... N22: =970*1350/385 -> 3401.2987

Sheet 기계경비(PLN)
B1: 1월 | C1: 2월 | D1: 3월 | E1: 4월 | F1: 5월 | G1: 6월 | H1: 7월 | I1: 8월 | J1: 9월 | K1: 10월 | L1: 11월 | M1: 12월 | N1: 비고
A2: 기계경비(PLN) | B2: 8000 | C2: 8000 | D2: =C2*0.9 -> 7200 | E2: =D2 -> 7200 | F2: =E2 -> 7200 | G2: =C2 -> 8000 | H2: =B2 -> 8000 | I2: =B2 -> 8000 | J2: =D2 -> 7200 | K2: =E2 -> 7200 | L2: =F2 -> 7200 | M2: =B2 -> 8000 | N2: 봄, 가을 10% 인하적용

Sheet 운반비(PLN),통관물류(PLN)
B1: 1월 | C1: 2월 | D1: 3월 | E1: 4월 | F1: 5월 | G1: 6월 | H1: 7월 | I1: 8월 | J1: 9월 | K1: 10월 | L1: 11월 | M1: 12월 | N1: 비고
A2: 단가(LGESWA, EUR) | B2: 100 | C2: =B2 -> 100 | D2: =C2 -> 100 | E2: =D2 -> 100 | F2: =E2 -> 100 | G2: =F2 -> 100 | H2: =G2 -> 100 | I2: =H2 -> 100 | J2: =I2 -> 100 | ... M2: =L2 -> 100 | N2: 100EUR(1회/일, 납품), 리턴은 미적용
A3: 운반일수 | B3: ='인원급여리스트(PLN)'!I2 -> 20 | C3: ='인원급여리스트(PLN)'!J2 -> 20 | D3: ='인원급여리스트(PLN)'!K2 -> 22 | E3: ='인원급여리스트(PLN)'!L2 -> 21 | F3: ='인원급여리스트(PLN)'!M2 -> 18 | G3: ='인원급여리스트(PLN)'!N2 -> 21 | H3: ='인원급여리스트(PLN)'!O2 -> 23 | I3: ='인원급여리스트(PLN)'!P2 -> 20 | ... M3: ='인원급여리스트(PLN)'!T2 -> 22
A4: 합계금액(EUR) | B4: =B2*B3 -> 2000 | C4: =C2*C3 -> 2000 | D4: =D2*D3 -> 2200 | E4: =E2*E3 -> 2100 | F4: =F2*F3 -> 1800 | G4: =G2*G3 -> 2100 | H4: =H2*H3 -> 2300 | I4: =I2*I3 -> 2000 | ... M4: =M2*M3 -> 2200
A5: 합계금액(PLN) | B5: =B4*환율기준!$D$4 -> 8400 | C5: =C4*환율기준!$D$4 -> 8400 | D5: =D4*환율기준!$D$4 -> 9240 | E5: =E4*환율기준!$D$4 -> 8820 | F5: =F4*환율기준!$D$4 -> 7560 | G5: =G4*환율기준!$D$4 -> 8820 | H5: =H4*환율기준!$D$4 -> 9660 | I5: =I4*환율기준!$D$4 -> 8400 | ... M5: =M4*환율기준!$D$4 -> 9240
A8: 중구분(PLN) | B8: 1월 | C8: 2월 | D8: 3월 | E8: 4월 | F8: 5월 | G8: 6월 | H8: 7월 | I8: 8월 | J8: 9월 | K8: 10월 | L8: 11월 | M8: 12월 | N8: 비고
A9: 통관비, 물류비 | B9: =1000*8+10000*1 -> 18000 | C9: =1000*8+10000*1 -> 18000 | D9: =1000*10+10000*1 -> 20000 | E9: =1000*8+10000 -> 18000 | F9: =1000*8+10000 -> 18000 | G9: =1000*10+10000 -> 20000 | H9: =1000*8+10000 -> 18000 | I9: =1000*8+10000 -> 18000 | J9: =1000*10+10000 -> 20000 | K9: =1000*8+10000 -> 18000 | L9: =1000*8+10000 -> 18000 | M9: =1000*8+10000 -> 18000 | N9: 주당 2대기준(입고,리턴), 물류비 1,000PLN적용 창저우 12월까지 월 1회 적용(회당 10,000PLN)

Sheet 인원급여리스트(PLN)
A1: 인별로 작성 바람 | U1: 단위: PLN
H2: Working day | I2: 20 | J2: 20 | K2: 22 | L2: 21 | M2: 18 | N2: 21 | O2: 23 | P2: 20 | Q2: 22 | R2: 22 | S2: 19 | T2: 22
A3: 사업장 | B3: 구분 | C3: 사업부 | D3: 팀 | E3: 사번 | F3: 이름 | G3: 기능영역 | H3: 월급여 | I3: 1월 | J3: 2월 | K3: 3월 | L3: 4월 | M3: 5월 | N3: 6월 | O3: 7월 | P3: 8월 | Q3: 9월 | R3: 10월 | S3: 11월 | T3: 12월 | U3: 비고
A4: KSCP | B4: 주재원 | C4: COMMON | D4: AD | E4: 5025 | F4: Yunsung Jung | G4: 판관 | H4: =AVERAGE(I4:T4) -> 4600 | I4: 4600 | J4: 4600 | K4: 4600 | L4: 4600 | M4: 4600 | N4: 4600 | O4: 4600 | P4: 4600 | Q4: 4600 | R4: 4600 | S4: 4600 | T4: 4600 | U4: 주재원 최소급여적용
A5: KSCP | B5: 현채인 | C5: COMMON | D5: AD | E5: P1803001 | F5: Katarzyna Spiewak | G5: 판관 | H5: =(AVERAGE(I5:T5)) -> 12627.586 | I5: 12555.3 | J5: 12806.06 | K5: 12734.525 | L5: 12608.387 | M5: 12354.804 | N5: 12725.867 | O5: 12025.938 | P5: 12024.519 | Q5: 13515.018 | R5: 11683.749 | S5: 12616.868 | T5: 13880
A6: KSCP | B6: 현채인 | C6: COMMON | D6: AD | E6: P1906001 | F6: Anastazja Zagajewska | G6: 판관 | H6: =(AVERAGE(I6:T6)) -> 7929.6256 | I6: 7283.293 | J6: 7567.25 | K6: 7394.2585 | L6: 8346.9755 | M6: 7875.8295 | N6: 7381.2149 | O6: 8199.4253 | P6: 8201.2244 | Q6: 8001.1175 | R6: 8204.9188 | S6: 8350 | T6: 8350
A7: KSCP | B7: 현채인 | C7: COMMON | D7: QC | E7: P1908002 | F7: Katarzyna Ruminkiewicz | G7: 제조간접 | H7: =(AVERAGE(I7:T7)) -> 8314.3042 | I7: 7269.654 | J7: 9442.7235 | K7: 8293.362 | L7: =K7 -> 8293.362 | M7: =L7 -> 8293.362 | N7: =M7 -> 8293.362 | U7: 상반기 내 인원조정
A8: KSCP | B8: 현채인 | C8: COMMON | D8: PC | E8: P1910001 | F8: Konrad Janeczek | G8: 제조간접 | H8: =(AVERAGE(I8:T8)) -> 11657.088 | I8: 11271.153 | J8: 11462.022 | K8: 11866.933 | L8: 11628.436 | M8: 10714.033 | N8: 12123.931 | O8: 12305.518 | P8: 11283.185 | Q8: 12147.398 | R8: 11082.447 | S8: 12000 | T8: 12000
A9: KSCP | B9: 현채인 | C9: COMMON | D9: QC | E9: P1807001 | F9: Robert Lachowicz | G9: 제조간접 | H9: =(AVERAGE(I9:T9)) -> 8092.407 | I9: 7517.644 | J9: 8083.551 | K9: 8029.392 | L9: 7642.95 | M9: 8127.672 | N9: 8456.68 | O9: 7788.3225 | P9: 8275.849 | Q9: 8643.8845 | R9: 7596.9285 | S9: 8266.3465 | T9: =(S9)*1.05 -> 8679.6638
A10: KSCP | B10: 현채인 | C10: COMMON | D10: PC | E10: P1908003 | F10: Maciej Przydzial | G10: 제조간접 | H10: =(AVERAGE(I10:T10)) -> 9147.6376 | I10: 8269.654 | J10: 9442.7235 | K10: 9293.362 | L10: =K10 -> 9293.362 | M10: =L10 -> 9293.362 | N10: =M10 -> 9293.362 | U10: 상반기 내 인원조정
A11: KSCP | B11: Out-sourcing(LD) | C11: COMMON | D11: PC | E11: - | F11: Dubrovna Ivanna | G11: 제조직접 | H11: =AVERAGE(I11:T11) -> 14020.833 | I11: =(59*11*20)+500 -> 13480 | J11: =(59*11*20)+500 -> 13480 | K11: =(59*11*22)+500 -> 14778 | L11: =(59*11*21)+500 -> 14129 | M11: =(59*11*18)+500 -> 12182 | N11: =(59*11*21)+500 -> 14129 | O11: =(59*11*23)+500 -> 15427 | P11: =(59*11*20)+500 -> 13480 | Q11: =(59*11*22)+500 -> 14778 | R11: =(59*11*22)+500 -> 14778 | S11: =(59*11*19)+500 -> 12831 | T11: =(59*11*22)+500 -> 14778 | U11: 최저임금 48PLN(VAT 포함시 59PLN)
A12: KSCP | B12: Out-sourcing | C12: COMMON | D12: PC | E12: - | F12: Olga Perepadchenko | G12: 제조직접 | H12: =AVERAGE(I12:T12) -> 13520.833 | I12: =(59*11*20) -> 12980 | J12: =(59*11*20) -> 12980 | K12: =(59*11*22) -> 14278 | L12: =(59*11*21) -> 13629 | M12: =(59*11*18) -> 11682 | N12: =(59*11*21) -> 13629 | O12: =(59*11*23) -> 14927 | P12: =(59*11*20) -> 12980 | Q12: =(59*11*22) -> 14278 | R12: =(59*11*22) -> 14278 | S12: =(59*11*19) -> 12331 | T12: =(59*11*22) -> 14278 | U12: 최저임금 48PLN(VAT 포함시 59PLN)
A13: KSCP | B13: Out-sourcing | C13: COMMON | D13: PC | E13: - | F13: Yafremenka Alesia | G13: 제조직접 | H13: =AVERAGE(I13:T13) -> 13520.833 | I13: =I12 -> 12980 | J13: =J12 -> 12980 | K13: =K12 -> 14278 | L13: =L12 -> 13629 | M13: =M12 -> 11682 | N13: =N12 -> 13629 | O13: =O12 -> 14927 | P13: =P12 -> 12980 | ... T13: =T12 -> 14278 | U13: 최저임금 48PLN(VAT 포함시 59PLN)
A14: KSCP | B14: Out-sourcing | C14: COMMON | D14: PC | E14: - | F14: Gencas Svitlana | G14: 제조직접 | H14: =AVERAGE(I14:T14) -> 13520.833 | I14: =I13 -> 12980 | J14: =J13 -> 12980 | K14: =K13 -> 14278 | L14: =L13 -> 13629 | M14: =M13 -> 11682 | N14: =N13 -> 13629 | O14: =O13 -> 14927 | P14: =P13 -> 12980 | ... T14: =T13 -> 14278 | U14: 최저임금 48PLN(VAT 포함시 59PLN)
A15: 제조직접 | F15: 직접합계 | G15: PLN | H15: =AVERAGE(I15:T15) -> 54583.333 | I15: =SUMIF($G:$G,"제조직접",I:I) -> 52420 | J15: =SUMIF($G:$G,"제조직접",J:J) -> 52420 | K15: =SUMIF($G:$G,"제조직접",K:K) -> 57612 | L15: =SUMIF($G:$G,"제조직접",L:L) -> 55016 | M15: =SUMIF($G:$G,"제조직접",M:M) -> 47228 | N15: =SUMIF($G:$G,"제조직접",N:N) -> 55016 | O15: =SUMIF($G:$G,"제조직접",O:O) -> 60208 | P15: =SUMIF($G:$G,"제조직접",P:P) -> 52420 | Q15: =SUMIF($G:$G,"제조직접",Q:Q) -> 57612 | R15: =SUMIF($G:$G,"제조직접",R:R) -> 57612 | S15: =SUMIF($G:$G,"제조직접",S:S) -> 49824 | T15: =SUMIF($G:$G,"제조직접",T:T) -> 57612
A16: 제조간접 | F16: 간접합계 | G16: PLN | H16: =AVERAGE(I16:T16) -> 28480.466 | I16: =SUMIF($G:$G,"제조간접",I:I) -> 34328.105 | J16: =SUMIF($G:$G,"제조간접",J:J) -> 38431.02 | K16: =SUMIF($G:$G,"제조간접",K:K) -> 37483.049 | L16: =SUMIF($G:$G,"제조간접",L:L) -> 36858.11 | M16: =SUMIF($G:$G,"제조간접",M:M) -> 36428.429 | N16: =SUMIF($G:$G,"제조간접",N:N) -> 38167.335 | O16: =SUMIF($G:$G,"제조간접",O:O) -> 20093.84 | P16: =SUMIF($G:$G,"제조간접",P:P) -> 19559.035 | Q16: =SUMIF($G:$G,"제조간접",Q:Q) -> 20791.282 | R16: =SUMIF($G:$G,"제조간접",R:R) -> 18679.375 | S16: =SUMIF($G:$G,"제조간접",S:S) -> 20266.346 | T16: =SUMIF($G:$G,"제조간접",T:T) -> 20679.664
A17: 사무직 | F17: 판관합계 | G17: PLN | H17: =AVERAGE(I17:T17) -> 25157.212 | I17: =SUMIF($G:$G,"판관",I:I) -> 24438.593 | J17: =SUMIF($G:$G,"판관",J:J) -> 24973.31 | K17: =SUMIF($G:$G,"판관",K:K) -> 24728.784 | L17: =SUMIF($G:$G,"판관",L:L) -> 25555.362 | M17: =SUMIF($G:$G,"판관",M:M) -> 24830.633 | N17: =SUMIF($G:$G,"판관",N:N) -> 24707.082 | O17: =SUMIF($G:$G,"판관",O:O) -> 24825.363 | P17: =SUMIF($G:$G,"판관",P:P) -> 24825.743 | Q17: =SUMIF($G:$G,"판관",Q:Q) -> 26116.136 | R17: =SUMIF($G:$G,"판관",R:R) -> 24488.668 | S17: =SUMIF($G:$G,"판관",S:S) -> 25566.868 | T17: =SUMIF($G:$G,"판관",T:T) -> 26830

Sheet 관세(PLN)
C1: 매입가 | D1: 관세율 | E1: 1월 | F1: 2월 | G1: 3월 | H1: 4월 | I1: 5월 | J1: 6월 | K1: 7월 | L1: 8월 | M1: 9월 | N1: 10월 | O1: 11월 | P1: 12월 | Q1: Total | R1: 비고
A2: PSA W1 SDN | B2: EBB00412AC(SDN) | C2: =VLOOKUP(B:B,'판매가,매입가'!B:H,7,0) -> 2.55 | D2: 0.033 | E2: =사업계획!F9*$C$2*$D$2 -> 0 | F2: =사업계획!G9*$C$2*$D$2 -> 0 | G2: =사업계획!H9*$C$2*$D$2 -> 84.15 | H2: =사업계획!I9*$C$2*$D$2 -> 0 | I2: =사업계획!J9*$C$2*$D$2 -> 0 | Q2: =SUM(E2:P2) -> 84.15 | T2: EBB00412AC(SDN)
A3: PSA W1 SDN | B3: EBB00414AE(SDN) | C3: =VLOOKUP(B:B,'판매가,매입가'!B:H,7,0) -> 8.25 | D3: 0.033 | E3: =사업계획!F10*$C$3*$D$3 -> 0 | F3: =사업계획!G10*$C$3*$D$3 -> 0 | G3: =사업계획!H10*$C$3*$D$3 -> 163.35 | H3: =사업계획!I10*$C$3*$D$3 -> 163.35 | I3: =사업계획!J10*$C$3*$D$3 -> 0 | Q3: =SUM(E3:P3) -> 326.7 | T3: EBB00414AE(SDN)
A4: PSA W1 SDN | B4: ECW01188AD(SDN) | C4: =VLOOKUP(B:B,'판매가,매입가'!B:H,7,0) -> 98.23 | D4: 0.037 | E4: =사업계획!F11*$C$4*$D$4 -> 1221.1954 | F4: =사업계획!G11*$C$4*$D$4 -> 1424.7279 | G4: =사업계획!H11*$C$4*$D$4 -> 1526.4942 | H4: =사업계획!I11*$C$4*$D$4 -> 1526.4942 | I4: =사업계획!J11*$C$4*$D$4 -> 1526.4942 | Q4: =SUM(E4:P4) -> 7225.4059 | T4: ECW01188AD(SDN)
A5: PSA W1 SDN | B5: EEA00306AC(SDN) | C5: =VLOOKUP(B:B,'판매가,매입가'!B:H,7,0) -> 19.51 | D5: 0.023 | E5: =사업계획!F12*$C$5*$D$5 -> 0 | F5: =사업계획!G12*$C$5*$D$5 -> 0 | G5: =사업계획!H12*$C$5*$D$5 -> 0 | H5: =사업계획!I12*$C$5*$D$5 -> 0 | I5: =사업계획!J12*$C$5*$D$5 -> 0 | Q5: =SUM(E5:P5) -> 0 | T5: EEA00306AC(SDN)
A6: PSA W1 SDN | B6: EEA00308AF(SDN) | C6: =VLOOKUP(B:B,'판매가,매입가'!B:H,7,0) -> 114.58 | D6: 0.017 | E6: =사업계획!F13*$C$6*$D$6 -> 0 | F6: =사업계획!G13*$C$6*$D$6 -> 0 | G6: =사업계획!H13*$C$6*$D$6 -> 0 | H6: =사업계획!I13*$C$6*$D$6 -> 0 | I6: =사업계획!J13*$C$6*$D$6 -> 0 | Q6: =SUM(E6:P6) -> 0 | T6: EEA00308AF(SDN)
A7: PSA W1 SDN | B7: EBB00412AC(SDN)RE | C7: =VLOOKUP(B:B,'판매가,매입가'!B:H,7,0) -> 3.1534698 | D7: 0.033 | J7: =사업계획!K14*$C$7*$D$7 -> 0 | K7: =사업계획!L14*$C$7*$D$7 -> 0 | L7: =사업계획!M14*$C$7*$D$7 -> 0 | M7: =사업계획!N14*$C$7*$D$7 -> 0 | N7: =사업계획!O14*$C$7*$D$7 -> 0 | O7: =사업계획!P14*$C$7*$D$7 -> 0 | P7: =사업계획!Q14*$C$7*$D$7 -> 0 | Q7: =SUM(E7:P7) -> 0
A8: PSA W1 SDN | B8: EBB00414AE(SDN)RE | C8: =VLOOKUP(B:B,'판매가,매입가'!B:H,7,0) -> 10.202402 | D8: 0.033 | J8: =사업계획!K15*$C$8*$D$8 -> 0 | K8: =사업계획!L15*$C$8*$D$8 -> 0 | L8: =사업계획!M15*$C$8*$D$8 -> 0 | M8: =사업계획!N15*$C$8*$D$8 -> 0 | N8: =사업계획!O15*$C$8*$D$8 -> 0 | O8: =사업계획!P15*$C$8*$D$8 -> 0 | P8: =사업계획!Q15*$C$8*$D$8 -> 0 | Q8: =SUM(E8:P8) -> 0
A9: PSA W1 SDN | B9: ECW01188AD(SDN)RE | C9: =VLOOKUP(B:B,'판매가,매입가'!B:H,7,0) -> 169.74075 | D9: 0.037 | J9: =사업계획!K16*$C$9*$D$9 -> 3517.0283 | K9: =사업계획!L16*$C$9*$D$9 -> 2637.7712 | L9: =사업계획!M16*$C$9*$D$9 -> 4747.9882 | M9: =사업계획!N16*$C$9*$D$9 -> 2637.7712 | N9: =사업계획!O16*$C$9*$D$9 -> 3517.0283 | O9: =사업계획!P16*$C$9*$D$9 -> 1758.5142 | P9: =사업계획!Q16*$C$9*$D$9 -> 1230.9599 | Q9: =SUM(E9:P9) -> 20047.061
A10: PSA W1 SDN | B10: EEA00306AC(SDN)RE | C10: =VLOOKUP(B:B,'판매가,매입가'!B:H,7,0) -> 24.12 | D10: 0.023 | J10: =사업계획!K17*$C$9*$D$9 -> 0 | K10: =사업계획!L17*$C$9*$D$9 -> 0 | L10: =사업계획!M17*$C$9*$D$9 -> 0 | M10: =사업계획!N17*$C$9*$D$9 -> 0 | N10: =사업계획!O17*$C$9*$D$9 -> 0 | O10: =사업계획!P17*$C$9*$D$9 -> 0 | P10: =사업계획!Q17*$C$9*$D$9 -> 0 | Q10: =SUM(E10:P10) -> 0
A11: PSA W1 SDN | B11: EEA00308AF(SDN)RE | C11: =VLOOKUP(B:B,'판매가,매입가'!B:H,7,0) -> 141.68 | D11: 0.017 | J11: =사업계획!K18*$C$10*$D$10 -> 0 | K11: =사업계획!L18*$C$10*$D$10 -> 0 | L11: =사업계획!M18*$C$10*$D$10 -> 0 | M11: =사업계획!N18*$C$10*$D$10 -> 0 | N11: =사업계획!O18*$C$10*$D$10 -> 0 | O11: =사업계획!P18*$C$10*$D$10 -> 0 | P11: =사업계획!Q18*$C$10*$D$10 -> 0 | Q11: =SUM(E11:P11) -> 0
A12: PSA W1 SDN | B12: EBB00416AC | C12: =VLOOKUP(B:B,'판매가,매입가'!B:H,7,0) -> 0.61 | D12: 0 | E12: =사업계획!F19*$C$12*$D$12 -> 0 | F12: =사업계획!G19*$C$12*$D$12 -> 0 | G12: =사업계획!H19*$C$12*$D$12 -> 0 | H12: =사업계획!I19*$C$12*$D$12 -> 0 | I12: =사업계획!J19*$C$12*$D$12 -> 0 | J12: =사업계획!K19*$C$12*$D$12 -> 0 | K12: =사업계획!L19*$C$12*$D$12 -> 0 | L12: =사업계획!M19*$C$12*$D$12 -> 0 | ... P12: =사업계획!Q19*$C$12*$D$12 -> 0 | Q12: =SUM(E12:P12) -> 0
A13: PSA W1 SUV | B13: EBB00418AC | C13: =VLOOKUP(B:B,'판매가,매입가'!B:H,7,0) -> 3.41 | D13: 0.033 | E13: =사업계획!F20*$C$13*$D$13 -> 112.53 | F13: =사업계획!G20*$C$13*$D$13 -> 0 | G13: =사업계획!H20*$C$13*$D$13 -> 0 | H13: =사업계획!I20*$C$13*$D$13 -> 0 | I13: =사업계획!J20*$C$13*$D$13 -> 202.554 | J13: =사업계획!K20*$C$13*$D$13 -> 202.554 | K13: =사업계획!L20*$C$13*$D$13 -> 202.554 | L13: =사업계획!M20*$C$13*$D$13 -> 202.554 | ... P13: =사업계획!Q20*$C$13*$D$13 -> 202.554 | Q13: =SUM(E13:P13) -> 1732.962
A14: PSA W1 SUV | B14: EBB00420AD | C14: =VLOOKUP(B:B,'판매가,매입가'!B:H,7,0) -> 6.95 | D14: 0.033 | E14: =사업계획!F21*$C$14*$D$14 -> 229.35 | F14: =사업계획!G21*$C$14*$D$14 -> 263.7525 | G14: =사업계획!H21*$C$14*$D$14 -> 0 | H14: =사업계획!I21*$C$14*$D$14 -> 0 | I14: =사업계획!J21*$C$14*$D$14 -> 412.83 | J14: =사업계획!K21*$C$14*$D$14 -> 412.83 | K14: =사업계획!L21*$C$14*$D$14 -> 412.83 | L14: =사업계획!M21*$C$14*$D$14 -> 412.83 | ... P14: =사업계획!Q21*$C$14*$D$14 -> 412.83 | Q14: =SUM(E14:P14) -> 3795.7425
A15: PSA W1 SUV | B15: EBB00422AD | C15: =VLOOKUP(B:B,'판매가,매입가'!B:H,7,0) -> 4.79 | D15: 0.033 | E15: =사업계획!F22*$C$15*$D$15 -> 158.07 | F15: =사업계획!G22*$C$15*$D$15 -> 158.07 | G15: =사업계획!H22*$C$15*$D$15 -> 0 | H15: =사업계획!I22*$C$15*$D$15 -> 0 | I15: =사업계획!J22*$C$15*$D$15 -> 284.526 | J15: =사업계획!K22*$C$15*$D$15 -> 284.526 | K15: =사업계획!L22*$C$15*$D$15 -> 284.526 | L15: =사업계획!M22*$C$15*$D$15 -> 284.526 | ... P15: =사업계획!Q22*$C$15*$D$15 -> 284.526 | Q15: =SUM(E15:P15) -> 2592.348
A16: PSA W1 SUV | B16: ECW01190AD | C16: =VLOOKUP(B:B,'판매가,매입가'!B:H,7,0) -> 157.04 | D16: 0.037 | E16: =사업계획!F23*$C$16*$D$16 -> 11992.831 | F16: =사업계획!G23*$C$16*$D$16 -> 13991.636 | G16: =사업계획!H23*$C$16*$D$16 -> 14991.038 | H16: =사업계획!I23*$C$16*$D$16 -> 14991.038 | I16: =사업계획!J23*$C$16*$D$16 -> 14991.038 | J16: =사업계획!K23*$C$16*$D$16 -> 19988.051 | K16: =사업계획!L23*$C$16*$D$16 -> 14991.038 | L16: =사업계획!M23*$C$16*$D$16 -> 26983.869 | ... P16: =사업계획!Q23*$C$16*$D$16 -> 6995.8179 | Q16: =SUM(E16:P16) -> 184889.47
A17: PSA W1 SUV | B17: EEA00306AC | C17: =VLOOKUP(B:B,'판매가,매입가'!B:H,7,0) -> 24.12 | D17: 0.023 | E17: =사업계획!F24*$C$17*$D$17 -> 1091.7677 | F17: =사업계획!G24*$C$17*$D$17 -> 532.5696 | G17: =사업계획!H24*$C$17*$D$17 -> 517.03632 | H17: =사업계획!I24*$C$17*$D$17 -> 0 | I17: =사업계획!J24*$C$17*$D$17 -> 998.568 | J17: =사업계획!K24*$C$17*$D$17 -> 998.568 | K17: =사업계획!L24*$C$17*$D$17 -> 998.568 | L17: =사업계획!M24*$C$17*$D$17 -> 998.568 | ... P17: =사업계획!Q24*$C$17*$D$17 -> 998.568 | Q17: =SUM(E17:P17) -> 10129.918
A18: PSA W1 SUV | B18: EEA00308AF | C18: =VLOOKUP(B:B,'판매가,매입가'!B:H,7,0) -> 141.68 | D18: 0.017 | E18: =사업계획!F25*$C$18*$D$18 -> 4812.3029 | F18: =사업계획!G25*$C$18*$D$18 -> 5289.1978 | G18: =사업계획!H25*$C$18*$D$18 -> 5780.544 | H18: =사업계획!I25*$C$18*$D$18 -> 7071.5322 | I18: =사업계획!J25*$C$18*$D$18 -> 0 | J18: =사업계획!K25*$C$18*$D$18 -> 4335.408 | K18: =사업계획!L25*$C$18*$D$18 -> 4335.408 | L18: =사업계획!M25*$C$18*$D$18 -> 4335.408 | ... P18: =사업계획!Q25*$C$18*$D$18 -> 4335.408 | Q18: =SUM(E18:P18) -> 53301.433
A19: PSA W1 SUV | B19: EBB00416AC | C19: =VLOOKUP(B:B,'판매가,매입가'!B:H,7,0) -> 0.61 | D19: 0 | E19: =사업계획!F26*$C$19*$D$19 -> 0 | F19: =사업계획!G26*$C$19*$D$19 -> 0 | G19: =사업계획!H26*$C$19*$D$19 -> 0 | H19: =사업계획!I26*$C$19*$D$19 -> 0 | I19: =사업계획!J26*$C$19*$D$19 -> 0 | J19: =사업계획!K26*$C$19*$D$19 -> 0 | K19: =사업계획!L26*$C$19*$D$19 -> 0 | L19: =사업계획!M26*$C$19*$D$19 -> 0 | ... P19: =사업계획!Q26*$C$19*$D$19 -> 0 | Q19: =SUM(E19:P19) -> 0
A20: EV2020 | B20: MFR01053AD | C20: =VLOOKUP(B:B,'판매가,매입가'!B:H,7,0) -> 6.97 | D20: 0.027 | E20: =사업계획!F28*$C$20*$D$20 -> 8500.5423 | F20: =사업계획!G28*$C$20*$D$20 -> 11462.841 | G20: =사업계획!H28*$C$20*$D$20 -> 11688.857 | H20: =사업계획!I28*$C$20*$D$20 -> 11698.267 | I20: =사업계획!J28*$C$20*$D$20 -> 14816.011 | J20: =사업계획!K28*$C$20*$D$20 -> 10360.8 | K20: =사업계획!L28*$C$20*$D$20 -> 8326.2784 | L20: =사업계획!M28*$C$20*$D$20 -> 9852.1229 | ... P20: =사업계획!Q28*$C$20*$D$20 -> 5457.51 | Q20: =SUM(E20:P20) -> 113199.67
A21: EV2020 | B21: MFR01055AC | C21: =VLOOKUP(B:B,'판매가,매입가'!B:H,7,0) -> 9.45 | D21: 0.027 | E21: =사업계획!F28*$C$21*$D$21 -> 11525.125 | F21: =사업계획!G28*$C$21*$D$21 -> 15541.442 | G21: =사업계획!H28*$C$21*$D$21 -> 15847.877 | H21: =사업계획!I28*$C$21*$D$21 -> 15860.634 | I21: =사업계획!J28*$C$21*$D$21 -> 20087.704 | J21: =사업계획!K28*$C$21*$D$21 -> 14047.283 | K21: =사업계획!L28*$C$21*$D$21 -> 11288.857 | L21: =사업계획!M28*$C$21*$D$21 -> 13357.613 | ... P21: =사업계획!Q28*$C$21*$D$21 -> 7399.35 | Q21: =SUM(E21:P21) -> 153477.32
A22: BMW | B22: ECW01550AF | C22: =VLOOKUP(B:B,'판매가,매입가'!B:H,7,0) -> 6.11 | D22: 0.037 | E22: =사업계획!F29*$C$22*$D$22 -> 203.463 | F22: =사업계획!G29*$C$22*$D$22 -> 271.284 | G22: =사업계획!H29*$C$22*$D$22 -> 316.498 | H22: =사업계획!I29*$C$22*$D$22 -> 271.284 | I22: =사업계획!J29*$C$22*$D$22 -> 203.463 | J22: =사업계획!K29*$C$22*$D$22 -> 293.891 | K22: =사업계획!L29*$C$22*$D$22 -> 226.07 | L22: =사업계획!M29*$C$22*$D$22 -> 339.105 | ... P22: =사업계획!Q29*$C$22*$D$22 -> 271.284 | Q22: =SUM(E22:P22) -> 3210.194
A25: PSA W1 SDN | B25: EBB00412AC(SDN) | E25: =E2*1.1 -> 0 | F25: =F2*1.1 -> 0 | G25: =G2*1.1 -> 92.565 | H25: =H2*1.1 -> 0 | I25: =I2*1.1 -> 0 | J25: =J2*1.1 -> 0 | K25: =K2*1.1 -> 0 | L25: =L2*1.1 -> 0 | ... P25: =P2*1.1 -> 0 | Q25: =SUM(E25:P25) -> 92.565
A26: PSA W1 SDN | B26: EBB00414AE(SDN) | E26: =E3*1.1 -> 0 | F26: =F3*1.1 -> 0 | G26: =G3*1.1 -> 179.685 | H26: =H3*1.1 -> 179.685 | I26: =I3*1.1 -> 0 | J26: =J3*1.1 -> 0 | K26: =K3*1.1 -> 0 | L26: =L3*1.1 -> 0 | ... P26: =P3*1.1 -> 0 | Q26: =SUM(E26:P26) -> 359.37
A27: PSA W1 SDN | B27: ECW01188AD(SDN) | E27: =E4*1.1 -> 1343.3149 | F27: =F4*1.1 -> 1567.2007 | G27: =G4*1.1 -> 1679.1436 | H27: =H4*1.1 -> 1679.1436 | I27: =I4*1.1 -> 1679.1436 | J27: =J4*1.1 -> 0 | K27: =K4*1.1 -> 0 | L27: =L4*1.1 -> 0 | ... P27: =P4*1.1 -> 0 | Q27: =SUM(E27:P27) -> 7947.9465
A28: PSA W1 SDN | B28: EEA00306AC(SDN) | E28: =E5*1.1 -> 0 | F28: =F5*1.1 -> 0 | G28: =G5*1.1 -> 0 | H28: =H5*1.1 -> 0 | I28: =I5*1.1 -> 0 | J28: =J5*1.1 -> 0 | K28: =K5*1.1 -> 0 | L28: =L5*1.1 -> 0 | ... P28: =P5*1.1 -> 0 | Q28: =SUM(E28:P28) -> 0
A29: PSA W1 SDN | B29: EEA00308AF(SDN) | E29: =E6*1.1 -> 0 | F29: =F6*1.1 -> 0 | G29: =G6*1.1 -> 0 | H29: =H6*1.1 -> 0 | I29: =I6*1.1 -> 0 | J29: =J6*1.1 -> 0 | K29: =K6*1.1 -> 0 | L29: =L6*1.1 -> 0 | ... P29: =P6*1.1 -> 0 | Q29: =SUM(E29:P29) -> 0
A30: PSA W1 SDN | B30: EBB00412AC(SDN)RE | E30: =E7*1.1 -> 0 | F30: =F7*1.1 -> 0 | G30: =G7*1.1 -> 0 | H30: =H7*1.1 -> 0 | I30: =I7*1.1 -> 0 | J30: =J7*1.1 -> 0 | K30: =K7*1.1 -> 0 | L30: =L7*1.1 -> 0 | ... P30: =P7*1.1 -> 0 | Q30: =SUM(E30:P30) -> 0 | R30: 무관세
A31: PSA W1 SDN | B31: EBB00414AE(SDN)RE | E31: =E8*1.1 -> 0 | F31: =F8*1.1 -> 0 | G31: =G8*1.1 -> 0 | H31: =H8*1.1 -> 0 | I31: =I8*1.1 -> 0 | J31: =J8*1.1 -> 0 | K31: =K8*1.1 -> 0 | L31: =L8*1.1 -> 0 | ... P31: =P8*1.1 -> 0 | Q31: =SUM(E31:P31) -> 0
A32: PSA W1 SDN | B32: ECW01188AD(SDN)RE | E32: =E9*1.1 -> 0 | F32: =F9*1.1 -> 0 | G32: =G9*1.1 -> 0 | H32: =H9*1.1 -> 0 | I32: =I9*1.1 -> 0 | J32: =J9*1.1 -> 3868.7311 | K32: =K9*1.1 -> 2901.5484 | L32: =L9*1.1 -> 5222.787 | ... P32: =P9*1.1 -> 1354.0559 | Q32: =SUM(E32:P32) -> 22051.767
A33: PSA W1 SDN | B33: EEA00306AC(SDN)RE | E33: =E10*1.1 -> 0 | F33: =F10*1.1 -> 0 | G33: =G10*1.1 -> 0 | H33: =H10*1.1 -> 0 | I33: =I10*1.1 -> 0 | J33: =J10*1.1 -> 0 | K33: =K10*1.1 -> 0 | L33: =L10*1.1 -> 0 | ... P33: =P10*1.1 -> 0 | Q33: =SUM(E33:P33) -> 0
A34: PSA W1 SDN | B34: EEA00308AF(SDN)RE | E34: =E11*1.1 -> 0 | F34: =F11*1.1 -> 0 | G34: =G11*1.1 -> 0 | H34: =H11*1.1 -> 0 | I34: =I11*1.1 -> 0 | J34: =J11*1.1 -> 0 | K34: =K11*1.1 -> 0 | L34: =L11*1.1 -> 0 | ... P34: =P11*1.1 -> 0 | Q34: =SUM(E34:P34) -> 0
A35: PSA W1 SDN | B35: EBB00416AC | E35: =E12*1.1 -> 0 | F35: =F12*1.1 -> 0 | G35: =G12*1.1 -> 0 | H35: =H12*1.1 -> 0 | I35: =I12*1.1 -> 0 | J35: =J12*1.1 -> 0 | K35: =K12*1.1 -> 0 | L35: =L12*1.1 -> 0 | ... P35: =P12*1.1 -> 0 | Q35: =SUM(E35:P35) -> 0 | R35: 무관세
A36: PSA W1 SUV | B36: EBB00418AC | E36: =E13*1.1 -> 123.783 | F36: =F13*1.1 -> 0 | G36: =G13*1.1 -> 0 | H36: =H13*1.1 -> 0 | I36: =I13*1.1 -> 222.8094 | J36: =J13*1.1 -> 222.8094 | K36: =K13*1.1 -> 222.8094 | L36: =L13*1.1 -> 222.8094 | ... P36: =P13*1.1 -> 222.8094 | Q36: =SUM(E36:P36) -> 1906.2582
A37: PSA W1 SUV | B37: EBB00420AD | E37: =E14*1.1 -> 252.285 | F37: =F14*1.1 -> 290.12775 | G37: =G14*1.1 -> 0 | H37: =H14*1.1 -> 0 | I37: =I14*1.1 -> 454.113 | J37: =J14*1.1 -> 454.113 | K37: =K14*1.1 -> 454.113 | L37: =L14*1.1 -> 454.113 | ... P37: =P14*1.1 -> 454.113 | Q37: =SUM(E37:P37) -> 4175.3168
A38: PSA W1 SUV | B38: EBB00422AD | E38: =E15*1.1 -> 173.877 | F38: =F15*1.1 -> 173.877 | G38: =G15*1.1 -> 0 | H38: =H15*1.1 -> 0 | I38: =I15*1.1 -> 312.9786 | J38: =J15*1.1 -> 312.9786 | K38: =K15*1.1 -> 312.9786 | L38: =L15*1.1 -> 312.9786 | ... P38: =P15*1.1 -> 312.9786 | Q38: =SUM(E38:P38) -> 2851.5828
A39: PSA W1 SUV | B39: ECW01190AD | E39: =E16*1.1 -> 13192.114 | F39: =F16*1.1 -> 15390.799 | G39: =G16*1.1 -> 16490.142 | H39: =H16*1.1 -> 16490.142 | I39: =I16*1.1 -> 16490.142 | J39: =J16*1.1 -> 21986.856 | K39: =K16*1.1 -> 16490.142 | L39: =L16*1.1 -> 29682.256 | ... P39: =P16*1.1 -> 7695.3997 | Q39: =SUM(E39:P39) -> 203378.42
A40: PSA W1 SUV | B40: EEA00306AC | E40: =E17*1.1 -> 1200.9444 | F40: =F17*1.1 -> 585.82656 | G40: =G17*1.1 -> 568.73995 | H40: =H17*1.1 -> 0 | I40: =I17*1.1 -> 1098.4248 | J40: =J17*1.1 -> 1098.4248 | K40: =K17*1.1 -> 1098.4248 | L40: =L17*1.1 -> 1098.4248 | ... P40: =P17*1.1 -> 1098.4248 | Q40: =SUM(E40:P40) -> 11142.909
A41: PSA W1 SUV | B41: EEA00308AF | E41: =E18*1.1 -> 5293.5332 | F41: =F18*1.1 -> 5818.1175 | G41: =G18*1.1 -> 6358.5984 | H41: =H18*1.1 -> 7778.6854 | I41: =I18*1.1 -> 0 | J41: =J18*1.1 -> 4768.9488 | K41: =K18*1.1 -> 4768.9488 | L41: =L18*1.1 -> 4768.9488 | ... P41: =P18*1.1 -> 4768.9488 | Q41: =SUM(E41:P41) -> 58631.576
A42: PSA W1 SUV | B42: EBB00416AC | E42: =E19*1.1 -> 0 | F42: =F19*1.1 -> 0 | G42: =G19*1.1 -> 0 | H42: =H19*1.1 -> 0 | I42: =I19*1.1 -> 0 | J42: =J19*1.1 -> 0 | K42: =K19*1.1 -> 0 | L42: =L19*1.1 -> 0 | ... P42: =P19*1.1 -> 0 | Q42: =SUM(E42:P42) -> 0 | R42: 무관세
...

Sheet 판매가,매입가
A2: 아이템 | B2: 품번(옵션) | C2: 2025Y판가(EUR) (4Q) | D2: 2026Y판가(EUR) | E2: 증감 | F2: 증감율 | G2: 2025Y매입가 (4Q) | H2: 2026Y매입가(USD) | I2: 증감 | J2: 증감율 | K2: 비고 | M2: 환율
A3: BDU_ASSY | B3: EEA00308AF(SDN) | C3: 106.61 | D3: 106.61 | E3: =D3-C3 -> 0 | F3: =D3/C3 -> 1 | G3: 114.58 | H3: =G3 -> 114.58 | I3: =H3-G3 -> 0 | J3: =H3/G3 -> 1 | M3: KWR/USD | N3: 1350
A4: FUSE_BOX_ASSY | B4: EEA00306AC(SDN) | C4: 18.46 | D4: 18.46 | E4: =D4-C4 -> 0 | F4: =D4/C4 -> 1 | G4: 19.51 | H4: =G4 -> 19.51 | I4: =H4-G4 -> 0 | J4: =H4/G4 -> 1 | M4: KWD/EUR | N4: 1600
A5: INTER_BUSBAR_ASSY | B5: EBB00416AC | C5: 0.56 | D5: 0.56 | E5: =D5-C5 -> 0 | F5: =D5/C5 -> 1 | G5: 0.61 | H5: =G5 -> 0.61 | I5: =H5-G5 -> 0 | J5: =H5/G5 -> 1
A6: Wiring Harness Ass'y_SDN | B6: ECW01188AD(SDN) | C6: 85.86 | D6: 85.86 | E6: =D6-C6 -> 0 | F6: =D6/C6 -> 1 | G6: 98.23 | H6: =G6 -> 98.23 | I6: =H6-G6 -> 0 | J6: =H6/G6 -> 1 | M6: PLN/USD | N6: 3.6
A7: Flexible Busbar (CMA1_to_BDU_NEG ASM) | B7: EBB00412AC(SDN) | C7: 2.35 | D7: 2.35 | E7: =D7-C7 -> 0 | F7: =D7/C7 -> 1 | G7: 2.55 | H7: =G7 -> 2.55 | I7: =H7-G7 -> 0 | J7: =H7/G7 -> 1 | M7: PLN/EUR | N7: 4.2
A8: Flexible Busbar (CMA6 to BDU POS ASM) | B8: EBB00414AE(SDN) | C8: 7.68 | D8: 7.68 | E8: =D8-C8 -> 0 | F8: =D8/C8 -> 1 | G8: 8.25 | H8: =G8 -> 8.25 | I8: =H8-G8 -> 0 | J8: =H8/G8 -> 1 | M8: KWR/PLN | N8: 385
A9: BDU_ASSY | B9: EEA00308AF(SDN)RE | C9: 106.61 | D9: 156.75 | E9: =D9-C9 -> 50.14 | F9: =D9/C9 -> 1.4703124 | G9: 114.58 | H9: =H15 -> 141.68 | I9: =H9-G9 -> 27.1 | J9: =H9/G9 -> 1.236516 | K9: AS단가(6월부터)
A10: FUSE_BOX_ASSY | B10: EEA00306AC(SDN)RE | C10: 18.46 | D10: 27.14 | E10: =D10-C10 -> 8.68 | F10: =D10/C10 -> 1.4702059 | G10: 19.51 | H10: =H16 -> 24.12 | I10: =H10-G10 -> 4.61 | J10: =H10/G10 -> 1.2362891 | K10: AS단가(6월부터)
A11: INTER_BUSBAR_ASSY | B11: EBB00416AC | C11: 0.56 | D11: 0.56 | E11: =D11-C11 -> 0 | F11: =D11/C11 -> 1 | G11: 0.61 | H11: =G11*F11 -> 0.61 | I11: =H11-G11 -> 0 | J11: =H11/G11 -> 1
A12: Wiring Harness Ass'y_SDN | B12: ECW01188AD(SDN)RE | C12: 85.86 | D12: 126.26 | E12: =D12-C12 -> 40.4 | F12: =D12/C12 -> 1.4705334 | G12: 98.23 | H12: =G12*J18 -> 169.74075 | I12: =H12-G12 -> 71.510748 | J12: =H12/G12 -> 1.727993 | K12: AS단가(6월부터)
A13: Flexible Busbar (CMA1_to_BDU_NEG ASM) | B13: EBB00412AC(SDN)RE | C13: 2.35 | D13: 3.46 | E13: =D13-C13 -> 1.11 | F13: =D13/C13 -> 1.4723404 | G13: 2.55 | H13: =G13*J20 -> 3.1534698 | I13: =H13-G13 -> 0.60346975 | J13: =H13/G13 -> 1.2366548 | K13: AS단가(6월부터)
A14: Flexible Busbar (CMA6 to BDU POS ASM) | B14: EBB00414AE(SDN)RE | C14: 7.68 | D14: 11.29 | E14: =D14-C14 -> 3.61 | F14: =D14/C14 -> 1.4700521 | G14: 8.25 | H14: =G14*J20 -> 10.202402 | I14: =H14-G14 -> 1.9524021 | J14: =H14/G14 -> 1.2366548 | K14: AS단가(6월부터)
A15: BDU_ASSY | B15: EEA00308AF | C15: 106.61 | D15: 156.75 | E15: =D15-C15 -> 50.14 | F15: =D15/C15 -> 1.4703124 | G15: 114.58 | H15: 141.68 | I15: =H15-G15 -> 27.1 | J15: =H15/G15 -> 1.236516 | K15: AS단가
A16: FUSE_BOX_ASSY | B16: EEA00306AC | C16: 18.46 | D16: 27.14 | E16: =D16-C16 -> 8.68 | F16: =D16/C16 -> 1.4702059 | G16: 19.51 | H16: 24.12 | I16: =H16-G16 -> 4.61 | J16: =H16/G16 -> 1.2362891 | K16: AS단가
A17: INTER_BUSBAR_ASSY | B17: EBB00416AC | C17: 0.56 | D17: 0.56 | E17: =D17-C17 -> 0 | F17: =D17/C17 -> 1 | G17: 0.61 | H17: =G17 -> 0.61 | I17: =H17-G17 -> 0 | J17: =H17/G17 -> 1
A18: Wiring Harness Ass'y_SUV | B18: ECW01190AD | C18: 79.7 | D18: 117.2 | E18: =D18-C18 -> 37.5 | F18: =D18/C18 -> 1.4705144 | G18: 90.88 | H18: 157.04 | I18: =H18-G18 -> 66.16 | J18: =H18/G18 -> 1.727993 | K18: AS단가
A19: Flexible Busbar (CMA1 to BDU NEG ASM) | B19: EBB00418AC | C19: 2.54 | D19: 3.74 | E19: =D19-C19 -> 1.2 | F19: =D19/C19 -> 1.4724409 | G19: 2.76 | H19: 3.41 | I19: =H19-G19 -> 0.65 | J19: =H19/G19 -> 1.2355072 | K19: AS단가
A20: Flexible Busbar (CMA7 to BDU POS ASM) | B20: EBB00420AD | C20: 5.24 | D20: 7.71 | E20: =D20-C20 -> 2.47 | F20: =D20/C20 -> 1.471374 | G20: 5.62 | H20: 6.95 | I20: =H20-G20 -> 1.33 | J20: =H20/G20 -> 1.2366548 | K20: AS단가
A21: Flexible Busbar (CMA6 to CMA7 ASM) | B21: EBB00422AD | C21: 3.61 | D21: 5.31 | E21: =D21-C21 -> 1.7 | F21: =D21/C21 -> 1.4709141 | G21: 3.87 | H21: 4.79 | I21: =H21-G21 -> 0.92 | J21: =H21/G21 -> 1.2377261 | K21: AS단가
A22: FUSE_BOX_ASSY | B22: EEA00379AC | C22: 15.62 | D22: 15.62 | E22: =D22-C22 -> 0 | F22: =D22/C22 -> 1 | G22: 17.82 | H22: =G22 -> 17.82 | I22: =H22-G22 -> 0 | J22: =H22/G22 -> 1
A23: F_BBAR_MD4_POS | B23: EBB00689AB | C23: 4.06 | D23: 4.06 | E23: =D23-C23 -> 0 | F23: =D23/C23 -> 1 | G23: 4.39 | H23: =G23 -> 4.39 | I23: =H23-G23 -> 0 | J23: =H23/G23 -> 1
A24: F_BBAR_MD1_BNEG | B24: EBB00539AD | C24: 4.98 | D24: 4.98 | E24: =D24-C24 -> 0 | F24: =D24/C24 -> 1 | G24: 5.4 | H24: =G24 -> 5.4 | I24: =H24-G24 -> 0 | J24: =H24/G24 -> 1
A25: F_BBAR_MD6_BPOS | B25: EBB00540AD | C25: 3.64 | D25: 3.64 | E25: =D25-C25 -> 0 | F25: =D25/C25 -> 1 | G25: 3.93 | H25: =G25 -> 3.93 | I25: =H25-G25 -> 0 | J25: =H25/G25 -> 1
A26: C_BLOCK_WH_ASSY (와이어링) | B26: EEA00376AD | C26: 71.13 | D26: 71.13 | E26: =D26-C26 -> 0 | F26: =D26/C26 -> 1 | G26: 81.19 | H26: =G26 -> 81.19 | I26: =H26-G26 -> 0 | J26: =H26/G26 -> 1
A27: INTER BUSBAR ASSY | B27: EBB00416AC | C27: 0.56 | D27: 0.56 | E27: =D27-C27 -> 0 | F27: =D27/C27 -> 1 | G27: 0.61 | H27: =G27 -> 0.61 | I27: =H27-G27 -> 0 | J27: =H27/G27 -> 1
A28: INTER BUSBAR ASSY_LONG | B28: EEA00373AB | C28: 0.56 | D28: 0.56 | E28: =D28-C28 -> 0 | F28: =D28/C28 -> 1 | G28: 0.63 | H28: =G28 -> 0.63 | I28: =H28-G28 -> 0 | J28: =H28/G28 -> 1
A29: HOUSING UNIT | B29: MHU00264AE | C29: 10.02 | D29: 10.02 | E29: =D29-C29 -> 0 | F29: =D29/C29 -> 1 | G29: 11.43 | H29: =G29 -> 11.43 | I29: =H29-G29 -> 0 | J29: =H29/G29 -> 1
A30: CABLE ASSY PIM TO P1 CONNECTOR | B30: EEA00383AI | C30: 37.38 | D30: 37.38 | E30: =D30-C30 -> 0 | F30: =D30/C30 -> 1 | G30: 34.99 | H30: =G30 -> 34.99 | I30: =H30-G30 -> 0 | J30: =H30/G30 -> 1
A31: W-CABLE-PIM TO P4 CONNECTOR ASSEMBLY | B31: ECW01503AM | C31: 4.66 | D31: 4.66 | E31: =D31-C31 -> 0 | F31: =D31/C31 -> 1 | G31: 5.4 | H31: =G31 -> 5.4 | I31: =H31-G31 -> 0 | J31: =H31/G31 -> 1
A32: V-CABLE-PIM TO P4 CONNECTOR ASSEMBLY | B32: ECW01504AM | C32: 4.46 | D32: 4.46 | E32: =D32-C32 -> 0 | F32: =D32/C32 -> 1 | G32: 5.25 | H32: =G32 -> 5.25 | I32: =H32-G32 -> 0 | J32: =H32/G32 -> 1
A33: U-CABLE-PIM TO P4 CONNECTOR ASSEMBLY | B33: ECW01505AM | C33: 4.36 | D33: 4.36 | E33: =D33-C33 -> 0 | F33: =D33/C33 -> 1 | G33: 5.14 | H33: =G33 -> 5.14 | I33: =H33-G33 -> 0 | J33: =H33/G33 -> 1
A34: CABLE-PIM_POS_NEG_TO_BDU_POS_NEG | B34: EEA00415AH | C34: 16.09 | D34: 16.09 | E34: =D34-C34 -> 0 | F34: =D34/C34 -> 1 | G34: 16.12 | H34: =G34 -> 16.12 | I34: =H34-G34 -> 0 | J34: =H34/G34 -> 1
A35: FRAME ASSY REAR | B35: MFR01053AD | C35: 7.59 | D35: 7.14 | E35: =D35-C35 -> -0.45 | F35: =D35/C35 -> 0.94071146 | G35: 7.41 | H35: 6.97 | I35: =H35-G35 -> -0.44 | J35: =H35/G35 -> 0.94062078
A36: FRAME ASSY FRONT | B36: MFR01055AC | C36: 10.28 | D36: 9.69 | E36: =D36-C36 -> -0.59 | F36: =D36/C36 -> 0.942607 | G36: 10.03 | H36: 9.45 | I36: =H36-G36 -> -0.58 | J36: =H36/G36 -> 0.94217348
A37: HAF WIRING HARNESS | B37: ECW01550AF | C37: 6.59 | D37: 6.38 | E37: =D37-C37 -> -0.21 | F37: =D37/C37 -> 0.96813354 | G37: 6.31 | H37: 6.11 | I37: =H37-G37 -> -0.2 | J37: =H37/G37 -> 0.96830428
